Workbook
Name Banco_Tipologias: Banco_Tipologias!$C$4:$N$17
Name colunaclasses: Simulações!$BS$2:$BS$25
Name ilumatic: '[1]Banco de dados (2)'!#REF!
Name ilumatic: 'Banco de dados'!#REF!
Name philips: '[1]Banco de dados (2)'!#REF!
Name philips: 'Banco de dados'!#REF!
Name red_global: '[1]Banco de dados (2)'!#REF!
Name red_global: 'Banco de dados'!#REF!
Name red_juganu: '[1]Banco de dados (2)'!#REF!
Name red_juganu: 'Banco de dados'!#REF!
Name red_philips: '[1]Banco de dados (2)'!#REF!
Name red_philips: 'Banco de dados'!#REF!
Name red_repume: '[1]Banco de dados (2)'!#REF!
Name red_repume: 'Banco de dados'!#REF!
Name red_tecno: '[1]Banco de dados (2)'!#REF!
Name red_tecno: 'Banco de dados'!#REF!
Name redglobal: '[1]Banco de dados (2)'!#REF!
Name redglobal: 'Banco de dados'!#REF!
Name tecnowat: '[1]Banco de dados (2)'!#REF!
Name tecnowat: 'Banco de dados'!#REF!

Sheet DefiniçãoFornecedores
D2: Estruturas
B3: Definição | D3: V1 | E3: V2 | F3: V3 | G3: V4 | H3: V5 | I3: Observação
B4: Fornecedor L1 | C4: Conexled | D4: 0 | E4: 0 | F4: 0 | G4: 0 | H4: 0 | I4: Não possui orçamento
B5: Fornecedor L2 | C5: Ilumatic | D5: 0 | E5: 0 | F5: 0 | G5: 0 | H5: 0 | I5: Não possui orçamento
B6: Fornecedor L3 | C6: Juganu | D6: 0 | E6: 0 | F6: 0 | G6: 0 | H6: 0 | I6: Possui orçamento, definir qual classe melhor atende
B7: Fornecedor L4 | C7: Philips | D7: 1 | E7: 1 | F7: 1 | G7: 1 | H7: 1 | I7: Não possui orçamento
B8: Fornecedor L5 | C8: Repume | D8: 0 | E8: 0 | F8: 0 | G8: 0 | H8: 0 | I8: Não possui orçamento
B9: Fornecedor L6 | C9: Tecnowatt | D9: 1 | E9: 1 | F9: 1 | G9: 1 | H9: 1 | I9: Possui orçamento, definir qual classe melhor atende
B10: Fornecedor L7 | C10: Unicoba | D10: 1 | E10: 1 | F10: 1 | G10: 1 | H10: 1 | I10: Possui orçamento, definir qual classe melhor atende
B11: Fornecedor L8 | C11: SX Lighting | D11: 0 | E11: 0 | F11: 0 | G11: 0 | H11: 0 | I11: Não possui orçamento

Sheet Simulações
A1: Observações | B1: Estrutura | C1: Concluído estrutura | D1: Simulação | E1: Concluído simulação | F1: ID | G1: Padrão | H1: Logradouro | I1: latitude | J1: longitude | K1: Classificação viária (Análise do Cadastro) | L1: Classificação ciclovia | M1: Classificação pedonal | N1: Tipo de lâmpada | O1: Potencia da lâmpada | P1: Potência Reator | Q1: Potencia 2o nivel | R1: POT TOTAL MALHA | S1: Faixas de Rodagem via C | T1: Largura Passeio 1 | U1: Largura Via 1 | V1: largura Passeio Central 1 | W1: largura Passeio Central 2 | X1: Largura Via 2 | Y1: largura Passeio 2 | Z1: largura Canteiro Central | AA1: largura Ciclovia 1 | AB1: largura Ciclovia 2 | AC1: estacionamento 1 | AD1: estacionamento 2 | AE1: posteacao | AF1: Tipo de estrutura | AG1: Distância entre postes | AH1: Altura da luminária | AI1: qtd de Lampadas IP Princ | AJ1: distancia Poste a via | AK1: projecao do braço | AL1: Pendor | AM1: Altura de Instalação | AN1: Projeção Vertical | AO1: Exclusivo | AP1: Quantidade de pontos inspecionados IP Veic | AQ1: qtd de Lampadas IP 2o nivel | AR1: Tipo de posteação 2o nivel | AS1: Distanciamento 2o nivel | AT1: Altura da luminaria 2o nivel | AU1: Projecao 2o nivel | AV1: Distancia poste-via 2o nivel | AW1: Quantidade de pontos inspecionados IP Sec | AX1: informacoes Adicionais | AY1: Emed - Norma | AZ1: U - Norma | BA1: Luminância Média Exigida | BB1: Uo Uniformidade Global Exigida | BC1: Uniformidade Longitudinal Exigida | BD1: Incremento Linear Exigido | BE1: Atendimento pleno à norma | BF1: Excesso de iluminância média IV | BG1: Excesso de Uniformidade IV | BH1: Excesso de luminância média IV | BI1: Iluminância Média | BJ1: Fator de Uniformidade | BK1: Luminância Média | BL1: Uniformidade Longitudinal | BM1: Incremento Linear (TI) | BN1: EIR | BO1: ATENDE TUDO - RUA SIMU | BP1: Atende à Iluminância Média | BQ1: Atende à Uniformidade Global Miníma | BR1: Atende à Luminância Média | BS1: Classe IV | BT1: Classe IP | BU1: Excesso de iluminância média P1 | BV1: Iluminância Média | BW1: Iluminância mínima horizontal E (lux) | BX1: Iluminância Média (Exigida) | BY1: Iluminância mínima horizontal E (lux) | BZ1: Atende à NBR 5101 - TUDO SIMU | CA1: Atende à Iluminância Média | CB1: Atende à Iluminância mínima horizontal | CC1: Classe IP | CD1: Excesso de iluminância média P2 | CE1: Iluminância Média | CF1: Iluminância mínima horizontal E (lux) | CG1: Iluminância Média (Exigida) | CH1: Iluminância mínima horizontal E (lux) exigida | CI1: Atende à NBR 5101 - TUDO SIMU P2 | CJ1: Atende à Iluminância Média | CK1: Atende à Iluminância mínima horizontal | CL1: Fornecedor | CM1: Código Luminária 1 | CN1: Luminária Simulada (IP Principal) | CO1: Código Luminária 2 | CP1: Luminária Simulada (IP Secundário) | CQ1: Pontos por poste (IP Principal) | CR1: Potência simulada - IP Principal (W) | CS1: Potência simulada - IP Secundário (W) | CT1: Fluxo Luminoso - IP Principal (lm) | CU1: Fluxo Luminoso - IP Secundário (lm) | CV1: Ângulo antigo | CW1: Ângulo Simulado | CX1: Braço Antigo | CY1: Braço Novo | CZ1: Projeção com alteração | DA1: Altura de luminária com alteração | DB1: Correção de Ponto Escuro (CPE) | DC1: Quantidade de pontos adicionados para via de veículo | DD1: Quantidade de pontos adicionados para via de pedestres | DE1: Observação CPE (Reduçao entre postes e/ou Tipo de Posteação) | DF1: obs conferência | DG1: rev conferência | DH1: IP PRINC SIM | DI1: IP SEC SIM | DJ1: TOTAL SIMULADO | DK1: Eficientização | DL1: Simulação | DM1: Conferência | DN1: Considerar na Extrapolação | DO1: Inspeção | DQ1: eficientização
A2: 0.5 - Projeção do braço segundo nível | B2: Alexandre | C2: ok | D2: Penelope | E2: ok | F2: 219474977 | G2: PVVP | H2: Avenida Caio Martins | I2: -19.565708 | J2: -44.078041 | K2: C1 | M2: P4 | N2: LED | O2: 80 | Q2: 60 | R2: 4 | S2: 2 | T2: 1.7 | U2: 7 | Y2: 1.7 | Z2: (7.5) 2.00 | AC2: 4.5 | AE2: Canteiro central | AF2: Braço | AG2: 37.8 | AH2: 7.8 | AI2: 1 | AJ2: 0.4 | AK2: 2.7 | AL2: =AK2-AJ2 -> 2.3 | AM2: - | AN2: - | AO2: Não | AP2: =IF(AE2="Unilateral",2*AI2,IF(AE2="Bilateral Alternada",3*AI2,IF(AE2="Bilateral Frontal",4*AI2,IF(AE2="Canteiro Central",2*AI2,"erro")))) -> 2 | AQ2: 0 | AR2: 0 | AS2: 0 | AT2: 0 | AU2: 0 | AV2: 0 | AW2: =IF(AQ2=0,0,IF(AE2="Unilateral",2*AQ2,IF(AE2="Bilateral Alternada",3*AQ2,IF(AE2="Bilateral Frontal",4*AQ2,IF(AE2="Canteiro Central",2*AQ2,"erro"))))) -> 0 | AY2: =VLOOKUP(K2,ABNT5101!$I$3:$J$9,2) -> 30 | AZ2: =VLOOKUP(K2,ABNT5101!$I$3:$M$9,5) -> 0.38 | BA2: =_xlfn.XLOOKUP(K2,ABNT5101!$I:$I,ABNT5101!$L:$L) -> - | BB2: =_xlfn.XLOOKUP(K2,ABNT5101!$I:$I,ABNT5101!M:M) -> 0.38 | BC2: =_xlfn.XLOOKUP(K2,ABNT5101!$I:$I,ABNT5101!N:N) -> - | BD2: =_xlfn.XLOOKUP(K2,ABNT5101!$I:$I,ABNT5101!O:O) -> 14 | BE2: =IF(BO2="NÃO ATENDE","NÃO ATENDE",IF(BZ2="NÃO ATENDE","NÃO ATENDE",IF(CI2="NÃO ATENDE","NÃO ATENDE","ATENDE"))) -> ATENDE | BF2: =BI2/AY2-1 -> 0.025 | BG2: =BJ2/AZ2-1 -> 0.42105263 | BH2: =IF($K2="M6",BK2/BA2-1,"-") -> - | BI2: 30.75 | BJ2: 0.54 | BO2: =IF(OR(BP2="NÃO ATENDE",BQ2="NÃO ATENDE",BR2="NÃO ATENDE"),"NÃO ATENDE","ATENDE") -> ATENDE | BP2: =IF(BI2>=AY2,"ATENDE",IF(BI2>=0.99*AY2,"ATENDIMENTO LIMIAR","NÃO ATENDE")) -> ATENDE | BQ2: =IF(BJ2>=AZ2,"ATENDE",IF(BJ2>=(AZ2-0.02),"ATENDIMENTO LIMIAR","NÃO ATENDE")) -> ATENDE | BR2: =IF(BA2="-","ATENDE",IF(BK2>=BA2,"ATENDE",IF(BK2>=(BA2-0.02),"ATENDIMENTO LIMIAR","NÃO ATENDE"))) -> ATENDE | BS2: =K2 -> C1 | BT2: =M2 -> P4 | BU2: =IF(BV2="-","-",BV2/BX2-1) -> 1.1653333 | BV2: 16.24 | BW2: 10.26 | BX2: =IF(BT2="-","-",_xlfn.XLOOKUP(BT2,ABNT5101!$B$4:$B$9,ABNT5101!$C$4:$C$9)) -> 7.5 | BY2: =IF(BT2="-","-",_xlfn.XLOOKUP(BT2,ABNT5101!$B$4:$B$9,ABNT5101!$D$4:$D$9)) -> 1.5 | BZ2: =IF(CA2="-","-",IF(CA2="NÃO ATENDE","NÃO ATENDE",IF(CB2="NÃO ATENDE","NÃO ATENDE","ATENDE"))) -> ATENDE | CA2: =IF(BT2="-","-",IF(BV2>=BX2,"ATENDE",IF(BV2>=(BX2*0.99),"ATENDIMENTO LIMIAR","NÃO ATENDE"))) -> ATENDE | CB2: =IF(BT2="-","-",IF(BW2>=BY2,"ATENDE","NÃO ATENDE")) -> ATENDE | CC2: =BT2 -> P4 | CD2: =IF(CE2="-","-",CE2/CG2-1) -> #DIV/0! | CE2: 16.24 | CF2: 10.28 | CI2: =IF(CJ2="-","-",IF(CJ2="NÃO ATENDE","NÃO ATENDE",IF(CK2="NÃO ATENDE","NÃO ATENDE","ATENDE"))) -> ATENDE | CJ2: =IF(CC2="-","-",IF(CE2>=(CG2),"ATENDE",IF(CE2>=(0.99*CG2),"ATENDIMENTO LIMIAR","NÃO ATENDE"))) -> ATENDE | CK2: =IF(CC2="-","-",IF(CF2>=CH2,"ATENDE","NÃO ATENDE")) -> ATENDE | CL2: =_xlfn.XLOOKUP(CM2,'Banco de dados'!$B:$B,'Banco de dados'!$D:$D) -> LEDSTAR | CM2: ='Banco de dados'!B28 -> SL VT 9.1 100W | CN2: =_xlfn.XLOOKUP(CM2,'Banco de dados'!$B:$B,'Banco de dados'!$E:$E) -> LUM LED SL VT 9.1 100W | CP2: =IF(CO2="-","-",_xlfn.XLOOKUP(CO2,'Banco de dados'!$B:$B,'Banco de dados'!$E:$E)) -> 0 | CQ2: =AI2 -> 1 | CR2: =_xlfn.XLOOKUP(CM2,'Banco de dados'!$B:$B,'Banco de dados'!$H:$H) -> 100 | CS2: =_xlfn.XLOOKUP(CO2,'Banco de dados'!$B:$B,'Banco de dados'!$H:$H) -> 0 | CT2: =_xlfn.XLOOKUP(CM2,'Banco de dados'!$B:$B,'Banco de dados'!$F:$F) -> 15900 | CU2: =_xlfn.XLOOKUP(CO2,'Banco de dados'!$B:$B,'Banco de dados'!$F:$F) -> 0 | CW2: 5 | CX2: =IF(AK2<=0.5,"Curto I",IF(AND(AK2>='Braços de IP'!$B$9,AK2<='Braços de IP'!$D$9),'Braços de IP'!$E$9,IF(AND(AK2>='Braços de IP'!$B$10,AK2<='Braços de IP'!$D$10),'Braços de IP'!$E$10,IF(AND(AK2>='Braços de IP'!$B$11,AK2<='Braços de IP'!$D$11),'Braços de IP'!$E$11,IF(AND(AK2>='Braços de IP'!$B$12,AK2<='Braços de IP'!$D$12),'Braços de IP'!$E$12,IF(AND(AK2>='Braços de IP'!$B$13,AK2<='Braços de IP'!$D$13),'Braços de IP'!$E$13,IF(AND(AK2>='Braços de IP'!$B$14,AK2<='Braços de IP'!$D$14),'Braços de IP'!$E$14,"ERRO"))))))) -> Longo I | CZ2: =IF($CY2="","",VLOOKUP($CY2,'Braços de IP'!$E$9:$I$15,2,0)) | DA2: =IF($CY2="","",VLOOKUP($CY2,'Braços de IP'!$E$9:$I$15,5,0)) | DH2: =CR2 -> 100 | DI2: =O2 -> 80 | DJ2: =SUM(DH2:DI2)*CQ2 -> 180 | DK2: =1-DH2/DI2 -> -0.25 | DN2: Sim | DQ2: =((O2+P2)-CR2)/(O2+P2) -> -0.25
A3: 0.5 - Projeção do braço segundo nível | F3: 219474977 | G3: PVVP | H3: Avenida Caio Martins | I3: -19.565708 | J3: -44.078041 | K3: C1 | M3: P4 | N3: LED | O3: 80 | Q3: 60 | R3: 4 | S3: 2 | T3: 1.7 | U3: 7 | Y3: 1.7 | Z3: (7.5) 2.00 | AC3: 4.5 | AE3: Canteiro central | AF3: Braço | AG3: 37.8 | AH3: 7.8 | AI3: 1 | AJ3: 0.4 | AK3: 2.7 | AL3: =AK3-AJ3 -> 2.3 | AM3: - | AN3: - | AO3: Não | AP3: =IF(AE3="Unilateral",2*AI3,IF(AE3="Bilateral Alternada",3*AI3,IF(AE3="Bilateral Frontal",4*AI3,IF(AE3="Canteiro Central",2*AI3,"erro")))) -> 2 | AQ3: 0 | AR3: 0 | AS3: 0 | AT3: 0 | AU3: 0 | AV3: 0 | AW3: =IF(AQ3=0,0,IF(AE3="Unilateral",2*AQ3,IF(AE3="Bilateral Alternada",3*AQ3,IF(AE3="Bilateral Frontal",4*AQ3,IF(AE3="Canteiro Central",2*AQ3,"erro"))))) -> 0 | AY3: =VLOOKUP(K3,ABNT5101!$I$3:$J$9,2) -> 30 | AZ3: =VLOOKUP(K3,ABNT5101!$I$3:$M$9,5) -> 0.38 | BA3: =_xlfn.XLOOKUP(K3,ABNT5101!$I:$I,ABNT5101!$L:$L) -> - | BB3: =_xlfn.XLOOKUP(K3,ABNT5101!$I:$I,ABNT5101!M:M) -> 0.38 | BC3: =_xlfn.XLOOKUP(K3,ABNT5101!$I:$I,ABNT5101!N:N) -> - | BD3: =_xlfn.XLOOKUP(K3,ABNT5101!$I:$I,ABNT5101!O:O) -> 14 | BE3: =IF(BO3="NÃO ATENDE","NÃO ATENDE",IF(BZ3="NÃO ATENDE","NÃO ATENDE",IF(CI3="NÃO ATENDE","NÃO ATENDE","ATENDE"))) -> ATENDE | BF3: =BI3/AY3-1 -> 0.064 | BG3: =BJ3/AZ3-1 -> 0.28947368 | BH3: =IF($K3="M6",BK3/BA3-1,"-") -> - | BI3: 31.92 | BJ3: 0.49 | BO3: =IF(OR(BP3="NÃO ATENDE",BQ3="NÃO ATENDE",BR3="NÃO ATENDE"),"NÃO ATENDE","ATENDE") -> ATENDE | BP3: =IF(BI3>=AY3,"ATENDE",IF(BI3>=0.99*AY3,"ATENDIMENTO LIMIAR","NÃO ATENDE")) -> ATENDE | BQ3: =IF(BJ3>=AZ3,"ATENDE",IF(BJ3>=(AZ3-0.02),"ATENDIMENTO LIMIAR","NÃO ATENDE")) -> ATENDE | BR3: =IF(BA3="-","ATENDE",IF(BK3>=BA3,"ATENDE",IF(BK3>=(BA3-0.02),"ATENDIMENTO LIMIAR","NÃO ATENDE"))) -> ATENDE | BS3: =K3 -> C1 | BT3: =M3 -> P4 | BU3: =IF(BV3="-","-",BV3/BX3-1) -> 1.24 | BV3: 16.8 | BW3: 9.05 | BX3: =IF(BT3="-","-",_xlfn.XLOOKUP(BT3,ABNT5101!$B$4:$B$9,ABNT5101!$C$4:$C$9)) -> 7.5 | BY3: =IF(BT3="-","-",_xlfn.XLOOKUP(BT3,ABNT5101!$B$4:$B$9,ABNT5101!$D$4:$D$9)) -> 1.5 | BZ3: =IF(CA3="-","-",IF(CA3="NÃO ATENDE","NÃO ATENDE",IF(CB3="NÃO ATENDE","NÃO ATENDE","ATENDE"))) -> ATENDE | CA3: =IF(BT3="-","-",IF(BV3>=BX3,"ATENDE",IF(BV3>=(BX3*0.99),"ATENDIMENTO LIMIAR","NÃO ATENDE"))) -> ATENDE | CB3: =IF(BT3="-","-",IF(BW3>=BY3,"ATENDE","NÃO ATENDE")) -> ATENDE | CC3: =BT3 -> P4 | CD3: =IF(CE3="-","-",CE3/CG3-1) -> #DIV/0! | CE3: 16.71 | CF3: 8.77 | CI3: =IF(CJ3="-","-",IF(CJ3="NÃO ATENDE","NÃO ATENDE",IF(CK3="NÃO ATENDE","NÃO ATENDE","ATENDE"))) -> ATENDE | CJ3: =IF(CC3="-","-",IF(CE3>=(CG3),"ATENDE",IF(CE3>=(0.99*CG3),"ATENDIMENTO LIMIAR","NÃO ATENDE"))) -> ATENDE | CK3: =IF(CC3="-","-",IF(CF3>=CH3,"ATENDE","NÃO ATENDE")) -> ATENDE | CL3: =_xlfn.XLOOKUP(CM3,'Banco de dados'!$B:$B,'Banco de dados'!$D:$D) -> SX LIGHTING | CM3: ='Banco de dados'!B62 -> SX-INLPP090HF | CN3: =_xlfn.XLOOKUP(CM3,'Banco de dados'!$B:$B,'Banco de dados'!$E:$E) -> SXINLPP090K40L12CZF7PHF | CP3: =IF(CO3="-","-",_xlfn.XLOOKUP(CO3,'Banco de dados'!$B:$B,'Banco de dados'!$E:$E)) -> 0 | CQ3: =AI3 -> 1 | CR3: =_xlfn.XLOOKUP(CM3,'Banco de dados'!$B:$B,'Banco de dados'!$H:$H) -> 90 | CS3: =_xlfn.XLOOKUP(CO3,'Banco de dados'!$B:$B,'Banco de dados'!$H:$H) -> 0 | CT3: =_xlfn.XLOOKUP(CM3,'Banco de dados'!$B:$B,'Banco de dados'!$F:$F) -> 15476 | CU3: =_xlfn.XLOOKUP(CO3,'Banco de dados'!$B:$B,'Banco de dados'!$F:$F) -> 0 | CW3: 5 | CX3: =IF(AK3<=0.5,"Curto I",IF(AND(AK3>='Braços de IP'!$B$9,AK3<='Braços de IP'!$D$9),'Braços de IP'!$E$9,IF(AND(AK3>='Braços de IP'!$B$10,AK3<='Braços de IP'!$D$10),'Braços de IP'!$E$10,IF(AND(AK3>='Braços de IP'!$B$11,AK3<='Braços de IP'!$D$11),'Braços de IP'!$E$11,IF(AND(AK3>='Braços de IP'!$B$12,AK3<='Braços de IP'!$D$12),'Braços de IP'!$E$12,IF(AND(AK3>='Braços de IP'!$B$13,AK3<='Braços de IP'!$D$13),'Braços de IP'!$E$13,IF(AND(AK3>='Braços de IP'!$B$14,AK3<='Braços de IP'!$D$14),'Braços de IP'!$E$14,"ERRO"))))))) -> Longo I | CZ3: =IF($CY3="","",VLOOKUP($CY3,'Braços de IP'!$E$9:$I$15,2,0)) | DA3: =IF($CY3="","",VLOOKUP($CY3,'Braços de IP'!$E$9:$I$15,5,0)) | DH3: =CR3 -> 90 | DI3: =O3 -> 80 | DJ3: =SUM(DH3:DI3)*CQ3 -> 170 | DK3: =1-DH3/DI3 -> -0.125 | DN3: Sim | DQ3: =((O3+P3)-CR3)/(O3+P3) -> -0.125
A4: 0.5 - Projeção do braço segundo nível | F4: 219474977 | G4: PVVP | H4: Avenida Caio Martins | I4: -19.565708 | J4: -44.078041 | K4: C1 | M4: P4 | N4: LED | O4: 80 | Q4: 60 | R4: 4 | S4: 2 | T4: 1.7 | U4: 7 | Y4: 1.7 | Z4: (7.5) 2.00 | AC4: 4.5 | AE4: Canteiro central | AF4: Braço | AG4: 37.8 | AH4: 7.8 | AI4: 1 | AJ4: 0.4 | AK4: 2.7 | AL4: =AK4-AJ4 -> 2.3 | AM4: - | AN4: - | AO4: Não | AP4: =IF(AE4="Unilateral",2*AI4,IF(AE4="Bilateral Alternada",3*AI4,IF(AE4="Bilateral Frontal",4*AI4,IF(AE4="Canteiro Central",2*AI4,"erro")))) -> 2 | AQ4: 0 | AR4: 0 | AS4: 0 | AT4: 0 | AU4: 0 | AV4: 0 | AW4: =IF(AQ4=0,0,IF(AE4="Unilateral",2*AQ4,IF(AE4="Bilateral Alternada",3*AQ4,IF(AE4="Bilateral Frontal",4*AQ4,IF(AE4="Canteiro Central",2*AQ4,"erro"))))) -> 0 | AY4: =VLOOKUP(K4,ABNT5101!$I$3:$J$9,2) -> 30 | AZ4: =VLOOKUP(K4,ABNT5101!$I$3:$M$9,5) -> 0.38 | BA4: =_xlfn.XLOOKUP(K4,ABNT5101!$I:$I,ABNT5101!$L:$L) -> - | BB4: =_xlfn.XLOOKUP(K4,ABNT5101!$I:$I,ABNT5101!M:M) -> 0.38 | BC4: =_xlfn.XLOOKUP(K4,ABNT5101!$I:$I,ABNT5101!N:N) -> - | BD4: =_xlfn.XLOOKUP(K4,ABNT5101!$I:$I,ABNT5101!O:O) -> 14 | BE4: =IF(BO4="NÃO ATENDE","NÃO ATENDE",IF(BZ4="NÃO ATENDE","NÃO ATENDE",IF(CI4="NÃO ATENDE","NÃO ATENDE","ATENDE"))) -> ATENDE | BF4: =BI4/AY4-1 -> 0.17633333 | BG4: =BJ4/AZ4-1 -> 0.13157895 | BH4: =IF($K4="M6",BK4/BA4-1,"-") -> - | BI4: 35.29 | BJ4: 0.43 | BO4: =IF(OR(BP4="NÃO ATENDE",BQ4="NÃO ATENDE",BR4="NÃO ATENDE"),"NÃO ATENDE","ATENDE") -> ATENDE | BP4: =IF(BI4>=AY4,"ATENDE",IF(BI4>=0.99*AY4,"ATENDIMENTO LIMIAR","NÃO ATENDE")) -> ATENDE | BQ4: =IF(BJ4>=AZ4,"ATENDE",IF(BJ4>=(AZ4-0.02),"ATENDIMENTO LIMIAR","NÃO ATENDE")) -> ATENDE | BR4: =IF(BA4="-","ATENDE",IF(BK4>=BA4,"ATENDE",IF(BK4>=(BA4-0.02),"ATENDIMENTO LIMIAR","NÃO ATENDE"))) -> ATENDE | BS4: =K4 -> C1 | BT4: =M4 -> P4 | BU4: =IF(BV4="-","-",BV4/BX4-1) -> 1.6386667 | BV4: 19.79 | BW4: 11.24 | BX4: =IF(BT4="-","-",_xlfn.XLOOKUP(BT4,ABNT5101!$B$4:$B$9,ABNT5101!$C$4:$C$9)) -> 7.5 | BY4: =IF(BT4="-","-",_xlfn.XLOOKUP(BT4,ABNT5101!$B$4:$B$9,ABNT5101!$D$4:$D$9)) -> 1.5 | BZ4: =IF(CA4="-","-",IF(CA4="NÃO ATENDE","NÃO ATENDE",IF(CB4="NÃO ATENDE","NÃO ATENDE","ATENDE"))) -> ATENDE | CA4: =IF(BT4="-","-",IF(BV4>=BX4,"ATENDE",IF(BV4>=(BX4*0.99),"ATENDIMENTO LIMIAR","NÃO ATENDE"))) -> ATENDE | CB4: =IF(BT4="-","-",IF(BW4>=BY4,"ATENDE","NÃO ATENDE")) -> ATENDE | CC4: =BT4 -> P4 | CD4: =IF(CE4="-","-",CE4/CG4-1) -> #DIV/0! | CE4: 19.82 | CF4: 11.16 | CI4: =IF(CJ4="-","-",IF(CJ4="NÃO ATENDE","NÃO ATENDE",IF(CK4="NÃO ATENDE","NÃO ATENDE","ATENDE"))) -> ATENDE | CJ4: =IF(CC4="-","-",IF(CE4>=(CG4),"ATENDE",IF(CE4>=(0.99*CG4),"ATENDIMENTO LIMIAR","NÃO ATENDE"))) -> ATENDE | CK4: =IF(CC4="-","-",IF(CF4>=CH4,"ATENDE","NÃO ATENDE")) -> ATENDE | CL4: =_xlfn.XLOOKUP(CM4,'Banco de dados'!$B:$B,'Banco de dados'!$D:$D) -> TECNOWATT | CM4: ='Banco de dados'!B76 -> SIGMAGPTLRRSMNDL120W_82IBBR | CN4: =_xlfn.XLOOKUP(CM4,'Banco de dados'!$B:$B,'Banco de dados'!$E:$E) -> SIGMAGPTLRRSMNDL120W_82IBBR S1-10C1MUN6.5 | CP4: =IF(CO4="-","-",_xlfn.XLOOKUP(CO4,'Banco de dados'!$B:$B,'Banco de dados'!$E:$E)) -> 0 | CQ4: =AI4 -> 1 | CR4: =_xlfn.XLOOKUP(CM4,'Banco de dados'!$B:$B,'Banco de dados'!$H:$H) -> 120 | CS4: =_xlfn.XLOOKUP(CO4,'Banco de dados'!$B:$B,'Banco de dados'!$H:$H) -> 0 | CT4: =_xlfn.XLOOKUP(CM4,'Banco de dados'!$B:$B,'Banco de dados'!$F:$F) -> 19640 | CU4: =_xlfn.XLOOKUP(CO4,'Banco de dados'!$B:$B,'Banco de dados'!$F:$F) -> 0 | CX4: =IF(AK4<=0.5,"Curto I",IF(AND(AK4>='Braços de IP'!$B$9,AK4<='Braços de IP'!$D$9),'Braços de IP'!$E$9,IF(AND(AK4>='Braços de IP'!$B$10,AK4<='Braços de IP'!$D$10),'Braços de IP'!$E$10,IF(AND(AK4>='Braços de IP'!$B$11,AK4<='Braços de IP'!$D$11),'Braços de IP'!$E$11,IF(AND(AK4>='Braços de IP'!$B$12,AK4<='Braços de IP'!$D$12),'Braços de IP'!$E$12,IF(AND(AK4>='Braços de IP'!$B$13,AK4<='Braços de IP'!$D$13),'Braços de IP'!$E$13,IF(AND(AK4>='Braços de IP'!$B$14,AK4<='Braços de IP'!$D$14),'Braços de IP'!$E$14,"ERRO"))))))) -> Longo I | CZ4: =IF($CY4="","",VLOOKUP($CY4,'Braços de IP'!$E$9:$I$15,2,0)) | DA4: =IF($CY4="","",VLOOKUP($CY4,'Braços de IP'!$E$9:$I$15,5,0)) | DH4: =CR4 -> 120 | DI4: =O4 -> 80 | DJ4: =SUM(DH4:DI4)*CQ4 -> 200 | DK4: =1-DH4/DI4 -> -0.5 | DN4: Sim | DQ4: =((O4+P4)-CR4)/(O4+P4) -> -0.5
B5: Alexandre | D5: Penelope | F5: 221009264 | G5: PVP | H5: Rodovia Engenheiro Idsel Costa Martins | I5: -19.562524 | J5: -44.079276 | K5: C1 | M5: P4 | N5: LED | O5: 200 | S5: 2 | T5: 1.8 | U5: 8.5 | Y5: 1.8 | AE5: Unilateral | AF5: Braço | AG5: 35.3 | AH5: 8 | AI5: 1 | AJ5: 1 | AK5: 3.3 | AL5: =AK5-AJ5 -> 2.3 | AM5: - | AN5: - | AO5: Não | AP5: =IF(AE5="Unilateral",2*AI5,IF(AE5="Bilateral Alternada",3*AI5,IF(AE5="Bilateral Frontal",4*AI5,IF(AE5="Canteiro Central",2*AI5,"erro")))) -> 2 | AQ5: 0 | AR5: 0 | AS5: 0 | AT5: 0 | AU5: 0 | AV5: 0 | AW5: =IF(AQ5=0,0,IF(AE5="Unilateral",2*AQ5,IF(AE5="Bilateral Alternada",3*AQ5,IF(AE5="Bilateral Frontal",4*AQ5,IF(AE5="Canteiro Central",2*AQ5,"erro"))))) -> 0 | AY5: =VLOOKUP(K5,ABNT5101!$I$3:$J$9,2) -> 30 | AZ5: =VLOOKUP(K5,ABNT5101!$I$3:$M$9,5) -> 0.38 | BA5: =_xlfn.XLOOKUP(K5,ABNT5101!$I:$I,ABNT5101!$L:$L) -> - | BB5: =_xlfn.XLOOKUP(K5,ABNT5101!$I:$I,ABNT5101!M:M) -> 0.38 | BC5: =_xlfn.XLOOKUP(K5,ABNT5101!$I:$I,ABNT5101!N:N) -> - | BD5: =_xlfn.XLOOKUP(K5,ABNT5101!$I:$I,ABNT5101!O:O) -> 14 | BE5: =IF(BO5="NÃO ATENDE","NÃO ATENDE",IF(BZ5="NÃO ATENDE","NÃO ATENDE",IF(CI5="NÃO ATENDE","NÃO ATENDE","ATENDE"))) -> ATENDE | BF5: =BI5/AY5-1 -> 0.060666667 | BG5: =BJ5/AZ5-1 -> 0.078947368 | BH5: =IF($K5="M6",BK5/BA5-1,"-") -> - | BI5: 31.82 | BJ5: 0.41 | BO5: =IF(OR(BP5="NÃO ATENDE",BQ5="NÃO ATENDE",BR5="NÃO ATENDE"),"NÃO ATENDE","ATENDE") -> ATENDE | BP5: =IF(BI5>=AY5,"ATENDE",IF(BI5>=0.99*AY5,"ATENDIMENTO LIMIAR","NÃO ATENDE")) -> ATENDE | BQ5: =IF(BJ5>=AZ5,"ATENDE",IF(BJ5>=(AZ5-0.02),"ATENDIMENTO LIMIAR","NÃO ATENDE")) -> ATENDE | BR5: =IF(BA5="-","ATENDE",IF(BK5>=BA5,"ATENDE",IF(BK5>=(BA5-0.02),"ATENDIMENTO LIMIAR","NÃO ATENDE"))) -> ATENDE | BS5: =K5 -> C1 | BT5: =M5 -> P4 | BU5: =IF(BV5="-","-",BV5/BX5-1) -> 2.072 | BV5: 23.04 | BW5: 13.55 | BX5: =IF(BT5="-","-",_xlfn.XLOOKUP(BT5,ABNT5101!$B$4:$B$9,ABNT5101!$C$4:$C$9)) -> 7.5 | BY5: =IF(BT5="-","-",_xlfn.XLOOKUP(BT5,ABNT5101!$B$4:$B$9,ABNT5101!$D$4:$D$9)) -> 1.5 | BZ5: =IF(CA5="-","-",IF(CA5="NÃO ATENDE","NÃO ATENDE",IF(CB5="NÃO ATENDE","NÃO ATENDE","ATENDE"))) -> ATENDE | CA5: =IF(BT5="-","-",IF(BV5>=BX5,"ATENDE",IF(BV5>=(BX5*0.99),"ATENDIMENTO LIMIAR","NÃO ATENDE"))) -> ATENDE | CB5: =IF(BT5="-","-",IF(BW5>=BY5,"ATENDE","NÃO ATENDE")) -> ATENDE | CC5: =BT5 -> P4 | CD5: =IF(CE5="-","-",CE5/CG5-1) -> #DIV/0! | CE5: 23.06 | CF5: 9.26 | CI5: =IF(CJ5="-","-",IF(CJ5="NÃO ATENDE","NÃO ATENDE",IF(CK5="NÃO ATENDE","NÃO ATENDE","ATENDE"))) -> ATENDE | CJ5: =IF(CC5="-","-",IF(CE5>=(CG5),"ATENDE",IF(CE5>=(0.99*CG5),"ATENDIMENTO LIMIAR","NÃO ATENDE"))) -> ATENDE | CK5: =IF(CC5="-","-",IF(CF5>=CH5,"ATENDE","NÃO ATENDE")) -> ATENDE | CL5: =_xlfn.XLOOKUP(CM5,'Banco de dados'!$B:$B,'Banco de dados'!$D:$D) -> LEDSTAR | CM5: ='Banco de dados'!B35 -> SL VT 9.1 140W | CN5: =_xlfn.XLOOKUP(CM5,'Banco de dados'!$B:$B,'Banco de dados'!$E:$E) -> LUM LED SL VT 9.1 140W | CP5: =IF(CO5="-","-",_xlfn.XLOOKUP(CO5,'Banco de dados'!$B:$B,'Banco de dados'!$E:$E)) -> 0 | CQ5: =AI5 -> 1 | CR5: =_xlfn.XLOOKUP(CM5,'Banco de dados'!$B:$B,'Banco de dados'!$H:$H) -> 140 | CS5: =_xlfn.XLOOKUP(CO5,'Banco de dados'!$B:$B,'Banco de dados'!$H:$H) -> 0 | CT5: =_xlfn.XLOOKUP(CM5,'Banco de dados'!$B:$B,'Banco de dados'!$F:$F) -> 22440 | CU5: =_xlfn.XLOOKUP(CO5,'Banco de dados'!$B:$B,'Banco de dados'!$F:$F) -> 0 | CX5: =IF(AK5<=0.5,"Curto I",IF(AND(AK5>='Braços de IP'!$B$9,AK5<='Braços de IP'!$D$9),'Braços de IP'!$E$9,IF(AND(AK5>='Braços de IP'!$B$10,AK5<='Braços de IP'!$D$10),'Braços de IP'!$E$10,IF(AND(AK5>='Braços de IP'!$B$11,AK5<='Braços de IP'!$D$11),'Braços de IP'!$E$11,IF(AND(AK5>='Braços de IP'!$B$12,AK5<='Braços de IP'!$D$12),'Braços de IP'!$E$12,IF(AND(AK5>='Braços de IP'!$B$13,AK5<='Braços de IP'!$D$13),'Braços de IP'!$E$13,IF(AND(AK5>='Braços de IP'!$B$14,AK5<='Braços de IP'!$D$14),'Braços de IP'!$E$14,"ERRO"))))))) -> Longo II | CZ5: =IF($CY5="","",VLOOKUP($CY5,'Braços de IP'!$E$9:$I$15,2,0)) | DA5: =IF($CY5="","",VLOOKUP($CY5,'Braços de IP'!$E$9:$I$15,5,0)) | DH5: =CR5 -> 140 | DI5: =O5 -> 200 | DJ5: =SUM(DH5:DI5)*CQ5 -> 340 | DK5: =1-DH5/DI5 -> 0.3 | DN5: Sim | DQ5: =((O5+P5)-CR5)/(O5+P5) -> 0.3
F6: 221009264 | G6: PVP | H6: Rodovia Engenheiro Idsel Costa Martins | I6: -19.562524 | J6: -44.079276 | K6: C1 | M6: P4 | N6: LED | O6: 200 | S6: 2 | T6: 1.8 | U6: 8.5 | Y6: 1.8 | AE6: Unilateral | AF6: Braço | AG6: 35.3 | AH6: 8 | AI6: 1 | AJ6: 1 | AK6: 3.3 | AL6: =AK6-AJ6 -> 2.3 | AM6: - | AN6: - | AO6: Não | AP6: =IF(AE6="Unilateral",2*AI6,IF(AE6="Bilateral Alternada",3*AI6,IF(AE6="Bilateral Frontal",4*AI6,IF(AE6="Canteiro Central",2*AI6,"erro")))) -> 2 | AQ6: 0 | AR6: 0 | AS6: 0 | AT6: 0 | AU6: 0 | AV6: 0 | AW6: =IF(AQ6=0,0,IF(AE6="Unilateral",2*AQ6,IF(AE6="Bilateral Alternada",3*AQ6,IF(AE6="Bilateral Frontal",4*AQ6,IF(AE6="Canteiro Central",2*AQ6,"erro"))))) -> 0 | AY6: =VLOOKUP(K6,ABNT5101!$I$3:$J$9,2) -> 30 | AZ6: =VLOOKUP(K6,ABNT5101!$I$3:$M$9,5) -> 0.38 | BA6: =_xlfn.XLOOKUP(K6,ABNT5101!$I:$I,ABNT5101!$L:$L) -> - | BB6: =_xlfn.XLOOKUP(K6,ABNT5101!$I:$I,ABNT5101!M:M) -> 0.38 | BC6: =_xlfn.XLOOKUP(K6,ABNT5101!$I:$I,ABNT5101!N:N) -> - | BD6: =_xlfn.XLOOKUP(K6,ABNT5101!$I:$I,ABNT5101!O:O) -> 14 | BE6: =IF(BO6="NÃO ATENDE","NÃO ATENDE",IF(BZ6="NÃO ATENDE","NÃO ATENDE",IF(CI6="NÃO ATENDE","NÃO ATENDE","ATENDE"))) -> ATENDE | BF6: =BI6/AY6-1 -> 0.087333333 | BG6: =BJ6/AZ6-1 -> 0.28947368 | BH6: =IF($K6="M6",BK6/BA6-1,"-") -> - | BI6: 32.62 | BJ6: 0.49 | BO6: =IF(OR(BP6="NÃO ATENDE",BQ6="NÃO ATENDE",BR6="NÃO ATENDE"),"NÃO ATENDE","ATENDE") -> ATENDE | BP6: =IF(BI6>=AY6,"ATENDE",IF(BI6>=0.99*AY6,"ATENDIMENTO LIMIAR","NÃO ATENDE")) -> ATENDE | BQ6: =IF(BJ6>=AZ6,"ATENDE",IF(BJ6>=(AZ6-0.02),"ATENDIMENTO LIMIAR","NÃO ATENDE")) -> ATENDE | BR6: =IF(BA6="-","ATENDE",IF(BK6>=BA6,"ATENDE",IF(BK6>=(BA6-0.02),"ATENDIMENTO LIMIAR","NÃO ATENDE"))) -> ATENDE | BS6: =K6 -> C1 | BT6: =M6 -> P4 | BU6: =IF(BV6="-","-",BV6/BX6-1) -> 1.6093333 | BV6: 19.57 | BW6: 11.33 | BX6: =IF(BT6="-","-",_xlfn.XLOOKUP(BT6,ABNT5101!$B$4:$B$9,ABNT5101!$C$4:$C$9)) -> 7.5 | BY6: =IF(BT6="-","-",_xlfn.XLOOKUP(BT6,ABNT5101!$B$4:$B$9,ABNT5101!$D$4:$D$9)) -> 1.5 | BZ6: =IF(CA6="-","-",IF(CA6="NÃO ATENDE","NÃO ATENDE",IF(CB6="NÃO ATENDE","NÃO ATENDE","ATENDE"))) -> ATENDE | CA6: =IF(BT6="-","-",IF(BV6>=BX6,"ATENDE",IF(BV6>=(BX6*0.99),"ATENDIMENTO LIMIAR","NÃO ATENDE"))) -> ATENDE | CB6: =IF(BT6="-","-",IF(BW6>=BY6,"ATENDE","NÃO ATENDE")) -> ATENDE | CC6: =BT6 -> P4 | CD6: =IF(CE6="-","-",CE6/CG6-1) -> #DIV/0! | CE6: 25.52 | CF6: 15.62 | CI6: =IF(CJ6="-","-",IF(CJ6="NÃO ATENDE","NÃO ATENDE",IF(CK6="NÃO ATENDE","NÃO ATENDE","ATENDE"))) -> ATENDE | CJ6: =IF(CC6="-","-",IF(CE6>=(CG6),"ATENDE",IF(CE6>=(0.99*CG6),"ATENDIMENTO LIMIAR","NÃO ATENDE"))) -> ATENDE | CK6: =IF(CC6="-","-",IF(CF6>=CH6,"ATENDE","NÃO ATENDE")) -> ATENDE | CL6: =_xlfn.XLOOKUP(CM6,'Banco de dados'!$B:$B,'Banco de dados'!$D:$D) -> SX LIGHTING | CM6: ='Banco de dados'!B65 -> SX-INLPP150HF | CN6: =_xlfn.XLOOKUP(CM6,'Banco de dados'!$B:$B,'Banco de dados'!$E:$E) -> SXINLPP150K40L12CZF7PHF | CP6: =IF(CO6="-","-",_xlfn.XLOOKUP(CO6,'Banco de dados'!$B:$B,'Banco de dados'!$E:$E)) -> 0 | CQ6: =AI6 -> 1 | CR6: =_xlfn.XLOOKUP(CM6,'Banco de dados'!$B:$B,'Banco de dados'!$H:$H) -> 137 | CS6: =_xlfn.XLOOKUP(CO6,'Banco de dados'!$B:$B,'Banco de dados'!$H:$H) -> 0 | CT6: =_xlfn.XLOOKUP(CM6,'Banco de dados'!$B:$B,'Banco de dados'!$F:$F) -> 23817 | CU6: =_xlfn.XLOOKUP(CO6,'Banco de dados'!$B:$B,'Banco de dados'!$F:$F) -> 0 | CX6: =IF(AK6<=0.5,"Curto I",IF(AND(AK6>='Braços de IP'!$B$9,AK6<='Braços de IP'!$D$9),'Braços de IP'!$E$9,IF(AND(AK6>='Braços de IP'!$B$10,AK6<='Braços de IP'!$D$10),'Braços de IP'!$E$10,IF(AND(AK6>='Braços de IP'!$B$11,AK6<='Braços de IP'!$D$11),'Braços de IP'!$E$11,IF(AND(AK6>='Braços de IP'!$B$12,AK6<='Braços de IP'!$D$12),'Braços de IP'!$E$12,IF(AND(AK6>='Braços de IP'!$B$13,AK6<='Braços de IP'!$D$13),'Braços de IP'!$E$13,IF(AND(AK6>='Braços de IP'!$B$14,AK6<='Braços de IP'!$D$14),'Braços de IP'!$E$14,"ERRO"))))))) -> Longo II | CZ6: =IF($CY6="","",VLOOKUP($CY6,'Braços de IP'!$E$9:$I$15,2,0)) | DA6: =IF($CY6="","",VLOOKUP($CY6,'Braços de IP'!$E$9:$I$15,5,0)) | DH6: =CR6 -> 137 | DI6: =O6 -> 200 | DJ6: =SUM(DH6:DI6)*CQ6 -> 337 | DK6: =1-DH6/DI6 -> 0.315 | DN6: Sim | DQ6: =((O6+P6)-CR6)/(O6+P6) -> 0.315
F7: 221009264 | G7: PVP | H7: Rodovia Engenheiro Idsel Costa Martins | I7: -19.562524 | J7: -44.079276 | K7: C1 | M7: P4 | N7: LED | O7: 200 | S7: 2 | T7: 1.8 | U7: 8.5 | Y7: 1.8 | AE7: Unilateral | AF7: Braço | AG7: 35.3 | AH7: 8 | AI7: 1 | AJ7: 1 | AK7: 3.3 | AL7: =AK7-AJ7 -> 2.3 | AM7: - | AN7: - | AO7: Não | AP7: =IF(AE7="Unilateral",2*AI7,IF(AE7="Bilateral Alternada",3*AI7,IF(AE7="Bilateral Frontal",4*AI7,IF(AE7="Canteiro Central",2*AI7,"erro")))) -> 2 | AQ7: 0 | AR7: 0 | AS7: 0 | AT7: 0 | AU7: 0 | AV7: 0 | AW7: =IF(AQ7=0,0,IF(AE7="Unilateral",2*AQ7,IF(AE7="Bilateral Alternada",3*AQ7,IF(AE7="Bilateral Frontal",4*AQ7,IF(AE7="Canteiro Central",2*AQ7,"erro"))))) -> 0 | AY7: =VLOOKUP(K7,ABNT5101!$I$3:$J$9,2) -> 30 | AZ7: =VLOOKUP(K7,ABNT5101!$I$3:$M$9,5) -> 0.38 | BA7: =_xlfn.XLOOKUP(K7,ABNT5101!$I:$I,ABNT5101!$L:$L) -> - | BB7: =_xlfn.XLOOKUP(K7,ABNT5101!$I:$I,ABNT5101!M:M) -> 0.38 | BC7: =_xlfn.XLOOKUP(K7,ABNT5101!$I:$I,ABNT5101!N:N) -> - | BD7: =_xlfn.XLOOKUP(K7,ABNT5101!$I:$I,ABNT5101!O:O) -> 14 | BE7: =IF(BO7="NÃO ATENDE","NÃO ATENDE",IF(BZ7="NÃO ATENDE","NÃO ATENDE",IF(CI7="NÃO ATENDE","NÃO ATENDE","ATENDE"))) -> ATENDE | BF7: =BI7/AY7-1 -> 0.083666667 | BG7: =BJ7/AZ7-1 -> 0.39473684 | BH7: =IF($K7="M6",BK7/BA7-1,"-") -> - | BI7: 32.51 | BJ7: 0.53 | BO7: =IF(OR(BP7="NÃO ATENDE",BQ7="NÃO ATENDE",BR7="NÃO ATENDE"),"NÃO ATENDE","ATENDE") -> ATENDE | BP7: =IF(BI7>=AY7,"ATENDE",IF(BI7>=0.99*AY7,"ATENDIMENTO LIMIAR","NÃO ATENDE")) -> ATENDE | BQ7: =IF(BJ7>=AZ7,"ATENDE",IF(BJ7>=(AZ7-0.02),"ATENDIMENTO LIMIAR","NÃO ATENDE")) -> ATENDE | BR7: =IF(BA7="-","ATENDE",IF(BK7>=BA7,"ATENDE",IF(BK7>=(BA7-0.02),"ATENDIMENTO LIMIAR","NÃO ATENDE"))) -> ATENDE | BS7: =K7 -> C1 | BT7: =M7 -> P4 | BU7: =IF(BV7="-","-",BV7/BX7-1) -> 1.6106667 | BV7: 19.58 | BW7: 15.75 | BX7: =IF(BT7="-","-",_xlfn.XLOOKUP(BT7,ABNT5101!$B$4:$B$9,ABNT5101!$C$4:$C$9)) -> 7.5 | BY7: =IF(BT7="-","-",_xlfn.XLOOKUP(BT7,ABNT5101!$B$4:$B$9,ABNT5101!$D$4:$D$9)) -> 1.5 | BZ7: =IF(CA7="-","-",IF(CA7="NÃO ATENDE","NÃO ATENDE",IF(CB7="NÃO ATENDE","NÃO ATENDE","ATENDE"))) -> ATENDE | CA7: =IF(BT7="-","-",IF(BV7>=BX7,"ATENDE",IF(BV7>=(BX7*0.99),"ATENDIMENTO LIMIAR","NÃO ATENDE"))) -> ATENDE | CB7: =IF(BT7="-","-",IF(BW7>=BY7,"ATENDE","NÃO ATENDE")) -> ATENDE | CC7: =BT7 -> P4 | CD7: =IF(CE7="-","-",CE7/CG7-1) -> #DIV/0! | CE7: 22.39 | CF7: 13.06 | CI7: =IF(CJ7="-","-",IF(CJ7="NÃO ATENDE","NÃO ATENDE",IF(CK7="NÃO ATENDE","NÃO ATENDE","ATENDE"))) -> ATENDE | CJ7: =IF(CC7="-","-",IF(CE7>=(CG7),"ATENDE",IF(CE7>=(0.99*CG7),"ATENDIMENTO LIMIAR","NÃO ATENDE"))) -> ATENDE | CK7: =IF(CC7="-","-",IF(CF7>=CH7,"ATENDE","NÃO ATENDE")) -> ATENDE | CL7: =_xlfn.XLOOKUP(CM7,'Banco de dados'!$B:$B,'Banco de dados'!$D:$D) -> TECNOWATT | CM7: ='Banco de dados'!B77 -> SIGMAGPTLRRSMNDL150W102IBBR | CN7: =_xlfn.XLOOKUP(CM7,'Banco de dados'!$B:$B,'Banco de dados'!$E:$E) -> SIGMAGPTLRRSMNDL150W102IBBR S1-10C1MUN6.5 | CP7: =IF(CO7="-","-",_xlfn.XLOOKUP(CO7,'Banco de dados'!$B:$B,'Banco de dados'!$E:$E)) -> 0 | CQ7: =AI7 -> 1 | CR7: =_xlfn.XLOOKUP(CM7,'Banco de dados'!$B:$B,'Banco de dados'!$H:$H) -> 150 | CS7: =_xlfn.XLOOKUP(CO7,'Banco de dados'!$B:$B,'Banco de dados'!$H:$H) -> 0 | CT7: =_xlfn.XLOOKUP(CM7,'Banco de dados'!$B:$B,'Banco de dados'!$F:$F) -> 23000 | CU7: =_xlfn.XLOOKUP(CO7,'Banco de dados'!$B:$B,'Banco de dados'!$F:$F) -> 0 | CX7: =IF(AK7<=0.5,"Curto I",IF(AND(AK7>='Braços de IP'!$B$9,AK7<='Braços de IP'!$D$9),'Braços de IP'!$E$9,IF(AND(AK7>='Braços de IP'!$B$10,AK7<='Braços de IP'!$D$10),'Braços de IP'!$E$10,IF(AND(AK7>='Braços de IP'!$B$11,AK7<='Braços de IP'!$D$11),'Braços de IP'!$E$11,IF(AND(AK7>='Braços de IP'!$B$12,AK7<='Braços de IP'!$D$12),'Braços de IP'!$E$12,IF(AND(AK7>='Braços de IP'!$B$13,AK7<='Braços de IP'!$D$13),'Braços de IP'!$E$13,IF(AND(AK7>='Braços de IP'!$B$14,AK7<='Braços de IP'!$D$14),'Braços de IP'!$E$14,"ERRO"))))))) -> Longo II | CZ7: =IF($CY7="","",VLOOKUP($CY7,'Braços de IP'!$E$9:$I$15,2,0)) | DA7: =IF($CY7="","",VLOOKUP($CY7,'Braços de IP'!$E$9:$I$15,5,0)) | DH7: =CR7 -> 150 | DI7: =O7 -> 200 | DJ7: =SUM(DH7:DI7)*CQ7 -> 350 | DK7: =1-DH7/DI7 -> 0.25 | DN7: Sim | DQ7: =((O7+P7)-CR7)/(O7+P7) -> 0.25
A8: Verificado que a estrutura predominante é PVP / Corrigido a distancia do poste a via de 0.70 para 3, não foi considerado inicialmente o estacionamento de 2.30. | B8: Alexandre | C8: ok | D8: Penelope | E8: ok | F8: 221272180 | G8: (V) PVP | H8: Avenida Bento Gonçalves | I8: -19.557925 | J8: -44.085391 | K8: C2 | M8: P4 | N8: LED | O8: 200 | S8: 2 | T8: 1.5 | U8: 6.5 | Y8: 1.5 | AC8: 2.3 | AD8: 2.3 | AE8: Unilateral | AF8: Braço | AG8: 37.3 | AH8: 7.6 | AI8: 1 | AJ8: 3 | AK8: 3.2 | AL8: =AK8-AJ8 -> 0.2 | AM8: - | AN8: - | AO8: Não | AP8: =IF(AE8="Unilateral",2*AI8,IF(AE8="Bilateral Alternada",3*AI8,IF(AE8="Bilateral Frontal",4*AI8,IF(AE8="Canteiro Central",2*AI8,"erro")))) -> 2 | AQ8: 0 | AR8: 0 | AS8: 0 | AT8: 0 | AU8: 0 | AV8: 0 | AW8: =IF(AQ8=0,0,IF(AE8="Unilateral",2*AQ8,IF(AE8="Bilateral Alternada",3*AQ8,IF(AE8="Bilateral Frontal",4*AQ8,IF(AE8="Canteiro Central",2*AQ8,"erro"))))) -> 0 | AY8: =VLOOKUP(K8,ABNT5101!$I$3:$J$9,2) -> 20 | AZ8: =VLOOKUP(K8,ABNT5101!$I$3:$M$9,5) -> 0.28 | BA8: =_xlfn.XLOOKUP(K8,ABNT5101!$I:$I,ABNT5101!$L:$L) -> - | BB8: =_xlfn.XLOOKUP(K8,ABNT5101!$I:$I,ABNT5101!M:M) -> 0.28 | BC8: =_xlfn.XLOOKUP(K8,ABNT5101!$I:$I,ABNT5101!N:N) -> - | BD8: =_xlfn.XLOOKUP(K8,ABNT5101!$I:$I,ABNT5101!O:O) -> 14 | BE8: =IF(BO8="NÃO ATENDE","NÃO ATENDE",IF(BZ8="NÃO ATENDE","NÃO ATENDE",IF(CI8="NÃO ATENDE","NÃO ATENDE","ATENDE"))) -> ATENDE | BF8: =BI8/AY8-1 -> 0.173 | BG8: =BJ8/AZ8-1 -> 0 | BH8: =IF($K8="M6",BK8/BA8-1,"-") -> - | BI8: 23.46 | BJ8: 0.28 | BO8: =IF(OR(BP8="NÃO ATENDE",BQ8="NÃO ATENDE",BR8="NÃO ATENDE"),"NÃO ATENDE","ATENDE") -> ATENDE | BP8: =IF(BI8>=AY8,"ATENDE",IF(BI8>=0.99*AY8,"ATENDIMENTO LIMIAR","NÃO ATENDE")) -> ATENDE | BQ8: =IF(BJ8>=AZ8,"ATENDE",IF(BJ8>=(AZ8-0.02),"ATENDIMENTO LIMIAR","NÃO ATENDE")) -> ATENDE | BR8: =IF(BA8="-","ATENDE",IF(BK8>=BA8,"ATENDE",IF(BK8>=(BA8-0.02),"ATENDIMENTO LIMIAR","NÃO ATENDE"))) -> ATENDE | BS8: =K8 -> C2 | BT8: =M8 -> P4 | BU8: =IF(BV8="-","-",BV8/BX8-1) -> 0.041333333 | BV8: 7.81 | BW8: 2.29 | BX8: =IF(BT8="-","-",_xlfn.XLOOKUP(BT8,ABNT5101!$B$4:$B$9,ABNT5101!$C$4:$C$9)) -> 7.5 | BY8: =IF(BT8="-","-",_xlfn.XLOOKUP(BT8,ABNT5101!$B$4:$B$9,ABNT5101!$D$4:$D$9)) -> 1.5 | BZ8: =IF(CA8="-","-",IF(CA8="NÃO ATENDE","NÃO ATENDE",IF(CB8="NÃO ATENDE","NÃO ATENDE","ATENDE"))) -> ATENDE | CA8: =IF(BT8="-","-",IF(BV8>=BX8,"ATENDE",IF(BV8>=(BX8*0.99),"ATENDIMENTO LIMIAR","NÃO ATENDE"))) -> ATENDE | CB8: =IF(BT8="-","-",IF(BW8>=BY8,"ATENDE","NÃO ATENDE")) -> ATENDE | CC8: =BT8 -> P4 | CD8: =IF(CE8="-","-",CE8/CG8-1) -> #DIV/0! | CE8: 15.28 | CF8: 8.51 | CI8: =IF(CJ8="-","-",IF(CJ8="NÃO ATENDE","NÃO ATENDE",IF(CK8="NÃO ATENDE","NÃO ATENDE","ATENDE"))) -> ATENDE | CJ8: =IF(CC8="-","-",IF(CE8>=(CG8),"ATENDE",IF(CE8>=(0.99*CG8),"ATENDIMENTO LIMIAR","NÃO ATENDE"))) -> ATENDE | CK8: =IF(CC8="-","-",IF(CF8>=CH8,"ATENDE","NÃO ATENDE")) -> ATENDE | CL8: =_xlfn.XLOOKUP(CM8,'Banco de dados'!$B:$B,'Banco de dados'!$D:$D) -> LEDSTAR | CM8: ='Banco de dados'!B28 -> SL VT 9.1 100W | CN8: =_xlfn.XLOOKUP(CM8,'Banco de dados'!$B:$B,'Banco de dados'!$E:$E) -> LUM LED SL VT 9.1 100W | CP8: =IF(CO8="-","-",_xlfn.XLOOKUP(CO8,'Banco de dados'!$B:$B,'Banco de dados'!$E:$E)) -> 0 | CQ8: =AI8 -> 1 | CR8: =_xlfn.XLOOKUP(CM8,'Banco de dados'!$B:$B,'Banco de dados'!$H:$H) -> 100 | CS8: =_xlfn.XLOOKUP(CO8,'Banco de dados'!$B:$B,'Banco de dados'!$H:$H) -> 0 | CT8: =_xlfn.XLOOKUP(CM8,'Banco de dados'!$B:$B,'Banco de dados'!$F:$F) -> 15900 | CU8: =_xlfn.XLOOKUP(CO8,'Banco de dados'!$B:$B,'Banco de dados'!$F:$F) -> 0 | CX8: =IF(AK8<=0.5,"Curto I",IF(AND(AK8>='Braços de IP'!$B$9,AK8<='Braços de IP'!$D$9),'Braços de IP'!$E$9,IF(AND(AK8>='Braços de IP'!$B$10,AK8<='Braços de IP'!$D$10),'Braços de IP'!$E$10,IF(AND(AK8>='Braços de IP'!$B$11,AK8<='Braços de IP'!$D$11),'Braços de IP'!$E$11,IF(AND(AK8>='Braços de IP'!$B$12,AK8<='Braços de IP'!$D$12),'Braços de IP'!$E$12,IF(AND(AK8>='Braços de IP'!$B$13,AK8<='Braços de IP'!$D$13),'Braços de IP'!$E$13,IF(AND(AK8>='Braços de IP'!$B$14,AK8<='Braços de IP'!$D$14),'Braços de IP'!$E$14,"ERRO"))))))) -> Longo I | CZ8: =IF($CY8="","",VLOOKUP($CY8,'Braços de IP'!$E$9:$I$15,2,0)) | DA8: =IF($CY8="","",VLOOKUP($CY8,'Braços de IP'!$E$9:$I$15,5,0)) | DH8: =CR8 -> 100 | DI8: =O8 -> 200 | DJ8: =SUM(DH8:DI8)*CQ8 -> 300 | DK8: =1-DH8/DI8 -> 0.5 | DN8: Sim | DQ8: =((O8+P8)-CR8)/(O8+P8) -> 0.5
A9: Verificado que a estrutura predominante é PVP / Corrigido a distancia do poste a via de 0.70 para 3, não foi considerado inicialmente o estacionamento de 2.30. | F9: 221272180 | G9: (V) PVP | H9: Avenida Bento Gonçalves | I9: -19.557925 | J9: -44.085391 | K9: C2 | M9: P4 | N9: LED | O9: 200 | S9: 2 | T9: 1.5 | U9: 6.5 | Y9: 1.5 | AC9: 2.3 | AD9: 2.3 | AE9: Unilateral | AF9: Braço | AG9: 37.3 | AH9: 7.6 | AI9: 1 | AJ9: 3 | AK9: 3.2 | AL9: =AK9-AJ9 -> 0.2 | AM9: - | AN9: - | AO9: Não | AP9: =IF(AE9="Unilateral",2*AI9,IF(AE9="Bilateral Alternada",3*AI9,IF(AE9="Bilateral Frontal",4*AI9,IF(AE9="Canteiro Central",2*AI9,"erro")))) -> 2 | AQ9: 0 | AR9: 0 | AS9: 0 | AT9: 0 | AU9: 0 | AV9: 0 | AW9: =IF(AQ9=0,0,IF(AE9="Unilateral",2*AQ9,IF(AE9="Bilateral Alternada",3*AQ9,IF(AE9="Bilateral Frontal",4*AQ9,IF(AE9="Canteiro Central",2*AQ9,"erro"))))) -> 0 | AY9: =VLOOKUP(K9,ABNT5101!$I$3:$J$9,2) -> 20 | AZ9: =VLOOKUP(K9,ABNT5101!$I$3:$M$9,5) -> 0.28 | BA9: =_xlfn.XLOOKUP(K9,ABNT5101!$I:$I,ABNT5101!$L:$L) -> - | BB9: =_xlfn.XLOOKUP(K9,ABNT5101!$I:$I,ABNT5101!M:M) -> 0.28 | BC9: =_xlfn.XLOOKUP(K9,ABNT5101!$I:$I,ABNT5101!N:N) -> - | BD9: =_xlfn.XLOOKUP(K9,ABNT5101!$I:$I,ABNT5101!O:O) -> 14 | BE9: =IF(BO9="NÃO ATENDE","NÃO ATENDE",IF(BZ9="NÃO ATENDE","NÃO ATENDE",IF(CI9="NÃO ATENDE","NÃO ATENDE","ATENDE"))) -> ATENDE | BF9: =BI9/AY9-1 -> 0.1455 | BG9: =BJ9/AZ9-1 -> 0.53571429 | BH9: =IF($K9="M6",BK9/BA9-1,"-") -> - | BI9: 22.91 | BJ9: 0.43 | BO9: =IF(OR(BP9="NÃO ATENDE",BQ9="NÃO ATENDE",BR9="NÃO ATENDE"),"NÃO ATENDE","ATENDE") -> ATENDE | BP9: =IF(BI9>=AY9,"ATENDE",IF(BI9>=0.99*AY9,"ATENDIMENTO LIMIAR","NÃO ATENDE")) -> ATENDE | BQ9: =IF(BJ9>=AZ9,"ATENDE",IF(BJ9>=(AZ9-0.02),"ATENDIMENTO LIMIAR","NÃO ATENDE")) -> ATENDE | BR9: =IF(BA9="-","ATENDE",IF(BK9>=BA9,"ATENDE",IF(BK9>=(BA9-0.02),"ATENDIMENTO LIMIAR","NÃO ATENDE"))) -> ATENDE | BS9: =K9 -> C2 | BT9: =M9 -> P4 | BU9: =IF(BV9="-","-",BV9/BX9-1) -> 0.16133333 | BV9: 8.71 | BW9: 3.95 | BX9: =IF(BT9="-","-",_xlfn.XLOOKUP(BT9,ABNT5101!$B$4:$B$9,ABNT5101!$C$4:$C$9)) -> 7.5 | BY9: =IF(BT9="-","-",_xlfn.XLOOKUP(BT9,ABNT5101!$B$4:$B$9,ABNT5101!$D$4:$D$9)) -> 1.5 | BZ9: =IF(CA9="-","-",IF(CA9="NÃO ATENDE","NÃO ATENDE",IF(CB9="NÃO ATENDE","NÃO ATENDE","ATENDE"))) -> ATENDE | CA9: =IF(BT9="-","-",IF(BV9>=BX9,"ATENDE",IF(BV9>=(BX9*0.99),"ATENDIMENTO LIMIAR","NÃO ATENDE"))) -> ATENDE | CB9: =IF(BT9="-","-",IF(BW9>=BY9,"ATENDE","NÃO ATENDE")) -> ATENDE | CC9: =BT9 -> P4 | CD9: =IF(CE9="-","-",CE9/CG9-1) -> #DIV/0! | CE9: 16.32 | CF9: 7.07 | CI9: =IF(CJ9="-","-",IF(CJ9="NÃO ATENDE","NÃO ATENDE",IF(CK9="NÃO ATENDE","NÃO ATENDE","ATENDE"))) -> ATENDE | CJ9: =IF(CC9="-","-",IF(CE9>=(CG9),"ATENDE",IF(CE9>=(0.99*CG9),"ATENDIMENTO LIMIAR","NÃO ATENDE"))) -> ATENDE | CK9: =IF(CC9="-","-",IF(CF9>=CH9,"ATENDE","NÃO ATENDE")) -> ATENDE | CL9: =_xlfn.XLOOKUP(CM9,'Banco de dados'!$B:$B,'Banco de dados'!$D:$D) -> SX LIGHTING | CM9: ='Banco de dados'!B62 -> SX-INLPP090HF | CN9: =_xlfn.XLOOKUP(CM9,'Banco de dados'!$B:$B,'Banco de dados'!$E:$E) -> SXINLPP090K40L12CZF7PHF | CP9: =IF(CO9="-","-",_xlfn.XLOOKUP(CO9,'Banco de dados'!$B:$B,'Banco de dados'!$E:$E)) -> 0 | CQ9: =AI9 -> 1 | CR9: =_xlfn.XLOOKUP(CM9,'Banco de dados'!$B:$B,'Banco de dados'!$H:$H) -> 90 | CS9: =_xlfn.XLOOKUP(CO9,'Banco de dados'!$B:$B,'Banco de dados'!$H:$H) -> 0 | CT9: =_xlfn.XLOOKUP(CM9,'Banco de dados'!$B:$B,'Banco de dados'!$F:$F) -> 15476 | CU9: =_xlfn.XLOOKUP(CO9,'Banco de dados'!$B:$B,'Banco de dados'!$F:$F) -> 0 | CX9: =IF(AK9<=0.5,"Curto I",IF(AND(AK9>='Braços de IP'!$B$9,AK9<='Braços de IP'!$D$9),'Braços de IP'!$E$9,IF(AND(AK9>='Braços de IP'!$B$10,AK9<='Braços de IP'!$D$10),'Braços de IP'!$E$10,IF(AND(AK9>='Braços de IP'!$B$11,AK9<='Braços de IP'!$D$11),'Braços de IP'!$E$11,IF(AND(AK9>='Braços de IP'!$B$12,AK9<='Braços de IP'!$D$12),'Braços de IP'!$E$12,IF(AND(AK9>='Braços de IP'!$B$13,AK9<='Braços de IP'!$D$13),'Braços de IP'!$E$13,IF(AND(AK9>='Braços de IP'!$B$14,AK9<='Braços de IP'!$D$14),'Braços de IP'!$E$14,"ERRO"))))))) -> Longo I | CZ9: =IF($CY9="","",VLOOKUP($CY9,'Braços de IP'!$E$9:$I$15,2,0)) | DA9: =IF($CY9="","",VLOOKUP($CY9,'Braços de IP'!$E$9:$I$15,5,0)) | DH9: =CR9 -> 90 | DI9: =O9 -> 200 | DJ9: =SUM(DH9:DI9)*CQ9 -> 290 | DK9: =1-DH9/DI9 -> 0.55 | DN9: Sim | DQ9: =((O9+P9)-CR9)/(O9+P9) -> 0.55
A10: Verificado que a estrutura predominante é PVP / Corrigido a distancia do poste a via de 0.70 para 3, não foi considerado inicialmente o estacionamento de 2.30. | F10: 221272180 | G10: (V) PVP | H10: Avenida Bento Gonçalves | I10: -19.557925 | J10: -44.085391 | K10: C2 | M10: P4 | N10: LED | O10: 200 | S10: 2 | T10: 1.5 | U10: 6.5 | Y10: 1.5 | AC10: 2.3 | AD10: 2.3 | AE10: Unilateral | AF10: Braço | AG10: 37.3 | AH10: 7.6 | AI10: 1 | AJ10: 3 | AK10: 3.2 | AL10: =AK10-AJ10 -> 0.2 | AM10: - | AN10: - | AO10: Não | AP10: =IF(AE10="Unilateral",2*AI10,IF(AE10="Bilateral Alternada",3*AI10,IF(AE10="Bilateral Frontal",4*AI10,IF(AE10="Canteiro Central",2*AI10,"erro")))) -> 2 | AQ10: 0 | AR10: 0 | AS10: 0 | AT10: 0 | AU10: 0 | AV10: 0 | AW10: =IF(AQ10=0,0,IF(AE10="Unilateral",2*AQ10,IF(AE10="Bilateral Alternada",3*AQ10,IF(AE10="Bilateral Frontal",4*AQ10,IF(AE10="Canteiro Central",2*AQ10,"erro"))))) -> 0 | AY10: =VLOOKUP(K10,ABNT5101!$I$3:$J$9,2) -> 20 | AZ10: =VLOOKUP(K10,ABNT5101!$I$3:$M$9,5) -> 0.28 | BA10: =_xlfn.XLOOKUP(K10,ABNT5101!$I:$I,ABNT5101!$L:$L) -> - | BB10: =_xlfn.XLOOKUP(K10,ABNT5101!$I:$I,ABNT5101!M:M) -> 0.28 | BC10: =_xlfn.XLOOKUP(K10,ABNT5101!$I:$I,ABNT5101!N:N) -> - | BD10: =_xlfn.XLOOKUP(K10,ABNT5101!$I:$I,ABNT5101!O:O) -> 14 | BE10: =IF(BO10="NÃO ATENDE","NÃO ATENDE",IF(BZ10="NÃO ATENDE","NÃO ATENDE",IF(CI10="NÃO ATENDE","NÃO ATENDE","ATENDE"))) -> ATENDE | BF10: =BI10/AY10-1 -> 0.0655 | BG10: =BJ10/AZ10-1 -> 0.39285714 | BH10: =IF($K10="M6",BK10/BA10-1,"-") -> - | BI10: 21.31 | BJ10: 0.39 | BO10: =IF(OR(BP10="NÃO ATENDE",BQ10="NÃO ATENDE",BR10="NÃO ATENDE"),"NÃO ATENDE","ATENDE") -> ATENDE | BP10: =IF(BI10>=AY10,"ATENDE",IF(BI10>=0.99*AY10,"ATENDIMENTO LIMIAR","NÃO ATENDE")) -> ATENDE | BQ10: =IF(BJ10>=AZ10,"ATENDE",IF(BJ10>=(AZ10-0.02),"ATENDIMENTO LIMIAR","NÃO ATENDE")) -> ATENDE | BR10: =IF(BA10="-","ATENDE",IF(BK10>=BA10,"ATENDE",IF(BK10>=(BA10-0.02),"ATENDIMENTO LIMIAR","NÃO ATENDE"))) -> ATENDE | BS10: =K10 -> C2 | BT10: =M10 -> P4 | BU10: =IF(BV10="-","-",BV10/BX10-1) -> 0.132 | BV10: 8.49 | BW10: 6.58 | BX10: =IF(BT10="-","-",_xlfn.XLOOKUP(BT10,ABNT5101!$B$4:$B$9,ABNT5101!$C$4:$C$9)) -> 7.5 | BY10: =IF(BT10="-","-",_xlfn.XLOOKUP(BT10,ABNT5101!$B$4:$B$9,ABNT5101!$D$4:$D$9)) -> 1.5 | BZ10: =IF(CA10="-","-",IF(CA10="NÃO ATENDE","NÃO ATENDE",IF(CB10="NÃO ATENDE","NÃO ATENDE","ATENDE"))) -> ATENDE | CA10: =IF(BT10="-","-",IF(BV10>=BX10,"ATENDE",IF(BV10>=(BX10*0.99),"ATENDIMENTO LIMIAR","NÃO ATENDE"))) -> ATENDE | CB10: =IF(BT10="-","-",IF(BW10>=BY10,"ATENDE","NÃO ATENDE")) -> ATENDE | CC10: =BT10 -> P4 | CD10: =IF(CE10="-","-",CE10/CG10-1) -> #DIV/0! | CE10: 10.63 | CF10: 2.55 | CI10: =IF(CJ10="-","-",IF(CJ10="NÃO ATENDE","NÃO ATENDE",IF(CK10="NÃO ATENDE","NÃO ATENDE","ATENDE"))) -> ATENDE | CJ10: =IF(CC10="-","-",IF(CE10>=(CG10),"ATENDE",IF(CE10>=(0.99*CG10),"ATENDIMENTO LIMIAR","NÃO ATENDE"))) -> ATENDE | CK10: =IF(CC10="-","-",IF(CF10>=CH10,"ATENDE","NÃO ATENDE")) -> ATENDE | CL10: =_xlfn.XLOOKUP(CM10,'Banco de dados'!$B:$B,'Banco de dados'!$D:$D) -> TECNOWATT | CM10: ='Banco de dados'!B75 -> SIGSAGPTLRRSSNDL100W125IBBRS | CN10: =_xlfn.XLOOKUP(CM10,'Banco de dados'!$B:$B,'Banco de dados'!$E:$E) -> SIGSAGPTLRRSSNDL100W125IBBRS 1-10C1MUN6.5 | CP10: =IF(CO10="-","-",_xlfn.XLOOKUP(CO10,'Banco de dados'!$B:$B,'Banco de dados'!$E:$E)) -> 0 | CQ10: =AI10 -> 1 | CR10: =_xlfn.XLOOKUP(CM10,'Banco de dados'!$B:$B,'Banco de dados'!$H:$H) -> 100 | CS10: =_xlfn.XLOOKUP(CO10,'Banco de dados'!$B:$B,'Banco de dados'!$H:$H) -> 0 | CT10: =_xlfn.XLOOKUP(CM10,'Banco de dados'!$B:$B,'Banco de dados'!$F:$F) -> 15162 | CU10: =_xlfn.XLOOKUP(CO10,'Banco de dados'!$B:$B,'Banco de dados'!$F:$F) -> 0 | CW10: 10 | CX10: =IF(AK10<=0.5,"Curto I",IF(AND(AK10>='Braços de IP'!$B$9,AK10<='Braços de IP'!$D$9),'Braços de IP'!$E$9,IF(AND(AK10>='Braços de IP'!$B$10,AK10<='Braços de IP'!$D$10),'Braços de IP'!$E$10,IF(AND(AK10>='Braços de IP'!$B$11,AK10<='Braços de IP'!$D$11),'Braços de IP'!$E$11,IF(AND(AK10>='Braços de IP'!$B$12,AK10<='Braços de IP'!$D$12),'Braços de IP'!$E$12,IF(AND(AK10>='Braços de IP'!$B$13,AK10<='Braços de IP'!$D$13),'Braços de IP'!$E$13,IF(AND(AK10>='Braços de IP'!$B$14,AK10<='Braços de IP'!$D$14),'Braços de IP'!$E$14,"ERRO"))))))) -> Longo I | CZ10: =IF($CY10="","",VLOOKUP($CY10,'Braços de IP'!$E$9:$I$15,2,0)) | DA10: =IF($CY10="","",VLOOKUP($CY10,'Braços de IP'!$E$9:$I$15,5,0)) | DH10: =CR10 -> 100 | DI10: =O10 -> 200 | DJ10: =SUM(DH10:DI10)*CQ10 -> 300 | DK10: =1-DH10/DI10 -> 0.5 | DN10: Sim | DQ10: =((O10+P10)-CR10)/(O10+P10) -> 0.5
B11: Alexandre | C11: ok | D11: Penelope | E11: ok | F11: 223927679 | G11: PVP | H11: Avenida André Faveli | I11: -19.555051 | J11: -44.096336 | K11: C2 | M11: P6 | N11: LED | O11: 100 | S11: 1 | T11: 1.6 | U11: 9.2 | Y11: 1.6 | AE11: Unilateral | AF11: Braço | AG11: 25.3 | AH11: 8.5 | AI11: 1 | AJ11: 0.15 | AK11: 2.9 | AL11: =AK11-AJ11 -> 2.75 | AM11: - | AN11: - | AO11: Não | AP11: =IF(AE11="Unilateral",2*AI11,IF(AE11="Bilateral Alternada",3*AI11,IF(AE11="Bilateral Frontal",4*AI11,IF(AE11="Canteiro Central",2*AI11,"erro")))) -> 2 | AQ11: 0 | AR11: 0 | AS11: 0 | AT11: 0 | AU11: 0 | AV11: 0 | AW11: =IF(AQ11=0,0,IF(AE11="Unilateral",2*AQ11,IF(AE11="Bilateral Alternada",3*AQ11,IF(AE11="Bilateral Frontal",4*AQ11,IF(AE11="Canteiro Central",2*AQ11,"erro"))))) -> 0 | AY11: =VLOOKUP(K11,ABNT5101!$I$3:$J$9,2) -> 20 | AZ11: =VLOOKUP(K11,ABNT5101!$I$3:$M$9,5) -> 0.28 | BA11: =_xlfn.XLOOKUP(K11,ABNT5101!$I:$I,ABNT5101!$L:$L) -> - | BB11: =_xlfn.XLOOKUP(K11,ABNT5101!$I:$I,ABNT5101!M:M) -> 0.28 | BC11: =_xlfn.XLOOKUP(K11,ABNT5101!$I:$I,ABNT5101!N:N) -> - | BD11: =_xlfn.XLOOKUP(K11,ABNT5101!$I:$I,ABNT5101!O:O) -> 14 | BE11: =IF(BO11="NÃO ATENDE","NÃO ATENDE",IF(BZ11="NÃO ATENDE","NÃO ATENDE",IF(CI11="NÃO ATENDE","NÃO ATENDE","ATENDE"))) -> ATENDE | BF11: =BI11/AY11-1 -> 0.0505 | BG11: =BJ11/AZ11-1 -> 1.2857143 | BH11: =IF($K11="M6",BK11/BA11-1,"-") -> - | BI11: 21.01 | BJ11: 0.64 | BO11: =IF(OR(BP11="NÃO ATENDE",BQ11="NÃO ATENDE",BR11="NÃO ATENDE"),"NÃO ATENDE","ATENDE") -> ATENDE | BP11: =IF(BI11>=AY11,"ATENDE",IF(BI11>=0.99*AY11,"ATENDIMENTO LIMIAR","NÃO ATENDE")) -> ATENDE | BQ11: =IF(BJ11>=AZ11,"ATENDE",IF(BJ11>=(AZ11-0.02),"ATENDIMENTO LIMIAR","NÃO ATENDE")) -> ATENDE | BR11: =IF(BA11="-","ATENDE",IF(BK11>=BA11,"ATENDE",IF(BK11>=(BA11-0.02),"ATENDIMENTO LIMIAR","NÃO ATENDE"))) -> ATENDE | BS11: =K11 -> C2 | BT11: =M11 -> P6 | BU11: =IF(BV11="-","-",BV11/BX11-1) -> 4.03 | BV11: 15.09 | BW11: 9.75 | BX11: =IF(BT11="-","-",_xlfn.XLOOKUP(BT11,ABNT5101!$B$4:$B$9,ABNT5101!$C$4:$C$9)) -> 3 | BY11: =IF(BT11="-","-",_xlfn.XLOOKUP(BT11,ABNT5101!$B$4:$B$9,ABNT5101!$D$4:$D$9)) -> 0.6 | BZ11: =IF(CA11="-","-",IF(CA11="NÃO ATENDE","NÃO ATENDE",IF(CB11="NÃO ATENDE","NÃO ATENDE","ATENDE"))) -> ATENDE | CA11: =IF(BT11="-","-",IF(BV11>=BX11,"ATENDE",IF(BV11>=(BX11*0.99),"ATENDIMENTO LIMIAR","NÃO ATENDE"))) -> ATENDE | CB11: =IF(BT11="-","-",IF(BW11>=BY11,"ATENDE","NÃO ATENDE")) -> ATENDE | CC11: =BT11 -> P6 | CD11: =IF(CE11="-","-",CE11/CG11-1) -> #DIV/0! | CE11: 14.24 | CF11: 10.83 | CI11: =IF(CJ11="-","-",IF(CJ11="NÃO ATENDE","NÃO ATENDE",IF(CK11="NÃO ATENDE","NÃO ATENDE","ATENDE"))) -> ATENDE | CJ11: =IF(CC11="-","-",IF(CE11>=(CG11),"ATENDE",IF(CE11>=(0.99*CG11),"ATENDIMENTO LIMIAR","NÃO ATENDE"))) -> ATENDE | CK11: =IF(CC11="-","-",IF(CF11>=CH11,"ATENDE","NÃO ATENDE")) -> ATENDE | CL11: =_xlfn.XLOOKUP(CM11,'Banco de dados'!$B:$B,'Banco de dados'!$D:$D) -> LEDSTAR | CM11: ='Banco de dados'!B22 -> SL VT 9.1 72W | CN11: =_xlfn.XLOOKUP(CM11,'Banco de dados'!$B:$B,'Banco de dados'!$E:$E) -> LUM LED SL VT 9.1 72W | CP11: =IF(CO11="-","-",_xlfn.XLOOKUP(CO11,'Banco de dados'!$B:$B,'Banco de dados'!$E:$E)) -> 0 | CQ11: =AI11 -> 1 | CR11: =_xlfn.XLOOKUP(CM11,'Banco de dados'!$B:$B,'Banco de dados'!$H:$H) -> 72 | CS11: =_xlfn.XLOOKUP(CO11,'Banco de dados'!$B:$B,'Banco de dados'!$H:$H) -> 0 | CT11: =_xlfn.XLOOKUP(CM11,'Banco de dados'!$B:$B,'Banco de dados'!$F:$F) -> 12107 | CU11: =_xlfn.XLOOKUP(CO11,'Banco de dados'!$B:$B,'Banco de dados'!$F:$F) -> 0 | CX11: =IF(AK11<=0.5,"Curto I",IF(AND(AK11>='Braços de IP'!$B$9,AK11<='Braços de IP'!$D$9),'Braços de IP'!$E$9,IF(AND(AK11>='Braços de IP'!$B$10,AK11<='Braços de IP'!$D$10),'Braços de IP'!$E$10,IF(AND(AK11>='Braços de IP'!$B$11,AK11<='Braços de IP'!$D$11),'Braços de IP'!$E$11,IF(AND(AK11>='Braços de IP'!$B$12,AK11<='Braços de IP'!$D$12),'Braços de IP'!$E$12,IF(AND(AK11>='Braços de IP'!$B$13,AK11<='Braços de IP'!$D$13),'Braços de IP'!$E$13,IF(AND(AK11>='Braços de IP'!$B$14,AK11<='Braços de IP'!$D$14),'Braços de IP'!$E$14,"ERRO"))))))) -> Longo I | CZ11: =IF($CY11="","",VLOOKUP($CY11,'Braços de IP'!$E$9:$I$15,2,0)) | DA11: =IF($CY11="","",VLOOKUP($CY11,'Braços de IP'!$E$9:$I$15,5,0)) | DH11: =CR11 -> 72 | DI11: =O11 -> 100 | DJ11: =SUM(DH11:DI11)*CQ11 -> 172 | DK11: =1-DH11/DI11 -> 0.28 | DN11: Sim | DQ11: =((O11+P11)-CR11)/(O11+P11) -> 0.28
F12: 223927679 | G12: PVP | H12: Avenida André Faveli | I12: -19.555051 | J12: -44.096336 | K12: C2 | M12: P6 | N12: LED | O12: 100 | S12: 1 | T12: 1.6 | U12: 9.2 | Y12: 1.6 | AE12: Unilateral | AF12: Braço | AG12: 25.3 | AH12: 8.5 | AI12: 1 | AJ12: 0.15 | AK12: 2.9 | AL12: =AK12-AJ12 -> 2.75 | AM12: - | AN12: - | AO12: Não | AP12: =IF(AE12="Unilateral",2*AI12,IF(AE12="Bilateral Alternada",3*AI12,IF(AE12="Bilateral Frontal",4*AI12,IF(AE12="Canteiro Central",2*AI12,"erro")))) -> 2 | AQ12: 0 | AR12: 0 | AS12: 0 | AT12: 0 | AU12: 0 | AV12: 0 | AW12: =IF(AQ12=0,0,IF(AE12="Unilateral",2*AQ12,IF(AE12="Bilateral Alternada",3*AQ12,IF(AE12="Bilateral Frontal",4*AQ12,IF(AE12="Canteiro Central",2*AQ12,"erro"))))) -> 0 | AY12: =VLOOKUP(K12,ABNT5101!$I$3:$J$9,2) -> 20 | AZ12: =VLOOKUP(K12,ABNT5101!$I$3:$M$9,5) -> 0.28 | BA12: =_xlfn.XLOOKUP(K12,ABNT5101!$I:$I,ABNT5101!$L:$L) -> - | BB12: =_xlfn.XLOOKUP(K12,ABNT5101!$I:$I,ABNT5101!M:M) -> 0.28 | BC12: =_xlfn.XLOOKUP(K12,ABNT5101!$I:$I,ABNT5101!N:N) -> - | BD12: =_xlfn.XLOOKUP(K12,ABNT5101!$I:$I,ABNT5101!O:O) -> 14 | BE12: =IF(BO12="NÃO ATENDE","NÃO ATENDE",IF(BZ12="NÃO ATENDE","NÃO ATENDE",IF(CI12="NÃO ATENDE","NÃO ATENDE","ATENDE"))) -> ATENDE | BF12: =BI12/AY12-1 -> 0.219 | BG12: =BJ12/AZ12-1 -> 1.3928571 | BH12: =IF($K12="M6",BK12/BA12-1,"-") -> - | BI12: 24.38 | BJ12: 0.67 | BO12: =IF(OR(BP12="NÃO ATENDE",BQ12="NÃO ATENDE",BR12="NÃO ATENDE"),"NÃO ATENDE","ATENDE") -> ATENDE | BP12: =IF(BI12>=AY12,"ATENDE",IF(BI12>=0.99*AY12,"ATENDIMENTO LIMIAR","NÃO ATENDE")) -> ATENDE | BQ12: =IF(BJ12>=AZ12,"ATENDE",IF(BJ12>=(AZ12-0.02),"ATENDIMENTO LIMIAR","NÃO ATENDE")) -> ATENDE | BR12: =IF(BA12="-","ATENDE",IF(BK12>=BA12,"ATENDE",IF(BK12>=(BA12-0.02),"ATENDIMENTO LIMIAR","NÃO ATENDE"))) -> ATENDE | BS12: =K12 -> C2 | BT12: =M12 -> P6 | BU12: =IF(BV12="-","-",BV12/BX12-1) -> 5 | BV12: 18 | BW12: 13.4 | BX12: =IF(BT12="-","-",_xlfn.XLOOKUP(BT12,ABNT5101!$B$4:$B$9,ABNT5101!$C$4:$C$9)) -> 3 | BY12: =IF(BT12="-","-",_xlfn.XLOOKUP(BT12,ABNT5101!$B$4:$B$9,ABNT5101!$D$4:$D$9)) -> 0.6 | BZ12: =IF(CA12="-","-",IF(CA12="NÃO ATENDE","NÃO ATENDE",IF(CB12="NÃO ATENDE","NÃO ATENDE","ATENDE"))) -> ATENDE | CA12: =IF(BT12="-","-",IF(BV12>=BX12,"ATENDE",IF(BV12>=(BX12*0.99),"ATENDIMENTO LIMIAR","NÃO ATENDE"))) -> ATENDE | CB12: =IF(BT12="-","-",IF(BW12>=BY12,"ATENDE","NÃO ATENDE")) -> ATENDE | CC12: =BT12 -> P6 | CD12: =IF(CE12="-","-",CE12/CG12-1) -> #DIV/0! | CE12: 18.06 | CF12: 13.17 | CI12: =IF(CJ12="-","-",IF(CJ12="NÃO ATENDE","NÃO ATENDE",IF(CK12="NÃO ATENDE","NÃO ATENDE","ATENDE"))) -> ATENDE | CJ12: =IF(CC12="-","-",IF(CE12>=(CG12),"ATENDE",IF(CE12>=(0.99*CG12),"ATENDIMENTO LIMIAR","NÃO ATENDE"))) -> ATENDE | CK12: =IF(CC12="-","-",IF(CF12>=CH12,"ATENDE","NÃO ATENDE")) -> ATENDE | CL12: =_xlfn.XLOOKUP(CM12,'Banco de dados'!$B:$B,'Banco de dados'!$D:$D) -> SX LIGHTING | CM12: ='Banco de dados'!B60 -> SX-INLPP070HF | CN12: =_xlfn.XLOOKUP(CM12,'Banco de dados'!$B:$B,'Banco de dados'!$E:$E) -> SXINLPP070K40L12CZF7PHF | CP12: =IF(CO12="-","-",_xlfn.XLOOKUP(CO12,'Banco de dados'!$B:$B,'Banco de dados'!$E:$E)) -> 0 | CQ12: =AI12 -> 1 | CR12: =_xlfn.XLOOKUP(CM12,'Banco de dados'!$B:$B,'Banco de dados'!$H:$H) -> 70 | CS12: =_xlfn.XLOOKUP(CO12,'Banco de dados'!$B:$B,'Banco de dados'!$H:$H) -> 0 | CT12: =_xlfn.XLOOKUP(CM12,'Banco de dados'!$B:$B,'Banco de dados'!$F:$F) -> 11970 | CU12: =_xlfn.XLOOKUP(CO12,'Banco de dados'!$B:$B,'Banco de dados'!$F:$F) -> 0 | CX12: =IF(AK12<=0.5,"Curto I",IF(AND(AK12>='Braços de IP'!$B$9,AK12<='Braços de IP'!$D$9),'Braços de IP'!$E$9,IF(AND(AK12>='Braços de IP'!$B$10,AK12<='Braços de IP'!$D$10),'Braços de IP'!$E$10,IF(AND(AK12>='Braços de IP'!$B$11,AK12<='Braços de IP'!$D$11),'Braços de IP'!$E$11,IF(AND(AK12>='Braços de IP'!$B$12,AK12<='Braços de IP'!$D$12),'Braços de IP'!$E$12,IF(AND(AK12>='Braços de IP'!$B$13,AK12<='Braços de IP'!$D$13),'Braços de IP'!$E$13,IF(AND(AK12>='Braços de IP'!$B$14,AK12<='Braços de IP'!$D$14),'Braços de IP'!$E$14,"ERRO"))))))) -> Longo I | CZ12: =IF($CY12="","",VLOOKUP($CY12,'Braços de IP'!$E$9:$I$15,2,0)) | DA12: =IF($CY12="","",VLOOKUP($CY12,'Braços de IP'!$E$9:$I$15,5,0)) | DH12: =CR12 -> 70 | DI12: =O12 -> 100 | DJ12: =SUM(DH12:DI12)*CQ12 -> 170 | DK12: =1-DH12/DI12 -> 0.3 | DN12: Sim | DQ12: =((O12+P12)-CR12)/(O12+P12) -> 0.3
F13: 223927679 | G13: PVP | H13: Avenida André Faveli | I13: -19.555051 | J13: -44.096336 | K13: C2 | M13: P6 | N13: LED | O13: 100 | S13: 1 | T13: 1.6 | U13: 9.2 | Y13: 1.6 | AE13: Unilateral | AF13: Braço | AG13: 25.3 | AH13: 8.5 | AI13: 1 | AJ13: 0.15 | AK13: 2.9 | AL13: =AK13-AJ13 -> 2.75 | AM13: - | AN13: - | AO13: Não | AP13: =IF(AE13="Unilateral",2*AI13,IF(AE13="Bilateral Alternada",3*AI13,IF(AE13="Bilateral Frontal",4*AI13,IF(AE13="Canteiro Central",2*AI13,"erro")))) -> 2 | AQ13: 0 | AR13: 0 | AS13: 0 | AT13: 0 | AU13: 0 | AV13: 0 | AW13: =IF(AQ13=0,0,IF(AE13="Unilateral",2*AQ13,IF(AE13="Bilateral Alternada",3*AQ13,IF(AE13="Bilateral Frontal",4*AQ13,IF(AE13="Canteiro Central",2*AQ13,"erro"))))) -> 0 | AY13: =VLOOKUP(K13,ABNT5101!$I$3:$J$9,2) -> 20 | AZ13: =VLOOKUP(K13,ABNT5101!$I$3:$M$9,5) -> 0.28 | BA13: =_xlfn.XLOOKUP(K13,ABNT5101!$I:$I,ABNT5101!$L:$L) -> - | BB13: =_xlfn.XLOOKUP(K13,ABNT5101!$I:$I,ABNT5101!M:M) -> 0.28 | BC13: =_xlfn.XLOOKUP(K13,ABNT5101!$I:$I,ABNT5101!N:N) -> - | BD13: =_xlfn.XLOOKUP(K13,ABNT5101!$I:$I,ABNT5101!O:O) -> 14 | BE13: =IF(BO13="NÃO ATENDE","NÃO ATENDE",IF(BZ13="NÃO ATENDE","NÃO ATENDE",IF(CI13="NÃO ATENDE","NÃO ATENDE","ATENDE"))) -> ATENDE | BF13: =BI13/AY13-1 -> 0.0575 | BG13: =BJ13/AZ13-1 -> 1.9642857 | BH13: =IF($K13="M6",BK13/BA13-1,"-") -> - | BI13: 21.15 | BJ13: 0.83 | BO13: =IF(OR(BP13="NÃO ATENDE",BQ13="NÃO ATENDE",BR13="NÃO ATENDE"),"NÃO ATENDE","ATENDE") -> ATENDE | BP13: =IF(BI13>=AY13,"ATENDE",IF(BI13>=0.99*AY13,"ATENDIMENTO LIMIAR","NÃO ATENDE")) -> ATENDE | BQ13: =IF(BJ13>=AZ13,"ATENDE",IF(BJ13>=(AZ13-0.02),"ATENDIMENTO LIMIAR","NÃO ATENDE")) -> ATENDE | BR13: =IF(BA13="-","ATENDE",IF(BK13>=BA13,"ATENDE",IF(BK13>=(BA13-0.02),"ATENDIMENTO LIMIAR","NÃO ATENDE"))) -> ATENDE | BS13: =K13 -> C2 | BT13: =M13 -> P6 | BU13: =IF(BV13="-","-",BV13/BX13-1) -> 3.2033333 | BV13: 12.61 | BW13: 10.01 | BX13: =IF(BT13="-","-",_xlfn.XLOOKUP(BT13,ABNT5101!$B$4:$B$9,ABNT5101!$C$4:$C$9)) -> 3 | BY13: =IF(BT13="-","-",_xlfn.XLOOKUP(BT13,ABNT5101!$B$4:$B$9,ABNT5101!$D$4:$D$9)) -> 0.6 | BZ13: =IF(CA13="-","-",IF(CA13="NÃO ATENDE","NÃO ATENDE",IF(CB13="NÃO ATENDE","NÃO ATENDE","ATENDE"))) -> ATENDE | CA13: =IF(BT13="-","-",IF(BV13>=BX13,"ATENDE",IF(BV13>=(BX13*0.99),"ATENDIMENTO LIMIAR","NÃO ATENDE"))) -> ATENDE | CB13: =IF(BT13="-","-",IF(BW13>=BY13,"ATENDE","NÃO ATENDE")) -> ATENDE | CC13: =BT13 -> P6 | CD13: =IF(CE13="-","-",CE13/CG13-1) -> #DIV/0! | CE13: 13.48 | CF13: 11.34 | CI13: =IF(CJ13="-","-",IF(CJ13="NÃO ATENDE","NÃO ATENDE",IF(CK13="NÃO ATENDE","NÃO ATENDE","ATENDE"))) -> ATENDE | CJ13: =IF(CC13="-","-",IF(CE13>=(CG13),"ATENDE",IF(CE13>=(0.99*CG13),"ATENDIMENTO LIMIAR","NÃO ATENDE"))) -> ATENDE | CK13: =IF(CC13="-","-",IF(CF13>=CH13,"ATENDE","NÃO ATENDE")) -> ATENDE | CL13: =_xlfn.XLOOKUP(CM13,'Banco de dados'!$B:$B,'Banco de dados'!$D:$D) -> TECNOWATT | CM13: ='Banco de dados'!B72 -> SIGSAGPTLRRSSNDL_68W_83IBBRS | CN13: =_xlfn.XLOOKUP(CM13,'Banco de dados'!$B:$B,'Banco de dados'!$E:$E) -> SIGSAGPTLRRSSNDL_68W_83IBBRS 1-10C1MUN6.5 | CP13: =IF(CO13="-","-",_xlfn.XLOOKUP(CO13,'Banco de dados'!$B:$B,'Banco de dados'!$E:$E)) -> 0 | CQ13: =AI13 -> 1 | CR13: =_xlfn.XLOOKUP(CM13,'Banco de dados'!$B:$B,'Banco de dados'!$H:$H) -> 68 | CS13: =_xlfn.XLOOKUP(CO13,'Banco de dados'!$B:$B,'Banco de dados'!$H:$H) -> 0 | CT13: =_xlfn.XLOOKUP(CM13,'Banco de dados'!$B:$B,'Banco de dados'!$F:$F) -> 10884 | CU13: =_xlfn.XLOOKUP(CO13,'Banco de dados'!$B:$B,'Banco de dados'!$F:$F) -> 0 | CX13: =IF(AK13<=0.5,"Curto I",IF(AND(AK13>='Braços de IP'!$B$9,AK13<='Braços de IP'!$D$9),'Braços de IP'!$E$9,IF(AND(AK13>='Braços de IP'!$B$10,AK13<='Braços de IP'!$D$10),'Braços de IP'!$E$10,IF(AND(AK13>='Braços de IP'!$B$11,AK13<='Braços de IP'!$D$11),'Braços de IP'!$E$11,IF(AND(AK13>='Braços de IP'!$B$12,AK13<='Braços de IP'!$D$12),'Braços de IP'!$E$12,IF(AND(AK13>='Braços de IP'!$B$13,AK13<='Braços de IP'!$D$13),'Braços de IP'!$E$13,IF(AND(AK13>='Braços de IP'!$B$14,AK13<='Braços de IP'!$D$14),'Braços de IP'!$E$14,"ERRO"))))))) -> Longo I | CZ13: =IF($CY13="","",VLOOKUP($CY13,'Braços de IP'!$E$9:$I$15,2,0)) | DA13: =IF($CY13="","",VLOOKUP($CY13,'Braços de IP'!$E$9:$I$15,5,0)) | DH13: =CR13 -> 68 | DI13: =O13 -> 100 | DJ13: =SUM(DH13:DI13)*CQ13 -> 168 | DK13: =1-DH13/DI13 -> 0.32 | DN13: Sim | DQ13: =((O13+P13)-CR13)/(O13+P13) -> 0.32
