Workbook
Name Banco_Tipologias: Banco_Tipologias!$C$4:$N$17
Name colunaclasses: Simulações!$BQ$2:$BQ$964
Name ilumatic: '[1]Banco de dados (2)'!#REF!
Name ilumatic: 'Banco de dados'!#REF!
Name philips: '[1]Banco de dados (2)'!#REF!
Name philips: 'Banco de dados'!#REF!
Name red_global: '[1]Banco de dados (2)'!#REF!
Name red_global: 'Banco de dados'!#REF!
Name red_juganu: '[1]Banco de dados (2)'!#REF!
Name red_juganu: 'Banco de dados'!#REF!
Name red_philips: '[1]Banco de dados (2)'!#REF!
Name red_philips: 'Banco de dados'!#REF!
Name red_repume: '[1]Banco de dados (2)'!#REF!
Name red_repume: 'Banco de dados'!#REF!
Name red_tecno: '[1]Banco de dados (2)'!#REF!
Name red_tecno: 'Banco de dados'!#REF!
Name redglobal: '[1]Banco de dados (2)'!#REF!
Name redglobal: 'Banco de dados'!#REF!
Name tecnowat: '[1]Banco de dados (2)'!#REF!
Name tecnowat: 'Banco de dados'!#REF!

Sheet DefiniçãoFornecedores
D2: Estruturas
B3: Definição | D3: V1 | E3: V2 | F3: V3 | G3: V4 | H3: V5 | I3: Observação
B4: Fornecedor L1 | C4: Conexled | D4: 0 | E4: 0 | F4: 0 | G4: 0 | H4: 0 | I4: Não possui orçamento
B5: Fornecedor L2 | C5: Ilumatic | D5: 0 | E5: 0 | F5: 0 | G5: 0 | H5: 0 | I5: Não possui orçamento
B6: Fornecedor L3 | C6: Juganu | D6: 0 | E6: 0 | F6: 0 | G6: 0 | H6: 0 | I6: Possui orçamento, definir qual classe melhor atende
B7: Fornecedor L4 | C7: Philips | D7: 1 | E7: 1 | F7: 1 | G7: 1 | H7: 1 | I7: Não possui orçamento
B8: Fornecedor L5 | C8: Repume | D8: 0 | E8: 0 | F8: 0 | G8: 0 | H8: 0 | I8: Não possui orçamento
B9: Fornecedor L6 | C9: Tecnowatt | D9: 1 | E9: 1 | F9: 1 | G9: 1 | H9: 1 | I9: Possui orçamento, definir qual classe melhor atende
B10: Fornecedor L7 | C10: Unicoba | D10: 1 | E10: 1 | F10: 1 | G10: 1 | H10: 1 | I10: Possui orçamento, definir qual classe melhor atende
B11: Fornecedor L8 | C11: SX Lighting | D11: 0 | E11: 0 | F11: 0 | G11: 0 | H11: 0 | I11: Não possui orçamento

Sheet Simulações
A1: Correção Classes | B1: Correção Canteiro Central | D1: ID | E1: Padrão | F1: Logradouro | G1: latitude | H1: longitude | I1: Classificação viária | J1: Classificação ciclovia | K1: Classificação pedonal | L1: Tipo de lâmpada | M1: Potencia da lâmpada | N1: Potência Reator | O1: Potencia 2o nivel | P1: POT TOTAL MALHA | Q1: Faixas de Rodagem | R1: Largura Passeio 1 | S1: Largura Via 1 | T1: largura Passeio Central 1 | U1: largura Passeio Central 2 | V1: Largura Via 2 | W1: largura Passeio 2 | X1: largura Canteiro Central | Y1: largura Ciclovia 1 | Z1: largura Ciclovia 2 | AA1: estacionamento 1 | AB1: estacionamento 2 | AC1: posteacao | AD1: Tipo de estrutura | AE1: distancia entre postes | AF1: altura da luminaria | AG1: qtd de Lampadas IP Princ | AH1: distancia Poste a via | AI1: projecao do braço | AJ1: Pendor | AK1: Altura de Instalação | AL1: Projeção Vertical | AM1: Exclusivo | AN1: Quantidade de pontos inspecionados IP Veic | AO1: qtd de Lampadas IP 2o nivel | AP1: Tipo de posteação 2o nivel | AQ1: Distanciamento 2o nivel | AR1: Altura da luminaria 2o nivel | AS1: Projecao 2o nivel | AT1: Distancia poste-via 2o nivel | AU1: Quantidade de pontos inspecionados IP Sec | AV1: informacoes Adicionais | AW1: Emed - Norma | AX1: U - Norma | AY1: Luminância Média Exigida | AZ1: Uo Uniformidade Global Exigida | BA1: Uniformidade Longitudinal Exigida | BB1: Incremento Linear Exigido | BC1: Atendimento pleno à norma | BD1: Excesso de iluminância média IV | BE1: Excesso de Uniformidade IV | BF1: Excesso de luminância média IV | BG1: Iluminância Média | BH1: Fator de Uniformidade | BI1: Luminância Média | BJ1: Uniformidade Longitudinal | BK1: Incremento Linear (TI) | BL1: EIR | BM1: ATENDE TUDO - RUA SIMU | BN1: Atende à Iluminância Média | BO1: Atende à Uniformidade Global Miníma | BP1: Atende à Luminância Média | BQ1: Classe IV | BR1: Classe IP | BS1: Excesso de iluminância média P1 | BT1: Iluminância Média | BU1: Iluminância mínima horizontal E (lux) | BV1: Iluminância Média (Exigida) | BW1: Iluminância mínima horizontal E (lux) | BX1: Atende à NBR 5101 - TUDO SIMU | BY1: Atende à Iluminância Média | BZ1: Atende à Iluminância mínima horizontal | CA1: Classe IP | CB1: Excesso de iluminância média P2 | CC1: Iluminância Média | CD1: Iluminância mínima horizontal E (lux) | CE1: Iluminância Média (Exigida) | CF1: Iluminância mínima horizontal E (lux) exigida | CG1: Atende à NBR 5101 - TUDO SIMU P2 | CH1: Atende à Iluminância Média | CI1: Atende à Iluminância mínima horizontal | CJ1: Fornecedor | CK1: Código Luminária 1 | CL1: Luminária Simulada (IP Principal) | CM1: Código Luminária 2 | CN1: Luminária Simulada (IP Secundário) | CO1: Pontos por poste (IP Principal) | CP1: Potência simulada - IP Principal (W) | CQ1: Potência simulada - IP Secundário (W) | CR1: Fluxo Luminoso - IP Principal (lm) | CS1: Fluxo Luminoso - IP Secundário (lm) | CT1: Ângulo antigo | CU1: Ângulo Simulado | CV1: Braço Antigo | CW1: Braço Novo | CX1: Projeção com alteração | CY1: Altura de luminária com alteração | CZ1: Correção de Ponto Escuro (CPE) | DA1: Quantidade de pontos adicionados para via de veículo | DB1: Quantidade de pontos adicionados para via de pedestres | DC1: Observação CPE (Reduçao entre postes e/ou Tipo de Posteação) | DD1: obs conferência | DE1: rev conferência | DF1: IP PRINC SIM | DG1: IP SEC SIM | DH1: TOTAL SIMULADO | DI1: Eficientização | DJ1: Simulação | DK1: Conferência | DL1: Considerar na Extrapolação | DM1: Inspeção | DO1: eficientização
C2: Carol | D2: 38 | E2: PVCP | F2: Avenida Beira-Mar, 1577 | G2: -29.992885 | H2: -50.12708 | I2: C1 | J2: - | K2: P5 | L2: LED | M2: 99 | N2: 0 | O2: 0 | P2: =M2*AG2*2 -> 198 | Q2: 2 | R2: 4.5 | S2: 8.5 | V2: 0 | W2: 5 | X2: 0 | Y2: 0 | Z2: 2.5 | AA2: 3 | AB2: 0 | AC2: Unilateral | AD2: Braço | AE2: 27.3 | AF2: 8.2 | AG2: 1 | AH2: 0.2 | AI2: 2.5 | AJ2: =AI2-AH2 -> 2.3 | AK2: - | AL2: - | AM2: Não | AN2: =IF(AC2="Unilateral",2*AG2,IF(AC2="Bilateral Alternada",3*AG2,IF(AC2="Bilateral Frontal",4*AG2,IF(AC2="Canteiro Central",2*AG2,"erro")))) -> 2 | AO2: 0 | AP2: 0 | AQ2: 0 | AR2: 0 | AS2: 0 | AT2: - | AU2: =IF(AO2=0,0,IF(AC2="Unilateral",2*AO2,IF(AC2="Bilateral Alternada",3*AO2,IF(AC2="Bilateral Frontal",4*AO2,IF(AC2="Canteiro Central",2*AO2,"erro"))))) -> 0 | AW2: =VLOOKUP(I2,ABNT5101!$I$3:$J$9,2) -> 30 | AX2: =VLOOKUP(I2,ABNT5101!$I$3:$M$9,5) -> 0.38 | AY2: =_xlfn.XLOOKUP(I2,ABNT5101!$I:$I,ABNT5101!$L:$L) -> - | AZ2: =_xlfn.XLOOKUP(I2,ABNT5101!$I:$I,ABNT5101!M:M) -> 0.38 | BA2: =_xlfn.XLOOKUP(I2,ABNT5101!$I:$I,ABNT5101!N:N) -> - | BB2: =_xlfn.XLOOKUP(I2,ABNT5101!$I:$I,ABNT5101!O:O) -> 14 | BC2: =IF(BM2="NÃO ATENDE","NÃO ATENDE",IF(BX2="NÃO ATENDE","NÃO ATENDE",IF(CG2="NÃO ATENDE","NÃO ATENDE","ATENDE"))) -> ATENDE | BD2: =BG2/AW2-1 -> 0.035666667 | BE2: =BH2/AX2-1 -> 0.47368421 | BF2: =IF($I2="M6",BI2/AY2-1,"-") -> - | BG2: 31.07 | BH2: 0.56 | BM2: =IF(OR(BN2="NÃO ATENDE",BO2="NÃO ATENDE",BP2="NÃO ATENDE"),"NÃO ATENDE","ATENDE") -> ATENDE | BN2: =IF(BG2>=AW2,"ATENDE",IF(BG2>=0.99*AW2,"ATENDIMENTO LIMIAR","NÃO ATENDE")) -> ATENDE | BO2: =IF(BH2>=AX2,"ATENDE",IF(BH2>=(AX2-0.02),"ATENDIMENTO LIMIAR","NÃO ATENDE")) -> ATENDE | BP2: =IF(AY2="-","ATENDE",IF(BI2>=AY2,"ATENDE",IF(BI2>=(AY2-0.02),"ATENDIMENTO LIMIAR","NÃO ATENDE"))) -> ATENDE | BQ2: =I2 -> C1 | BR2: =K2 -> P5 | BS2: =IF(BT2="-","-",BT2/BV2-1) -> 2.302 | BT2: 16.51 | BU2: 4.38 | BV2: =IF(BR2="-","-",_xlfn.XLOOKUP(BR2,ABNT5101!$B$4:$B$9,ABNT5101!$C$4:$C$9)) -> 5 | BW2: =IF(BR2="-","-",_xlfn.XLOOKUP(BR2,ABNT5101!$B$4:$B$9,ABNT5101!$D$4:$D$9)) -> 1 | BX2: =IF(BY2="-","-",IF(BY2="NÃO ATENDE","NÃO ATENDE",IF(BZ2="NÃO ATENDE","NÃO ATENDE","ATENDE"))) -> ATENDE | BY2: =IF(BR2="-","-",IF(BT2>=BV2,"ATENDE",IF(BT2>=(BV2*0.99),"ATENDIMENTO LIMIAR","NÃO ATENDE"))) -> ATENDE | BZ2: =IF(BR2="-","-",IF(BU2>=BW2,"ATENDE","NÃO ATENDE")) -> ATENDE | CA2: =BR2 -> P5 | CB2: =IF(CC2="-","-",CC2/CE2-1) -> 0.03 | CC2: 5.15 | CD2: 1.34 | CE2: =IF(CA2="-","-",_xlfn.XLOOKUP(CA2,ABNT5101!$B$4:$B$9,ABNT5101!$C$4:$C$9)) -> 5 | CF2: =IF(CA2="-","-",_xlfn.XLOOKUP(CA2,ABNT5101!$B$4:$B$9,ABNT5101!$D$4:$D$9)) -> 1 | CG2: =IF(CH2="-","-",IF(CH2="NÃO ATENDE","NÃO ATENDE",IF(CI2="NÃO ATENDE","NÃO ATENDE","ATENDE"))) -> ATENDE | CH2: =IF(CA2="-","-",IF(CC2>=(CE2),"ATENDE",IF(CC2>=(0.99*CE2),"ATENDIMENTO LIMIAR","NÃO ATENDE"))) -> ATENDE | CI2: =IF(CA2="-","-",IF(CD2>=CF2,"ATENDE","NÃO ATENDE")) -> ATENDE | CJ2: =_xlfn.XLOOKUP(CK2,'Banco de dados'!$B:$B,'Banco de dados'!$D:$D) -> LEDSTAR | CK2: SL VT 9.1 120W | CL2: =_xlfn.XLOOKUP(CK2,'Banco de dados'!$B:$B,'Banco de dados'!$E:$E) -> LUM LED SL VT 9.1 120W | CN2: =IF(CM2="-","-",_xlfn.XLOOKUP(CM2,'Banco de dados'!$B:$B,'Banco de dados'!$E:$E)) -> #N/A | CO2: =AG2 -> 1 | CP2: =_xlfn.XLOOKUP(CK2,'Banco de dados'!$B:$B,'Banco de dados'!$H:$H) -> 120 | CQ2: =_xlfn.XLOOKUP(CM2,'Banco de dados'!$B:$B,'Banco de dados'!$H:$H) -> 0 | CR2: =_xlfn.XLOOKUP(CK2,'Banco de dados'!$B:$B,'Banco de dados'!$F:$F) -> 18730 | CS2: =_xlfn.XLOOKUP(CM2,'Banco de dados'!$B:$B,'Banco de dados'!$F:$F) -> 0 | CT2: 0 | CU2: 5 | CV2: =IF(AI2<=0.5,"Curto I",IF(AND(AI2>='Braços de IP'!$B$9,AI2<='Braços de IP'!$D$9),'Braços de IP'!$E$9,IF(AND(AI2>='Braços de IP'!$B$10,AI2<='Braços de IP'!$D$10),'Braços de IP'!$E$10,IF(AND(AI2>='Braços de IP'!$B$11,AI2<='Braços de IP'!$D$11),'Braços de IP'!$E$11,IF(AND(AI2>='Braços de IP'!$B$12,AI2<='Braços de IP'!$D$12),'Braços de IP'!$E$12,IF(AND(AI2>='Braços de IP'!$B$13,AI2<='Braços de IP'!$D$13),'Braços de IP'!$E$13,IF(AND(AI2>='Braços de IP'!$B$14,AI2<='Braços de IP'!$D$14),'Braços de IP'!$E$14,"ERRO"))))))) -> Médio II | CX2: =IF($CW2="","",VLOOKUP($CW2,'Braços de IP'!$E$9:$I$15,2,0)) | CY2: =IF($CW2="","",VLOOKUP($CW2,'Braços de IP'!$E$9:$I$15,5,0)) | DF2: =CP2 -> 120 | DG2: =M2 -> 99 | DH2: =SUM(DF2:DG2)*CO2 -> 219 | DI2: =1-DF2/DG2 -> -0.21212121 | DL2: Sim | DO2: =((M2+N2)-CP2)/(M2+N2) -> -0.21212121 | DQ2: V4 | DR2: =COUNTIF(I:I,DQ2)/3 -> 0 | DS2: =DR2/$DR$434 -> #DIV/0! | DT2: =DR2/SUM($DR$326:$DR$353) -> #DIV/0!
C3: Carol | D3: 38 | E3: PVCP | F3: Avenida Beira-Mar, 1577 | G3: -29.992885 | H3: -50.12708 | I3: C1 | J3: - | K3: P5 | L3: LED | M3: 99 | N3: 0 | O3: 0 | P3: =M3*AG3*2 -> 198 | Q3: 2 | R3: 4.5 | S3: 8.5 | V3: 0 | W3: 5 | X3: 0 | Y3: 0 | Z3: 2.5 | AA3: 3 | AB3: 0 | AC3: Unilateral | AD3: Braço | AE3: 27.3 | AF3: 8.2 | AG3: 1 | AH3: 0.2 | AI3: 2.5 | AJ3: =AI3-AH3 -> 2.3 | AK3: - | AL3: - | AM3: Não | AN3: =IF(AC3="Unilateral",2*AG3,IF(AC3="Bilateral Alternada",3*AG3,IF(AC3="Bilateral Frontal",4*AG3,IF(AC3="Canteiro Central",2*AG3,"erro")))) -> 2 | AO3: 0 | AP3: 0 | AQ3: 0 | AR3: 0 | AS3: 0 | AT3: - | AU3: =IF(AO3=0,0,IF(AC3="Unilateral",2*AO3,IF(AC3="Bilateral Alternada",3*AO3,IF(AC3="Bilateral Frontal",4*AO3,IF(AC3="Canteiro Central",2*AO3,"erro"))))) -> 0 | AW3: =VLOOKUP(I3,ABNT5101!$I$3:$J$9,2) -> 30 | AX3: =VLOOKUP(I3,ABNT5101!$I$3:$M$9,5) -> 0.38 | AY3: =_xlfn.XLOOKUP(I3,ABNT5101!$I:$I,ABNT5101!$L:$L) -> - | AZ3: =_xlfn.XLOOKUP(I3,ABNT5101!$I:$I,ABNT5101!M:M) -> 0.38 | BA3: =_xlfn.XLOOKUP(I3,ABNT5101!$I:$I,ABNT5101!N:N) -> - | BB3: =_xlfn.XLOOKUP(I3,ABNT5101!$I:$I,ABNT5101!O:O) -> 14 | BC3: =IF(BM3="NÃO ATENDE","NÃO ATENDE",IF(BX3="NÃO ATENDE","NÃO ATENDE",IF(CG3="NÃO ATENDE","NÃO ATENDE","ATENDE"))) -> ATENDE | BD3: =BG3/AW3-1 -> 0.018 | BE3: =BH3/AX3-1 -> 0.34210526 | BF3: =IF($I3="M6",BI3/AY3-1,"-") -> - | BG3: 30.54 | BH3: 0.51 | BM3: =IF(OR(BN3="NÃO ATENDE",BO3="NÃO ATENDE",BP3="NÃO ATENDE"),"NÃO ATENDE","ATENDE") -> ATENDE | BN3: =IF(BG3>=AW3,"ATENDE",IF(BG3>=0.99*AW3,"ATENDIMENTO LIMIAR","NÃO ATENDE")) -> ATENDE | BO3: =IF(BH3>=AX3,"ATENDE",IF(BH3>=(AX3-0.02),"ATENDIMENTO LIMIAR","NÃO ATENDE")) -> ATENDE | BP3: =IF(AY3="-","ATENDE",IF(BI3>=AY3,"ATENDE",IF(BI3>=(AY3-0.02),"ATENDIMENTO LIMIAR","NÃO ATENDE"))) -> ATENDE | BQ3: =I3 -> C1 | BR3: =K3 -> P5 | BS3: =IF(BT3="-","-",BT3/BV3-1) -> 3.196 | BT3: 20.98 | BU3: 13.59 | BV3: =IF(BR3="-","-",_xlfn.XLOOKUP(BR3,ABNT5101!$B$4:$B$9,ABNT5101!$C$4:$C$9)) -> 5 | BW3: =IF(BR3="-","-",_xlfn.XLOOKUP(BR3,ABNT5101!$B$4:$B$9,ABNT5101!$D$4:$D$9)) -> 1 | BX3: =IF(BY3="-","-",IF(BY3="NÃO ATENDE","NÃO ATENDE",IF(BZ3="NÃO ATENDE","NÃO ATENDE","ATENDE"))) -> ATENDE | BY3: =IF(BR3="-","-",IF(BT3>=BV3,"ATENDE",IF(BT3>=(BV3*0.99),"ATENDIMENTO LIMIAR","NÃO ATENDE"))) -> ATENDE | BZ3: =IF(BR3="-","-",IF(BU3>=BW3,"ATENDE","NÃO ATENDE")) -> ATENDE | CA3: =BR3 -> P5 | CB3: =IF(CC3="-","-",CC3/CE3-1) -> 0.142 | CC3: 5.71 | CD3: 2.84 | CE3: =IF(CA3="-","-",_xlfn.XLOOKUP(CA3,ABNT5101!$B$4:$B$9,ABNT5101!$C$4:$C$9)) -> 5 | CF3: =IF(CA3="-","-",_xlfn.XLOOKUP(CA3,ABNT5101!$B$4:$B$9,ABNT5101!$D$4:$D$9)) -> 1 | CG3: =IF(CH3="-","-",IF(CH3="NÃO ATENDE","NÃO ATENDE",IF(CI3="NÃO ATENDE","NÃO ATENDE","ATENDE"))) -> ATENDE | CH3: =IF(CA3="-","-",IF(CC3>=(CE3),"ATENDE",IF(CC3>=(0.99*CE3),"ATENDIMENTO LIMIAR","NÃO ATENDE"))) -> ATENDE | CI3: =IF(CA3="-","-",IF(CD3>=CF3,"ATENDE","NÃO ATENDE")) -> ATENDE | CJ3: =_xlfn.XLOOKUP(CK3,'Banco de dados'!$B:$B,'Banco de dados'!$D:$D) -> SX LIGHTING | CK3: SX-INLPP120HF | CL3: =_xlfn.XLOOKUP(CK3,'Banco de dados'!$B:$B,'Banco de dados'!$E:$E) -> SXINLPP120K40L12CZF7PHF | CN3: =IF(CM3="-","-",_xlfn.XLOOKUP(CM3,'Banco de dados'!$B:$B,'Banco de dados'!$E:$E)) -> #N/A | CO3: =AG3 -> 1 | CP3: =_xlfn.XLOOKUP(CK3,'Banco de dados'!$B:$B,'Banco de dados'!$H:$H) -> 120 | CQ3: =_xlfn.XLOOKUP(CM3,'Banco de dados'!$B:$B,'Banco de dados'!$H:$H) -> #N/A | CR3: =_xlfn.XLOOKUP(CK3,'Banco de dados'!$B:$B,'Banco de dados'!$F:$F) -> 20748 | CS3: =_xlfn.XLOOKUP(CM3,'Banco de dados'!$B:$B,'Banco de dados'!$F:$F) -> 0 | CT3: 0 | CU3: 5 | CV3: =IF(AI3<=0.5,"Curto I",IF(AND(AI3>='Braços de IP'!$B$9,AI3<='Braços de IP'!$D$9),'Braços de IP'!$E$9,IF(AND(AI3>='Braços de IP'!$B$10,AI3<='Braços de IP'!$D$10),'Braços de IP'!$E$10,IF(AND(AI3>='Braços de IP'!$B$11,AI3<='Braços de IP'!$D$11),'Braços de IP'!$E$11,IF(AND(AI3>='Braços de IP'!$B$12,AI3<='Braços de IP'!$D$12),'Braços de IP'!$E$12,IF(AND(AI3>='Braços de IP'!$B$13,AI3<='Braços de IP'!$D$13),'Braços de IP'!$E$13,IF(AND(AI3>='Braços de IP'!$B$14,AI3<='Braços de IP'!$D$14),'Braços de IP'!$E$14,"ERRO"))))))) -> Médio II | CX3: =IF($CW3="","",VLOOKUP($CW3,'Braços de IP'!$E$9:$I$15,2,0)) | CY3: =IF($CW3="","",VLOOKUP($CW3,'Braços de IP'!$E$9:$I$15,5,0)) | DF3: =CP3 -> 120 | DG3: =M3 -> 99 | DH3: =SUM(DF3:DG3)*CO3 -> 219 | DI3: =1-DF3/DG3 -> -0.21212121 | DL3: Sim | DO3: =((M3+N3)-CP3)/(M3+N3) -> -0.21212121 | DQ3: V4 | DR3: =COUNTIF(I:I,DQ3)/3 -> 0 | DS3: =DR3/$DR$434 -> #DIV/0! | DT3: =DR3/SUM($DR$326:$DR$353) -> #DIV/0!
C4: Carol | D4: 38 | E4: PVCP | F4: Avenida Beira-Mar, 1577 | G4: -29.992885 | H4: -50.12708 | I4: C1 | J4: - | K4: P5 | L4: LED | M4: 99 | N4: 0 | O4: 0 | P4: =M4*AG4*2 -> 198 | Q4: 2 | R4: 4.5 | S4: 8.5 | V4: 0 | W4: 5 | X4: 0 | Y4: 0 | Z4: 2.5 | AA4: 3 | AB4: 0 | AC4: Unilateral | AD4: Braço | AE4: 27.3 | AF4: 8.2 | AG4: 1 | AH4: 0.2 | AI4: 2.5 | AJ4: =AI4-AH4 -> 2.3 | AK4: - | AL4: - | AM4: Não | AN4: =IF(AC4="Unilateral",2*AG4,IF(AC4="Bilateral Alternada",3*AG4,IF(AC4="Bilateral Frontal",4*AG4,IF(AC4="Canteiro Central",2*AG4,"erro")))) -> 2 | AO4: 0 | AP4: 0 | AQ4: 0 | AR4: 0 | AS4: 0 | AT4: - | AU4: =IF(AO4=0,0,IF(AC4="Unilateral",2*AO4,IF(AC4="Bilateral Alternada",3*AO4,IF(AC4="Bilateral Frontal",4*AO4,IF(AC4="Canteiro Central",2*AO4,"erro"))))) -> 0 | AW4: =VLOOKUP(I4,ABNT5101!$I$3:$J$9,2) -> 30 | AX4: =VLOOKUP(I4,ABNT5101!$I$3:$M$9,5) -> 0.38 | AY4: =_xlfn.XLOOKUP(I4,ABNT5101!$I:$I,ABNT5101!$L:$L) -> - | AZ4: =_xlfn.XLOOKUP(I4,ABNT5101!$I:$I,ABNT5101!M:M) -> 0.38 | BA4: =_xlfn.XLOOKUP(I4,ABNT5101!$I:$I,ABNT5101!N:N) -> - | BB4: =_xlfn.XLOOKUP(I4,ABNT5101!$I:$I,ABNT5101!O:O) -> 14 | BC4: =IF(BM4="NÃO ATENDE","NÃO ATENDE",IF(BX4="NÃO ATENDE","NÃO ATENDE",IF(CG4="NÃO ATENDE","NÃO ATENDE","ATENDE"))) -> ATENDE | BD4: =BG4/AW4-1 -> 0.049666667 | BE4: =BH4/AX4-1 -> 0.60526316 | BF4: =IF($I4="M6",BI4/AY4-1,"-") -> - | BG4: 31.49 | BH4: 0.61 | BM4: =IF(OR(BN4="NÃO ATENDE",BO4="NÃO ATENDE",BP4="NÃO ATENDE"),"NÃO ATENDE","ATENDE") -> ATENDE | BN4: =IF(BG4>=AW4,"ATENDE",IF(BG4>=0.99*AW4,"ATENDIMENTO LIMIAR","NÃO ATENDE")) -> ATENDE | BO4: =IF(BH4>=AX4,"ATENDE",IF(BH4>=(AX4-0.02),"ATENDIMENTO LIMIAR","NÃO ATENDE")) -> ATENDE | BP4: =IF(AY4="-","ATENDE",IF(BI4>=AY4,"ATENDE",IF(BI4>=(AY4-0.02),"ATENDIMENTO LIMIAR","NÃO ATENDE"))) -> ATENDE | BQ4: =I4 -> C1 | BR4: =K4 -> P5 | BS4: =IF(BT4="-","-",BT4/BV4-1) -> 1.554 | BT4: 12.77 | BU4: 7.92 | BV4: =IF(BR4="-","-",_xlfn.XLOOKUP(BR4,ABNT5101!$B$4:$B$9,ABNT5101!$C$4:$C$9)) -> 5 | BW4: =IF(BR4="-","-",_xlfn.XLOOKUP(BR4,ABNT5101!$B$4:$B$9,ABNT5101!$D$4:$D$9)) -> 1 | BX4: =IF(BY4="-","-",IF(BY4="NÃO ATENDE","NÃO ATENDE",IF(BZ4="NÃO ATENDE","NÃO ATENDE","ATENDE"))) -> ATENDE | BY4: =IF(BR4="-","-",IF(BT4>=BV4,"ATENDE",IF(BT4>=(BV4*0.99),"ATENDIMENTO LIMIAR","NÃO ATENDE"))) -> ATENDE | BZ4: =IF(BR4="-","-",IF(BU4>=BW4,"ATENDE","NÃO ATENDE")) -> ATENDE | CA4: =BR4 -> P5 | CB4: =IF(CC4="-","-",CC4/CE4-1) -> 0.454 | CC4: 7.27 | CD4: 4.22 | CE4: =IF(CA4="-","-",_xlfn.XLOOKUP(CA4,ABNT5101!$B$4:$B$9,ABNT5101!$C$4:$C$9)) -> 5 | CF4: =IF(CA4="-","-",_xlfn.XLOOKUP(CA4,ABNT5101!$B$4:$B$9,ABNT5101!$D$4:$D$9)) -> 1 | CG4: =IF(CH4="-","-",IF(CH4="NÃO ATENDE","NÃO ATENDE",IF(CI4="NÃO ATENDE","NÃO ATENDE","ATENDE"))) -> ATENDE | CH4: =IF(CA4="-","-",IF(CC4>=(CE4),"ATENDE",IF(CC4>=(0.99*CE4),"ATENDIMENTO LIMIAR","NÃO ATENDE"))) -> ATENDE | CI4: =IF(CA4="-","-",IF(CD4>=CF4,"ATENDE","NÃO ATENDE")) -> ATENDE | CJ4: =_xlfn.XLOOKUP(CK4,'Banco de dados'!$B:$B,'Banco de dados'!$D:$D) -> TECNOWATT | CK4: SIGMAGPTLRRSMNDL120W_82IBBR | CL4: =_xlfn.XLOOKUP(CK4,'Banco de dados'!$B:$B,'Banco de dados'!$E:$E) -> SIGMAGPTLRRSMNDL120W_82IBBR S1-10C1MUN6.5 | CN4: =IF(CM4="-","-",_xlfn.XLOOKUP(CM4,'Banco de dados'!$B:$B,'Banco de dados'!$E:$E)) -> #N/A | CO4: =AG4 -> 1 | CP4: =_xlfn.XLOOKUP(CK4,'Banco de dados'!$B:$B,'Banco de dados'!$H:$H) -> 120 | CQ4: =_xlfn.XLOOKUP(CM4,'Banco de dados'!$B:$B,'Banco de dados'!$H:$H) -> 0 | CR4: =_xlfn.XLOOKUP(CK4,'Banco de dados'!$B:$B,'Banco de dados'!$F:$F) -> 19640 | CS4: =_xlfn.XLOOKUP(CM4,'Banco de dados'!$B:$B,'Banco de dados'!$F:$F) -> 0 | CT4: 0 | CU4: 5 | CV4: =IF(AI4<=0.5,"Curto I",IF(AND(AI4>='Braços de IP'!$B$9,AI4<='Braços de IP'!$D$9),'Braços de IP'!$E$9,IF(AND(AI4>='Braços de IP'!$B$10,AI4<='Braços de IP'!$D$10),'Braços de IP'!$E$10,IF(AND(AI4>='Braços de IP'!$B$11,AI4<='Braços de IP'!$D$11),'Braços de IP'!$E$11,IF(AND(AI4>='Braços de IP'!$B$12,AI4<='Braços de IP'!$D$12),'Braços de IP'!$E$12,IF(AND(AI4>='Braços de IP'!$B$13,AI4<='Braços de IP'!$D$13),'Braços de IP'!$E$13,IF(AND(AI4>='Braços de IP'!$B$14,AI4<='Braços de IP'!$D$14),'Braços de IP'!$E$14,"ERRO"))))))) -> Médio II | CW4: Longo II | CX4: =IF($CW4="","",VLOOKUP($CW4,'Braços de IP'!$E$9:$I$15,2,0)) -> 3.5 | CY4: =IF($CW4="","",VLOOKUP($CW4,'Braços de IP'!$E$9:$I$15,5,0)) -> 8.5 | DF4: =CP4 -> 120 | DG4: =M4 -> 99 | DH4: =SUM(DF4:DG4)*CO4 -> 219 | DI4: =1-DF4/DG4 -> -0.21212121 | DL4: Sim | DO4: =((M4+N4)-CP4)/(M4+N4) -> -0.21212121 | DQ4: V4 | DR4: =COUNTIF(I:I,DQ4)/3 -> 0 | DS4: =DR4/$DR$434 -> #DIV/0! | DT4: =DR4/SUM($DR$326:$DR$353) -> #DIV/0!
C5: André | D5: 126 | E5: PCVP | F5: Avenida Beira-Mar, 500 [Q] | G5: -29.982797 | H5: -50.12266 | I5: C1 | J5: P3 | K5: P6 | L5: LED | M5: 99 | N5: 0 | O5: 0 | P5: =M5*AG5*2 -> 198 | Q5: 2 | R5: 3 | S5: 8.4 | V5: 0 | W5: 3 | X5: 0 | Y5: 2.5 | Z5: 0 | AA5: 0 | AB5: 0 | AC5: Bilateral alternada | AD5: Braço | AE5: 55.8 | AF5: 7.3 | AG5: 1 | AH5: 0.3 | AI5: 0.5 | AJ5: =AI5-AH5 -> 0.2 | AK5: - | AL5: - | AM5: Sim | AN5: =IF(AC5="Unilateral",2*AG5,IF(AC5="Bilateral Alternada",3*AG5,IF(AC5="Bilateral Frontal",4*AG5,IF(AC5="Canteiro Central",2*AG5,"erro")))) -> 3 | AO5: 0 | AP5: 0 | AQ5: 0 | AR5: 0 | AS5: 0 | AT5: - | AU5: =IF(AO5=0,0,IF(AC5="Unilateral",2*AO5,IF(AC5="Bilateral Alternada",3*AO5,IF(AC5="Bilateral Frontal",4*AO5,IF(AC5="Canteiro Central",2*AO5,"erro"))))) -> 0 | AW5: =VLOOKUP(I5,ABNT5101!$I$3:$J$9,2) -> 30 | AX5: =VLOOKUP(I5,ABNT5101!$I$3:$M$9,5) -> 0.38 | AY5: =_xlfn.XLOOKUP(I5,ABNT5101!$I:$I,ABNT5101!$L:$L) -> - | AZ5: =_xlfn.XLOOKUP(I5,ABNT5101!$I:$I,ABNT5101!M:M) -> 0.38 | BA5: =_xlfn.XLOOKUP(I5,ABNT5101!$I:$I,ABNT5101!N:N) -> - | BB5: =_xlfn.XLOOKUP(I5,ABNT5101!$I:$I,ABNT5101!O:O) -> 14 | BC5: =IF(BM5="NÃO ATENDE","NÃO ATENDE",IF(BX5="NÃO ATENDE","NÃO ATENDE",IF(CG5="NÃO ATENDE","NÃO ATENDE","ATENDE"))) -> ATENDE | BD5: =BG5/AW5-1 -> -0.004 | BE5: =BH5/AX5-1 -> 0.52631579 | BF5: =IF($I5="M6",BI5/AY5-1,"-") -> - | BG5: 29.88 | BH5: 0.58 | BM5: =IF(OR(BN5="NÃO ATENDE",BO5="NÃO ATENDE",BP5="NÃO ATENDE"),"NÃO ATENDE","ATENDE") -> ATENDE | BN5: =IF(BG5>=AW5,"ATENDE",IF(BG5>=0.99*AW5,"ATENDIMENTO LIMIAR","NÃO ATENDE")) -> ATENDIMENTO LIMIAR | BO5: =IF(BH5>=AX5,"ATENDE",IF(BH5>=(AX5-0.02),"ATENDIMENTO LIMIAR","NÃO ATENDE")) -> ATENDE | BP5: =IF(AY5="-","ATENDE",IF(BI5>=AY5,"ATENDE",IF(BI5>=(AY5-0.02),"ATENDIMENTO LIMIAR","NÃO ATENDE"))) -> ATENDE | BQ5: =I5 -> C1 | BR5: =K5 -> P6 | BS5: =IF(BT5="-","-",BT5/BV5-1) -> 6.4466667 | BT5: 22.34 | BU5: 0.63 | BV5: =IF(BR5="-","-",_xlfn.XLOOKUP(BR5,ABNT5101!$B$4:$B$9,ABNT5101!$C$4:$C$9)) -> 3 | BW5: =IF(BR5="-","-",_xlfn.XLOOKUP(BR5,ABNT5101!$B$4:$B$9,ABNT5101!$D$4:$D$9)) -> 0.6 | BX5: =IF(BY5="-","-",IF(BY5="NÃO ATENDE","NÃO ATENDE",IF(BZ5="NÃO ATENDE","NÃO ATENDE","ATENDE"))) -> ATENDE | BY5: =IF(BR5="-","-",IF(BT5>=BV5,"ATENDE",IF(BT5>=(BV5*0.99),"ATENDIMENTO LIMIAR","NÃO ATENDE"))) -> ATENDE | BZ5: =IF(BR5="-","-",IF(BU5>=BW5,"ATENDE","NÃO ATENDE")) -> ATENDE | CA5: =BR5 -> P6 | CB5: =IF(CC5="-","-",CC5/CE5-1) -> 4.2266667 | CC5: 15.68 | CD5: 9.94 | CE5: =IF(CA5="-","-",_xlfn.XLOOKUP(CA5,ABNT5101!$B$4:$B$9,ABNT5101!$C$4:$C$9)) -> 3 | CF5: =IF(CA5="-","-",_xlfn.XLOOKUP(CA5,ABNT5101!$B$4:$B$9,ABNT5101!$D$4:$D$9)) -> 0.6 | CG5: =IF(CH5="-","-",IF(CH5="NÃO ATENDE","NÃO ATENDE",IF(CI5="NÃO ATENDE","NÃO ATENDE","ATENDE"))) -> ATENDE | CH5: =IF(CA5="-","-",IF(CC5>=(CE5),"ATENDE",IF(CC5>=(0.99*CE5),"ATENDIMENTO LIMIAR","NÃO ATENDE"))) -> ATENDE | CI5: =IF(CA5="-","-",IF(CD5>=CF5,"ATENDE","NÃO ATENDE")) -> ATENDE | CJ5: =_xlfn.XLOOKUP(CK5,'Banco de dados'!$B:$B,'Banco de dados'!$D:$D) -> LEDSTAR | CK5: SL VT 9.1 120W | CL5: =_xlfn.XLOOKUP(CK5,'Banco de dados'!$B:$B,'Banco de dados'!$E:$E) -> LUM LED SL VT 9.1 120W | CN5: =IF(CM5="-","-",_xlfn.XLOOKUP(CM5,'Banco de dados'!$B:$B,'Banco de dados'!$E:$E)) -> #N/A | CO5: =AG5 -> 1 | CP5: =_xlfn.XLOOKUP(CK5,'Banco de dados'!$B:$B,'Banco de dados'!$H:$H) -> 120 | CQ5: =_xlfn.XLOOKUP(CM5,'Banco de dados'!$B:$B,'Banco de dados'!$H:$H) -> 0 | CR5: =_xlfn.XLOOKUP(CK5,'Banco de dados'!$B:$B,'Banco de dados'!$F:$F) -> 18730 | CS5: =_xlfn.XLOOKUP(CM5,'Banco de dados'!$B:$B,'Banco de dados'!$F:$F) -> 0 | CT5: 0 | CU5: 10 | CV5: =IF(AI5<=0.5,"Curto I",IF(AND(AI5>='Braços de IP'!$B$9,AI5<='Braços de IP'!$D$9),'Braços de IP'!$E$9,IF(AND(AI5>='Braços de IP'!$B$10,AI5<='Braços de IP'!$D$10),'Braços de IP'!$E$10,IF(AND(AI5>='Braços de IP'!$B$11,AI5<='Braços de IP'!$D$11),'Braços de IP'!$E$11,IF(AND(AI5>='Braços de IP'!$B$12,AI5<='Braços de IP'!$D$12),'Braços de IP'!$E$12,IF(AND(AI5>='Braços de IP'!$B$13,AI5<='Braços de IP'!$D$13),'Braços de IP'!$E$13,IF(AND(AI5>='Braços de IP'!$B$14,AI5<='Braços de IP'!$D$14),'Braços de IP'!$E$14,"ERRO"))))))) -> Curto I | CW5: Longo II | CX5: =IF($CW5="","",VLOOKUP($CW5,'Braços de IP'!$E$9:$I$15,2,0)) -> 3.5 | CY5: =IF($CW5="","",VLOOKUP($CW5,'Braços de IP'!$E$9:$I$15,5,0)) -> 8.5 | DF5: =CP5 -> 120 | DG5: =M5 -> 99 | DH5: =SUM(DF5:DG5)*CO5 -> 219 | DI5: =1-DF5/DG5 -> -0.21212121 | DL5: Sim | DO5: =((M5+N5)-CP5)/(M5+N5) -> -0.21212121
C6: André | D6: 126 | E6: PCVP | F6: Avenida Beira-Mar, 500 [Q] | G6: -29.982797 | H6: -50.12266 | I6: C1 | J6: P3 | K6: P6 | L6: LED | M6: 99 | N6: 0 | O6: 0 | P6: =M6*AG6*2 -> 198 | Q6: 2 | R6: 3 | S6: 8.4 | V6: 0 | W6: 3 | X6: 0 | Y6: 2.5 | Z6: 0 | AA6: 0 | AB6: 0 | AC6: Bilateral alternada | AD6: Braço | AE6: 55.8 | AF6: 7.3 | AG6: 1 | AH6: 0.3 | AI6: 0.5 | AJ6: =AI6-AH6 -> 0.2 | AK6: - | AL6: - | AM6: Sim | AN6: =IF(AC6="Unilateral",2*AG6,IF(AC6="Bilateral Alternada",3*AG6,IF(AC6="Bilateral Frontal",4*AG6,IF(AC6="Canteiro Central",2*AG6,"erro")))) -> 3 | AO6: 0 | AP6: 0 | AQ6: 0 | AR6: 0 | AS6: 0 | AT6: - | AU6: =IF(AO6=0,0,IF(AC6="Unilateral",2*AO6,IF(AC6="Bilateral Alternada",3*AO6,IF(AC6="Bilateral Frontal",4*AO6,IF(AC6="Canteiro Central",2*AO6,"erro"))))) -> 0 | AW6: =VLOOKUP(I6,ABNT5101!$I$3:$J$9,2) -> 30 | AX6: =VLOOKUP(I6,ABNT5101!$I$3:$M$9,5) -> 0.38 | AY6: =_xlfn.XLOOKUP(I6,ABNT5101!$I:$I,ABNT5101!$L:$L) -> - | AZ6: =_xlfn.XLOOKUP(I6,ABNT5101!$I:$I,ABNT5101!M:M) -> 0.38 | BA6: =_xlfn.XLOOKUP(I6,ABNT5101!$I:$I,ABNT5101!N:N) -> - | BB6: =_xlfn.XLOOKUP(I6,ABNT5101!$I:$I,ABNT5101!O:O) -> 14 | BC6: =IF(BM6="NÃO ATENDE","NÃO ATENDE",IF(BX6="NÃO ATENDE","NÃO ATENDE",IF(CG6="NÃO ATENDE","NÃO ATENDE","ATENDE"))) -> ATENDE | BD6: =BG6/AW6-1 -> 0.22533333 | BE6: =BH6/AX6-1 -> 0.57894737 | BF6: =IF($I6="M6",BI6/AY6-1,"-") -> - | BG6: 36.76 | BH6: 0.6 | BM6: =IF(OR(BN6="NÃO ATENDE",BO6="NÃO ATENDE",BP6="NÃO ATENDE"),"NÃO ATENDE","ATENDE") -> ATENDE | BN6: =IF(BG6>=AW6,"ATENDE",IF(BG6>=0.99*AW6,"ATENDIMENTO LIMIAR","NÃO ATENDE")) -> ATENDE | BO6: =IF(BH6>=AX6,"ATENDE",IF(BH6>=(AX6-0.02),"ATENDIMENTO LIMIAR","NÃO ATENDE")) -> ATENDE | BP6: =IF(AY6="-","ATENDE",IF(BI6>=AY6,"ATENDE",IF(BI6>=(AY6-0.02),"ATENDIMENTO LIMIAR","NÃO ATENDE"))) -> ATENDE | BQ6: =I6 -> C1 | BR6: =K6 -> P6 | BS6: =IF(BT6="-","-",BT6/BV6-1) -> 6.19 | BT6: 21.57 | BU6: 0.63 | BV6: =IF(BR6="-","-",_xlfn.XLOOKUP(BR6,ABNT5101!$B$4:$B$9,ABNT5101!$C$4:$C$9)) -> 3 | BW6: =IF(BR6="-","-",_xlfn.XLOOKUP(BR6,ABNT5101!$B$4:$B$9,ABNT5101!$D$4:$D$9)) -> 0.6 | BX6: =IF(BY6="-","-",IF(BY6="NÃO ATENDE","NÃO ATENDE",IF(BZ6="NÃO ATENDE","NÃO ATENDE","ATENDE"))) -> ATENDE | BY6: =IF(BR6="-","-",IF(BT6>=BV6,"ATENDE",IF(BT6>=(BV6*0.99),"ATENDIMENTO LIMIAR","NÃO ATENDE"))) -> ATENDE | BZ6: =IF(BR6="-","-",IF(BU6>=BW6,"ATENDE","NÃO ATENDE")) -> ATENDE | CA6: =BR6 -> P6 | CB6: =IF(CC6="-","-",CC6/CE6-1) -> 3.1066667 | CC6: 12.32 | CD6: 7.3 | CE6: =IF(CA6="-","-",_xlfn.XLOOKUP(CA6,ABNT5101!$B$4:$B$9,ABNT5101!$C$4:$C$9)) -> 3 | CF6: =IF(CA6="-","-",_xlfn.XLOOKUP(CA6,ABNT5101!$B$4:$B$9,ABNT5101!$D$4:$D$9)) -> 0.6 | CG6: =IF(CH6="-","-",IF(CH6="NÃO ATENDE","NÃO ATENDE",IF(CI6="NÃO ATENDE","NÃO ATENDE","ATENDE"))) -> ATENDE | CH6: =IF(CA6="-","-",IF(CC6>=(CE6),"ATENDE",IF(CC6>=(0.99*CE6),"ATENDIMENTO LIMIAR","NÃO ATENDE"))) -> ATENDE | CI6: =IF(CA6="-","-",IF(CD6>=CF6,"ATENDE","NÃO ATENDE")) -> ATENDE | CJ6: =_xlfn.XLOOKUP(CK6,'Banco de dados'!$B:$B,'Banco de dados'!$D:$D) -> SX LIGHTING | CK6: SX-INLPP120HF | CL6: =_xlfn.XLOOKUP(CK6,'Banco de dados'!$B:$B,'Banco de dados'!$E:$E) -> SXINLPP120K40L12CZF7PHF | CN6: =IF(CM6="-","-",_xlfn.XLOOKUP(CM6,'Banco de dados'!$B:$B,'Banco de dados'!$E:$E)) -> #N/A | CO6: =AG6 -> 1 | CP6: =_xlfn.XLOOKUP(CK6,'Banco de dados'!$B:$B,'Banco de dados'!$H:$H) -> 120 | CQ6: =_xlfn.XLOOKUP(CM6,'Banco de dados'!$B:$B,'Banco de dados'!$H:$H) -> #N/A | CR6: =_xlfn.XLOOKUP(CK6,'Banco de dados'!$B:$B,'Banco de dados'!$F:$F) -> 20748 | CS6: =_xlfn.XLOOKUP(CM6,'Banco de dados'!$B:$B,'Banco de dados'!$F:$F) -> 0 | CT6: 0 | CU6: 10 | CV6: =IF(AI6<=0.5,"Curto I",IF(AND(AI6>='Braços de IP'!$B$9,AI6<='Braços de IP'!$D$9),'Braços de IP'!$E$9,IF(AND(AI6>='Braços de IP'!$B$10,AI6<='Braços de IP'!$D$10),'Braços de IP'!$E$10,IF(AND(AI6>='Braços de IP'!$B$11,AI6<='Braços de IP'!$D$11),'Braços de IP'!$E$11,IF(AND(AI6>='Braços de IP'!$B$12,AI6<='Braços de IP'!$D$12),'Braços de IP'!$E$12,IF(AND(AI6>='Braços de IP'!$B$13,AI6<='Braços de IP'!$D$13),'Braços de IP'!$E$13,IF(AND(AI6>='Braços de IP'!$B$14,AI6<='Braços de IP'!$D$14),'Braços de IP'!$E$14,"ERRO"))))))) -> Curto I | CW6: Longo I | CX6: =IF($CW6="","",VLOOKUP($CW6,'Braços de IP'!$E$9:$I$15,2,0)) -> 2.8 | CY6: =IF($CW6="","",VLOOKUP($CW6,'Braços de IP'!$E$9:$I$15,5,0)) -> 8 | DF6: =CP6 -> 120 | DG6: =M6 -> 99 | DH6: =SUM(DF6:DG6)*CO6 -> 219 | DI6: =1-DF6/DG6 -> -0.21212121 | DL6: Sim | DO6: =((M6+N6)-CP6)/(M6+N6) -> -0.21212121
C7: André | D7: 126 | E7: PCVP | F7: Avenida Beira-Mar, 500 [Q] | G7: -29.982797 | H7: -50.12266 | I7: C1 | J7: P3 | K7: P6 | L7: LED | M7: 99 | N7: 0 | O7: 0 | P7: =M7*AG7*2 -> 198 | Q7: 2 | R7: 3 | S7: 8.4 | V7: 0 | W7: 3 | X7: 0 | Y7: 2.5 | Z7: 0 | AA7: 0 | AB7: 0 | AC7: Bilateral alternada | AD7: Braço | AE7: 55.8 | AF7: 7.3 | AG7: 1 | AH7: 0.3 | AI7: 0.5 | AJ7: =AI7-AH7 -> 0.2 | AK7: - | AL7: - | AM7: Sim | AN7: =IF(AC7="Unilateral",2*AG7,IF(AC7="Bilateral Alternada",3*AG7,IF(AC7="Bilateral Frontal",4*AG7,IF(AC7="Canteiro Central",2*AG7,"erro")))) -> 3 | AO7: 0 | AP7: 0 | AQ7: 0 | AR7: 0 | AS7: 0 | AT7: - | AU7: =IF(AO7=0,0,IF(AC7="Unilateral",2*AO7,IF(AC7="Bilateral Alternada",3*AO7,IF(AC7="Bilateral Frontal",4*AO7,IF(AC7="Canteiro Central",2*AO7,"erro"))))) -> 0 | AW7: =VLOOKUP(I7,ABNT5101!$I$3:$J$9,2) -> 30 | AX7: =VLOOKUP(I7,ABNT5101!$I$3:$M$9,5) -> 0.38 | AY7: =_xlfn.XLOOKUP(I7,ABNT5101!$I:$I,ABNT5101!$L:$L) -> - | AZ7: =_xlfn.XLOOKUP(I7,ABNT5101!$I:$I,ABNT5101!M:M) -> 0.38 | BA7: =_xlfn.XLOOKUP(I7,ABNT5101!$I:$I,ABNT5101!N:N) -> - | BB7: =_xlfn.XLOOKUP(I7,ABNT5101!$I:$I,ABNT5101!O:O) -> 14 | BC7: =IF(BM7="NÃO ATENDE","NÃO ATENDE",IF(BX7="NÃO ATENDE","NÃO ATENDE",IF(CG7="NÃO ATENDE","NÃO ATENDE","ATENDE"))) -> ATENDE | BD7: =BG7/AW7-1 -> 0.027 | BE7: =BH7/AX7-1 -> 0.68421053 | BF7: =IF($I7="M6",BI7/AY7-1,"-") -> - | BG7: 30.81 | BH7: 0.64 | BM7: =IF(OR(BN7="NÃO ATENDE",BO7="NÃO ATENDE",BP7="NÃO ATENDE"),"NÃO ATENDE","ATENDE") -> ATENDE | BN7: =IF(BG7>=AW7,"ATENDE",IF(BG7>=0.99*AW7,"ATENDIMENTO LIMIAR","NÃO ATENDE")) -> ATENDE | BO7: =IF(BH7>=AX7,"ATENDE",IF(BH7>=(AX7-0.02),"ATENDIMENTO LIMIAR","NÃO ATENDE")) -> ATENDE | BP7: =IF(AY7="-","ATENDE",IF(BI7>=AY7,"ATENDE",IF(BI7>=(AY7-0.02),"ATENDIMENTO LIMIAR","NÃO ATENDE"))) -> ATENDE | BQ7: =I7 -> C1 | BR7: =K7 -> P6 | BS7: =IF(BT7="-","-",BT7/BV7-1) -> 5.2466667 | BT7: 18.74 | BU7: 0.69 | BV7: =IF(BR7="-","-",_xlfn.XLOOKUP(BR7,ABNT5101!$B$4:$B$9,ABNT5101!$C$4:$C$9)) -> 3 | BW7: =IF(BR7="-","-",_xlfn.XLOOKUP(BR7,ABNT5101!$B$4:$B$9,ABNT5101!$D$4:$D$9)) -> 0.6 | BX7: =IF(BY7="-","-",IF(BY7="NÃO ATENDE","NÃO ATENDE",IF(BZ7="NÃO ATENDE","NÃO ATENDE","ATENDE"))) -> ATENDE | BY7: =IF(BR7="-","-",IF(BT7>=BV7,"ATENDE",IF(BT7>=(BV7*0.99),"ATENDIMENTO LIMIAR","NÃO ATENDE"))) -> ATENDE | BZ7: =IF(BR7="-","-",IF(BU7>=BW7,"ATENDE","NÃO ATENDE")) -> ATENDE | CA7: =BR7 -> P6 | CB7: =IF(CC7="-","-",CC7/CE7-1) -> 3.0033333 | CC7: 12.01 | CD7: 8.72 | CE7: =IF(CA7="-","-",_xlfn.XLOOKUP(CA7,ABNT5101!$B$4:$B$9,ABNT5101!$C$4:$C$9)) -> 3 | CF7: =IF(CA7="-","-",_xlfn.XLOOKUP(CA7,ABNT5101!$B$4:$B$9,ABNT5101!$D$4:$D$9)) -> 0.6 | CG7: =IF(CH7="-","-",IF(CH7="NÃO ATENDE","NÃO ATENDE",IF(CI7="NÃO ATENDE","NÃO ATENDE","ATENDE"))) -> ATENDE | CH7: =IF(CA7="-","-",IF(CC7>=(CE7),"ATENDE",IF(CC7>=(0.99*CE7),"ATENDIMENTO LIMIAR","NÃO ATENDE"))) -> ATENDE | CI7: =IF(CA7="-","-",IF(CD7>=CF7,"ATENDE","NÃO ATENDE")) -> ATENDE | CJ7: =_xlfn.XLOOKUP(CK7,'Banco de dados'!$B:$B,'Banco de dados'!$D:$D) -> TECNOWATT | CK7: SIGMAGPTLRRSMNDL120W_82IBBR | CL7: =_xlfn.XLOOKUP(CK7,'Banco de dados'!$B:$B,'Banco de dados'!$E:$E) -> SIGMAGPTLRRSMNDL120W_82IBBR S1-10C1MUN6.5 | CN7: =IF(CM7="-","-",_xlfn.XLOOKUP(CM7,'Banco de dados'!$B:$B,'Banco de dados'!$E:$E)) -> #N/A | CO7: =AG7 -> 1 | CP7: =_xlfn.XLOOKUP(CK7,'Banco de dados'!$B:$B,'Banco de dados'!$H:$H) -> 120 | CQ7: =_xlfn.XLOOKUP(CM7,'Banco de dados'!$B:$B,'Banco de dados'!$H:$H) -> 0 | CR7: =_xlfn.XLOOKUP(CK7,'Banco de dados'!$B:$B,'Banco de dados'!$F:$F) -> 19640 | CS7: =_xlfn.XLOOKUP(CM7,'Banco de dados'!$B:$B,'Banco de dados'!$F:$F) -> 0 | CT7: 0 | CU7: 10 | CV7: =IF(AI7<=0.5,"Curto I",IF(AND(AI7>='Braços de IP'!$B$9,AI7<='Braços de IP'!$D$9),'Braços de IP'!$E$9,IF(AND(AI7>='Braços de IP'!$B$10,AI7<='Braços de IP'!$D$10),'Braços de IP'!$E$10,IF(AND(AI7>='Braços de IP'!$B$11,AI7<='Braços de IP'!$D$11),'Braços de IP'!$E$11,IF(AND(AI7>='Braços de IP'!$B$12,AI7<='Braços de IP'!$D$12),'Braços de IP'!$E$12,IF(AND(AI7>='Braços de IP'!$B$13,AI7<='Braços de IP'!$D$13),'Braços de IP'!$E$13,IF(AND(AI7>='Braços de IP'!$B$14,AI7<='Braços de IP'!$D$14),'Braços de IP'!$E$14,"ERRO"))))))) -> Curto I | CW7: Longo II | CX7: =IF($CW7="","",VLOOKUP($CW7,'Braços de IP'!$E$9:$I$15,2,0)) -> 3.5 | CY7: =IF($CW7="","",VLOOKUP($CW7,'Braços de IP'!$E$9:$I$15,5,0)) -> 8.5 | DF7: =CP7 -> 120 | DG7: =M7 -> 99 | DH7: =SUM(DF7:DG7)*CO7 -> 219 | DI7: =1-DF7/DG7 -> -0.21212121 | DL7: Sim | DO7: =((M7+N7)-CP7)/(M7+N7) -> -0.21212121
C8: Carol | D8: 1 | E8: PVP | F8: Condominio Maritimo | G8: -29.995958 | H8: -50.194662 | I8: C5 | J8: - | K8: P6 | L8: LED | M8: 50 | N8: 0 | O8: 0 | P8: =M8*AG8*2 -> 100 | Q8: 2 | R8: 1.2 | S8: 5.8 | V8: 0 | W8: 1.2 | X8: 0 | Y8: 0 | Z8: 0 | AA8: 0 | AB8: 0 | AC8: Unilateral | AD8: Braço | AE8: 25.6 | AF8: 8.1 | AG8: 1 | AH8: 0.3 | AI8: 2.5 | AJ8: =AI8-AH8 -> 2.2 | AK8: - | AL8: - | AM8: Não | AN8: =IF(AC8="Unilateral",2*AG8,IF(AC8="Bilateral Alternada",3*AG8,IF(AC8="Bilateral Frontal",4*AG8,IF(AC8="Canteiro Central",2*AG8,"erro")))) -> 2 | AO8: 0 | AP8: 0 | AQ8: 0 | AR8: 0 | AS8: 0 | AT8: - | AU8: =IF(AO8=0,0,IF(AC8="Unilateral",2*AO8,IF(AC8="Bilateral Alternada",3*AO8,IF(AC8="Bilateral Frontal",4*AO8,IF(AC8="Canteiro Central",2*AO8,"erro"))))) -> 0 | AW8: =VLOOKUP(I8,ABNT5101!$I$3:$J$9,2) -> 7.5 | AX8: =VLOOKUP(I8,ABNT5101!$I$3:$M$9,5) -> 0.18 | AY8: =_xlfn.XLOOKUP(I8,ABNT5101!$I:$I,ABNT5101!$L:$L) -> - | AZ8: =_xlfn.XLOOKUP(I8,ABNT5101!$I:$I,ABNT5101!M:M) -> 0.18 | BA8: =_xlfn.XLOOKUP(I8,ABNT5101!$I:$I,ABNT5101!N:N) -> - | BB8: =_xlfn.XLOOKUP(I8,ABNT5101!$I:$I,ABNT5101!O:O) -> 16 | BC8: =IF(BM8="NÃO ATENDE","NÃO ATENDE",IF(BX8="NÃO ATENDE","NÃO ATENDE",IF(CG8="NÃO ATENDE","NÃO ATENDE","ATENDE"))) -> ATENDE | BD8: =BG8/AW8-1 -> 0.14133333 | BE8: =BH8/AX8-1 -> 2.2777778 | BF8: =IF($I8="M6",BI8/AY8-1,"-") -> - | BG8: 8.56 | BH8: 0.59 | BM8: =IF(OR(BN8="NÃO ATENDE",BO8="NÃO ATENDE",BP8="NÃO ATENDE"),"NÃO ATENDE","ATENDE") -> ATENDE | BN8: =IF(BG8>=AW8,"ATENDE",IF(BG8>=0.99*AW8,"ATENDIMENTO LIMIAR","NÃO ATENDE")) -> ATENDE | BO8: =IF(BH8>=AX8,"ATENDE",IF(BH8>=(AX8-0.02),"ATENDIMENTO LIMIAR","NÃO ATENDE")) -> ATENDE | BP8: =IF(AY8="-","ATENDE",IF(BI8>=AY8,"ATENDE",IF(BI8>=(AY8-0.02),"ATENDIMENTO LIMIAR","NÃO ATENDE"))) -> ATENDE | BQ8: =I8 -> C5 | BR8: =K8 -> P6 | BS8: =IF(BT8="-","-",BT8/BV8-1) -> 1.7233333 | BT8: 8.17 | BU8: 5.58 | BV8: =IF(BR8="-","-",_xlfn.XLOOKUP(BR8,ABNT5101!$B$4:$B$9,ABNT5101!$C$4:$C$9)) -> 3 | BW8: =IF(BR8="-","-",_xlfn.XLOOKUP(BR8,ABNT5101!$B$4:$B$9,ABNT5101!$D$4:$D$9)) -> 0.6 | BX8: =IF(BY8="-","-",IF(BY8="NÃO ATENDE","NÃO ATENDE",IF(BZ8="NÃO ATENDE","NÃO ATENDE","ATENDE"))) -> ATENDE | BY8: =IF(BR8="-","-",IF(BT8>=BV8,"ATENDE",IF(BT8>=(BV8*0.99),"ATENDIMENTO LIMIAR","NÃO ATENDE"))) -> ATENDE | BZ8: =IF(BR8="-","-",IF(BU8>=BW8,"ATENDE","NÃO ATENDE")) -> ATENDE | CA8: =BR8 -> P6 | CB8: =IF(CC8="-","-",CC8/CE8-1) -> 1.1666667 | CC8: 6.5 | CD8: 4.38 | CE8: =IF(CA8="-","-",_xlfn.XLOOKUP(CA8,ABNT5101!$B$4:$B$9,ABNT5101!$C$4:$C$9)) -> 3 | CF8: =IF(CA8="-","-",_xlfn.XLOOKUP(CA8,ABNT5101!$B$4:$B$9,ABNT5101!$D$4:$D$9)) -> 0.6 | CG8: =IF(CH8="-","-",IF(CH8="NÃO ATENDE","NÃO ATENDE",IF(CI8="NÃO ATENDE","NÃO ATENDE","ATENDE"))) -> ATENDE | CH8: =IF(CA8="-","-",IF(CC8>=(CE8),"ATENDE",IF(CC8>=(0.99*CE8),"ATENDIMENTO LIMIAR","NÃO ATENDE"))) -> ATENDE | CI8: =IF(CA8="-","-",IF(CD8>=CF8,"ATENDE","NÃO ATENDE")) -> ATENDE | CJ8: =_xlfn.XLOOKUP(CK8,'Banco de dados'!$B:$B,'Banco de dados'!$D:$D) -> LEDSTAR | CK8: SL VT 9.1 28W | CL8: =_xlfn.XLOOKUP(CK8,'Banco de dados'!$B:$B,'Banco de dados'!$E:$E) -> LUM LED SL VT 9.1 28W | CN8: =IF(CM8="-","-",_xlfn.XLOOKUP(CM8,'Banco de dados'!$B:$B,'Banco de dados'!$E:$E)) -> #N/A | CO8: =AG8 -> 1 | CP8: =_xlfn.XLOOKUP(CK8,'Banco de dados'!$B:$B,'Banco de dados'!$H:$H) -> 28 | CQ8: =_xlfn.XLOOKUP(CM8,'Banco de dados'!$B:$B,'Banco de dados'!$H:$H) -> #N/A | CR8: =_xlfn.XLOOKUP(CK8,'Banco de dados'!$B:$B,'Banco de dados'!$F:$F) -> 4927.35 | CS8: =_xlfn.XLOOKUP(CM8,'Banco de dados'!$B:$B,'Banco de dados'!$F:$F) -> 0 | CT8: 0 | CV8: =IF(AI8<=0.5,"Curto I",IF(AND(AI8>='Braços de IP'!$B$9,AI8<='Braços de IP'!$D$9),'Braços de IP'!$E$9,IF(AND(AI8>='Braços de IP'!$B$10,AI8<='Braços de IP'!$D$10),'Braços de IP'!$E$10,IF(AND(AI8>='Braços de IP'!$B$11,AI8<='Braços de IP'!$D$11),'Braços de IP'!$E$11,IF(AND(AI8>='Braços de IP'!$B$12,AI8<='Braços de IP'!$D$12),'Braços de IP'!$E$12,IF(AND(AI8>='Braços de IP'!$B$13,AI8<='Braços de IP'!$D$13),'Braços de IP'!$E$13,IF(AND(AI8>='Braços de IP'!$B$14,AI8<='Braços de IP'!$D$14),'Braços de IP'!$E$14,"ERRO"))))))) -> Médio II | CX8: =IF($CW8="","",VLOOKUP($CW8,'Braços de IP'!$E$9:$I$15,2,0)) | CY8: =IF($CW8="","",VLOOKUP($CW8,'Braços de IP'!$E$9:$I$15,5,0)) | DF8: =CP8 -> 28 | DG8: =M8 -> 50 | DH8: =SUM(DF8:DG8)*CO8 -> 78 | DI8: =1-DF8/DG8 -> 0.44 | DL8: Não | DO8: =((M8+N8)-CP8)/(M8+N8) -> 0.44 | DQ8: Classe | DR8: Quantidade | DS8: %
C9: Carol | D9: 1 | E9: PVP | F9: Condominio Maritimo | G9: -29.995958 | H9: -50.194662 | I9: C5 | J9: - | K9: P6 | L9: LED | M9: 50 | N9: 0 | O9: 0 | P9: =M9*AG9*2 -> 100 | Q9: 2 | R9: 1.2 | S9: 5.8 | V9: 0 | W9: 1.2 | X9: 0 | Y9: 0 | Z9: 0 | AA9: 0 | AB9: 0 | AC9: Unilateral | AD9: Braço | AE9: 25.6 | AF9: 8.1 | AG9: 1 | AH9: 0.3 | AI9: 2.5 | AJ9: =AI9-AH9 -> 2.2 | AK9: - | AL9: - | AM9: Não | AN9: =IF(AC9="Unilateral",2*AG9,IF(AC9="Bilateral Alternada",3*AG9,IF(AC9="Bilateral Frontal",4*AG9,IF(AC9="Canteiro Central",2*AG9,"erro")))) -> 2 | AO9: 0 | AP9: 0 | AQ9: 0 | AR9: 0 | AS9: 0 | AT9: - | AU9: =IF(AO9=0,0,IF(AC9="Unilateral",2*AO9,IF(AC9="Bilateral Alternada",3*AO9,IF(AC9="Bilateral Frontal",4*AO9,IF(AC9="Canteiro Central",2*AO9,"erro"))))) -> 0 | AW9: =VLOOKUP(I9,ABNT5101!$I$3:$J$9,2) -> 7.5 | AX9: =VLOOKUP(I9,ABNT5101!$I$3:$M$9,5) -> 0.18 | AY9: =_xlfn.XLOOKUP(I9,ABNT5101!$I:$I,ABNT5101!$L:$L) -> - | AZ9: =_xlfn.XLOOKUP(I9,ABNT5101!$I:$I,ABNT5101!M:M) -> 0.18 | BA9: =_xlfn.XLOOKUP(I9,ABNT5101!$I:$I,ABNT5101!N:N) -> - | BB9: =_xlfn.XLOOKUP(I9,ABNT5101!$I:$I,ABNT5101!O:O) -> 16 | BC9: =IF(BM9="NÃO ATENDE","NÃO ATENDE",IF(BX9="NÃO ATENDE","NÃO ATENDE",IF(CG9="NÃO ATENDE","NÃO ATENDE","ATENDE"))) -> ATENDE | BD9: =BG9/AW9-1 -> 0.40666667 | BE9: =BH9/AX9-1 -> 3 | BF9: =IF($I9="M6",BI9/AY9-1,"-") -> - | BG9: 10.55 | BH9: 0.72 | BM9: =IF(OR(BN9="NÃO ATENDE",BO9="NÃO ATENDE",BP9="NÃO ATENDE"),"NÃO ATENDE","ATENDE") -> ATENDE | BN9: =IF(BG9>=AW9,"ATENDE",IF(BG9>=0.99*AW9,"ATENDIMENTO LIMIAR","NÃO ATENDE")) -> ATENDE | BO9: =IF(BH9>=AX9,"ATENDE",IF(BH9>=(AX9-0.02),"ATENDIMENTO LIMIAR","NÃO ATENDE")) -> ATENDE | BP9: =IF(AY9="-","ATENDE",IF(BI9>=AY9,"ATENDE",IF(BI9>=(AY9-0.02),"ATENDIMENTO LIMIAR","NÃO ATENDE"))) -> ATENDE | BQ9: =I9 -> C5 | BR9: =K9 -> P6 | BS9: =IF(BT9="-","-",BT9/BV9-1) -> 2.4533333 | BT9: 10.36 | BU9: 9.07 | BV9: =IF(BR9="-","-",_xlfn.XLOOKUP(BR9,ABNT5101!$B$4:$B$9,ABNT5101!$C$4:$C$9)) -> 3 | BW9: =IF(BR9="-","-",_xlfn.XLOOKUP(BR9,ABNT5101!$B$4:$B$9,ABNT5101!$D$4:$D$9)) -> 0.6 | BX9: =IF(BY9="-","-",IF(BY9="NÃO ATENDE","NÃO ATENDE",IF(BZ9="NÃO ATENDE","NÃO ATENDE","ATENDE"))) -> ATENDE | BY9: =IF(BR9="-","-",IF(BT9>=BV9,"ATENDE",IF(BT9>=(BV9*0.99),"ATENDIMENTO LIMIAR","NÃO ATENDE"))) -> ATENDE | BZ9: =IF(BR9="-","-",IF(BU9>=BW9,"ATENDE","NÃO ATENDE")) -> ATENDE | CA9: =BR9 -> P6 | CB9: =IF(CC9="-","-",CC9/CE9-1) -> 1.4666667 | CC9: 7.4 | CD9: 5.84 | CE9: =IF(CA9="-","-",_xlfn.XLOOKUP(CA9,ABNT5101!$B$4:$B$9,ABNT5101!$C$4:$C$9)) -> 3 | CF9: =IF(CA9="-","-",_xlfn.XLOOKUP(CA9,ABNT5101!$B$4:$B$9,ABNT5101!$D$4:$D$9)) -> 0.6 | CG9: =IF(CH9="-","-",IF(CH9="NÃO ATENDE","NÃO ATENDE",IF(CI9="NÃO ATENDE","NÃO ATENDE","ATENDE"))) -> ATENDE | CH9: =IF(CA9="-","-",IF(CC9>=(CE9),"ATENDE",IF(CC9>=(0.99*CE9),"ATENDIMENTO LIMIAR","NÃO ATENDE"))) -> ATENDE | CI9: =IF(CA9="-","-",IF(CD9>=CF9,"ATENDE","NÃO ATENDE")) -> ATENDE | CJ9: =_xlfn.XLOOKUP(CK9,'Banco de dados'!$B:$B,'Banco de dados'!$D:$D) -> SX LIGHTING | CK9: SX-INEVO030HF | CL9: =_xlfn.XLOOKUP(CK9,'Banco de dados'!$B:$B,'Banco de dados'!$E:$E) -> SXINEVO030K40L12CZF7PHF | CN9: =IF(CM9="-","-",_xlfn.XLOOKUP(CM9,'Banco de dados'!$B:$B,'Banco de dados'!$E:$E)) -> #N/A | CO9: =AG9 -> 1 | CP9: =_xlfn.XLOOKUP(CK9,'Banco de dados'!$B:$B,'Banco de dados'!$H:$H) -> 31 | CQ9: =_xlfn.XLOOKUP(CM9,'Banco de dados'!$B:$B,'Banco de dados'!$H:$H) -> 0 | CR9: =_xlfn.XLOOKUP(CK9,'Banco de dados'!$B:$B,'Banco de dados'!$F:$F) -> 5270 | CS9: =_xlfn.XLOOKUP(CM9,'Banco de dados'!$B:$B,'Banco de dados'!$F:$F) -> 0 | CT9: 0 | CV9: =IF(AI9<=0.5,"Curto I",IF(AND(AI9>='Braços de IP'!$B$9,AI9<='Braços de IP'!$D$9),'Braços de IP'!$E$9,IF(AND(AI9>='Braços de IP'!$B$10,AI9<='Braços de IP'!$D$10),'Braços de IP'!$E$10,IF(AND(AI9>='Braços de IP'!$B$11,AI9<='Braços de IP'!$D$11),'Braços de IP'!$E$11,IF(AND(AI9>='Braços de IP'!$B$12,AI9<='Braços de IP'!$D$12),'Braços de IP'!$E$12,IF(AND(AI9>='Braços de IP'!$B$13,AI9<='Braços de IP'!$D$13),'Braços de IP'!$E$13,IF(AND(AI9>='Braços de IP'!$B$14,AI9<='Braços de IP'!$D$14),'Braços de IP'!$E$14,"ERRO"))))))) -> Médio II | CX9: =IF($CW9="","",VLOOKUP($CW9,'Braços de IP'!$E$9:$I$15,2,0)) | CY9: =IF($CW9="","",VLOOKUP($CW9,'Braços de IP'!$E$9:$I$15,5,0)) | DF9: =CP9 -> 31 | DG9: =M9 -> 50 | DH9: =SUM(DF9:DG9)*CO9 -> 81 | DI9: =1-DF9/DG9 -> 0.38 | DL9: Não | DO9: =((M9+N9)-CP9)/(M9+N9) -> 0.38 | DQ9: Classe | DR9: Quantidade | DS9: %
C10: Carol | D10: 1 | E10: PVP | F10: Condominio Maritimo | G10: -29.995958 | H10: -50.194662 | I10: C5 | J10: - | K10: P6 | L10: LED | M10: 50 | N10: 0 | O10: 0 | P10: =M10*AG10*2 -> 100 | Q10: 2 | R10: 1.2 | S10: 5.8 | V10: 0 | W10: 1.2 | X10: 0 | Y10: 0 | Z10: 0 | AA10: 0 | AB10: 0 | AC10: Unilateral | AD10: Braço | AE10: 25.6 | AF10: 8.1 | AG10: 1 | AH10: 0.3 | AI10: 2.5 | AJ10: =AI10-AH10 -> 2.2 | AK10: - | AL10: - | AM10: Não | AN10: =IF(AC10="Unilateral",2*AG10,IF(AC10="Bilateral Alternada",3*AG10,IF(AC10="Bilateral Frontal",4*AG10,IF(AC10="Canteiro Central",2*AG10,"erro")))) -> 2 | AO10: 0 | AP10: 0 | AQ10: 0 | AR10: 0 | AS10: 0 | AT10: - | AU10: =IF(AO10=0,0,IF(AC10="Unilateral",2*AO10,IF(AC10="Bilateral Alternada",3*AO10,IF(AC10="Bilateral Frontal",4*AO10,IF(AC10="Canteiro Central",2*AO10,"erro"))))) -> 0 | AW10: =VLOOKUP(I10,ABNT5101!$I$3:$J$9,2) -> 7.5 | AX10: =VLOOKUP(I10,ABNT5101!$I$3:$M$9,5) -> 0.18 | AY10: =_xlfn.XLOOKUP(I10,ABNT5101!$I:$I,ABNT5101!$L:$L) -> - | AZ10: =_xlfn.XLOOKUP(I10,ABNT5101!$I:$I,ABNT5101!M:M) -> 0.18 | BA10: =_xlfn.XLOOKUP(I10,ABNT5101!$I:$I,ABNT5101!N:N) -> - | BB10: =_xlfn.XLOOKUP(I10,ABNT5101!$I:$I,ABNT5101!O:O) -> 16 | BC10: =IF(BM10="NÃO ATENDE","NÃO ATENDE",IF(BX10="NÃO ATENDE","NÃO ATENDE",IF(CG10="NÃO ATENDE","NÃO ATENDE","ATENDE"))) -> ATENDE | BD10: =BG10/AW10-1 -> 0.428 | BE10: =BH10/AX10-1 -> 2.7777778 | BF10: =IF($I10="M6",BI10/AY10-1,"-") -> - | BG10: 10.71 | BH10: 0.68 | BM10: =IF(OR(BN10="NÃO ATENDE",BO10="NÃO ATENDE",BP10="NÃO ATENDE"),"NÃO ATENDE","ATENDE") -> ATENDE | BN10: =IF(BG10>=AW10,"ATENDE",IF(BG10>=0.99*AW10,"ATENDIMENTO LIMIAR","NÃO ATENDE")) -> ATENDE | BO10: =IF(BH10>=AX10,"ATENDE",IF(BH10>=(AX10-0.02),"ATENDIMENTO LIMIAR","NÃO ATENDE")) -> ATENDE | BP10: =IF(AY10="-","ATENDE",IF(BI10>=AY10,"ATENDE",IF(BI10>=(AY10-0.02),"ATENDIMENTO LIMIAR","NÃO ATENDE"))) -> ATENDE | BQ10: =I10 -> C5 | BR10: =K10 -> P6 | BS10: =IF(BT10="-","-",BT10/BV10-1) -> 2.3166667 | BT10: 9.95 | BU10: 8.58 | BV10: =IF(BR10="-","-",_xlfn.XLOOKUP(BR10,ABNT5101!$B$4:$B$9,ABNT5101!$C$4:$C$9)) -> 3 | BW10: =IF(BR10="-","-",_xlfn.XLOOKUP(BR10,ABNT5101!$B$4:$B$9,ABNT5101!$D$4:$D$9)) -> 0.6 | BX10: =IF(BY10="-","-",IF(BY10="NÃO ATENDE","NÃO ATENDE",IF(BZ10="NÃO ATENDE","NÃO ATENDE","ATENDE"))) -> ATENDE | BY10: =IF(BR10="-","-",IF(BT10>=BV10,"ATENDE",IF(BT10>=(BV10*0.99),"ATENDIMENTO LIMIAR","NÃO ATENDE"))) -> ATENDE | BZ10: =IF(BR10="-","-",IF(BU10>=BW10,"ATENDE","NÃO ATENDE")) -> ATENDE | CA10: =BR10 -> P6 | CB10: =IF(CC10="-","-",CC10/CE10-1) -> 1.4833333 | CC10: 7.45 | CD10: 5.83 | CE10: =IF(CA10="-","-",_xlfn.XLOOKUP(CA10,ABNT5101!$B$4:$B$9,ABNT5101!$C$4:$C$9)) -> 3 | CF10: =IF(CA10="-","-",_xlfn.XLOOKUP(CA10,ABNT5101!$B$4:$B$9,ABNT5101!$D$4:$D$9)) -> 0.6 | CG10: =IF(CH10="-","-",IF(CH10="NÃO ATENDE","NÃO ATENDE",IF(CI10="NÃO ATENDE","NÃO ATENDE","ATENDE"))) -> ATENDE | CH10: =IF(CA10="-","-",IF(CC10>=(CE10),"ATENDE",IF(CC10>=(0.99*CE10),"ATENDIMENTO LIMIAR","NÃO ATENDE"))) -> ATENDE | CI10: =IF(CA10="-","-",IF(CD10>=CF10,"ATENDE","NÃO ATENDE")) -> ATENDE | CJ10: =_xlfn.XLOOKUP(CK10,'Banco de dados'!$B:$B,'Banco de dados'!$D:$D) -> TECNOWATT | CK10: SIGSAGPTLRRSSNDL_30W_38IBBRS | CL10: =_xlfn.XLOOKUP(CK10,'Banco de dados'!$B:$B,'Banco de dados'!$E:$E) -> SIGSAGPTLRRSSNDL_30W_38IBBRS 1-10C1MUN6.5 | CN10: =IF(CM10="-","-",_xlfn.XLOOKUP(CM10,'Banco de dados'!$B:$B,'Banco de dados'!$E:$E)) -> #N/A | CO10: =AG10 -> 1 | CP10: =_xlfn.XLOOKUP(CK10,'Banco de dados'!$B:$B,'Banco de dados'!$H:$H) -> 30 | CQ10: =_xlfn.XLOOKUP(CM10,'Banco de dados'!$B:$B,'Banco de dados'!$H:$H) -> 0 | CR10: =_xlfn.XLOOKUP(CK10,'Banco de dados'!$B:$B,'Banco de dados'!$F:$F) -> 5266 | CS10: =_xlfn.XLOOKUP(CM10,'Banco de dados'!$B:$B,'Banco de dados'!$F:$F) -> 0 | CT10: 0 | CV10: =IF(AI10<=0.5,"Curto I",IF(AND(AI10>='Braços de IP'!$B$9,AI10<='Braços de IP'!$D$9),'Braços de IP'!$E$9,IF(AND(AI10>='Braços de IP'!$B$10,AI10<='Braços de IP'!$D$10),'Braços de IP'!$E$10,IF(AND(AI10>='Braços de IP'!$B$11,AI10<='Braços de IP'!$D$11),'Braços de IP'!$E$11,IF(AND(AI10>='Braços de IP'!$B$12,AI10<='Braços de IP'!$D$12),'Braços de IP'!$E$12,IF(AND(AI10>='Braços de IP'!$B$13,AI10<='Braços de IP'!$D$13),'Braços de IP'!$E$13,IF(AND(AI10>='Braços de IP'!$B$14,AI10<='Braços de IP'!$D$14),'Braços de IP'!$E$14,"ERRO"))))))) -> Médio II | CX10: =IF($CW10="","",VLOOKUP($CW10,'Braços de IP'!$E$9:$I$15,2,0)) | CY10: =IF($CW10="","",VLOOKUP($CW10,'Braços de IP'!$E$9:$I$15,5,0)) | DF10: =CP10 -> 30 | DG10: =M10 -> 50 | DH10: =SUM(DF10:DG10)*CO10 -> 80 | DI10: =1-DF10/DG10 -> 0.4 | DL10: Não | DO10: =((M10+N10)-CP10)/(M10+N10) -> 0.4 | DQ10: Classe | DR10: Quantidade | DS10: %
C11: Carol | D11: 2 | E11: PVP | F11: Marina Park Residence | G11: -29.997438 | H11: -50.185203 | I11: C5 | J11: - | K11: P6 | L11: LED | M11: 50 | N11: 0 | O11: 0 | P11: =M11*AG11*2 -> 100 | Q11: 2 | R11: 3 | S11: 7 | V11: 0 | W11: 3 | X11: 0 | Y11: 0 | Z11: 0 | AA11: 0 | AB11: 0 | AC11: Unilateral | AD11: Braço | AE11: 33.9 | AF11: 6.8 | AG11: 1 | AH11: 0.2 | AI11: 1.3 | AJ11: =AI11-AH11 -> 1.1 | AK11: - | AL11: - | AM11: Não | AN11: =IF(AC11="Unilateral",2*AG11,IF(AC11="Bilateral Alternada",3*AG11,IF(AC11="Bilateral Frontal",4*AG11,IF(AC11="Canteiro Central",2*AG11,"erro")))) -> 2 | AO11: 0 | AP11: 0 | AQ11: 0 | AR11: 0 | AS11: 0 | AT11: - | AU11: =IF(AO11=0,0,IF(AC11="Unilateral",2*AO11,IF(AC11="Bilateral Alternada",3*AO11,IF(AC11="Bilateral Frontal",4*AO11,IF(AC11="Canteiro Central",2*AO11,"erro"))))) -> 0 | AW11: =VLOOKUP(I11,ABNT5101!$I$3:$J$9,2) -> 7.5 | AX11: =VLOOKUP(I11,ABNT5101!$I$3:$M$9,5) -> 0.18 | AY11: =_xlfn.XLOOKUP(I11,ABNT5101!$I:$I,ABNT5101!$L:$L) -> - | AZ11: =_xlfn.XLOOKUP(I11,ABNT5101!$I:$I,ABNT5101!M:M) -> 0.18 | BA11: =_xlfn.XLOOKUP(I11,ABNT5101!$I:$I,ABNT5101!N:N) -> - | BB11: =_xlfn.XLOOKUP(I11,ABNT5101!$I:$I,ABNT5101!O:O) -> 16 | BC11: =IF(BM11="NÃO ATENDE","NÃO ATENDE",IF(BX11="NÃO ATENDE","NÃO ATENDE",IF(CG11="NÃO ATENDE","NÃO ATENDE","ATENDE"))) -> ATENDE | BD11: =BG11/AW11-1 -> 0.26266667 | BE11: =BH11/AX11-1 -> 1.0555556 | BF11: =IF($I11="M6",BI11/AY11-1,"-") -> - | BG11: 9.47 | BH11: 0.37 | BM11: =IF(OR(BN11="NÃO ATENDE",BO11="NÃO ATENDE",BP11="NÃO ATENDE"),"NÃO ATENDE","ATENDE") -> ATENDE | BN11: =IF(BG11>=AW11,"ATENDE",IF(BG11>=0.99*AW11,"ATENDIMENTO LIMIAR","NÃO ATENDE")) -> ATENDE | BO11: =IF(BH11>=AX11,"ATENDE",IF(BH11>=(AX11-0.02),"ATENDIMENTO LIMIAR","NÃO ATENDE")) -> ATENDE | BP11: =IF(AY11="-","ATENDE",IF(BI11>=AY11,"ATENDE",IF(BI11>=(AY11-0.02),"ATENDIMENTO LIMIAR","NÃO ATENDE"))) -> ATENDE | BQ11: =I11 -> C5 | BR11: =K11 -> P6 | BS11: =IF(BT11="-","-",BT11/BV11-1) -> 1.3033333 | BT11: 6.91 | BU11: 2.18 | BV11: =IF(BR11="-","-",_xlfn.XLOOKUP(BR11,ABNT5101!$B$4:$B$9,ABNT5101!$C$4:$C$9)) -> 3 | BW11: =IF(BR11="-","-",_xlfn.XLOOKUP(BR11,ABNT5101!$B$4:$B$9,ABNT5101!$D$4:$D$9)) -> 0.6 | BX11: =IF(BY11="-","-",IF(BY11="NÃO ATENDE","NÃO ATENDE",IF(BZ11="NÃO ATENDE","NÃO ATENDE","ATENDE"))) -> ATENDE | BY11: =IF(BR11="-","-",IF(BT11>=BV11,"ATENDE",IF(BT11>=(BV11*0.99),"ATENDIMENTO LIMIAR","NÃO ATENDE"))) -> ATENDE | BZ11: =IF(BR11="-","-",IF(BU11>=BW11,"ATENDE","NÃO ATENDE")) -> ATENDE | CA11: =BR11 -> P6 | CB11: =IF(CC11="-","-",CC11/CE11-1) -> 0.67333333 | CC11: 5.02 | CD11: 2.09 | CE11: =IF(CA11="-","-",_xlfn.XLOOKUP(CA11,ABNT5101!$B$4:$B$9,ABNT5101!$C$4:$C$9)) -> 3 | CF11: =IF(CA11="-","-",_xlfn.XLOOKUP(CA11,ABNT5101!$B$4:$B$9,ABNT5101!$D$4:$D$9)) -> 0.6 | CG11: =IF(CH11="-","-",IF(CH11="NÃO ATENDE","NÃO ATENDE",IF(CI11="NÃO ATENDE","NÃO ATENDE","ATENDE"))) -> ATENDE | CH11: =IF(CA11="-","-",IF(CC11>=(CE11),"ATENDE",IF(CC11>=(0.99*CE11),"ATENDIMENTO LIMIAR","NÃO ATENDE"))) -> ATENDE | CI11: =IF(CA11="-","-",IF(CD11>=CF11,"ATENDE","NÃO ATENDE")) -> ATENDE | CJ11: =_xlfn.XLOOKUP(CK11,'Banco de dados'!$B:$B,'Banco de dados'!$D:$D) -> LEDSTAR | CK11: SL VT 9.1 35W | CL11: =_xlfn.XLOOKUP(CK11,'Banco de dados'!$B:$B,'Banco de dados'!$E:$E) -> LUM LED SL VT 9.1 35W | CN11: =IF(CM11="-","-",_xlfn.XLOOKUP(CM11,'Banco de dados'!$B:$B,'Banco de dados'!$E:$E)) -> #N/A | CO11: =AG11 -> 1 | CP11: =_xlfn.XLOOKUP(CK11,'Banco de dados'!$B:$B,'Banco de dados'!$H:$H) -> 35 | CQ11: =_xlfn.XLOOKUP(CM11,'Banco de dados'!$B:$B,'Banco de dados'!$H:$H) -> #N/A | CR11: =_xlfn.XLOOKUP(CK11,'Banco de dados'!$B:$B,'Banco de dados'!$F:$F) -> 5955.62 | CS11: =_xlfn.XLOOKUP(CM11,'Banco de dados'!$B:$B,'Banco de dados'!$F:$F) -> 0 | CT11: 0 | CV11: =IF(AI11<=0.5,"Curto I",IF(AND(AI11>='Braços de IP'!$B$9,AI11<='Braços de IP'!$D$9),'Braços de IP'!$E$9,IF(AND(AI11>='Braços de IP'!$B$10,AI11<='Braços de IP'!$D$10),'Braços de IP'!$E$10,IF(AND(AI11>='Braços de IP'!$B$11,AI11<='Braços de IP'!$D$11),'Braços de IP'!$E$11,IF(AND(AI11>='Braços de IP'!$B$12,AI11<='Braços de IP'!$D$12),'Braços de IP'!$E$12,IF(AND(AI11>='Braços de IP'!$B$13,AI11<='Braços de IP'!$D$13),'Braços de IP'!$E$13,IF(AND(AI11>='Braços de IP'!$B$14,AI11<='Braços de IP'!$D$14),'Braços de IP'!$E$14,"ERRO"))))))) -> Curto II | CX11: =IF($CW11="","",VLOOKUP($CW11,'Braços de IP'!$E$9:$I$15,2,0)) | CY11: =IF($CW11="","",VLOOKUP($CW11,'Braços de IP'!$E$9:$I$15,5,0)) | DF11: =CP11 -> 35 | DG11: =M11 -> 50 | DH11: =SUM(DF11:DG11)*CO11 -> 85 | DI11: =1-DF11/DG11 -> 0.3 | DL11: Não | DO11: =((M11+N11)-CP11)/(M11+N11) -> 0.3 | DQ11: Classe | DR11: Quantidade | DS11: %
C12: Carol | D12: 2 | E12: PVP | F12: Marina Park Residence | G12: -29.997438 | H12: -50.185203 | I12: C5 | J12: - | K12: P6 | L12: LED | M12: 50 | N12: 0 | O12: 0 | P12: =M12*AG12*2 -> 100 | Q12: 2 | R12: 3 | S12: 7 | V12: 0 | W12: 3 | X12: 0 | Y12: 0 | Z12: 0 | AA12: 0 | AB12: 0 | AC12: Unilateral | AD12: Braço | AE12: 33.9 | AF12: 6.8 | AG12: 1 | AH12: 0.2 | AI12: 1.3 | AJ12: =AI12-AH12 -> 1.1 | AK12: - | AL12: - | AM12: Não | AN12: =IF(AC12="Unilateral",2*AG12,IF(AC12="Bilateral Alternada",3*AG12,IF(AC12="Bilateral Frontal",4*AG12,IF(AC12="Canteiro Central",2*AG12,"erro")))) -> 2 | AO12: 0 | AP12: 0 | AQ12: 0 | AR12: 0 | AS12: 0 | AT12: - | AU12: =IF(AO12=0,0,IF(AC12="Unilateral",2*AO12,IF(AC12="Bilateral Alternada",3*AO12,IF(AC12="Bilateral Frontal",4*AO12,IF(AC12="Canteiro Central",2*AO12,"erro"))))) -> 0 | AW12: =VLOOKUP(I12,ABNT5101!$I$3:$J$9,2) -> 7.5 | AX12: =VLOOKUP(I12,ABNT5101!$I$3:$M$9,5) -> 0.18 | AY12: =_xlfn.XLOOKUP(I12,ABNT5101!$I:$I,ABNT5101!$L:$L) -> - | AZ12: =_xlfn.XLOOKUP(I12,ABNT5101!$I:$I,ABNT5101!M:M) -> 0.18 | BA12: =_xlfn.XLOOKUP(I12,ABNT5101!$I:$I,ABNT5101!N:N) -> - | BB12: =_xlfn.XLOOKUP(I12,ABNT5101!$I:$I,ABNT5101!O:O) -> 16 | BC12: =IF(BM12="NÃO ATENDE","NÃO ATENDE",IF(BX12="NÃO ATENDE","NÃO ATENDE",IF(CG12="NÃO ATENDE","NÃO ATENDE","ATENDE"))) -> ATENDE | BD12: =BG12/AW12-1 -> 0.21866667 | BE12: =BH12/AX12-1 -> 1.0555556 | BF12: =IF($I12="M6",BI12/AY12-1,"-") -> - | BG12: 9.14 | BH12: 0.37 | BM12: =IF(OR(BN12="NÃO ATENDE",BO12="NÃO ATENDE",BP12="NÃO ATENDE"),"NÃO ATENDE","ATENDE") -> ATENDE | BN12: =IF(BG12>=AW12,"ATENDE",IF(BG12>=0.99*AW12,"ATENDIMENTO LIMIAR","NÃO ATENDE")) -> ATENDE | BO12: =IF(BH12>=AX12,"ATENDE",IF(BH12>=(AX12-0.02),"ATENDIMENTO LIMIAR","NÃO ATENDE")) -> ATENDE | BP12: =IF(AY12="-","ATENDE",IF(BI12>=AY12,"ATENDE",IF(BI12>=(AY12-0.02),"ATENDIMENTO LIMIAR","NÃO ATENDE"))) -> ATENDE | BQ12: =I12 -> C5 | BR12: =K12 -> P6 | BS12: =IF(BT12="-","-",BT12/BV12-1) -> 1.0633333 | BT12: 6.19 | BU12: 1.1 | BV12: =IF(BR12="-","-",_xlfn.XLOOKUP(BR12,ABNT5101!$B$4:$B$9,ABNT5101!$C$4:$C$9)) -> 3 | BW12: =IF(BR12="-","-",_xlfn.XLOOKUP(BR12,ABNT5101!$B$4:$B$9,ABNT5101!$D$4:$D$9)) -> 0.6 | BX12: =IF(BY12="-","-",IF(BY12="NÃO ATENDE","NÃO ATENDE",IF(BZ12="NÃO ATENDE","NÃO ATENDE","ATENDE"))) -> ATENDE | BY12: =IF(BR12="-","-",IF(BT12>=BV12,"ATENDE",IF(BT12>=(BV12*0.99),"ATENDIMENTO LIMIAR","NÃO ATENDE"))) -> ATENDE | BZ12: =IF(BR12="-","-",IF(BU12>=BW12,"ATENDE","NÃO ATENDE")) -> ATENDE | CA12: =BR12 -> P6 | CB12: =IF(CC12="-","-",CC12/CE12-1) -> 0.34 | CC12: 4.02 | CD12: 1.7 | CE12: =IF(CA12="-","-",_xlfn.XLOOKUP(CA12,ABNT5101!$B$4:$B$9,ABNT5101!$C$4:$C$9)) -> 3 | CF12: =IF(CA12="-","-",_xlfn.XLOOKUP(CA12,ABNT5101!$B$4:$B$9,ABNT5101!$D$4:$D$9)) -> 0.6 | CG12: =IF(CH12="-","-",IF(CH12="NÃO ATENDE","NÃO ATENDE",IF(CI12="NÃO ATENDE","NÃO ATENDE","ATENDE"))) -> ATENDE | CH12: =IF(CA12="-","-",IF(CC12>=(CE12),"ATENDE",IF(CC12>=(0.99*CE12),"ATENDIMENTO LIMIAR","NÃO ATENDE"))) -> ATENDE | CI12: =IF(CA12="-","-",IF(CD12>=CF12,"ATENDE","NÃO ATENDE")) -> ATENDE | CJ12: =_xlfn.XLOOKUP(CK12,'Banco de dados'!$B:$B,'Banco de dados'!$D:$D) -> SX LIGHTING | CK12: SX-INEVO030HF | CL12: =_xlfn.XLOOKUP(CK12,'Banco de dados'!$B:$B,'Banco de dados'!$E:$E) -> SXINEVO030K40L12CZF7PHF | CN12: =IF(CM12="-","-",_xlfn.XLOOKUP(CM12,'Banco de dados'!$B:$B,'Banco de dados'!$E:$E)) -> #N/A | CO12: =AG12 -> 1 | CP12: =_xlfn.XLOOKUP(CK12,'Banco de dados'!$B:$B,'Banco de dados'!$H:$H) -> 31 | CQ12: =_xlfn.XLOOKUP(CM12,'Banco de dados'!$B:$B,'Banco de dados'!$H:$H) -> #N/A | CR12: =_xlfn.XLOOKUP(CK12,'Banco de dados'!$B:$B,'Banco de dados'!$F:$F) -> 5270 | CS12: =_xlfn.XLOOKUP(CM12,'Banco de dados'!$B:$B,'Banco de dados'!$F:$F) -> 0 | CT12: 0 | CV12: =IF(AI12<=0.5,"Curto I",IF(AND(AI12>='Braços de IP'!$B$9,AI12<='Braços de IP'!$D$9),'Braços de IP'!$E$9,IF(AND(AI12>='Braços de IP'!$B$10,AI12<='Braços de IP'!$D$10),'Braços de IP'!$E$10,IF(AND(AI12>='Braços de IP'!$B$11,AI12<='Braços de IP'!$D$11),'Braços de IP'!$E$11,IF(AND(AI12>='Braços de IP'!$B$12,AI12<='Braços de IP'!$D$12),'Braços de IP'!$E$12,IF(AND(AI12>='Braços de IP'!$B$13,AI12<='Braços de IP'!$D$13),'Braços de IP'!$E$13,IF(AND(AI12>='Braços de IP'!$B$14,AI12<='Braços de IP'!$D$14),'Braços de IP'!$E$14,"ERRO"))))))) -> Curto II | CX12: =IF($CW12="","",VLOOKUP($CW12,'Braços de IP'!$E$9:$I$15,2,0)) | CY12: =IF($CW12="","",VLOOKUP($CW12,'Braços de IP'!$E$9:$I$15,5,0)) | DF12: =CP12 -> 31 | DG12: =M12 -> 50 | DH12: =SUM(DF12:DG12)*CO12 -> 81 | DI12: =1-DF12/DG12 -> 0.38 | DL12: Não | DO12: =((M12+N12)-CP12)/(M12+N12) -> 0.38 | DQ12: Classe | DR12: Quantidade | DS12: %
C13: Carol | D13: 2 | E13: PVP | F13: Marina Park Residence | G13: -29.997438 | H13: -50.185203 | I13: C5 | J13: - | K13: P6 | L13: LED | M13: 50 | N13: 0 | O13: 0 | P13: =M13*AG13*2 -> 100 | Q13: 2 | R13: 3 | S13: 7 | V13: 0 | W13: 3 | X13: 0 | Y13: 0 | Z13: 0 | AA13: 0 | AB13: 0 | AC13: Unilateral | AD13: Braço | AE13: 33.9 | AF13: 6.8 | AG13: 1 | AH13: 0.2 | AI13: 1.3 | AJ13: =AI13-AH13 -> 1.1 | AK13: - | AL13: - | AM13: Não | AN13: =IF(AC13="Unilateral",2*AG13,IF(AC13="Bilateral Alternada",3*AG13,IF(AC13="Bilateral Frontal",4*AG13,IF(AC13="Canteiro Central",2*AG13,"erro")))) -> 2 | AO13: 0 | AP13: 0 | AQ13: 0 | AR13: 0 | AS13: 0 | AT13: - | AU13: =IF(AO13=0,0,IF(AC13="Unilateral",2*AO13,IF(AC13="Bilateral Alternada",3*AO13,IF(AC13="Bilateral Frontal",4*AO13,IF(AC13="Canteiro Central",2*AO13,"erro"))))) -> 0 | AW13: =VLOOKUP(I13,ABNT5101!$I$3:$J$9,2) -> 7.5 | AX13: =VLOOKUP(I13,ABNT5101!$I$3:$M$9,5) -> 0.18 | AY13: =_xlfn.XLOOKUP(I13,ABNT5101!$I:$I,ABNT5101!$L:$L) -> - | AZ13: =_xlfn.XLOOKUP(I13,ABNT5101!$I:$I,ABNT5101!M:M) -> 0.18 | BA13: =_xlfn.XLOOKUP(I13,ABNT5101!$I:$I,ABNT5101!N:N) -> - | BB13: =_xlfn.XLOOKUP(I13,ABNT5101!$I:$I,ABNT5101!O:O) -> 16 | BC13: =IF(BM13="NÃO ATENDE","NÃO ATENDE",IF(BX13="NÃO ATENDE","NÃO ATENDE",IF(CG13="NÃO ATENDE","NÃO ATENDE","ATENDE"))) -> ATENDE | BD13: =BG13/AW13-1 -> 0.2 | BE13: =BH13/AX13-1 -> 1.5555556 | BF13: =IF($I13="M6",BI13/AY13-1,"-") -> - | BG13: 9 | BH13: 0.46 | BM13: =IF(OR(BN13="NÃO ATENDE",BO13="NÃO ATENDE",BP13="NÃO ATENDE"),"NÃO ATENDE","ATENDE") -> ATENDE | BN13: =IF(BG13>=AW13,"ATENDE",IF(BG13>=0.99*AW13,"ATENDIMENTO LIMIAR","NÃO ATENDE")) -> ATENDE | BO13: =IF(BH13>=AX13,"ATENDE",IF(BH13>=(AX13-0.02),"ATENDIMENTO LIMIAR","NÃO ATENDE")) -> ATENDE | BP13: =IF(AY13="-","ATENDE",IF(BI13>=AY13,"ATENDE",IF(BI13>=(AY13-0.02),"ATENDIMENTO LIMIAR","NÃO ATENDE"))) -> ATENDE | BQ13: =I13 -> C5 | BR13: =K13 -> P6 | BS13: =IF(BT13="-","-",BT13/BV13-1) -> 1.11 | BT13: 6.33 | BU13: 2.47 | BV13: =IF(BR13="-","-",_xlfn.XLOOKUP(BR13,ABNT5101!$B$4:$B$9,ABNT5101!$C$4:$C$9)) -> 3 | BW13: =IF(BR13="-","-",_xlfn.XLOOKUP(BR13,ABNT5101!$B$4:$B$9,ABNT5101!$D$4:$D$9)) -> 0.6 | BX13: =IF(BY13="-","-",IF(BY13="NÃO ATENDE","NÃO ATENDE",IF(BZ13="NÃO ATENDE","NÃO ATENDE","ATENDE"))) -> ATENDE | BY13: =IF(BR13="-","-",IF(BT13>=BV13,"ATENDE",IF(BT13>=(BV13*0.99),"ATENDIMENTO LIMIAR","NÃO ATENDE"))) -> ATENDE | BZ13: =IF(BR13="-","-",IF(BU13>=BW13,"ATENDE","NÃO ATENDE")) -> ATENDE | CA13: =BR13 -> P6 | CB13: =IF(CC13="-","-",CC13/CE13-1) -> 0.27 | CC13: 3.81 | CD13: 2.27 | CE13: =IF(CA13="-","-",_xlfn.XLOOKUP(CA13,ABNT5101!$B$4:$B$9,ABNT5101!$C$4:$C$9)) -> 3 | CF13: =IF(CA13="-","-",_xlfn.XLOOKUP(CA13,ABNT5101!$B$4:$B$9,ABNT5101!$D$4:$D$9)) -> 0.6 | CG13: =IF(CH13="-","-",IF(CH13="NÃO ATENDE","NÃO ATENDE",IF(CI13="NÃO ATENDE","NÃO ATENDE","ATENDE"))) -> ATENDE | CH13: =IF(CA13="-","-",IF(CC13>=(CE13),"ATENDE",IF(CC13>=(0.99*CE13),"ATENDIMENTO LIMIAR","NÃO ATENDE"))) -> ATENDE | CI13: =IF(CA13="-","-",IF(CD13>=CF13,"ATENDE","NÃO ATENDE")) -> ATENDE | CJ13: =_xlfn.XLOOKUP(CK13,'Banco de dados'!$B:$B,'Banco de dados'!$D:$D) -> TECNOWATT | CK13: SIGSAGPTLRRSSNDL_30W_38IBBRS | CL13: =_xlfn.XLOOKUP(CK13,'Banco de dados'!$B:$B,'Banco de dados'!$E:$E) -> SIGSAGPTLRRSSNDL_30W_38IBBRS 1-10C1MUN6.5 | CN13: =IF(CM13="-","-",_xlfn.XLOOKUP(CM13,'Banco de dados'!$B:$B,'Banco de dados'!$E:$E)) -> #N/A | CO13: =AG13 -> 1 | CP13: =_xlfn.XLOOKUP(CK13,'Banco de dados'!$B:$B,'Banco de dados'!$H:$H) -> 30 | CQ13: =_xlfn.XLOOKUP(CM13,'Banco de dados'!$B:$B,'Banco de dados'!$H:$H) -> #N/A | CR13: =_xlfn.XLOOKUP(CK13,'Banco de dados'!$B:$B,'Banco de dados'!$F:$F) -> 5266 | CS13: =_xlfn.XLOOKUP(CM13,'Banco de dados'!$B:$B,'Banco de dados'!$F:$F) -> 0 | CT13: 0 | CV13: =IF(AI13<=0.5,"Curto I",IF(AND(AI13>='Braços de IP'!$B$9,AI13<='Braços de IP'!$D$9),'Braços de IP'!$E$9,IF(AND(AI13>='Braços de IP'!$B$10,AI13<='Braços de IP'!$D$10),'Braços de IP'!$E$10,IF(AND(AI13>='Braços de IP'!$B$11,AI13<='Braços de IP'!$D$11),'Braços de IP'!$E$11,IF(AND(AI13>='Braços de IP'!$B$12,AI13<='Braços de IP'!$D$12),'Braços de IP'!$E$12,IF(AND(AI13>='Braços de IP'!$B$13,AI13<='Braços de IP'!$D$13),'Braços de IP'!$E$13,IF(AND(AI13>='Braços de IP'!$B$14,AI13<='Braços de IP'!$D$14),'Braços de IP'!$E$14,"ERRO"))))))) -> Curto II | CX13: =IF($CW13="","",VLOOKUP($CW13,'Braços de IP'!$E$9:$I$15,2,0)) | CY13: =IF($CW13="","",VLOOKUP($CW13,'Braços de IP'!$E$9:$I$15,5,0)) | DF13: =CP13 -> 30 | DG13: =M13 -> 50 | DH13: =SUM(DF13:DG13)*CO13 -> 80 | DI13: =1-DF13/DG13 -> 0.4 | DL13: Não | DO13: =((M13+N13)-CP13)/(M13+N13) -> 0.4 | DQ13: Classe | DR13: Quantidade | DS13: %
