Workbook
Name Banco_Tipologias: Banco_Tipologias!$C$4:$N$17
Name colunaclasses: Simulações!$BR$2:$BR$1237
Name ilumatic: 'Banco de dados'!#REF!
Name philips: 'Banco de dados'!#REF!
Name red_global: 'Banco de dados'!#REF!
Name red_juganu: 'Banco de dados'!#REF!
Name red_philips: 'Banco de dados'!#REF!
Name red_repume: 'Banco de dados'!#REF!
Name red_tecno: 'Banco de dados'!#REF!
Name redglobal: 'Banco de dados'!#REF!
Name tecnowat: 'Banco de dados'!#REF!

Sheet DefiniçãoFornecedores
D2: Estruturas
B3: Definição | D3: V1 | E3: V2 | F3: V3 | G3: V4 | H3: V5 | I3: Observação
B4: Fornecedor L1 | C4: Conexled | D4: 0 | E4: 0 | F4: 0 | G4: 0 | H4: 0 | I4: Não possui orçamento
B5: Fornecedor L2 | C5: Ilumatic | D5: 0 | E5: 0 | F5: 0 | G5: 0 | H5: 0 | I5: Não possui orçamento
B6: Fornecedor L3 | C6: Juganu | D6: 0 | E6: 0 | F6: 0 | G6: 0 | H6: 0 | I6: Possui orçamento, definir qual classe melhor atende
B7: Fornecedor L4 | C7: Philips | D7: 1 | E7: 1 | F7: 1 | G7: 1 | H7: 1 | I7: Não possui orçamento
B8: Fornecedor L5 | C8: Repume | D8: 0 | E8: 0 | F8: 0 | G8: 0 | H8: 0 | I8: Não possui orçamento
B9: Fornecedor L6 | C9: Tecnowatt | D9: 1 | E9: 1 | F9: 1 | G9: 1 | H9: 1 | I9: Possui orçamento, definir qual classe melhor atende
B10: Fornecedor L7 | C10: Unicoba | D10: 1 | E10: 1 | F10: 1 | G10: 1 | H10: 1 | I10: Possui orçamento, definir qual classe melhor atende
B11: Fornecedor L8 | C11: SX Lighting | D11: 0 | E11: 0 | F11: 0 | G11: 0 | H11: 0 | I11: Não possui orçamento

Sheet Simulações
B1: Id cadastro | C1: Simular | D1: Automatizada | E1: Etiqueta | F1: Padrão | G1: Logradouro | H1: latitude | I1: longitude | J1: Classificação viária | K1: Classificação ciclovia | L1: Classificação pedonal | M1: Tipo de lâmpada | N1: Potencia da lâmpada | O1: Reator | P1: Potencia 2o nivel | Q1: POT TOTAL MALHA | R1: Faixas de Rodagem | S1: Largura Passeio 1 | T1: Largura Via 1 | U1: largura Passeio Central 1 | V1: largura Passeio Central 2 | W1: Largura Via 2 | X1: largura Passeio 2 | Y1: largura Canteiro Central | Z1: largura Ciclovia 1 | AA1: largura Ciclovia 2 | AB1: estacionamento 1 | AC1: estacionamento 2 | AD1: posteacao | AE1: Tipo de estrutura | AF1: distancia entre postes | AG1: altura da luminaria | AH1: qtd de Lampadas IP Princ | AI1: distancia Poste a via | AJ1: projecao do braço | AK1: Pendor | AL1: Altura de Instalação | AM1: Projeção Vertical | AN1: Exclusivo | AO1: Quantidade de pontos inspecionados IP Veic | AP1: qtd de Lampadas IP 2o nivel | AQ1: Tipo de posteação 2o nivel | AR1: Distanciamento 2o nivel | AS1: Altura da luminaria 2o nivel | AT1: Projecao 2o nivel | AU1: Distancia poste-via 2o nivel | AV1: Quantidade de pontos inspecionados IP Sec | AW1: informacoes Adicionais | AX1: Emed - Norma | AY1: U - Norma | AZ1: Luminância Média Exigida | BA1: Uo Uniformidade Global Exigida | BB1: Uniformidade Longitudinal Exigida | BC1: Incremento Linear Exigido | BD1: Atendimento pleno à norma | BE1: Excesso de iluminância média IV | BF1: Excesso de Uniformidade IV | BG1: Excesso de luminância média IV | BH1: Iluminância Média | BI1: Uniformidade Global Mínima | BJ1: Luminância Média | BK1: Uniformidade Longitudinal | BL1: Incremento Linear (TI) | BM1: EIR | BN1: ATENDE TUDO - RUA SIMU | BO1: Atende à Iluminância Média | BP1: Atende à Uniformidade Global Miníma | BQ1: Atende à Luminância Média | BR1: Classe IV | BS1: Classe IP | BT1: Excesso de iluminância média P1 | BU1: Iluminância Média | BV1: Iluminância mínima horizontal E (lux) | BW1: Iluminância Média (Exigida) | BX1: Iluminância mínima horizontal E (lux) | BY1: Atende à NBR 5101 - TUDO SIMU | BZ1: Atende à Iluminância Média | CA1: Atende à Iluminância mínima horizontal | CB1: Classe IP | CC1: Excesso de iluminância média P2 | CD1: Iluminância Média | CE1: Iluminância mínima horizontal E (lux) | CF1: Iluminância Média (Exigida) | CG1: Iluminância mínima horizontal E (lux) exigida | CH1: Atende à NBR 5101 - TUDO SIMU P2 | CI1: Atende à Iluminância Média | CJ1: Atende à Iluminância mínima horizontal | CK1: Fornecedor | CL1: Código Luminária 1 | CM1: Luminária Simulada (IP Principal) | CN1: Código Luminária 2 | CO1: Luminária Simulada (IP Secundário) | CP1: Pontos por poste (IP Principal) | CQ1: Potência simulada - IP Principal (W) | CR1: Potência simulada - IP Secundário (W) | CS1: Fluxo Luminoso - IP Principal (lm) | CT1: Fluxo Luminoso - IP Secundário (lm) | CU1: Ângulo antigo | CV1: Ângulo Simulado | CW1: Braço Antigo | CX1: Braço Novo | CY1: Projeção com alteração | CZ1: Altura de luminária com alteração | DA1: Correção de Ponto Escuro (CPE) | DB1: Quantidade de pontos adicionados para via de veículo | DC1: Quantidade de pontos adicionados para 2º nível | DD1: Observação CPE (Reduçao entre postes e/ou Tipo de Posteação) | DE1: obs conferência | DF1: rev conferência | DG1: IP PRINC SIM | DH1: IP SEC SIM | DI1: TOTAL SIMULADO | DJ1: Eficientização | DK1: Estrutura | DL1: Simulação | DM1: Conferência | DN1: Considerar na Extrapolação | DO1: Inspeção | DQ1: eficientização
E2: IP01982 | F2: PVP | G2: Rua Rua Madalena Gilouski | H2: -23.341599 | I2: -46.826291 | J2: C5 | L2: P6 | M2: LED | N2: 60 | O2: Interno | P2: - | Q2: =N2*AH2*2 -> 120 | R2: 1 | S2: 2 | T2: 5 | X2: 1.5 | AD2: Unilateral | AE2: Braço | AF2: 22 | AG2: 7.3 | AH2: 1 | AI2: 0.65 | AJ2: 1.3 | AK2: =AJ2-AI2 -> 0.65 | AL2: - | AM2: - | AN2: Não | AO2: =IF(AD2="Unilateral",2*AH2,IF(AD2="Bilateral Alternada",3*AH2,IF(AD2="Bilateral Frontal",4*AH2,IF(AD2="Canteiro Central",2*AH2,"erro")))) -> 2 | AV2: =IF(AP2=0,0,IF(AD2="Unilateral",2*AP2,IF(AD2="Bilateral Alternada",3*AP2,IF(AD2="Bilateral Frontal",4*AP2,IF(AD2="Canteiro Central",2*AP2,"erro"))))) -> 0 | AX2: =VLOOKUP(J2,ABNT5101!$I$3:$J$9,2) -> 7.5 | AY2: =VLOOKUP(J2,ABNT5101!$I$3:$M$9,5) -> 0.18 | AZ2: =_xlfn.XLOOKUP(J2,ABNT5101!I:I,ABNT5101!L:L) -> - | BA2: =_xlfn.XLOOKUP(J2,ABNT5101!$I:$I,ABNT5101!M:M) -> 0.18 | BB2: =_xlfn.XLOOKUP(J2,ABNT5101!$I:$I,ABNT5101!N:N) -> - | BC2: =_xlfn.XLOOKUP(J2,ABNT5101!$I:$I,ABNT5101!O:O) -> 16 | BD2: =IF(BN2="NÃO ATENDE","NÃO ATENDE",IF(BY2="NÃO ATENDE","NÃO ATENDE",IF(CH2="NÃO ATENDE","NÃO ATENDE","ATENDE"))) -> NÃO ATENDE | BE2: =BH2/AX2-1 -> -1 | BF2: =BI2/AY2-1 -> -1 | BG2: =IF($J2="M6",BJ2/AZ2-1,"-") -> - | BN2: =IF(OR(BO2="NÃO ATENDE",BP2="NÃO ATENDE",BQ2="NÃO ATENDE"),"NÃO ATENDE","ATENDE") -> NÃO ATENDE | BO2: =IF(BH2>=AX2,"ATENDE",IF(BH2>=0.99*AX2,"ATENDIMENTO LIMIAR","NÃO ATENDE")) -> NÃO ATENDE | BP2: =IF(BI2>=AY2,"ATENDE",IF(BI2>=(AY2-0.02),"ATENDIMENTO LIMIAR","NÃO ATENDE")) -> NÃO ATENDE | BQ2: =IF(AZ2="-","ATENDE",IF(BJ2>=AZ2,"ATENDE",IF(BJ2>=(AZ2-0.02),"ATENDIMENTO LIMIAR","NÃO ATENDE"))) -> ATENDE | BR2: =J2 -> C5 | BS2: =L2 -> P6 | BT2: =IF(BU2="-","-",BU2/BW2-1) -> -1 | BW2: =IF(BS2="-","-",_xlfn.XLOOKUP(BS2,ABNT5101!$B$4:$B$9,ABNT5101!$C$4:$C$9)) -> 3 | BX2: =IF(BS2="-","-",_xlfn.XLOOKUP(BS2,ABNT5101!$B$4:$B$9,ABNT5101!$D$4:$D$9)) -> 0.6 | BY2: =IF(BZ2="-","-",IF(BZ2="NÃO ATENDE","NÃO ATENDE",IF(CA2="NÃO ATENDE","NÃO ATENDE","ATENDE"))) -> NÃO ATENDE | BZ2: =IF(BS2="-","-",IF(BU2>=BW2,"ATENDE",IF(BU2>=(BW2*0.99),"ATENDIMENTO LIMIAR","NÃO ATENDE"))) -> NÃO ATENDE | CA2: =IF(BS2="-","-",IF(BV2>=BX2,"ATENDE","NÃO ATENDE")) -> NÃO ATENDE | CB2: =BS2 -> P6 | CC2: =IF(CD2="-","-",CD2/CF2-1) -> -1 | CF2: =IF(CB2="-","-",_xlfn.XLOOKUP(CB2,ABNT5101!$B$4:$B$9,ABNT5101!$C$4:$C$9)) -> 3 | CG2: =IF(CB2="-","-",_xlfn.XLOOKUP(CB2,ABNT5101!$B$4:$B$9,ABNT5101!$D$4:$D$9)) -> 0.6 | CH2: =IF(CI2="-","-",IF(CI2="NÃO ATENDE","NÃO ATENDE",IF(CJ2="NÃO ATENDE","NÃO ATENDE","ATENDE"))) -> NÃO ATENDE | CI2: =IF(CB2="-","-",IF(CD2>=(CF2),"ATENDE",IF(CD2>=(0.99*CF2),"ATENDIMENTO LIMIAR","NÃO ATENDE"))) -> NÃO ATENDE | CJ2: =IF(CB2="-","-",IF(CE2>=CG2,"ATENDE","NÃO ATENDE")) -> NÃO ATENDE | CK2: =_xlfn.XLOOKUP(CL2,'Banco de dados'!$B:$B,'Banco de dados'!$D:$D) -> #N/A | CM2: =_xlfn.XLOOKUP(CL2,'Banco de dados'!$B:$B,'Banco de dados'!$E:$E) -> #N/A | CO2: =IF(CN2="-","-",_xlfn.XLOOKUP(CN2,'Banco de dados'!$B:$B,'Banco de dados'!$E:$E)) -> #N/A | CP2: =AH2 -> 1 | CQ2: =_xlfn.XLOOKUP(CL2,'Banco de dados'!$B:$B,'Banco de dados'!$H:$H) -> #N/A | CR2: {=_xludf.xlookup(CN2,'Banco de dados'!$B:$B,'Banco de dados'!$H:$H)} -> #NAME? | CS2: {=_xludf.xlookup(CL2,'Banco de dados'!$B:$B,'Banco de dados'!$F:$F)} -> #NAME? | CT2: {=_xludf.xlookup(CN2,'Banco de dados'!$B:$B,'Banco de dados'!$F:$F)} -> #NAME? | CW2: =IF(AJ2=0.5,"Suporte",IF(AND(AJ2>='Braços de IP'!$B$9,AJ2<='Braços de IP'!$D$9),'Braços de IP'!$E$9,IF(AND(AJ2>='Braços de IP'!$B$10,AJ2<='Braços de IP'!$D$10),'Braços de IP'!$E$10,IF(AND(AJ2>='Braços de IP'!$B$11,AJ2<='Braços de IP'!$D$11),'Braços de IP'!$E$11,IF(AND(AJ2>='Braços de IP'!$B$12,AJ2<='Braços de IP'!$D$12),'Braços de IP'!$E$12,IF(AND(AJ2>='Braços de IP'!$B$13,AJ2<='Braços de IP'!$D$13),'Braços de IP'!$E$13,IF(AND(AJ2>='Braços de IP'!$B$14,AJ2<='Braços de IP'!$D$14),'Braços de IP'!$E$14,"ERRO"))))))) -> Curto II | CY2: =IF($CX2="","",VLOOKUP($CX2,'Braços de IP'!$E$9:$I$15,2,0)) | CZ2: =IF($CX2="","",VLOOKUP($CX2,'Braços de IP'!$E$9:$I$15,5,0)) | DG2: =CQ2 -> #N/A | DH2: =N2 -> 60 | DI2: =SUM(DG2:DH2)*CP2 -> #N/A | DJ2: =1-DG2/DH2 -> #N/A | DK2: Lucas | DN2: Sim | DQ2: =((N2+O2)-CQ2)/(N2+O2) -> #VALUE! | DS2: V4 | DT2: =COUNTIF(J:J,DS2)/3 -> 0 | DU2: =DT2/$DT$414 -> #DIV/0! | DV2: =DT2/SUM($DT$315:$DT$342) -> #DIV/0!
E3: IP01982 | F3: PVP | G3: Rua Rua Madalena Gilouski | H3: -23.341599 | I3: -46.826291 | J3: C5 | L3: P6 | M3: LED | N3: 60 | O3: Interno | P3: - | Q3: =N3*AH3*2 -> 120 | R3: 1 | S3: 2 | T3: 5 | X3: 1.5 | AD3: Unilateral | AE3: Braço | AF3: 22 | AG3: 7.3 | AH3: 1 | AI3: 0.65 | AJ3: 1.3 | AK3: =AJ3-AI3 -> 0.65 | AL3: - | AM3: - | AN3: Não | AO3: =IF(AD3="Unilateral",2*AH3,IF(AD3="Bilateral Alternada",3*AH3,IF(AD3="Bilateral Frontal",4*AH3,IF(AD3="Canteiro Central",2*AH3,"erro")))) -> 2 | AV3: =IF(AP3=0,0,IF(AD3="Unilateral",2*AP3,IF(AD3="Bilateral Alternada",3*AP3,IF(AD3="Bilateral Frontal",4*AP3,IF(AD3="Canteiro Central",2*AP3,"erro"))))) -> 0 | AX3: =VLOOKUP(J3,ABNT5101!$I$3:$J$9,2) -> 7.5 | AY3: =VLOOKUP(J3,ABNT5101!$I$3:$M$9,5) -> 0.18 | AZ3: =_xlfn.XLOOKUP(J3,ABNT5101!I:I,ABNT5101!L:L) -> - | BA3: =_xlfn.XLOOKUP(J3,ABNT5101!$I:$I,ABNT5101!M:M) -> 0.18 | BB3: =_xlfn.XLOOKUP(J3,ABNT5101!$I:$I,ABNT5101!N:N) -> - | BC3: =_xlfn.XLOOKUP(J3,ABNT5101!$I:$I,ABNT5101!O:O) -> 16 | BD3: =IF(BN3="NÃO ATENDE","NÃO ATENDE",IF(BY3="NÃO ATENDE","NÃO ATENDE",IF(CH3="NÃO ATENDE","NÃO ATENDE","ATENDE"))) -> NÃO ATENDE | BE3: =BH3/AX3-1 -> -1 | BF3: =BI3/AY3-1 -> -1 | BG3: =IF($J3="M6",BJ3/AZ3-1,"-") -> - | BN3: =IF(OR(BO3="NÃO ATENDE",BP3="NÃO ATENDE",BQ3="NÃO ATENDE"),"NÃO ATENDE","ATENDE") -> NÃO ATENDE | BO3: =IF(BH3>=AX3,"ATENDE",IF(BH3>=0.99*AX3,"ATENDIMENTO LIMIAR","NÃO ATENDE")) -> NÃO ATENDE | BP3: =IF(BI3>=AY3,"ATENDE",IF(BI3>=(AY3-0.02),"ATENDIMENTO LIMIAR","NÃO ATENDE")) -> NÃO ATENDE | BQ3: =IF(AZ3="-","ATENDE",IF(BJ3>=AZ3,"ATENDE",IF(BJ3>=(AZ3-0.02),"ATENDIMENTO LIMIAR","NÃO ATENDE"))) -> ATENDE | BR3: =J3 -> C5 | BS3: =L3 -> P6 | BT3: =IF(BU3="-","-",BU3/BW3-1) -> -1 | BW3: =IF(BS3="-","-",_xlfn.XLOOKUP(BS3,ABNT5101!$B$4:$B$9,ABNT5101!$C$4:$C$9)) -> 3 | BX3: =IF(BS3="-","-",_xlfn.XLOOKUP(BS3,ABNT5101!$B$4:$B$9,ABNT5101!$D$4:$D$9)) -> 0.6 | BY3: =IF(BZ3="-","-",IF(BZ3="NÃO ATENDE","NÃO ATENDE",IF(CA3="NÃO ATENDE","NÃO ATENDE","ATENDE"))) -> NÃO ATENDE | BZ3: =IF(BS3="-","-",IF(BU3>=BW3,"ATENDE",IF(BU3>=(BW3*0.99),"ATENDIMENTO LIMIAR","NÃO ATENDE"))) -> NÃO ATENDE | CA3: =IF(BS3="-","-",IF(BV3>=BX3,"ATENDE","NÃO ATENDE")) -> NÃO ATENDE | CB3: =BS3 -> P6 | CC3: =IF(CD3="-","-",CD3/CF3-1) -> -1 | CF3: =IF(CB3="-","-",_xlfn.XLOOKUP(CB3,ABNT5101!$B$4:$B$9,ABNT5101!$C$4:$C$9)) -> 3 | CG3: =IF(CB3="-","-",_xlfn.XLOOKUP(CB3,ABNT5101!$B$4:$B$9,ABNT5101!$D$4:$D$9)) -> 0.6 | CH3: =IF(CI3="-","-",IF(CI3="NÃO ATENDE","NÃO ATENDE",IF(CJ3="NÃO ATENDE","NÃO ATENDE","ATENDE"))) -> NÃO ATENDE | CI3: =IF(CB3="-","-",IF(CD3>=(CF3),"ATENDE",IF(CD3>=(0.99*CF3),"ATENDIMENTO LIMIAR","NÃO ATENDE"))) -> NÃO ATENDE | CJ3: =IF(CB3="-","-",IF(CE3>=CG3,"ATENDE","NÃO ATENDE")) -> NÃO ATENDE | CK3: =_xlfn.XLOOKUP(CL3,'Banco de dados'!$B:$B,'Banco de dados'!$D:$D) -> #N/A | CM3: =_xlfn.XLOOKUP(CL3,'Banco de dados'!$B:$B,'Banco de dados'!$E:$E) -> #N/A | CO3: =IF(CN3="-","-",_xlfn.XLOOKUP(CN3,'Banco de dados'!$B:$B,'Banco de dados'!$E:$E)) -> #N/A | CP3: =AH3 -> 1 | CQ3: =_xlfn.XLOOKUP(CL3,'Banco de dados'!$B:$B,'Banco de dados'!$H:$H) -> #N/A | CR3: {=_xludf.xlookup(CN3,'Banco de dados'!$B:$B,'Banco de dados'!$H:$H)} -> #NAME? | CS3: {=_xludf.xlookup(CL3,'Banco de dados'!$B:$B,'Banco de dados'!$F:$F)} -> #NAME? | CT3: {=_xludf.xlookup(CN3,'Banco de dados'!$B:$B,'Banco de dados'!$F:$F)} -> #NAME? | CW3: =IF(AJ3=0.5,"Suporte",IF(AND(AJ3>='Braços de IP'!$B$9,AJ3<='Braços de IP'!$D$9),'Braços de IP'!$E$9,IF(AND(AJ3>='Braços de IP'!$B$10,AJ3<='Braços de IP'!$D$10),'Braços de IP'!$E$10,IF(AND(AJ3>='Braços de IP'!$B$11,AJ3<='Braços de IP'!$D$11),'Braços de IP'!$E$11,IF(AND(AJ3>='Braços de IP'!$B$12,AJ3<='Braços de IP'!$D$12),'Braços de IP'!$E$12,IF(AND(AJ3>='Braços de IP'!$B$13,AJ3<='Braços de IP'!$D$13),'Braços de IP'!$E$13,IF(AND(AJ3>='Braços de IP'!$B$14,AJ3<='Braços de IP'!$D$14),'Braços de IP'!$E$14,"ERRO"))))))) -> Curto II | CY3: =IF($CX3="","",VLOOKUP($CX3,'Braços de IP'!$E$9:$I$15,2,0)) | CZ3: =IF($CX3="","",VLOOKUP($CX3,'Braços de IP'!$E$9:$I$15,5,0)) | DG3: =CQ3 -> #N/A | DH3: =N3 -> 60 | DI3: =SUM(DG3:DH3)*CP3 -> #N/A | DJ3: =1-DG3/DH3 -> #N/A | DK3: Lucas | DN3: Sim | DQ3: =((N3+O3)-CQ3)/(N3+O3) -> #VALUE! | DS3: V4 | DT3: =COUNTIF(J:J,DS3)/3 -> 0 | DU3: =DT3/$DT$414 -> #DIV/0! | DV3: =DT3/SUM($DT$315:$DT$342) -> #DIV/0!
E4: IP01982 | F4: PVP | G4: Rua Rua Madalena Gilouski | H4: -23.341599 | I4: -46.826291 | J4: C5 | L4: P6 | M4: LED | N4: 60 | O4: Interno | P4: - | Q4: =N4*AH4*2 -> 120 | R4: 1 | S4: 2 | T4: 5 | X4: 1.5 | AD4: Unilateral | AE4: Braço | AF4: 22 | AG4: 7.3 | AH4: 1 | AI4: 0.65 | AJ4: 1.3 | AK4: =AJ4-AI4 -> 0.65 | AL4: - | AM4: - | AN4: Não | AO4: =IF(AD4="Unilateral",2*AH4,IF(AD4="Bilateral Alternada",3*AH4,IF(AD4="Bilateral Frontal",4*AH4,IF(AD4="Canteiro Central",2*AH4,"erro")))) -> 2 | AV4: =IF(AP4=0,0,IF(AD4="Unilateral",2*AP4,IF(AD4="Bilateral Alternada",3*AP4,IF(AD4="Bilateral Frontal",4*AP4,IF(AD4="Canteiro Central",2*AP4,"erro"))))) -> 0 | AX4: =VLOOKUP(J4,ABNT5101!$I$3:$J$9,2) -> 7.5 | AY4: =VLOOKUP(J4,ABNT5101!$I$3:$M$9,5) -> 0.18 | AZ4: =_xlfn.XLOOKUP(J4,ABNT5101!I:I,ABNT5101!L:L) -> - | BA4: =_xlfn.XLOOKUP(J4,ABNT5101!$I:$I,ABNT5101!M:M) -> 0.18 | BB4: =_xlfn.XLOOKUP(J4,ABNT5101!$I:$I,ABNT5101!N:N) -> - | BC4: =_xlfn.XLOOKUP(J4,ABNT5101!$I:$I,ABNT5101!O:O) -> 16 | BD4: =IF(BN4="NÃO ATENDE","NÃO ATENDE",IF(BY4="NÃO ATENDE","NÃO ATENDE",IF(CH4="NÃO ATENDE","NÃO ATENDE","ATENDE"))) -> NÃO ATENDE | BE4: =BH4/AX4-1 -> -1 | BF4: =BI4/AY4-1 -> -1 | BG4: =IF($J4="M6",BJ4/AZ4-1,"-") -> - | BN4: =IF(OR(BO4="NÃO ATENDE",BP4="NÃO ATENDE",BQ4="NÃO ATENDE"),"NÃO ATENDE","ATENDE") -> NÃO ATENDE | BO4: =IF(BH4>=AX4,"ATENDE",IF(BH4>=0.99*AX4,"ATENDIMENTO LIMIAR","NÃO ATENDE")) -> NÃO ATENDE | BP4: =IF(BI4>=AY4,"ATENDE",IF(BI4>=(AY4-0.02),"ATENDIMENTO LIMIAR","NÃO ATENDE")) -> NÃO ATENDE | BQ4: =IF(AZ4="-","ATENDE",IF(BJ4>=AZ4,"ATENDE",IF(BJ4>=(AZ4-0.02),"ATENDIMENTO LIMIAR","NÃO ATENDE"))) -> ATENDE | BR4: =J4 -> C5 | BS4: =L4 -> P6 | BT4: =IF(BU4="-","-",BU4/BW4-1) -> -1 | BW4: =IF(BS4="-","-",_xlfn.XLOOKUP(BS4,ABNT5101!$B$4:$B$9,ABNT5101!$C$4:$C$9)) -> 3 | BX4: =IF(BS4="-","-",_xlfn.XLOOKUP(BS4,ABNT5101!$B$4:$B$9,ABNT5101!$D$4:$D$9)) -> 0.6 | BY4: =IF(BZ4="-","-",IF(BZ4="NÃO ATENDE","NÃO ATENDE",IF(CA4="NÃO ATENDE","NÃO ATENDE","ATENDE"))) -> NÃO ATENDE | BZ4: =IF(BS4="-","-",IF(BU4>=BW4,"ATENDE",IF(BU4>=(BW4*0.99),"ATENDIMENTO LIMIAR","NÃO ATENDE"))) -> NÃO ATENDE | CA4: =IF(BS4="-","-",IF(BV4>=BX4,"ATENDE","NÃO ATENDE")) -> NÃO ATENDE | CB4: =BS4 -> P6 | CC4: =IF(CD4="-","-",CD4/CF4-1) -> -1 | CF4: =IF(CB4="-","-",_xlfn.XLOOKUP(CB4,ABNT5101!$B$4:$B$9,ABNT5101!$C$4:$C$9)) -> 3 | CG4: =IF(CB4="-","-",_xlfn.XLOOKUP(CB4,ABNT5101!$B$4:$B$9,ABNT5101!$D$4:$D$9)) -> 0.6 | CH4: =IF(CI4="-","-",IF(CI4="NÃO ATENDE","NÃO ATENDE",IF(CJ4="NÃO ATENDE","NÃO ATENDE","ATENDE"))) -> NÃO ATENDE | CI4: =IF(CB4="-","-",IF(CD4>=(CF4),"ATENDE",IF(CD4>=(0.99*CF4),"ATENDIMENTO LIMIAR","NÃO ATENDE"))) -> NÃO ATENDE | CJ4: =IF(CB4="-","-",IF(CE4>=CG4,"ATENDE","NÃO ATENDE")) -> NÃO ATENDE | CK4: =_xlfn.XLOOKUP(CL4,'Banco de dados'!$B:$B,'Banco de dados'!$D:$D) -> #N/A | CM4: =_xlfn.XLOOKUP(CL4,'Banco de dados'!$B:$B,'Banco de dados'!$E:$E) -> #N/A | CO4: =IF(CN4="-","-",_xlfn.XLOOKUP(CN4,'Banco de dados'!$B:$B,'Banco de dados'!$E:$E)) -> #N/A | CP4: =AH4 -> 1 | CQ4: =_xlfn.XLOOKUP(CL4,'Banco de dados'!$B:$B,'Banco de dados'!$H:$H) -> #N/A | CR4: {=_xludf.xlookup(CN4,'Banco de dados'!$B:$B,'Banco de dados'!$H:$H)} -> #NAME? | CS4: {=_xludf.xlookup(CL4,'Banco de dados'!$B:$B,'Banco de dados'!$F:$F)} -> #NAME? | CT4: {=_xludf.xlookup(CN4,'Banco de dados'!$B:$B,'Banco de dados'!$F:$F)} -> #NAME? | CW4: =IF(AJ4=0.5,"Suporte",IF(AND(AJ4>='Braços de IP'!$B$9,AJ4<='Braços de IP'!$D$9),'Braços de IP'!$E$9,IF(AND(AJ4>='Braços de IP'!$B$10,AJ4<='Braços de IP'!$D$10),'Braços de IP'!$E$10,IF(AND(AJ4>='Braços de IP'!$B$11,AJ4<='Braços de IP'!$D$11),'Braços de IP'!$E$11,IF(AND(AJ4>='Braços de IP'!$B$12,AJ4<='Braços de IP'!$D$12),'Braços de IP'!$E$12,IF(AND(AJ4>='Braços de IP'!$B$13,AJ4<='Braços de IP'!$D$13),'Braços de IP'!$E$13,IF(AND(AJ4>='Braços de IP'!$B$14,AJ4<='Braços de IP'!$D$14),'Braços de IP'!$E$14,"ERRO"))))))) -> Curto II | CY4: =IF($CX4="","",VLOOKUP($CX4,'Braços de IP'!$E$9:$I$15,2,0)) | CZ4: =IF($CX4="","",VLOOKUP($CX4,'Braços de IP'!$E$9:$I$15,5,0)) | DG4: =CQ4 -> #N/A | DH4: =N4 -> 60 | DI4: =SUM(DG4:DH4)*CP4 -> #N/A | DJ4: =1-DG4/DH4 -> #N/A | DK4: Lucas | DN4: Sim | DQ4: =((N4+O4)-CQ4)/(N4+O4) -> #VALUE! | DS4: V4 | DT4: =COUNTIF(J:J,DS4)/3 -> 0 | DU4: =DT4/$DT$414 -> #DIV/0! | DV4: =DT4/SUM($DT$315:$DT$342) -> #DIV/0!
E5: IP04038 | F5: V | G5: Rua Praia Grande | H5: -23.289032 | I5: -46.875007 | J5: C5 | L5: Sem Passeio | M5: LED | N5: 87 | O5: Interno | P5: - | Q5: =N5*AH5*2 -> 174 | R5: 1 | S5: - | T5: 5.8 | X5: - | AD5: Unilateral | AE5: Braço | AF5: 34.5 | AG5: 6.5 | AH5: 1 | AI5: 1.3 | AJ5: 2.3 | AK5: =AJ5-AI5 -> 1 | AL5: - | AM5: - | AO5: =IF(AD5="Unilateral",2*AH5,IF(AD5="Bilateral Alternada",3*AH5,IF(AD5="Bilateral Frontal",4*AH5,IF(AD5="Canteiro Central",2*AH5,"erro")))) -> 2 | AV5: =IF(AP5=0,0,IF(AD5="Unilateral",2*AP5,IF(AD5="Bilateral Alternada",3*AP5,IF(AD5="Bilateral Frontal",4*AP5,IF(AD5="Canteiro Central",2*AP5,"erro"))))) -> 0 | AX5: =VLOOKUP(J5,ABNT5101!$I$3:$J$9,2) -> 7.5 | AY5: =VLOOKUP(J5,ABNT5101!$I$3:$M$9,5) -> 0.18 | AZ5: =_xlfn.XLOOKUP(J5,ABNT5101!I:I,ABNT5101!L:L) -> - | BA5: =_xlfn.XLOOKUP(J5,ABNT5101!$I:$I,ABNT5101!M:M) -> 0.18 | BB5: =_xlfn.XLOOKUP(J5,ABNT5101!$I:$I,ABNT5101!N:N) -> - | BC5: =_xlfn.XLOOKUP(J5,ABNT5101!$I:$I,ABNT5101!O:O) -> 16 | BD5: =IF(BN5="NÃO ATENDE","NÃO ATENDE",IF(BY5="NÃO ATENDE","NÃO ATENDE",IF(CH5="NÃO ATENDE","NÃO ATENDE","ATENDE"))) -> NÃO ATENDE | BE5: =BH5/AX5-1 -> -1 | BF5: =BI5/AY5-1 -> -1 | BG5: =IF($J5="M6",BJ5/AZ5-1,"-") -> - | BN5: =IF(OR(BO5="NÃO ATENDE",BP5="NÃO ATENDE",BQ5="NÃO ATENDE"),"NÃO ATENDE","ATENDE") -> NÃO ATENDE | BO5: =IF(BH5>=AX5,"ATENDE",IF(BH5>=0.99*AX5,"ATENDIMENTO LIMIAR","NÃO ATENDE")) -> NÃO ATENDE | BP5: =IF(BI5>=AY5,"ATENDE",IF(BI5>=(AY5-0.02),"ATENDIMENTO LIMIAR","NÃO ATENDE")) -> NÃO ATENDE | BQ5: =IF(AZ5="-","ATENDE",IF(BJ5>=AZ5,"ATENDE",IF(BJ5>=(AZ5-0.02),"ATENDIMENTO LIMIAR","NÃO ATENDE"))) -> ATENDE | BR5: =J5 -> C5 | BS5: =L5 -> Sem Passeio | BT5: =IF(BU5="-","-",BU5/BW5-1) -> #N/A | BW5: =IF(BS5="-","-",_xlfn.XLOOKUP(BS5,ABNT5101!$B$4:$B$9,ABNT5101!$C$4:$C$9)) -> #N/A | BX5: =IF(BS5="-","-",_xlfn.XLOOKUP(BS5,ABNT5101!$B$4:$B$9,ABNT5101!$D$4:$D$9)) -> #N/A | BY5: =IF(BZ5="-","-",IF(BZ5="NÃO ATENDE","NÃO ATENDE",IF(CA5="NÃO ATENDE","NÃO ATENDE","ATENDE"))) -> #N/A | BZ5: =IF(BS5="-","-",IF(BU5>=BW5,"ATENDE",IF(BU5>=(BW5*0.99),"ATENDIMENTO LIMIAR","NÃO ATENDE"))) -> #N/A | CA5: =IF(BS5="-","-",IF(BV5>=BX5,"ATENDE","NÃO ATENDE")) -> #N/A | CB5: =BS5 -> Sem Passeio | CC5: =IF(CD5="-","-",CD5/CF5-1) -> #N/A | CF5: =IF(CB5="-","-",_xlfn.XLOOKUP(CB5,ABNT5101!$B$4:$B$9,ABNT5101!$C$4:$C$9)) -> #N/A | CG5: =IF(CB5="-","-",_xlfn.XLOOKUP(CB5,ABNT5101!$B$4:$B$9,ABNT5101!$D$4:$D$9)) -> #N/A | CH5: =IF(CI5="-","-",IF(CI5="NÃO ATENDE","NÃO ATENDE",IF(CJ5="NÃO ATENDE","NÃO ATENDE","ATENDE"))) -> #N/A | CI5: =IF(CB5="-","-",IF(CD5>=(CF5),"ATENDE",IF(CD5>=(0.99*CF5),"ATENDIMENTO LIMIAR","NÃO ATENDE"))) -> #N/A | CJ5: =IF(CB5="-","-",IF(CE5>=CG5,"ATENDE","NÃO ATENDE")) -> #N/A | CK5: =_xlfn.XLOOKUP(CL5,'Banco de dados'!$B:$B,'Banco de dados'!$D:$D) -> #N/A | CM5: =_xlfn.XLOOKUP(CL5,'Banco de dados'!$B:$B,'Banco de dados'!$E:$E) -> #N/A | CO5: =IF(CN5="-","-",_xlfn.XLOOKUP(CN5,'Banco de dados'!$B:$B,'Banco de dados'!$E:$E)) -> #N/A | CP5: =AH5 -> 1 | CQ5: =_xlfn.XLOOKUP(CL5,'Banco de dados'!$B:$B,'Banco de dados'!$H:$H) -> #N/A | CR5: {=_xludf.xlookup(CN5,'Banco de dados'!$B:$B,'Banco de dados'!$H:$H)} -> #NAME? | CS5: {=_xludf.xlookup(CL5,'Banco de dados'!$B:$B,'Banco de dados'!$F:$F)} -> #NAME? | CT5: {=_xludf.xlookup(CN5,'Banco de dados'!$B:$B,'Banco de dados'!$F:$F)} -> #NAME? | CW5: =IF(AJ5=0.5,"Suporte",IF(AND(AJ5>='Braços de IP'!$B$9,AJ5<='Braços de IP'!$D$9),'Braços de IP'!$E$9,IF(AND(AJ5>='Braços de IP'!$B$10,AJ5<='Braços de IP'!$D$10),'Braços de IP'!$E$10,IF(AND(AJ5>='Braços de IP'!$B$11,AJ5<='Braços de IP'!$D$11),'Braços de IP'!$E$11,IF(AND(AJ5>='Braços de IP'!$B$12,AJ5<='Braços de IP'!$D$12),'Braços de IP'!$E$12,IF(AND(AJ5>='Braços de IP'!$B$13,AJ5<='Braços de IP'!$D$13),'Braços de IP'!$E$13,IF(AND(AJ5>='Braços de IP'!$B$14,AJ5<='Braços de IP'!$D$14),'Braços de IP'!$E$14,"ERRO"))))))) -> Médio II | CY5: =IF($CX5="","",VLOOKUP($CX5,'Braços de IP'!$E$9:$I$15,2,0)) | CZ5: =IF($CX5="","",VLOOKUP($CX5,'Braços de IP'!$E$9:$I$15,5,0)) | DG5: =CQ5 -> #N/A | DH5: =N5 -> 87 | DI5: =SUM(DG5:DH5)*CP5 -> #N/A | DJ5: =1-DG5/DH5 -> #N/A | DK5: Lucas | DN5: Sim | DQ5: =((N5+O5)-CQ5)/(N5+O5) -> #VALUE! | DS5: V4 | DT5: =COUNTIF(J:J,DS5)/3 -> 0 | DU5: =DT5/$DT$414 -> #DIV/0! | DV5: =DT5/SUM($DT$315:$DT$342) -> #DIV/0!
E6: IP04038 | F6: V | G6: Rua Praia Grande | H6: -23.289032 | I6: -46.875007 | J6: C5 | L6: Sem Passeio | M6: LED | N6: 87 | O6: Interno | P6: - | Q6: =N6*AH6*2 -> 174 | R6: 1 | S6: - | T6: 5.8 | X6: - | AD6: Unilateral | AE6: Braço | AF6: 34.5 | AG6: 6.5 | AH6: 1 | AI6: 1.3 | AJ6: 2.3 | AK6: =AJ6-AI6 -> 1 | AL6: - | AM6: - | AO6: =IF(AD6="Unilateral",2*AH6,IF(AD6="Bilateral Alternada",3*AH6,IF(AD6="Bilateral Frontal",4*AH6,IF(AD6="Canteiro Central",2*AH6,"erro")))) -> 2 | AV6: =IF(AP6=0,0,IF(AD6="Unilateral",2*AP6,IF(AD6="Bilateral Alternada",3*AP6,IF(AD6="Bilateral Frontal",4*AP6,IF(AD6="Canteiro Central",2*AP6,"erro"))))) -> 0 | AX6: =VLOOKUP(J6,ABNT5101!$I$3:$J$9,2) -> 7.5 | AY6: =VLOOKUP(J6,ABNT5101!$I$3:$M$9,5) -> 0.18 | AZ6: =_xlfn.XLOOKUP(J6,ABNT5101!I:I,ABNT5101!L:L) -> - | BA6: =_xlfn.XLOOKUP(J6,ABNT5101!$I:$I,ABNT5101!M:M) -> 0.18 | BB6: =_xlfn.XLOOKUP(J6,ABNT5101!$I:$I,ABNT5101!N:N) -> - | BC6: =_xlfn.XLOOKUP(J6,ABNT5101!$I:$I,ABNT5101!O:O) -> 16 | BD6: =IF(BN6="NÃO ATENDE","NÃO ATENDE",IF(BY6="NÃO ATENDE","NÃO ATENDE",IF(CH6="NÃO ATENDE","NÃO ATENDE","ATENDE"))) -> NÃO ATENDE | BE6: =BH6/AX6-1 -> -1 | BF6: =BI6/AY6-1 -> -1 | BG6: =IF($J6="M6",BJ6/AZ6-1,"-") -> - | BN6: =IF(OR(BO6="NÃO ATENDE",BP6="NÃO ATENDE",BQ6="NÃO ATENDE"),"NÃO ATENDE","ATENDE") -> NÃO ATENDE | BO6: =IF(BH6>=AX6,"ATENDE",IF(BH6>=0.99*AX6,"ATENDIMENTO LIMIAR","NÃO ATENDE")) -> NÃO ATENDE | BP6: =IF(BI6>=AY6,"ATENDE",IF(BI6>=(AY6-0.02),"ATENDIMENTO LIMIAR","NÃO ATENDE")) -> NÃO ATENDE | BQ6: =IF(AZ6="-","ATENDE",IF(BJ6>=AZ6,"ATENDE",IF(BJ6>=(AZ6-0.02),"ATENDIMENTO LIMIAR","NÃO ATENDE"))) -> ATENDE | BR6: =J6 -> C5 | BS6: =L6 -> Sem Passeio | BT6: =IF(BU6="-","-",BU6/BW6-1) -> #N/A | BW6: =IF(BS6="-","-",_xlfn.XLOOKUP(BS6,ABNT5101!$B$4:$B$9,ABNT5101!$C$4:$C$9)) -> #N/A | BX6: =IF(BS6="-","-",_xlfn.XLOOKUP(BS6,ABNT5101!$B$4:$B$9,ABNT5101!$D$4:$D$9)) -> #N/A | BY6: =IF(BZ6="-","-",IF(BZ6="NÃO ATENDE","NÃO ATENDE",IF(CA6="NÃO ATENDE","NÃO ATENDE","ATENDE"))) -> #N/A | BZ6: =IF(BS6="-","-",IF(BU6>=BW6,"ATENDE",IF(BU6>=(BW6*0.99),"ATENDIMENTO LIMIAR","NÃO ATENDE"))) -> #N/A | CA6: =IF(BS6="-","-",IF(BV6>=BX6,"ATENDE","NÃO ATENDE")) -> #N/A | CB6: =BS6 -> Sem Passeio | CC6: =IF(CD6="-","-",CD6/CF6-1) -> #N/A | CF6: =IF(CB6="-","-",_xlfn.XLOOKUP(CB6,ABNT5101!$B$4:$B$9,ABNT5101!$C$4:$C$9)) -> #N/A | CG6: =IF(CB6="-","-",_xlfn.XLOOKUP(CB6,ABNT5101!$B$4:$B$9,ABNT5101!$D$4:$D$9)) -> #N/A | CH6: =IF(CI6="-","-",IF(CI6="NÃO ATENDE","NÃO ATENDE",IF(CJ6="NÃO ATENDE","NÃO ATENDE","ATENDE"))) -> #N/A | CI6: =IF(CB6="-","-",IF(CD6>=(CF6),"ATENDE",IF(CD6>=(0.99*CF6),"ATENDIMENTO LIMIAR","NÃO ATENDE"))) -> #N/A | CJ6: =IF(CB6="-","-",IF(CE6>=CG6,"ATENDE","NÃO ATENDE")) -> #N/A | CK6: =_xlfn.XLOOKUP(CL6,'Banco de dados'!$B:$B,'Banco de dados'!$D:$D) -> #N/A | CM6: =_xlfn.XLOOKUP(CL6,'Banco de dados'!$B:$B,'Banco de dados'!$E:$E) -> #N/A | CO6: =IF(CN6="-","-",_xlfn.XLOOKUP(CN6,'Banco de dados'!$B:$B,'Banco de dados'!$E:$E)) -> #N/A | CP6: =AH6 -> 1 | CQ6: =_xlfn.XLOOKUP(CL6,'Banco de dados'!$B:$B,'Banco de dados'!$H:$H) -> #N/A | CR6: {=_xludf.xlookup(CN6,'Banco de dados'!$B:$B,'Banco de dados'!$H:$H)} -> #NAME? | CS6: {=_xludf.xlookup(CL6,'Banco de dados'!$B:$B,'Banco de dados'!$F:$F)} -> #NAME? | CT6: {=_xludf.xlookup(CN6,'Banco de dados'!$B:$B,'Banco de dados'!$F:$F)} -> #NAME? | CW6: =IF(AJ6=0.5,"Suporte",IF(AND(AJ6>='Braços de IP'!$B$9,AJ6<='Braços de IP'!$D$9),'Braços de IP'!$E$9,IF(AND(AJ6>='Braços de IP'!$B$10,AJ6<='Braços de IP'!$D$10),'Braços de IP'!$E$10,IF(AND(AJ6>='Braços de IP'!$B$11,AJ6<='Braços de IP'!$D$11),'Braços de IP'!$E$11,IF(AND(AJ6>='Braços de IP'!$B$12,AJ6<='Braços de IP'!$D$12),'Braços de IP'!$E$12,IF(AND(AJ6>='Braços de IP'!$B$13,AJ6<='Braços de IP'!$D$13),'Braços de IP'!$E$13,IF(AND(AJ6>='Braços de IP'!$B$14,AJ6<='Braços de IP'!$D$14),'Braços de IP'!$E$14,"ERRO"))))))) -> Médio II | CY6: =IF($CX6="","",VLOOKUP($CX6,'Braços de IP'!$E$9:$I$15,2,0)) | CZ6: =IF($CX6="","",VLOOKUP($CX6,'Braços de IP'!$E$9:$I$15,5,0)) | DG6: =CQ6 -> #N/A | DH6: =N6 -> 87 | DI6: =SUM(DG6:DH6)*CP6 -> #N/A | DJ6: =1-DG6/DH6 -> #N/A | DK6: Lucas | DN6: Sim | DQ6: =((N6+O6)-CQ6)/(N6+O6) -> #VALUE! | DS6: V4 | DT6: =COUNTIF(J:J,DS6)/3 -> 0 | DU6: =DT6/$DT$414 -> #DIV/0! | DV6: =DT6/SUM($DT$315:$DT$342) -> #DIV/0!
E7: IP04038 | F7: V | G7: Rua Praia Grande | H7: -23.289032 | I7: -46.875007 | J7: C5 | L7: Sem Passeio | M7: LED | N7: 87 | O7: Interno | P7: - | Q7: =N7*AH7*2 -> 174 | R7: 1 | S7: - | T7: 5.8 | X7: - | AD7: Unilateral | AE7: Braço | AF7: 34.5 | AG7: 6.5 | AH7: 1 | AI7: 1.3 | AJ7: 2.3 | AK7: =AJ7-AI7 -> 1 | AL7: - | AM7: - | AO7: =IF(AD7="Unilateral",2*AH7,IF(AD7="Bilateral Alternada",3*AH7,IF(AD7="Bilateral Frontal",4*AH7,IF(AD7="Canteiro Central",2*AH7,"erro")))) -> 2 | AV7: =IF(AP7=0,0,IF(AD7="Unilateral",2*AP7,IF(AD7="Bilateral Alternada",3*AP7,IF(AD7="Bilateral Frontal",4*AP7,IF(AD7="Canteiro Central",2*AP7,"erro"))))) -> 0 | AX7: =VLOOKUP(J7,ABNT5101!$I$3:$J$9,2) -> 7.5 | AY7: =VLOOKUP(J7,ABNT5101!$I$3:$M$9,5) -> 0.18 | AZ7: =_xlfn.XLOOKUP(J7,ABNT5101!I:I,ABNT5101!L:L) -> - | BA7: =_xlfn.XLOOKUP(J7,ABNT5101!$I:$I,ABNT5101!M:M) -> 0.18 | BB7: =_xlfn.XLOOKUP(J7,ABNT5101!$I:$I,ABNT5101!N:N) -> - | BC7: =_xlfn.XLOOKUP(J7,ABNT5101!$I:$I,ABNT5101!O:O) -> 16 | BD7: =IF(BN7="NÃO ATENDE","NÃO ATENDE",IF(BY7="NÃO ATENDE","NÃO ATENDE",IF(CH7="NÃO ATENDE","NÃO ATENDE","ATENDE"))) -> NÃO ATENDE | BE7: =BH7/AX7-1 -> -1 | BF7: =BI7/AY7-1 -> -1 | BG7: =IF($J7="M6",BJ7/AZ7-1,"-") -> - | BN7: =IF(OR(BO7="NÃO ATENDE",BP7="NÃO ATENDE",BQ7="NÃO ATENDE"),"NÃO ATENDE","ATENDE") -> NÃO ATENDE | BO7: =IF(BH7>=AX7,"ATENDE",IF(BH7>=0.99*AX7,"ATENDIMENTO LIMIAR","NÃO ATENDE")) -> NÃO ATENDE | BP7: =IF(BI7>=AY7,"ATENDE",IF(BI7>=(AY7-0.02),"ATENDIMENTO LIMIAR","NÃO ATENDE")) -> NÃO ATENDE | BQ7: =IF(AZ7="-","ATENDE",IF(BJ7>=AZ7,"ATENDE",IF(BJ7>=(AZ7-0.02),"ATENDIMENTO LIMIAR","NÃO ATENDE"))) -> ATENDE | BR7: =J7 -> C5 | BS7: =L7 -> Sem Passeio | BT7: =IF(BU7="-","-",BU7/BW7-1) -> #N/A | BW7: =IF(BS7="-","-",_xlfn.XLOOKUP(BS7,ABNT5101!$B$4:$B$9,ABNT5101!$C$4:$C$9)) -> #N/A | BX7: =IF(BS7="-","-",_xlfn.XLOOKUP(BS7,ABNT5101!$B$4:$B$9,ABNT5101!$D$4:$D$9)) -> #N/A | BY7: =IF(BZ7="-","-",IF(BZ7="NÃO ATENDE","NÃO ATENDE",IF(CA7="NÃO ATENDE","NÃO ATENDE","ATENDE"))) -> #N/A | BZ7: =IF(BS7="-","-",IF(BU7>=BW7,"ATENDE",IF(BU7>=(BW7*0.99),"ATENDIMENTO LIMIAR","NÃO ATENDE"))) -> #N/A | CA7: =IF(BS7="-","-",IF(BV7>=BX7,"ATENDE","NÃO ATENDE")) -> #N/A | CB7: =BS7 -> Sem Passeio | CC7: =IF(CD7="-","-",CD7/CF7-1) -> #N/A | CF7: =IF(CB7="-","-",_xlfn.XLOOKUP(CB7,ABNT5101!$B$4:$B$9,ABNT5101!$C$4:$C$9)) -> #N/A | CG7: =IF(CB7="-","-",_xlfn.XLOOKUP(CB7,ABNT5101!$B$4:$B$9,ABNT5101!$D$4:$D$9)) -> #N/A | CH7: =IF(CI7="-","-",IF(CI7="NÃO ATENDE","NÃO ATENDE",IF(CJ7="NÃO ATENDE","NÃO ATENDE","ATENDE"))) -> #N/A | CI7: =IF(CB7="-","-",IF(CD7>=(CF7),"ATENDE",IF(CD7>=(0.99*CF7),"ATENDIMENTO LIMIAR","NÃO ATENDE"))) -> #N/A | CJ7: =IF(CB7="-","-",IF(CE7>=CG7,"ATENDE","NÃO ATENDE")) -> #N/A | CK7: =_xlfn.XLOOKUP(CL7,'Banco de dados'!$B:$B,'Banco de dados'!$D:$D) -> #N/A | CM7: =_xlfn.XLOOKUP(CL7,'Banco de dados'!$B:$B,'Banco de dados'!$E:$E) -> #N/A | CO7: =IF(CN7="-","-",_xlfn.XLOOKUP(CN7,'Banco de dados'!$B:$B,'Banco de dados'!$E:$E)) -> #N/A | CP7: =AH7 -> 1 | CQ7: =_xlfn.XLOOKUP(CL7,'Banco de dados'!$B:$B,'Banco de dados'!$H:$H) -> #N/A | CR7: {=_xludf.xlookup(CN7,'Banco de dados'!$B:$B,'Banco de dados'!$H:$H)} -> #NAME? | CS7: {=_xludf.xlookup(CL7,'Banco de dados'!$B:$B,'Banco de dados'!$F:$F)} -> #NAME? | CT7: {=_xludf.xlookup(CN7,'Banco de dados'!$B:$B,'Banco de dados'!$F:$F)} -> #NAME? | CW7: =IF(AJ7=0.5,"Suporte",IF(AND(AJ7>='Braços de IP'!$B$9,AJ7<='Braços de IP'!$D$9),'Braços de IP'!$E$9,IF(AND(AJ7>='Braços de IP'!$B$10,AJ7<='Braços de IP'!$D$10),'Braços de IP'!$E$10,IF(AND(AJ7>='Braços de IP'!$B$11,AJ7<='Braços de IP'!$D$11),'Braços de IP'!$E$11,IF(AND(AJ7>='Braços de IP'!$B$12,AJ7<='Braços de IP'!$D$12),'Braços de IP'!$E$12,IF(AND(AJ7>='Braços de IP'!$B$13,AJ7<='Braços de IP'!$D$13),'Braços de IP'!$E$13,IF(AND(AJ7>='Braços de IP'!$B$14,AJ7<='Braços de IP'!$D$14),'Braços de IP'!$E$14,"ERRO"))))))) -> Médio II | CY7: =IF($CX7="","",VLOOKUP($CX7,'Braços de IP'!$E$9:$I$15,2,0)) | CZ7: =IF($CX7="","",VLOOKUP($CX7,'Braços de IP'!$E$9:$I$15,5,0)) | DG7: =CQ7 -> #N/A | DH7: =N7 -> 87 | DI7: =SUM(DG7:DH7)*CP7 -> #N/A | DJ7: =1-DG7/DH7 -> #N/A | DK7: Lucas | DN7: Sim | DQ7: =((N7+O7)-CQ7)/(N7+O7) -> #VALUE! | DS7: V4 | DT7: =COUNTIF(J:J,DS7)/3 -> 0 | DU7: =DT7/$DT$414 -> #DIV/0! | DV7: =DT7/SUM($DT$315:$DT$342) -> #DIV/0!
A8: FEITO | C8: Sim | E8: IP00974 | F8: PVP | G8: Avenida Jordano Mendes | H8: -23.333575 | I8: -46.837989 | J8: C2 | L8: P5 | M8: LED | N8: 150 | O8: Interno | P8: 10 | Q8: =N8*AH8*2 -> 300 | R8: 1 | S8: 3 | T8: 5.8 | X8: 1.2 | AB8: 3.5 | AC8: 2 | AD8: Unilateral | AE8: Braço | AF8: 36 | AG8: 7.5 | AH8: 1 | AI8: 0.35 | AJ8: 2.6 | AK8: =AJ8-AI8 -> 2.25 | AL8: - | AM8: - | AO8: =IF(AD8="Unilateral",2*AH8,IF(AD8="Bilateral Alternada",3*AH8,IF(AD8="Bilateral Frontal",4*AH8,IF(AD8="Canteiro Central",2*AH8,"erro")))) -> 2 | AV8: =IF(AP8=0,0,IF(AD8="Unilateral",2*AP8,IF(AD8="Bilateral Alternada",3*AP8,IF(AD8="Bilateral Frontal",4*AP8,IF(AD8="Canteiro Central",2*AP8,"erro"))))) -> 0 | AX8: =VLOOKUP(J8,ABNT5101!$I$3:$J$9,2) -> 20 | AY8: =VLOOKUP(J8,ABNT5101!$I$3:$M$9,5) -> 0.28 | AZ8: =_xlfn.XLOOKUP(J8,ABNT5101!I:I,ABNT5101!L:L) -> - | BA8: =_xlfn.XLOOKUP(J8,ABNT5101!$I:$I,ABNT5101!M:M) -> 0.28 | BB8: =_xlfn.XLOOKUP(J8,ABNT5101!$I:$I,ABNT5101!N:N) -> - | BC8: =_xlfn.XLOOKUP(J8,ABNT5101!$I:$I,ABNT5101!O:O) -> 14 | BD8: =IF(BN8="NÃO ATENDE","NÃO ATENDE",IF(BY8="NÃO ATENDE","NÃO ATENDE",IF(CH8="NÃO ATENDE","NÃO ATENDE","ATENDE"))) -> ATENDE | BE8: =BH8/AX8-1 -> 0.029 | BF8: =BI8/AY8-1 -> 0.17857143 | BG8: =IF($J8="M6",BJ8/AZ8-1,"-") -> - | BH8: 20.58 | BI8: 0.33 | BN8: =IF(OR(BO8="NÃO ATENDE",BP8="NÃO ATENDE",BQ8="NÃO ATENDE"),"NÃO ATENDE","ATENDE") -> ATENDE | BO8: =IF(BH8>=AX8,"ATENDE",IF(BH8>=0.99*AX8,"ATENDIMENTO LIMIAR","NÃO ATENDE")) -> ATENDE | BP8: =IF(BI8>=AY8,"ATENDE",IF(BI8>=(AY8-0.02),"ATENDIMENTO LIMIAR","NÃO ATENDE")) -> ATENDE | BQ8: =IF(AZ8="-","ATENDE",IF(BJ8>=AZ8,"ATENDE",IF(BJ8>=(AZ8-0.02),"ATENDIMENTO LIMIAR","NÃO ATENDE"))) -> ATENDE | BR8: =J8 -> C2 | BS8: =L8 -> P5 | BT8: =IF(BU8="-","-",BU8/BW8-1) -> 1.56 | BU8: 12.8 | BV8: 6.57 | BW8: =IF(BS8="-","-",_xlfn.XLOOKUP(BS8,ABNT5101!$B$4:$B$9,ABNT5101!$C$4:$C$9)) -> 5 | BX8: =IF(BS8="-","-",_xlfn.XLOOKUP(BS8,ABNT5101!$B$4:$B$9,ABNT5101!$D$4:$D$9)) -> 1 | BY8: =IF(BZ8="-","-",IF(BZ8="NÃO ATENDE","NÃO ATENDE",IF(CA8="NÃO ATENDE","NÃO ATENDE","ATENDE"))) -> ATENDE | BZ8: =IF(BS8="-","-",IF(BU8>=BW8,"ATENDE",IF(BU8>=(BW8*0.99),"ATENDIMENTO LIMIAR","NÃO ATENDE"))) -> ATENDE | CA8: =IF(BS8="-","-",IF(BV8>=BX8,"ATENDE","NÃO ATENDE")) -> ATENDE | CB8: =BS8 -> P5 | CC8: =IF(CD8="-","-",CD8/CF8-1) -> 0.456 | CD8: 7.28 | CE8: 2.7 | CF8: =IF(CB8="-","-",_xlfn.XLOOKUP(CB8,ABNT5101!$B$4:$B$9,ABNT5101!$C$4:$C$9)) -> 5 | CG8: =IF(CB8="-","-",_xlfn.XLOOKUP(CB8,ABNT5101!$B$4:$B$9,ABNT5101!$D$4:$D$9)) -> 1 | CH8: =IF(CI8="-","-",IF(CI8="NÃO ATENDE","NÃO ATENDE",IF(CJ8="NÃO ATENDE","NÃO ATENDE","ATENDE"))) -> ATENDE | CI8: =IF(CB8="-","-",IF(CD8>=(CF8),"ATENDE",IF(CD8>=(0.99*CF8),"ATENDIMENTO LIMIAR","NÃO ATENDE"))) -> ATENDE | CJ8: =IF(CB8="-","-",IF(CE8>=CG8,"ATENDE","NÃO ATENDE")) -> ATENDE | CK8: =_xlfn.XLOOKUP(CL8,'Banco de dados'!$B:$B,'Banco de dados'!$D:$D) -> LEDSTAR | CL8: ='Banco de dados'!B11 -> SL VT 9.1 85W | CM8: =_xlfn.XLOOKUP(CL8,'Banco de dados'!$B:$B,'Banco de dados'!$E:$E) -> LUM LED SL VT 9.1 85W | CO8: =IF(CN8="-","-",_xlfn.XLOOKUP(CN8,'Banco de dados'!$B:$B,'Banco de dados'!$E:$E)) -> #N/A | CP8: =AH8 -> 1 | CQ8: =_xlfn.XLOOKUP(CL8,'Banco de dados'!$B:$B,'Banco de dados'!$H:$H) -> 85 | CR8: {=_xludf.xlookup(CN8,'Banco de dados'!$B:$B,'Banco de dados'!$H:$H)} -> #NAME? | CS8: {=_xludf.xlookup(CL8,'Banco de dados'!$B:$B,'Banco de dados'!$F:$F)} -> #NAME? | CT8: {=_xludf.xlookup(CN8,'Banco de dados'!$B:$B,'Banco de dados'!$F:$F)} -> #NAME? | CU8: 0 | CV8: 0 | CW8: =IF(AJ8=0.5,"Suporte",IF(AND(AJ8>='Braços de IP'!$B$9,AJ8<='Braços de IP'!$D$9),'Braços de IP'!$E$9,IF(AND(AJ8>='Braços de IP'!$B$10,AJ8<='Braços de IP'!$D$10),'Braços de IP'!$E$10,IF(AND(AJ8>='Braços de IP'!$B$11,AJ8<='Braços de IP'!$D$11),'Braços de IP'!$E$11,IF(AND(AJ8>='Braços de IP'!$B$12,AJ8<='Braços de IP'!$D$12),'Braços de IP'!$E$12,IF(AND(AJ8>='Braços de IP'!$B$13,AJ8<='Braços de IP'!$D$13),'Braços de IP'!$E$13,IF(AND(AJ8>='Braços de IP'!$B$14,AJ8<='Braços de IP'!$D$14),'Braços de IP'!$E$14,"ERRO"))))))) -> Longo I | CY8: =IF($CX8="","",VLOOKUP($CX8,'Braços de IP'!$E$9:$I$15,2,0)) | CZ8: =IF($CX8="","",VLOOKUP($CX8,'Braços de IP'!$E$9:$I$15,5,0)) | DG8: =CQ8 -> 85 | DH8: =N8 -> 150 | DI8: =SUM(DG8:DH8)*CP8 -> 235 | DJ8: =1-DG8/DH8 -> 0.43333333 | DK8: Lucas | DN8: Sim | DQ8: =((N8+O8)-CQ8)/(N8+O8) -> #VALUE! | DS8: V4 | DT8: =COUNTIF(J:J,DS8)/3 -> 0 | DU8: =DT8/$DT$414 -> #DIV/0! | DV8: =DT8/SUM($DT$315:$DT$342) -> #DIV/0!
A9: FEITO | C9: Sim | E9: IP00974 | F9: PVP | G9: Avenida Jordano Mendes | H9: -23.333575 | I9: -46.837989 | J9: C2 | L9: P5 | M9: LED | N9: 150 | O9: Interno | P9: 10 | Q9: =N9*AH9*2 -> 300 | R9: 1 | S9: 3 | T9: 5.8 | X9: 1.2 | AB9: 3.5 | AC9: 2 | AD9: Unilateral | AE9: Braço | AF9: 36 | AG9: 7.5 | AH9: 1 | AI9: 0.35 | AJ9: 2.6 | AK9: =AJ9-AI9 -> 2.25 | AL9: - | AM9: - | AO9: =IF(AD9="Unilateral",2*AH9,IF(AD9="Bilateral Alternada",3*AH9,IF(AD9="Bilateral Frontal",4*AH9,IF(AD9="Canteiro Central",2*AH9,"erro")))) -> 2 | AV9: =IF(AP9=0,0,IF(AD9="Unilateral",2*AP9,IF(AD9="Bilateral Alternada",3*AP9,IF(AD9="Bilateral Frontal",4*AP9,IF(AD9="Canteiro Central",2*AP9,"erro"))))) -> 0 | AX9: =VLOOKUP(J9,ABNT5101!$I$3:$J$9,2) -> 20 | AY9: =VLOOKUP(J9,ABNT5101!$I$3:$M$9,5) -> 0.28 | AZ9: =_xlfn.XLOOKUP(J9,ABNT5101!I:I,ABNT5101!L:L) -> - | BA9: =_xlfn.XLOOKUP(J9,ABNT5101!$I:$I,ABNT5101!M:M) -> 0.28 | BB9: =_xlfn.XLOOKUP(J9,ABNT5101!$I:$I,ABNT5101!N:N) -> - | BC9: =_xlfn.XLOOKUP(J9,ABNT5101!$I:$I,ABNT5101!O:O) -> 14 | BD9: =IF(BN9="NÃO ATENDE","NÃO ATENDE",IF(BY9="NÃO ATENDE","NÃO ATENDE",IF(CH9="NÃO ATENDE","NÃO ATENDE","ATENDE"))) -> NÃO ATENDE | BE9: =BH9/AX9-1 -> 0.024 | BF9: =BI9/AY9-1 -> -0.28571429 | BG9: =IF($J9="M6",BJ9/AZ9-1,"-") -> - | BH9: 20.48 | BI9: 0.2 | BN9: =IF(OR(BO9="NÃO ATENDE",BP9="NÃO ATENDE",BQ9="NÃO ATENDE"),"NÃO ATENDE","ATENDE") -> NÃO ATENDE | BO9: =IF(BH9>=AX9,"ATENDE",IF(BH9>=0.99*AX9,"ATENDIMENTO LIMIAR","NÃO ATENDE")) -> ATENDE | BP9: =IF(BI9>=AY9,"ATENDE",IF(BI9>=(AY9-0.02),"ATENDIMENTO LIMIAR","NÃO ATENDE")) -> NÃO ATENDE | BQ9: =IF(AZ9="-","ATENDE",IF(BJ9>=AZ9,"ATENDE",IF(BJ9>=(AZ9-0.02),"ATENDIMENTO LIMIAR","NÃO ATENDE"))) -> ATENDE | BR9: =J9 -> C2 | BS9: =L9 -> P5 | BT9: =IF(BU9="-","-",BU9/BW9-1) -> 1.852 | BU9: 14.26 | BV9: 6.47 | BW9: =IF(BS9="-","-",_xlfn.XLOOKUP(BS9,ABNT5101!$B$4:$B$9,ABNT5101!$C$4:$C$9)) -> 5 | BX9: =IF(BS9="-","-",_xlfn.XLOOKUP(BS9,ABNT5101!$B$4:$B$9,ABNT5101!$D$4:$D$9)) -> 1 | BY9: =IF(BZ9="-","-",IF(BZ9="NÃO ATENDE","NÃO ATENDE",IF(CA9="NÃO ATENDE","NÃO ATENDE","ATENDE"))) -> ATENDE | BZ9: =IF(BS9="-","-",IF(BU9>=BW9,"ATENDE",IF(BU9>=(BW9*0.99),"ATENDIMENTO LIMIAR","NÃO ATENDE"))) -> ATENDE | CA9: =IF(BS9="-","-",IF(BV9>=BX9,"ATENDE","NÃO ATENDE")) -> ATENDE | CB9: =BS9 -> P5 | CC9: =IF(CD9="-","-",CD9/CF9-1) -> 0.468 | CD9: 7.34 | CE9: 3.58 | CF9: =IF(CB9="-","-",_xlfn.XLOOKUP(CB9,ABNT5101!$B$4:$B$9,ABNT5101!$C$4:$C$9)) -> 5 | CG9: =IF(CB9="-","-",_xlfn.XLOOKUP(CB9,ABNT5101!$B$4:$B$9,ABNT5101!$D$4:$D$9)) -> 1 | CH9: =IF(CI9="-","-",IF(CI9="NÃO ATENDE","NÃO ATENDE",IF(CJ9="NÃO ATENDE","NÃO ATENDE","ATENDE"))) -> ATENDE | CI9: =IF(CB9="-","-",IF(CD9>=(CF9),"ATENDE",IF(CD9>=(0.99*CF9),"ATENDIMENTO LIMIAR","NÃO ATENDE"))) -> ATENDE | CJ9: =IF(CB9="-","-",IF(CE9>=CG9,"ATENDE","NÃO ATENDE")) -> ATENDE | CK9: =_xlfn.XLOOKUP(CL9,'Banco de dados'!$B:$B,'Banco de dados'!$D:$D) -> SX LIGHTING | CL9: ='Banco de dados'!B59 -> SX-INLPP080HF | CM9: =_xlfn.XLOOKUP(CL9,'Banco de dados'!$B:$B,'Banco de dados'!$E:$E) -> SXINLPP080K50L12CZF7PHF | CO9: =IF(CN9="-","-",_xlfn.XLOOKUP(CN9,'Banco de dados'!$B:$B,'Banco de dados'!$E:$E)) -> #N/A | CP9: =AH9 -> 1 | CQ9: =_xlfn.XLOOKUP(CL9,'Banco de dados'!$B:$B,'Banco de dados'!$H:$H) -> 79 | CR9: {=_xludf.xlookup(CN9,'Banco de dados'!$B:$B,'Banco de dados'!$H:$H)} -> #NAME? | CS9: {=_xludf.xlookup(CL9,'Banco de dados'!$B:$B,'Banco de dados'!$F:$F)} -> #NAME? | CT9: {=_xludf.xlookup(CN9,'Banco de dados'!$B:$B,'Banco de dados'!$F:$F)} -> #NAME? | CU9: 0 | CV9: 0 | CW9: =IF(AJ9=0.5,"Suporte",IF(AND(AJ9>='Braços de IP'!$B$9,AJ9<='Braços de IP'!$D$9),'Braços de IP'!$E$9,IF(AND(AJ9>='Braços de IP'!$B$10,AJ9<='Braços de IP'!$D$10),'Braços de IP'!$E$10,IF(AND(AJ9>='Braços de IP'!$B$11,AJ9<='Braços de IP'!$D$11),'Braços de IP'!$E$11,IF(AND(AJ9>='Braços de IP'!$B$12,AJ9<='Braços de IP'!$D$12),'Braços de IP'!$E$12,IF(AND(AJ9>='Braços de IP'!$B$13,AJ9<='Braços de IP'!$D$13),'Braços de IP'!$E$13,IF(AND(AJ9>='Braços de IP'!$B$14,AJ9<='Braços de IP'!$D$14),'Braços de IP'!$E$14,"ERRO"))))))) -> Longo I | CY9: =IF($CX9="","",VLOOKUP($CX9,'Braços de IP'!$E$9:$I$15,2,0)) | CZ9: =IF($CX9="","",VLOOKUP($CX9,'Braços de IP'!$E$9:$I$15,5,0)) | DG9: =CQ9 -> 79 | DH9: =N9 -> 150 | DI9: =SUM(DG9:DH9)*CP9 -> 229 | DJ9: =1-DG9/DH9 -> 0.47333333 | DK9: Lucas | DN9: Sim | DQ9: =((N9+O9)-CQ9)/(N9+O9) -> #VALUE! | DS9: V4 | DT9: =COUNTIF(J:J,DS9)/3 -> 0 | DU9: =DT9/$DT$414 -> #DIV/0! | DV9: =DT9/SUM($DT$315:$DT$342) -> #DIV/0!
A10: FEITO | C10: Sim | E10: IP00974 | F10: PVP | G10: Avenida Jordano Mendes | H10: -23.333575 | I10: -46.837989 | J10: C2 | L10: P5 | M10: LED | N10: 150 | O10: Interno | P10: 10 | Q10: =N10*AH10*2 -> 300 | R10: 1 | S10: 3 | T10: 5.8 | X10: 1.2 | AB10: 3.5 | AC10: 2 | AD10: Unilateral | AE10: Braço | AF10: 36 | AG10: 7.5 | AH10: 1 | AI10: 0.35 | AJ10: 2.6 | AK10: =AJ10-AI10 -> 2.25 | AL10: - | AM10: - | AO10: =IF(AD10="Unilateral",2*AH10,IF(AD10="Bilateral Alternada",3*AH10,IF(AD10="Bilateral Frontal",4*AH10,IF(AD10="Canteiro Central",2*AH10,"erro")))) -> 2 | AV10: =IF(AP10=0,0,IF(AD10="Unilateral",2*AP10,IF(AD10="Bilateral Alternada",3*AP10,IF(AD10="Bilateral Frontal",4*AP10,IF(AD10="Canteiro Central",2*AP10,"erro"))))) -> 0 | AX10: =VLOOKUP(J10,ABNT5101!$I$3:$J$9,2) -> 20 | AY10: =VLOOKUP(J10,ABNT5101!$I$3:$M$9,5) -> 0.28 | AZ10: =_xlfn.XLOOKUP(J10,ABNT5101!I:I,ABNT5101!L:L) -> - | BA10: =_xlfn.XLOOKUP(J10,ABNT5101!$I:$I,ABNT5101!M:M) -> 0.28 | BB10: =_xlfn.XLOOKUP(J10,ABNT5101!$I:$I,ABNT5101!N:N) -> - | BC10: =_xlfn.XLOOKUP(J10,ABNT5101!$I:$I,ABNT5101!O:O) -> 14 | BD10: =IF(BN10="NÃO ATENDE","NÃO ATENDE",IF(BY10="NÃO ATENDE","NÃO ATENDE",IF(CH10="NÃO ATENDE","NÃO ATENDE","ATENDE"))) -> ATENDE | BE10: =BH10/AX10-1 -> 0.0605 | BF10: =BI10/AY10-1 -> 0.42857143 | BG10: =IF($J10="M6",BJ10/AZ10-1,"-") -> - | BH10: 21.21 | BI10: 0.4 | BN10: =IF(OR(BO10="NÃO ATENDE",BP10="NÃO ATENDE",BQ10="NÃO ATENDE"),"NÃO ATENDE","ATENDE") -> ATENDE | BO10: =IF(BH10>=AX10,"ATENDE",IF(BH10>=0.99*AX10,"ATENDIMENTO LIMIAR","NÃO ATENDE")) -> ATENDE | BP10: =IF(BI10>=AY10,"ATENDE",IF(BI10>=(AY10-0.02),"ATENDIMENTO LIMIAR","NÃO ATENDE")) -> ATENDE | BQ10: =IF(AZ10="-","ATENDE",IF(BJ10>=AZ10,"ATENDE",IF(BJ10>=(AZ10-0.02),"ATENDIMENTO LIMIAR","NÃO ATENDE"))) -> ATENDE | BR10: =J10 -> C2 | BS10: =L10 -> P5 | BT10: =IF(BU10="-","-",BU10/BW10-1) -> 1.286 | BU10: 11.43 | BV10: 2.96 | BW10: =IF(BS10="-","-",_xlfn.XLOOKUP(BS10,ABNT5101!$B$4:$B$9,ABNT5101!$C$4:$C$9)) -> 5 | BX10: =IF(BS10="-","-",_xlfn.XLOOKUP(BS10,ABNT5101!$B$4:$B$9,ABNT5101!$D$4:$D$9)) -> 1 | BY10: =IF(BZ10="-","-",IF(BZ10="NÃO ATENDE","NÃO ATENDE",IF(CA10="NÃO ATENDE","NÃO ATENDE","ATENDE"))) -> ATENDE | BZ10: =IF(BS10="-","-",IF(BU10>=BW10,"ATENDE",IF(BU10>=(BW10*0.99),"ATENDIMENTO LIMIAR","NÃO ATENDE"))) -> ATENDE | CA10: =IF(BS10="-","-",IF(BV10>=BX10,"ATENDE","NÃO ATENDE")) -> ATENDE | CB10: =BS10 -> P5 | CC10: =IF(CD10="-","-",CD10/CF10-1) -> 0.062 | CD10: 5.31 | CE10: 2.87 | CF10: =IF(CB10="-","-",_xlfn.XLOOKUP(CB10,ABNT5101!$B$4:$B$9,ABNT5101!$C$4:$C$9)) -> 5 | CG10: =IF(CB10="-","-",_xlfn.XLOOKUP(CB10,ABNT5101!$B$4:$B$9,ABNT5101!$D$4:$D$9)) -> 1 | CH10: =IF(CI10="-","-",IF(CI10="NÃO ATENDE","NÃO ATENDE",IF(CJ10="NÃO ATENDE","NÃO ATENDE","ATENDE"))) -> ATENDE | CI10: =IF(CB10="-","-",IF(CD10>=(CF10),"ATENDE",IF(CD10>=(0.99*CF10),"ATENDIMENTO LIMIAR","NÃO ATENDE"))) -> ATENDE | CJ10: =IF(CB10="-","-",IF(CE10>=CG10,"ATENDE","NÃO ATENDE")) -> ATENDE | CK10: =_xlfn.XLOOKUP(CL10,'Banco de dados'!$B:$B,'Banco de dados'!$D:$D) -> TECNOWATT | CL10: ='Banco de dados'!B71 -> SIGSAGPTLRRSSNDL_90W112IBBRS | CM10: =_xlfn.XLOOKUP(CL10,'Banco de dados'!$B:$B,'Banco de dados'!$E:$E) -> SIGSAGPTLRRSSNDL_90W112IBBRS 1-10C1MUN6.5 | CO10: =IF(CN10="-","-",_xlfn.XLOOKUP(CN10,'Banco de dados'!$B:$B,'Banco de dados'!$E:$E)) -> #N/A | CP10: =AH10 -> 1 | CQ10: =_xlfn.XLOOKUP(CL10,'Banco de dados'!$B:$B,'Banco de dados'!$H:$H) -> 90 | CR10: {=_xludf.xlookup(CN10,'Banco de dados'!$B:$B,'Banco de dados'!$H:$H)} -> #NAME? | CS10: {=_xludf.xlookup(CL10,'Banco de dados'!$B:$B,'Banco de dados'!$F:$F)} -> #NAME? | CT10: {=_xludf.xlookup(CN10,'Banco de dados'!$B:$B,'Banco de dados'!$F:$F)} -> #NAME? | CU10: 0 | CV10: 4 | CW10: =IF(AJ10=0.5,"Suporte",IF(AND(AJ10>='Braços de IP'!$B$9,AJ10<='Braços de IP'!$D$9),'Braços de IP'!$E$9,IF(AND(AJ10>='Braços de IP'!$B$10,AJ10<='Braços de IP'!$D$10),'Braços de IP'!$E$10,IF(AND(AJ10>='Braços de IP'!$B$11,AJ10<='Braços de IP'!$D$11),'Braços de IP'!$E$11,IF(AND(AJ10>='Braços de IP'!$B$12,AJ10<='Braços de IP'!$D$12),'Braços de IP'!$E$12,IF(AND(AJ10>='Braços de IP'!$B$13,AJ10<='Braços de IP'!$D$13),'Braços de IP'!$E$13,IF(AND(AJ10>='Braços de IP'!$B$14,AJ10<='Braços de IP'!$D$14),'Braços de IP'!$E$14,"ERRO"))))))) -> Longo I | CY10: =IF($CX10="","",VLOOKUP($CX10,'Braços de IP'!$E$9:$I$15,2,0)) | CZ10: =IF($CX10="","",VLOOKUP($CX10,'Braços de IP'!$E$9:$I$15,5,0)) | DG10: =CQ10 -> 90 | DH10: =N10 -> 150 | DI10: =SUM(DG10:DH10)*CP10 -> 240 | DJ10: =1-DG10/DH10 -> 0.4 | DK10: Lucas | DN10: Sim | DQ10: =((N10+O10)-CQ10)/(N10+O10) -> #VALUE! | DS10: V4 | DT10: =COUNTIF(J:J,DS10)/3 -> 0 | DU10: =DT10/$DT$414 -> #DIV/0! | DV10: =DT10/SUM($DT$315:$DT$342) -> #DIV/0!
A11: FEITO | C11: Sim | E11: IP01777 | F11: V | G11: Avenida Avenida Arujá | H11: -23.348773 | I11: -46.826275 | J11: C4 | L11: - | M11: LED | N11: 60 | O11: Interno | P11: - | Q11: =N11*AH11*2 -> 120 | R11: 1 | S11: - | T11: 7 | X11: - | AD11: Unilateral | AE11: Braço | AF11: 30 | AG11: 7.6 | AH11: 1 | AI11: 2.3 | AJ11: 2.6 | AK11: =AJ11-AI11 -> 0.3 | AL11: - | AM11: - | AO11: =IF(AD11="Unilateral",2*AH11,IF(AD11="Bilateral Alternada",3*AH11,IF(AD11="Bilateral Frontal",4*AH11,IF(AD11="Canteiro Central",2*AH11,"erro")))) -> 2 | AV11: =IF(AP11=0,0,IF(AD11="Unilateral",2*AP11,IF(AD11="Bilateral Alternada",3*AP11,IF(AD11="Bilateral Frontal",4*AP11,IF(AD11="Canteiro Central",2*AP11,"erro"))))) -> 0 | AX11: =VLOOKUP(J11,ABNT5101!$I$3:$J$9,2) -> 10 | AY11: =VLOOKUP(J11,ABNT5101!$I$3:$M$9,5) -> 0.18 | AZ11: =_xlfn.XLOOKUP(J11,ABNT5101!I:I,ABNT5101!L:L) -> - | BA11: =_xlfn.XLOOKUP(J11,ABNT5101!$I:$I,ABNT5101!M:M) -> 0.18 | BB11: =_xlfn.XLOOKUP(J11,ABNT5101!$I:$I,ABNT5101!N:N) -> - | BC11: =_xlfn.XLOOKUP(J11,ABNT5101!$I:$I,ABNT5101!O:O) -> 16 | BD11: =IF(BN11="NÃO ATENDE","NÃO ATENDE",IF(BY11="NÃO ATENDE","NÃO ATENDE",IF(CH11="NÃO ATENDE","NÃO ATENDE","ATENDE"))) -> ATENDE | BE11: =BH11/AX11-1 -> 0.023 | BF11: =BI11/AY11-1 -> 2.1666667 | BG11: =IF($J11="M6",BJ11/AZ11-1,"-") -> - | BH11: 10.23 | BI11: 0.57 | BN11: =IF(OR(BO11="NÃO ATENDE",BP11="NÃO ATENDE",BQ11="NÃO ATENDE"),"NÃO ATENDE","ATENDE") -> ATENDE | BO11: =IF(BH11>=AX11,"ATENDE",IF(BH11>=0.99*AX11,"ATENDIMENTO LIMIAR","NÃO ATENDE")) -> ATENDE | BP11: =IF(BI11>=AY11,"ATENDE",IF(BI11>=(AY11-0.02),"ATENDIMENTO LIMIAR","NÃO ATENDE")) -> ATENDE | BQ11: =IF(AZ11="-","ATENDE",IF(BJ11>=AZ11,"ATENDE",IF(BJ11>=(AZ11-0.02),"ATENDIMENTO LIMIAR","NÃO ATENDE"))) -> ATENDE | BR11: =J11 -> C4 | BS11: =L11 -> - | BT11: =IF(BU11="-","-",BU11/BW11-1) -> - | BU11: - | BV11: - | BW11: =IF(BS11="-","-",_xlfn.XLOOKUP(BS11,ABNT5101!$B$4:$B$9,ABNT5101!$C$4:$C$9)) -> - | BX11: =IF(BS11="-","-",_xlfn.XLOOKUP(BS11,ABNT5101!$B$4:$B$9,ABNT5101!$D$4:$D$9)) -> - | BY11: =IF(BZ11="-","-",IF(BZ11="NÃO ATENDE","NÃO ATENDE",IF(CA11="NÃO ATENDE","NÃO ATENDE","ATENDE"))) -> - | BZ11: =IF(BS11="-","-",IF(BU11>=BW11,"ATENDE",IF(BU11>=(BW11*0.99),"ATENDIMENTO LIMIAR","NÃO ATENDE"))) -> - | CA11: =IF(BS11="-","-",IF(BV11>=BX11,"ATENDE","NÃO ATENDE")) -> - | CB11: =BS11 -> - | CC11: =IF(CD11="-","-",CD11/CF11-1) -> - | CD11: - | CE11: - | CF11: =IF(CB11="-","-",_xlfn.XLOOKUP(CB11,ABNT5101!$B$4:$B$9,ABNT5101!$C$4:$C$9)) -> - | CG11: =IF(CB11="-","-",_xlfn.XLOOKUP(CB11,ABNT5101!$B$4:$B$9,ABNT5101!$D$4:$D$9)) -> - | CH11: =IF(CI11="-","-",IF(CI11="NÃO ATENDE","NÃO ATENDE",IF(CJ11="NÃO ATENDE","NÃO ATENDE","ATENDE"))) -> - | CI11: =IF(CB11="-","-",IF(CD11>=(CF11),"ATENDE",IF(CD11>=(0.99*CF11),"ATENDIMENTO LIMIAR","NÃO ATENDE"))) -> - | CJ11: =IF(CB11="-","-",IF(CE11>=CG11,"ATENDE","NÃO ATENDE")) -> - | CK11: =_xlfn.XLOOKUP(CL11,'Banco de dados'!$B:$B,'Banco de dados'!$D:$D) -> LEDSTAR | CL11: ='Banco de dados'!B6 -> SL VT 9.1 35W | CM11: =_xlfn.XLOOKUP(CL11,'Banco de dados'!$B:$B,'Banco de dados'!$E:$E) -> LUM LED SL VT 9.1 35W | CO11: =IF(CN11="-","-",_xlfn.XLOOKUP(CN11,'Banco de dados'!$B:$B,'Banco de dados'!$E:$E)) -> #N/A | CP11: =AH11 -> 1 | CQ11: =_xlfn.XLOOKUP(CL11,'Banco de dados'!$B:$B,'Banco de dados'!$H:$H) -> 35 | CR11: {=_xludf.xlookup(CN11,'Banco de dados'!$B:$B,'Banco de dados'!$H:$H)} -> #NAME? | CS11: {=_xludf.xlookup(CL11,'Banco de dados'!$B:$B,'Banco de dados'!$F:$F)} -> #NAME? | CT11: {=_xludf.xlookup(CN11,'Banco de dados'!$B:$B,'Banco de dados'!$F:$F)} -> #NAME? | CW11: =IF(AJ11=0.5,"Suporte",IF(AND(AJ11>='Braços de IP'!$B$9,AJ11<='Braços de IP'!$D$9),'Braços de IP'!$E$9,IF(AND(AJ11>='Braços de IP'!$B$10,AJ11<='Braços de IP'!$D$10),'Braços de IP'!$E$10,IF(AND(AJ11>='Braços de IP'!$B$11,AJ11<='Braços de IP'!$D$11),'Braços de IP'!$E$11,IF(AND(AJ11>='Braços de IP'!$B$12,AJ11<='Braços de IP'!$D$12),'Braços de IP'!$E$12,IF(AND(AJ11>='Braços de IP'!$B$13,AJ11<='Braços de IP'!$D$13),'Braços de IP'!$E$13,IF(AND(AJ11>='Braços de IP'!$B$14,AJ11<='Braços de IP'!$D$14),'Braços de IP'!$E$14,"ERRO"))))))) -> Longo I | CY11: =IF($CX11="","",VLOOKUP($CX11,'Braços de IP'!$E$9:$I$15,2,0)) | CZ11: =IF($CX11="","",VLOOKUP($CX11,'Braços de IP'!$E$9:$I$15,5,0)) | DG11: =CQ11 -> 35 | DH11: =N11 -> 60 | DI11: =SUM(DG11:DH11)*CP11 -> 95 | DJ11: =1-DG11/DH11 -> 0.41666667 | DN11: Sim | DQ11: =((N11+O11)-CQ11)/(N11+O11) -> #VALUE! | DS11: V4 | DT11: =COUNTIF(J:J,DS11)/3 -> 0 | DU11: =DT11/$DT$414 -> #DIV/0! | DV11: =DT11/SUM($DT$315:$DT$342) -> #DIV/0!
A12: FEITO | C12: Sim | E12: IP01777 | F12: V | G12: Avenida Avenida Arujá | H12: -23.348773 | I12: -46.826275 | J12: C4 | L12: - | M12: LED | N12: 60 | O12: Interno | P12: - | Q12: =N12*AH12*2 -> 120 | R12: 1 | S12: - | T12: 7 | X12: - | AD12: Unilateral | AE12: Braço | AF12: 30 | AG12: 7.6 | AH12: 1 | AI12: 2.3 | AJ12: 2.6 | AK12: =AJ12-AI12 -> 0.3 | AL12: - | AM12: - | AO12: =IF(AD12="Unilateral",2*AH12,IF(AD12="Bilateral Alternada",3*AH12,IF(AD12="Bilateral Frontal",4*AH12,IF(AD12="Canteiro Central",2*AH12,"erro")))) -> 2 | AV12: =IF(AP12=0,0,IF(AD12="Unilateral",2*AP12,IF(AD12="Bilateral Alternada",3*AP12,IF(AD12="Bilateral Frontal",4*AP12,IF(AD12="Canteiro Central",2*AP12,"erro"))))) -> 0 | AX12: =VLOOKUP(J12,ABNT5101!$I$3:$J$9,2) -> 10 | AY12: =VLOOKUP(J12,ABNT5101!$I$3:$M$9,5) -> 0.18 | AZ12: =_xlfn.XLOOKUP(J12,ABNT5101!I:I,ABNT5101!L:L) -> - | BA12: =_xlfn.XLOOKUP(J12,ABNT5101!$I:$I,ABNT5101!M:M) -> 0.18 | BB12: =_xlfn.XLOOKUP(J12,ABNT5101!$I:$I,ABNT5101!N:N) -> - | BC12: =_xlfn.XLOOKUP(J12,ABNT5101!$I:$I,ABNT5101!O:O) -> 16 | BD12: =IF(BN12="NÃO ATENDE","NÃO ATENDE",IF(BY12="NÃO ATENDE","NÃO ATENDE",IF(CH12="NÃO ATENDE","NÃO ATENDE","ATENDE"))) -> ATENDE | BE12: =BH12/AX12-1 -> 0.149 | BF12: =BI12/AY12-1 -> 2.8888889 | BG12: =IF($J12="M6",BJ12/AZ12-1,"-") -> - | BH12: 11.49 | BI12: 0.7 | BN12: =IF(OR(BO12="NÃO ATENDE",BP12="NÃO ATENDE",BQ12="NÃO ATENDE"),"NÃO ATENDE","ATENDE") -> ATENDE | BO12: =IF(BH12>=AX12,"ATENDE",IF(BH12>=0.99*AX12,"ATENDIMENTO LIMIAR","NÃO ATENDE")) -> ATENDE | BP12: =IF(BI12>=AY12,"ATENDE",IF(BI12>=(AY12-0.02),"ATENDIMENTO LIMIAR","NÃO ATENDE")) -> ATENDE | BQ12: =IF(AZ12="-","ATENDE",IF(BJ12>=AZ12,"ATENDE",IF(BJ12>=(AZ12-0.02),"ATENDIMENTO LIMIAR","NÃO ATENDE"))) -> ATENDE | BR12: =J12 -> C4 | BS12: =L12 -> - | BT12: =IF(BU12="-","-",BU12/BW12-1) -> - | BU12: - | BV12: - | BW12: =IF(BS12="-","-",_xlfn.XLOOKUP(BS12,ABNT5101!$B$4:$B$9,ABNT5101!$C$4:$C$9)) -> - | BX12: =IF(BS12="-","-",_xlfn.XLOOKUP(BS12,ABNT5101!$B$4:$B$9,ABNT5101!$D$4:$D$9)) -> - | BY12: =IF(BZ12="-","-",IF(BZ12="NÃO ATENDE","NÃO ATENDE",IF(CA12="NÃO ATENDE","NÃO ATENDE","ATENDE"))) -> - | BZ12: =IF(BS12="-","-",IF(BU12>=BW12,"ATENDE",IF(BU12>=(BW12*0.99),"ATENDIMENTO LIMIAR","NÃO ATENDE"))) -> - | CA12: =IF(BS12="-","-",IF(BV12>=BX12,"ATENDE","NÃO ATENDE")) -> - | CB12: =BS12 -> - | CC12: =IF(CD12="-","-",CD12/CF12-1) -> - | CD12: - | CE12: - | CF12: =IF(CB12="-","-",_xlfn.XLOOKUP(CB12,ABNT5101!$B$4:$B$9,ABNT5101!$C$4:$C$9)) -> - | CG12: =IF(CB12="-","-",_xlfn.XLOOKUP(CB12,ABNT5101!$B$4:$B$9,ABNT5101!$D$4:$D$9)) -> - | CH12: =IF(CI12="-","-",IF(CI12="NÃO ATENDE","NÃO ATENDE",IF(CJ12="NÃO ATENDE","NÃO ATENDE","ATENDE"))) -> - | CI12: =IF(CB12="-","-",IF(CD12>=(CF12),"ATENDE",IF(CD12>=(0.99*CF12),"ATENDIMENTO LIMIAR","NÃO ATENDE"))) -> - | CJ12: =IF(CB12="-","-",IF(CE12>=CG12,"ATENDE","NÃO ATENDE")) -> - | CK12: =_xlfn.XLOOKUP(CL12,'Banco de dados'!$B:$B,'Banco de dados'!$D:$D) -> SX LIGHTING | CL12: ='Banco de dados'!B55 -> SX-INEVO040HF | CM12: =_xlfn.XLOOKUP(CL12,'Banco de dados'!$B:$B,'Banco de dados'!$E:$E) -> SXINEVO040K50L12CZF7PHF | CO12: =IF(CN12="-","-",_xlfn.XLOOKUP(CN12,'Banco de dados'!$B:$B,'Banco de dados'!$E:$E)) -> #N/A | CP12: =AH12 -> 1 | CQ12: =_xlfn.XLOOKUP(CL12,'Banco de dados'!$B:$B,'Banco de dados'!$H:$H) -> 39 | CR12: {=_xludf.xlookup(CN12,'Banco de dados'!$B:$B,'Banco de dados'!$H:$H)} -> #NAME? | CS12: {=_xludf.xlookup(CL12,'Banco de dados'!$B:$B,'Banco de dados'!$F:$F)} -> #NAME? | CT12: {=_xludf.xlookup(CN12,'Banco de dados'!$B:$B,'Banco de dados'!$F:$F)} -> #NAME? | CW12: =IF(AJ12=0.5,"Suporte",IF(AND(AJ12>='Braços de IP'!$B$9,AJ12<='Braços de IP'!$D$9),'Braços de IP'!$E$9,IF(AND(AJ12>='Braços de IP'!$B$10,AJ12<='Braços de IP'!$D$10),'Braços de IP'!$E$10,IF(AND(AJ12>='Braços de IP'!$B$11,AJ12<='Braços de IP'!$D$11),'Braços de IP'!$E$11,IF(AND(AJ12>='Braços de IP'!$B$12,AJ12<='Braços de IP'!$D$12),'Braços de IP'!$E$12,IF(AND(AJ12>='Braços de IP'!$B$13,AJ12<='Braços de IP'!$D$13),'Braços de IP'!$E$13,IF(AND(AJ12>='Braços de IP'!$B$14,AJ12<='Braços de IP'!$D$14),'Braços de IP'!$E$14,"ERRO"))))))) -> Longo I | CY12: =IF($CX12="","",VLOOKUP($CX12,'Braços de IP'!$E$9:$I$15,2,0)) | CZ12: =IF($CX12="","",VLOOKUP($CX12,'Braços de IP'!$E$9:$I$15,5,0)) | DG12: =CQ12 -> 39 | DH12: =N12 -> 60 | DI12: =SUM(DG12:DH12)*CP12 -> 99 | DJ12: =1-DG12/DH12 -> 0.35 | DN12: Sim | DQ12: =((N12+O12)-CQ12)/(N12+O12) -> #VALUE! | DS12: V4 | DT12: =COUNTIF(J:J,DS12)/3 -> 0 | DU12: =DT12/$DT$414 -> #DIV/0! | DV12: =DT12/SUM($DT$315:$DT$342) -> #DIV/0!
A13: FEITO | C13: Sim | E13: IP01777 | F13: V | G13: Avenida Avenida Arujá | H13: -23.348773 | I13: -46.826275 | J13: C4 | L13: - | M13: LED | N13: 60 | O13: Interno | P13: - | Q13: =N13*AH13*2 -> 120 | R13: 1 | S13: - | T13: 7 | X13: - | AD13: Unilateral | AE13: Braço | AF13: 30 | AG13: 7.6 | AH13: 1 | AI13: 2.3 | AJ13: 2.6 | AK13: =AJ13-AI13 -> 0.3 | AL13: - | AM13: - | AO13: =IF(AD13="Unilateral",2*AH13,IF(AD13="Bilateral Alternada",3*AH13,IF(AD13="Bilateral Frontal",4*AH13,IF(AD13="Canteiro Central",2*AH13,"erro")))) -> 2 | AV13: =IF(AP13=0,0,IF(AD13="Unilateral",2*AP13,IF(AD13="Bilateral Alternada",3*AP13,IF(AD13="Bilateral Frontal",4*AP13,IF(AD13="Canteiro Central",2*AP13,"erro"))))) -> 0 | AX13: =VLOOKUP(J13,ABNT5101!$I$3:$J$9,2) -> 10 | AY13: =VLOOKUP(J13,ABNT5101!$I$3:$M$9,5) -> 0.18 | AZ13: =_xlfn.XLOOKUP(J13,ABNT5101!I:I,ABNT5101!L:L) -> - | BA13: =_xlfn.XLOOKUP(J13,ABNT5101!$I:$I,ABNT5101!M:M) -> 0.18 | BB13: =_xlfn.XLOOKUP(J13,ABNT5101!$I:$I,ABNT5101!N:N) -> - | BC13: =_xlfn.XLOOKUP(J13,ABNT5101!$I:$I,ABNT5101!O:O) -> 16 | BD13: =IF(BN13="NÃO ATENDE","NÃO ATENDE",IF(BY13="NÃO ATENDE","NÃO ATENDE",IF(CH13="NÃO ATENDE","NÃO ATENDE","ATENDE"))) -> ATENDE | BE13: =BH13/AX13-1 -> 0.296 | BF13: =BI13/AY13-1 -> 2.5 | BG13: =IF($J13="M6",BJ13/AZ13-1,"-") -> - | BH13: 12.96 | BI13: 0.63 | BN13: =IF(OR(BO13="NÃO ATENDE",BP13="NÃO ATENDE",BQ13="NÃO ATENDE"),"NÃO ATENDE","ATENDE") -> ATENDE | BO13: =IF(BH13>=AX13,"ATENDE",IF(BH13>=0.99*AX13,"ATENDIMENTO LIMIAR","NÃO ATENDE")) -> ATENDE | BP13: =IF(BI13>=AY13,"ATENDE",IF(BI13>=(AY13-0.02),"ATENDIMENTO LIMIAR","NÃO ATENDE")) -> ATENDE | BQ13: =IF(AZ13="-","ATENDE",IF(BJ13>=AZ13,"ATENDE",IF(BJ13>=(AZ13-0.02),"ATENDIMENTO LIMIAR","NÃO ATENDE"))) -> ATENDE | BR13: =J13 -> C4 | BS13: =L13 -> - | BT13: =IF(BU13="-","-",BU13/BW13-1) -> - | BU13: - | BV13: - | BW13: =IF(BS13="-","-",_xlfn.XLOOKUP(BS13,ABNT5101!$B$4:$B$9,ABNT5101!$C$4:$C$9)) -> - | BX13: =IF(BS13="-","-",_xlfn.XLOOKUP(BS13,ABNT5101!$B$4:$B$9,ABNT5101!$D$4:$D$9)) -> - | BY13: =IF(BZ13="-","-",IF(BZ13="NÃO ATENDE","NÃO ATENDE",IF(CA13="NÃO ATENDE","NÃO ATENDE","ATENDE"))) -> - | BZ13: =IF(BS13="-","-",IF(BU13>=BW13,"ATENDE",IF(BU13>=(BW13*0.99),"ATENDIMENTO LIMIAR","NÃO ATENDE"))) -> - | CA13: =IF(BS13="-","-",IF(BV13>=BX13,"ATENDE","NÃO ATENDE")) -> - | CB13: =BS13 -> - | CC13: =IF(CD13="-","-",CD13/CF13-1) -> - | CD13: - | CE13: - | CF13: =IF(CB13="-","-",_xlfn.XLOOKUP(CB13,ABNT5101!$B$4:$B$9,ABNT5101!$C$4:$C$9)) -> - | CG13: =IF(CB13="-","-",_xlfn.XLOOKUP(CB13,ABNT5101!$B$4:$B$9,ABNT5101!$D$4:$D$9)) -> - | CH13: =IF(CI13="-","-",IF(CI13="NÃO ATENDE","NÃO ATENDE",IF(CJ13="NÃO ATENDE","NÃO ATENDE","ATENDE"))) -> - | CI13: =IF(CB13="-","-",IF(CD13>=(CF13),"ATENDE",IF(CD13>=(0.99*CF13),"ATENDIMENTO LIMIAR","NÃO ATENDE"))) -> - | CJ13: =IF(CB13="-","-",IF(CE13>=CG13,"ATENDE","NÃO ATENDE")) -> - | CK13: =_xlfn.XLOOKUP(CL13,'Banco de dados'!$B:$B,'Banco de dados'!$D:$D) -> TECNOWATT | CL13: ='Banco de dados'!B66 -> SIGSAGPTLRRSSNDL_40W_50IBBRS | CM13: =_xlfn.XLOOKUP(CL13,'Banco de dados'!$B:$B,'Banco de dados'!$E:$E) -> SIGSAGPTLRRSSNDL_40W_50IBBRS 1-10C1MUN6.5 | CO13: =IF(CN13="-","-",_xlfn.XLOOKUP(CN13,'Banco de dados'!$B:$B,'Banco de dados'!$E:$E)) -> #N/A | CP13: =AH13 -> 1 | CQ13: =_xlfn.XLOOKUP(CL13,'Banco de dados'!$B:$B,'Banco de dados'!$H:$H) -> 40 | CR13: {=_xludf.xlookup(CN13,'Banco de dados'!$B:$B,'Banco de dados'!$H:$H)} -> #NAME? | CS13: {=_xludf.xlookup(CL13,'Banco de dados'!$B:$B,'Banco de dados'!$F:$F)} -> #NAME? | CT13: {=_xludf.xlookup(CN13,'Banco de dados'!$B:$B,'Banco de dados'!$F:$F)} -> #NAME? | CW13: =IF(AJ13=0.5,"Suporte",IF(AND(AJ13>='Braços de IP'!$B$9,AJ13<='Braços de IP'!$D$9),'Braços de IP'!$E$9,IF(AND(AJ13>='Braços de IP'!$B$10,AJ13<='Braços de IP'!$D$10),'Braços de IP'!$E$10,IF(AND(AJ13>='Braços de IP'!$B$11,AJ13<='Braços de IP'!$D$11),'Braços de IP'!$E$11,IF(AND(AJ13>='Braços de IP'!$B$12,AJ13<='Braços de IP'!$D$12),'Braços de IP'!$E$12,IF(AND(AJ13>='Braços de IP'!$B$13,AJ13<='Braços de IP'!$D$13),'Braços de IP'!$E$13,IF(AND(AJ13>='Braços de IP'!$B$14,AJ13<='Braços de IP'!$D$14),'Braços de IP'!$E$14,"ERRO"))))))) -> Longo I | CY13: =IF($CX13="","",VLOOKUP($CX13,'Braços de IP'!$E$9:$I$15,2,0)) | CZ13: =IF($CX13="","",VLOOKUP($CX13,'Braços de IP'!$E$9:$I$15,5,0)) | DG13: =CQ13 -> 40 | DH13: =N13 -> 60 | DI13: =SUM(DG13:DH13)*CP13 -> 100 | DJ13: =1-DG13/DH13 -> 0.33333333 | DN13: Sim | DQ13: =((N13+O13)-CQ13)/(N13+O13) -> #VALUE! | DS13: V4 | DT13: =COUNTIF(J:J,DS13)/3 -> 0 | DU13: =DT13/$DT$414 -> #DIV/0! | DV13: =DT13/SUM($DT$315:$DT$342) -> #DIV/0!
