Workbook
Name Banco_Tipologias: Banco_Tipologias!$C$4:$N$17
Name colunaclasses: Simulações!$BO$2:$BO$1263
Name ilumatic: 'Banco de dados'!#REF!
Name philips: 'Banco de dados'!#REF!
Name red_global: 'Banco de dados'!#REF!
Name red_juganu: 'Banco de dados'!#REF!
Name red_philips: 'Banco de dados'!#REF!
Name red_repume: 'Banco de dados'!#REF!
Name red_tecno: 'Banco de dados'!#REF!
Name redglobal: 'Banco de dados'!#REF!
Name tecnowat: 'Banco de dados'!#REF!

Sheet DefiniçãoFornecedores
D2: Estruturas
B3: Definição | D3: V1 | E3: V2 | F3: V3 | G3: V4 | H3: V5 | I3: Observação
B4: Fornecedor L1 | C4: Conexled | D4: 0 | E4: 0 | F4: 0 | G4: 0 | H4: 0 | I4: Não possui orçamento
B5: Fornecedor L2 | C5: Ilumatic | D5: 0 | E5: 0 | F5: 0 | G5: 0 | H5: 0 | I5: Não possui orçamento
B6: Fornecedor L3 | C6: Juganu | D6: 0 | E6: 0 | F6: 0 | G6: 0 | H6: 0 | I6: Possui orçamento, definir qual classe melhor atende
B7: Fornecedor L4 | C7: Philips | D7: 1 | E7: 1 | F7: 1 | G7: 1 | H7: 1 | I7: Não possui orçamento
B8: Fornecedor L5 | C8: Repume | D8: 0 | E8: 0 | F8: 0 | G8: 0 | H8: 0 | I8: Não possui orçamento
B9: Fornecedor L6 | C9: Tecnowatt | D9: 1 | E9: 1 | F9: 1 | G9: 1 | H9: 1 | I9: Possui orçamento, definir qual classe melhor atende
B10: Fornecedor L7 | C10: Unicoba | D10: 1 | E10: 1 | F10: 1 | G10: 1 | H10: 1 | I10: Possui orçamento, definir qual classe melhor atende
B11: Fornecedor L8 | C11: SX Lighting | D11: 0 | E11: 0 | F11: 0 | G11: 0 | H11: 0 | I11: Não possui orçamento

Sheet Simulações
C1: Padrão | D1: Logradouro | E1: latitude | F1: longitude | G1: Classificação viária | H1: Classificação ciclovia | I1: Classificação pedonal | J1: Tipo de lâmpada | K1: Potencia da lâmpada | L1: Reator | M1: Potencia 2o nivel | N1: POT TOTAL MALHA | O1: Faixas de Rodagem | P1: Largura Passeio 1 | Q1: Largura Via 1 | R1: largura Passeio Central 1 | S1: largura Passeio Central 2 | T1: Largura Via 2 | U1: largura Passeio 2 | V1: largura Canteiro Central | W1: largura Ciclovia 1 | X1: largura Ciclovia 2 | Y1: estacionamento 1 | Z1: estacionamento 2 | AA1: posteacao | AB1: Tipo de estrutura | AC1: distancia entre postes | AD1: altura da luminaria | AE1: qtd de Lampadas IP Princ | AF1: distancia Poste a via | AG1: projecao do braço | AH1: Pendor | AI1: Altura de Instalação | AJ1: Projeção Vertical | AK1: Exclusivo | AL1: Quantidade de pontos inspecionados IP Veic | AM1: qtd de Lampadas IP 2o nivel | AN1: Tipo de posteação 2o nivel | AO1: Distanciamento 2o nivel | AP1: Altura da luminaria 2o nivel | AQ1: Projecao 2o nivel | AR1: Distancia poste-via 2o nivel | AS1: Quantidade de pontos inspecionados IP Sec | AT1: informacoes Adicionais | AU1: Emed - Norma | AV1: U - Norma | AW1: Luminância Média Exigida | AX1: Uo Uniformidade Global Exigida | AY1: Uniformidade Longitudinal Exigida | AZ1: Incremento Linear Exigido | BA1: Atendimento pleno à norma | BB1: Excesso de iluminância média IV | BC1: Excesso de Uniformidade IV | BD1: Excesso de luminância média IV | BE1: Iluminância Média | BF1: Uniformidade Global Mínima | BG1: Luminância Média | BH1: Uniformidade Longitudinal | BI1: Incremento Linear (TI) | BJ1: EIR | BK1: ATENDE TUDO - RUA SIMU | BL1: Atende à Iluminância Média | BM1: Atende à Uniformidade Global Miníma | BN1: Atende à Luminância Média | BO1: Classe IV | BP1: Classe IP | BQ1: Excesso de iluminância média P1 | BR1: Iluminância Média | BS1: Iluminância mínima horizontal E (lux) | BT1: Iluminância Média (Exigida) | BU1: Iluminância mínima horizontal E (lux) | BV1: Atende à NBR 5101 - TUDO SIMU | BW1: Atende à Iluminância Média | BX1: Atende à Iluminância mínima horizontal | BY1: Classe IP | BZ1: Excesso de iluminância média P2 | CA1: Iluminância Média | CB1: Iluminância mínima horizontal E (lux) | CC1: Iluminância Média (Exigida) | CD1: Iluminância mínima horizontal E (lux) exigida | CE1: Atende à NBR 5101 - TUDO SIMU P2 | CF1: Atende à Iluminância Média | CG1: Atende à Iluminância mínima horizontal | CH1: Fornecedor | CI1: Código Luminária 1 | CJ1: Luminária Simulada (IP Principal) | CK1: Código Luminária 2 | CL1: Luminária Simulada (IP Secundário) | CM1: Pontos por poste (IP Principal) | CN1: Potência simulada - IP Principal (W) | CO1: Potência simulada - IP Secundário (W) | CP1: Fluxo Luminoso - IP Principal (lm) | CQ1: Fluxo Luminoso - IP Secundário (lm) | CR1: Ângulo antigo | CS1: Ângulo Simulado | CT1: Braço Antigo | CU1: Braço Novo | CV1: Projeção com alteração | CW1: Altura de luminária com alteração | CX1: Correção de Ponto Escuro (CPE) | CY1: Quantidade de pontos adicionados para via de veículo | CZ1: Quantidade de pontos adicionados para 2º nível | DA1: Observação CPE (Reduçao entre postes e/ou Tipo de Posteação) | DB1: obs conferência | DC1: rev conferência | DD1: IP PRINC SIM | DE1: IP SEC SIM | DF1: TOTAL SIMULADO | DG1: Eficientização | DH1: Estrutura | DI1: Simulação | DJ1: Conferência | DK1: Considerar na Extrapolação | DL1: Inspeção | DN1: eficientização
A2: Verificar preenchimento de dados como largura dos passeios,canteiro e pista, | B2: 36 | C2: PVCP | D2: Rua Doutor Leopoldo Lins | E2: -8.04963 | F2: -34.890749 | G2: P6 | H2: - | I2: P6 | J2: LED | K2: 96 | L2: Interno | M2: 0 | N2: =K2*AE2*2 -> 192 | O2: 1 | V2: 0 | Y2: 1.76 | Z2: 0 | AA2: Unilateral | AB2: Braço | AC2: 39.46 | AD2: 5.78 | AE2: 1 | AF2: 0.6 | AG2: 2.31 | AH2: =AG2-AF2 -> 1.71 | AI2: - | AJ2: - | AK2: Não | AL2: =IF(AA2="Unilateral",2*AE2,IF(AA2="Bilateral Alternada",3*AE2,IF(AA2="Bilateral Frontal",4*AE2,IF(AA2="Canteiro Central",2*AE2,"erro")))) -> 2 | AM2: 0 | AO2: 0 | AP2: 0 | AQ2: 0 | AR2: - | AS2: =IF(AM2=0,0,IF(AA2="Unilateral",2*AM2,IF(AA2="Bilateral Alternada",3*AM2,IF(AA2="Bilateral Frontal",4*AM2,IF(AA2="Canteiro Central",2*AM2,"erro"))))) -> 0 | AU2: =VLOOKUP(G2,ABNT5101!$I$3:$J$9,2) -> 7.5 | AV2: =VLOOKUP(G2,ABNT5101!$I$3:$M$9,5) -> 0.18 | AW2: =_xlfn.XLOOKUP(G2,ABNT5101!I:I,ABNT5101!L:L) -> - | AX2: =_xlfn.XLOOKUP(G2,ABNT5101!$I:$I,ABNT5101!M:M) -> - | AY2: =_xlfn.XLOOKUP(G2,ABNT5101!$I:$I,ABNT5101!N:N) -> - | AZ2: =_xlfn.XLOOKUP(G2,ABNT5101!$I:$I,ABNT5101!O:O) -> - | BA2: =IF(BK2="NÃO ATENDE","NÃO ATENDE",IF(BV2="NÃO ATENDE","NÃO ATENDE",IF(CE2="NÃO ATENDE","NÃO ATENDE","ATENDE"))) -> NÃO ATENDE | BB2: =BE2/AU2-1 -> -1 | BC2: =BF2/AV2-1 -> -1 | BD2: =IF($G2="M6",BG2/AW2-1,"-") -> - | BK2: =IF(OR(BL2="NÃO ATENDE",BM2="NÃO ATENDE",BN2="NÃO ATENDE"),"NÃO ATENDE","ATENDE") -> NÃO ATENDE | BL2: =IF(BE2>=AU2,"ATENDE",IF(BE2>=0.99*AU2,"ATENDIMENTO LIMIAR","NÃO ATENDE")) -> NÃO ATENDE | BM2: =IF(BF2>=AV2,"ATENDE",IF(BF2>=(AV2-0.02),"ATENDIMENTO LIMIAR","NÃO ATENDE")) -> NÃO ATENDE | BN2: =IF(AW2="-","ATENDE",IF(BG2>=AW2,"ATENDE",IF(BG2>=(AW2-0.02),"ATENDIMENTO LIMIAR","NÃO ATENDE"))) -> ATENDE | BO2: =G2 -> P6 | BP2: =I2 -> P6 | BQ2: =IF(BR2="-","-",BR2/BT2-1) -> -1 | BT2: =IF(BP2="-","-",_xlfn.XLOOKUP(BP2,ABNT5101!$B$4:$B$9,ABNT5101!$C$4:$C$9)) -> 3 | BU2: =IF(BP2="-","-",_xlfn.XLOOKUP(BP2,ABNT5101!$B$4:$B$9,ABNT5101!$D$4:$D$9)) -> 0.6 | BV2: =IF(BW2="-","-",IF(BW2="NÃO ATENDE","NÃO ATENDE",IF(BX2="NÃO ATENDE","NÃO ATENDE","ATENDE"))) -> NÃO ATENDE | BW2: =IF(BP2="-","-",IF(BR2>=BT2,"ATENDE",IF(BR2>=(BT2*0.99),"ATENDIMENTO LIMIAR","NÃO ATENDE"))) -> NÃO ATENDE | BX2: =IF(BP2="-","-",IF(BS2>=BU2,"ATENDE","NÃO ATENDE")) -> NÃO ATENDE | BY2: =BP2 -> P6 | BZ2: =IF(CA2="-","-",CA2/CC2-1) -> -1 | CC2: =IF(BY2="-","-",_xlfn.XLOOKUP(BY2,ABNT5101!$B$4:$B$9,ABNT5101!$C$4:$C$9)) -> 3 | CD2: =IF(BY2="-","-",_xlfn.XLOOKUP(BY2,ABNT5101!$B$4:$B$9,ABNT5101!$D$4:$D$9)) -> 0.6 | CE2: =IF(CF2="-","-",IF(CF2="NÃO ATENDE","NÃO ATENDE",IF(CG2="NÃO ATENDE","NÃO ATENDE","ATENDE"))) -> NÃO ATENDE | CF2: =IF(BY2="-","-",IF(CA2>=(CC2),"ATENDE",IF(CA2>=(0.99*CC2),"ATENDIMENTO LIMIAR","NÃO ATENDE"))) -> NÃO ATENDE | CG2: =IF(BY2="-","-",IF(CB2>=CD2,"ATENDE","NÃO ATENDE")) -> NÃO ATENDE | CH2: =_xlfn.XLOOKUP(CI2,'Banco de dados'!$B:$B,'Banco de dados'!$D:$D) -> #N/A | CJ2: =_xlfn.XLOOKUP(CI2,'Banco de dados'!$B:$B,'Banco de dados'!$E:$E) -> #N/A | CL2: =IF(CK2="-","-",_xlfn.XLOOKUP(CK2,'Banco de dados'!$B:$B,'Banco de dados'!$E:$E)) -> #N/A | CM2: =AE2 -> 1 | CN2: =_xlfn.XLOOKUP(CI2,'Banco de dados'!$B:$B,'Banco de dados'!$H:$H) -> #N/A | CO2: {=_xludf.XLOOKUP(CK2,'Banco de dados'!$B:$B,'Banco de dados'!$H:$H)} -> #NAME? | CP2: {=_xludf.XLOOKUP(CI2,'Banco de dados'!$B:$B,'Banco de dados'!$F:$F)} -> #NAME? | CQ2: {=_xludf.XLOOKUP(CK2,'Banco de dados'!$B:$B,'Banco de dados'!$F:$F)} -> #NAME? | CR2: 0 | CT2: =IF(AG2=0.5,"Suporte",IF(AND(AG2>='Braços de IP'!$B$9,AG2<='Braços de IP'!$D$9),'Braços de IP'!$E$9,IF(AND(AG2>='Braços de IP'!$B$10,AG2<='Braços de IP'!$D$10),'Braços de IP'!$E$10,IF(AND(AG2>='Braços de IP'!$B$11,AG2<='Braços de IP'!$D$11),'Braços de IP'!$E$11,IF(AND(AG2>='Braços de IP'!$B$12,AG2<='Braços de IP'!$D$12),'Braços de IP'!$E$12,IF(AND(AG2>='Braços de IP'!$B$13,AG2<='Braços de IP'!$D$13),'Braços de IP'!$E$13,IF(AND(AG2>='Braços de IP'!$B$14,AG2<='Braços de IP'!$D$14),'Braços de IP'!$E$14,"ERRO"))))))) -> Médio II | CU2: Médio I | CV2: =IF($CU2="","",VLOOKUP($CU2,'Braços de IP'!$E$9:$I$15,2,0)) -> 1.8 | CW2: =IF($CU2="","",VLOOKUP($CU2,'Braços de IP'!$E$9:$I$15,5,0)) -> 7 | DD2: =CN2 -> #N/A | DE2: =K2 -> 96 | DF2: =SUM(DD2:DE2)*CM2 -> #N/A | DG2: =1-DD2/DE2 -> #N/A | DH2: Lucas | DK2: Sim | DN2: =((K2+L2)-CN2)/(K2+L2) -> #VALUE! | DP2: V4 | DQ2: =COUNTIF(G:G,DP2)/3 -> 0 | DR2: =DQ2/$DQ$434 -> #DIV/0! | DS2: =DQ2/SUM($DQ$326:$DQ$353) -> #DIV/0!
A3: Verificar preenchimento de dados como largura dos passeios,canteiro e pista, | B3: 36 | C3: PVCP | D3: Rua Doutor Leopoldo Lins | E3: -8.04963 | F3: -34.890749 | G3: P6 | H3: - | I3: P6 | J3: LED | K3: 96 | L3: Interno | M3: 0 | N3: =K3*AE3*2 -> 192 | O3: 1 | V3: 0 | Y3: 1.76 | Z3: 0 | AA3: Unilateral | AB3: Braço | AC3: 39.46 | AD3: 5.78 | AE3: 1 | AF3: 0.6 | AG3: 2.31 | AH3: =AG3-AF3 -> 1.71 | AI3: - | AJ3: - | AK3: Não | AL3: =IF(AA3="Unilateral",2*AE3,IF(AA3="Bilateral Alternada",3*AE3,IF(AA3="Bilateral Frontal",4*AE3,IF(AA3="Canteiro Central",2*AE3,"erro")))) -> 2 | AM3: 0 | AO3: 0 | AP3: 0 | AQ3: 0 | AR3: - | AS3: =IF(AM3=0,0,IF(AA3="Unilateral",2*AM3,IF(AA3="Bilateral Alternada",3*AM3,IF(AA3="Bilateral Frontal",4*AM3,IF(AA3="Canteiro Central",2*AM3,"erro"))))) -> 0 | AU3: =VLOOKUP(G3,ABNT5101!$I$3:$J$9,2) -> 7.5 | AV3: =VLOOKUP(G3,ABNT5101!$I$3:$M$9,5) -> 0.18 | AW3: =_xlfn.XLOOKUP(G3,ABNT5101!I:I,ABNT5101!L:L) -> - | AX3: =_xlfn.XLOOKUP(G3,ABNT5101!$I:$I,ABNT5101!M:M) -> - | AY3: =_xlfn.XLOOKUP(G3,ABNT5101!$I:$I,ABNT5101!N:N) -> - | AZ3: =_xlfn.XLOOKUP(G3,ABNT5101!$I:$I,ABNT5101!O:O) -> - | BA3: =IF(BK3="NÃO ATENDE","NÃO ATENDE",IF(BV3="NÃO ATENDE","NÃO ATENDE",IF(CE3="NÃO ATENDE","NÃO ATENDE","ATENDE"))) -> NÃO ATENDE | BB3: =BE3/AU3-1 -> -1 | BC3: =BF3/AV3-1 -> -1 | BD3: =IF($G3="M6",BG3/AW3-1,"-") -> - | BK3: =IF(OR(BL3="NÃO ATENDE",BM3="NÃO ATENDE",BN3="NÃO ATENDE"),"NÃO ATENDE","ATENDE") -> NÃO ATENDE | BL3: =IF(BE3>=AU3,"ATENDE",IF(BE3>=0.99*AU3,"ATENDIMENTO LIMIAR","NÃO ATENDE")) -> NÃO ATENDE | BM3: =IF(BF3>=AV3,"ATENDE",IF(BF3>=(AV3-0.02),"ATENDIMENTO LIMIAR","NÃO ATENDE")) -> NÃO ATENDE | BN3: =IF(AW3="-","ATENDE",IF(BG3>=AW3,"ATENDE",IF(BG3>=(AW3-0.02),"ATENDIMENTO LIMIAR","NÃO ATENDE"))) -> ATENDE | BO3: =G3 -> P6 | BP3: =I3 -> P6 | BQ3: =IF(BR3="-","-",BR3/BT3-1) -> -1 | BT3: =IF(BP3="-","-",_xlfn.XLOOKUP(BP3,ABNT5101!$B$4:$B$9,ABNT5101!$C$4:$C$9)) -> 3 | BU3: =IF(BP3="-","-",_xlfn.XLOOKUP(BP3,ABNT5101!$B$4:$B$9,ABNT5101!$D$4:$D$9)) -> 0.6 | BV3: =IF(BW3="-","-",IF(BW3="NÃO ATENDE","NÃO ATENDE",IF(BX3="NÃO ATENDE","NÃO ATENDE","ATENDE"))) -> NÃO ATENDE | BW3: =IF(BP3="-","-",IF(BR3>=BT3,"ATENDE",IF(BR3>=(BT3*0.99),"ATENDIMENTO LIMIAR","NÃO ATENDE"))) -> NÃO ATENDE | BX3: =IF(BP3="-","-",IF(BS3>=BU3,"ATENDE","NÃO ATENDE")) -> NÃO ATENDE | BY3: =BP3 -> P6 | BZ3: =IF(CA3="-","-",CA3/CC3-1) -> -1 | CC3: =IF(BY3="-","-",_xlfn.XLOOKUP(BY3,ABNT5101!$B$4:$B$9,ABNT5101!$C$4:$C$9)) -> 3 | CD3: =IF(BY3="-","-",_xlfn.XLOOKUP(BY3,ABNT5101!$B$4:$B$9,ABNT5101!$D$4:$D$9)) -> 0.6 | CE3: =IF(CF3="-","-",IF(CF3="NÃO ATENDE","NÃO ATENDE",IF(CG3="NÃO ATENDE","NÃO ATENDE","ATENDE"))) -> NÃO ATENDE | CF3: =IF(BY3="-","-",IF(CA3>=(CC3),"ATENDE",IF(CA3>=(0.99*CC3),"ATENDIMENTO LIMIAR","NÃO ATENDE"))) -> NÃO ATENDE | CG3: =IF(BY3="-","-",IF(CB3>=CD3,"ATENDE","NÃO ATENDE")) -> NÃO ATENDE | CH3: =_xlfn.XLOOKUP(CI3,'Banco de dados'!$B:$B,'Banco de dados'!$D:$D) -> #N/A | CJ3: =_xlfn.XLOOKUP(CI3,'Banco de dados'!$B:$B,'Banco de dados'!$E:$E) -> #N/A | CL3: =IF(CK3="-","-",_xlfn.XLOOKUP(CK3,'Banco de dados'!$B:$B,'Banco de dados'!$E:$E)) -> #N/A | CM3: =AE3 -> 1 | CN3: =_xlfn.XLOOKUP(CI3,'Banco de dados'!$B:$B,'Banco de dados'!$H:$H) -> 0 | CO3: {=_xludf.XLOOKUP(CK3,'Banco de dados'!$B:$B,'Banco de dados'!$H:$H)} -> #NAME? | CP3: {=_xludf.XLOOKUP(CI3,'Banco de dados'!$B:$B,'Banco de dados'!$F:$F)} -> #NAME? | CQ3: {=_xludf.XLOOKUP(CK3,'Banco de dados'!$B:$B,'Banco de dados'!$F:$F)} -> #NAME? | CR3: 0 | CS3: 5 | CT3: =IF(AG3=0.5,"Suporte",IF(AND(AG3>='Braços de IP'!$B$9,AG3<='Braços de IP'!$D$9),'Braços de IP'!$E$9,IF(AND(AG3>='Braços de IP'!$B$10,AG3<='Braços de IP'!$D$10),'Braços de IP'!$E$10,IF(AND(AG3>='Braços de IP'!$B$11,AG3<='Braços de IP'!$D$11),'Braços de IP'!$E$11,IF(AND(AG3>='Braços de IP'!$B$12,AG3<='Braços de IP'!$D$12),'Braços de IP'!$E$12,IF(AND(AG3>='Braços de IP'!$B$13,AG3<='Braços de IP'!$D$13),'Braços de IP'!$E$13,IF(AND(AG3>='Braços de IP'!$B$14,AG3<='Braços de IP'!$D$14),'Braços de IP'!$E$14,"ERRO"))))))) -> Médio II | CV3: =IF($CU3="","",VLOOKUP($CU3,'Braços de IP'!$E$9:$I$15,2,0)) | CW3: =IF($CU3="","",VLOOKUP($CU3,'Braços de IP'!$E$9:$I$15,5,0)) | DD3: =CN3 -> 0 | DE3: =K3 -> 96 | DF3: =SUM(DD3:DE3)*CM3 -> 96 | DG3: =1-DD3/DE3 -> 1 | DH3: Lucas | DK3: Sim | DN3: =((K3+L3)-CN3)/(K3+L3) -> #VALUE! | DP3: V4 | DQ3: =COUNTIF(G:G,DP3)/3 -> 0 | DR3: =DQ3/$DQ$434 -> #DIV/0! | DS3: =DQ3/SUM($DQ$326:$DQ$353) -> #DIV/0!
A4: Verificar preenchimento de dados como largura dos passeios,canteiro e pista, | B4: 36 | C4: PVCP | D4: Rua Doutor Leopoldo Lins | E4: -8.04963 | F4: -34.890749 | G4: P6 | H4: - | I4: P6 | J4: LED | K4: 96 | L4: Interno | M4: 0 | N4: =K4*AE4*2 -> 192 | O4: 1 | V4: 0 | Y4: 1.76 | Z4: 0 | AA4: Unilateral | AB4: Braço | AC4: 39.46 | AD4: 5.78 | AE4: 1 | AF4: 0.6 | AG4: 2.31 | AH4: =AG4-AF4 -> 1.71 | AI4: - | AJ4: - | AK4: Não | AL4: =IF(AA4="Unilateral",2*AE4,IF(AA4="Bilateral Alternada",3*AE4,IF(AA4="Bilateral Frontal",4*AE4,IF(AA4="Canteiro Central",2*AE4,"erro")))) -> 2 | AM4: 0 | AO4: 0 | AP4: 0 | AQ4: 0 | AR4: - | AS4: =IF(AM4=0,0,IF(AA4="Unilateral",2*AM4,IF(AA4="Bilateral Alternada",3*AM4,IF(AA4="Bilateral Frontal",4*AM4,IF(AA4="Canteiro Central",2*AM4,"erro"))))) -> 0 | AU4: =VLOOKUP(G4,ABNT5101!$I$3:$J$9,2) -> 7.5 | AV4: =VLOOKUP(G4,ABNT5101!$I$3:$M$9,5) -> 0.18 | AW4: =_xlfn.XLOOKUP(G4,ABNT5101!I:I,ABNT5101!L:L) -> - | AX4: =_xlfn.XLOOKUP(G4,ABNT5101!$I:$I,ABNT5101!M:M) -> - | AY4: =_xlfn.XLOOKUP(G4,ABNT5101!$I:$I,ABNT5101!N:N) -> - | AZ4: =_xlfn.XLOOKUP(G4,ABNT5101!$I:$I,ABNT5101!O:O) -> - | BA4: =IF(BK4="NÃO ATENDE","NÃO ATENDE",IF(BV4="NÃO ATENDE","NÃO ATENDE",IF(CE4="NÃO ATENDE","NÃO ATENDE","ATENDE"))) -> NÃO ATENDE | BB4: =BE4/AU4-1 -> -1 | BC4: =BF4/AV4-1 -> -1 | BD4: =IF($G4="M6",BG4/AW4-1,"-") -> - | BK4: =IF(OR(BL4="NÃO ATENDE",BM4="NÃO ATENDE",BN4="NÃO ATENDE"),"NÃO ATENDE","ATENDE") -> NÃO ATENDE | BL4: =IF(BE4>=AU4,"ATENDE",IF(BE4>=0.99*AU4,"ATENDIMENTO LIMIAR","NÃO ATENDE")) -> NÃO ATENDE | BM4: =IF(BF4>=AV4,"ATENDE",IF(BF4>=(AV4-0.02),"ATENDIMENTO LIMIAR","NÃO ATENDE")) -> NÃO ATENDE | BN4: =IF(AW4="-","ATENDE",IF(BG4>=AW4,"ATENDE",IF(BG4>=(AW4-0.02),"ATENDIMENTO LIMIAR","NÃO ATENDE"))) -> ATENDE | BO4: =G4 -> P6 | BP4: =I4 -> P6 | BQ4: =IF(BR4="-","-",BR4/BT4-1) -> -1 | BT4: =IF(BP4="-","-",_xlfn.XLOOKUP(BP4,ABNT5101!$B$4:$B$9,ABNT5101!$C$4:$C$9)) -> 3 | BU4: =IF(BP4="-","-",_xlfn.XLOOKUP(BP4,ABNT5101!$B$4:$B$9,ABNT5101!$D$4:$D$9)) -> 0.6 | BV4: =IF(BW4="-","-",IF(BW4="NÃO ATENDE","NÃO ATENDE",IF(BX4="NÃO ATENDE","NÃO ATENDE","ATENDE"))) -> NÃO ATENDE | BW4: =IF(BP4="-","-",IF(BR4>=BT4,"ATENDE",IF(BR4>=(BT4*0.99),"ATENDIMENTO LIMIAR","NÃO ATENDE"))) -> NÃO ATENDE | BX4: =IF(BP4="-","-",IF(BS4>=BU4,"ATENDE","NÃO ATENDE")) -> NÃO ATENDE | BY4: =BP4 -> P6 | BZ4: =IF(CA4="-","-",CA4/CC4-1) -> -1 | CC4: =IF(BY4="-","-",_xlfn.XLOOKUP(BY4,ABNT5101!$B$4:$B$9,ABNT5101!$C$4:$C$9)) -> 3 | CD4: =IF(BY4="-","-",_xlfn.XLOOKUP(BY4,ABNT5101!$B$4:$B$9,ABNT5101!$D$4:$D$9)) -> 0.6 | CE4: =IF(CF4="-","-",IF(CF4="NÃO ATENDE","NÃO ATENDE",IF(CG4="NÃO ATENDE","NÃO ATENDE","ATENDE"))) -> NÃO ATENDE | CF4: =IF(BY4="-","-",IF(CA4>=(CC4),"ATENDE",IF(CA4>=(0.99*CC4),"ATENDIMENTO LIMIAR","NÃO ATENDE"))) -> NÃO ATENDE | CG4: =IF(BY4="-","-",IF(CB4>=CD4,"ATENDE","NÃO ATENDE")) -> NÃO ATENDE | CH4: =_xlfn.XLOOKUP(CI4,'Banco de dados'!$B:$B,'Banco de dados'!$D:$D) -> #N/A | CJ4: =_xlfn.XLOOKUP(CI4,'Banco de dados'!$B:$B,'Banco de dados'!$E:$E) -> #N/A | CL4: =IF(CK4="-","-",_xlfn.XLOOKUP(CK4,'Banco de dados'!$B:$B,'Banco de dados'!$E:$E)) -> #N/A | CM4: =AE4 -> 1 | CN4: =_xlfn.XLOOKUP(CI4,'Banco de dados'!$B:$B,'Banco de dados'!$H:$H) -> 0 | CO4: {=_xludf.XLOOKUP(CK4,'Banco de dados'!$B:$B,'Banco de dados'!$H:$H)} -> #NAME? | CP4: {=_xludf.XLOOKUP(CI4,'Banco de dados'!$B:$B,'Banco de dados'!$F:$F)} -> #NAME? | CQ4: {=_xludf.XLOOKUP(CK4,'Banco de dados'!$B:$B,'Banco de dados'!$F:$F)} -> #NAME? | CR4: 0 | CT4: =IF(AG4=0.5,"Suporte",IF(AND(AG4>='Braços de IP'!$B$9,AG4<='Braços de IP'!$D$9),'Braços de IP'!$E$9,IF(AND(AG4>='Braços de IP'!$B$10,AG4<='Braços de IP'!$D$10),'Braços de IP'!$E$10,IF(AND(AG4>='Braços de IP'!$B$11,AG4<='Braços de IP'!$D$11),'Braços de IP'!$E$11,IF(AND(AG4>='Braços de IP'!$B$12,AG4<='Braços de IP'!$D$12),'Braços de IP'!$E$12,IF(AND(AG4>='Braços de IP'!$B$13,AG4<='Braços de IP'!$D$13),'Braços de IP'!$E$13,IF(AND(AG4>='Braços de IP'!$B$14,AG4<='Braços de IP'!$D$14),'Braços de IP'!$E$14,"ERRO"))))))) -> Médio II | CV4: =IF($CU4="","",VLOOKUP($CU4,'Braços de IP'!$E$9:$I$15,2,0)) | CW4: =IF($CU4="","",VLOOKUP($CU4,'Braços de IP'!$E$9:$I$15,5,0)) | DD4: =CN4 -> 0 | DE4: =K4 -> 96 | DF4: =SUM(DD4:DE4)*CM4 -> 96 | DG4: =1-DD4/DE4 -> 1 | DH4: Lucas | DK4: Sim | DN4: =((K4+L4)-CN4)/(K4+L4) -> #VALUE! | DP4: V4 | DQ4: =COUNTIF(G:G,DP4)/3 -> 0 | DR4: =DQ4/$DQ$434 -> #DIV/0! | DS4: =DQ4/SUM($DQ$326:$DQ$353) -> #DIV/0!
A5: Verificar preenchimento de dados como largura dos passeios e pista, | B5: 37 | C5: PVP | D5: Rua Jornalista Paulo Bittencourt | E5: -8.053576 | F5: -34.899628 | G5: P6 | H5: - | I5: P6 | J5: LED | K5: 96 | L5: Interno | M5: 0 | N5: =K5*AE5*2 -> 192 | O5: 2 | V5: 0 | Y5: 0 | Z5: 1.6 | AA5: Unilateral | AB5: Braço | AC5: 40.3 | AD5: 6.63 | AE5: 1 | AF5: 0.85 | AG5: 2.44 | AH5: =AG5-AF5 -> 1.59 | AI5: - | AJ5: - | AK5: Sim | AL5: =IF(AA5="Unilateral",2*AE5,IF(AA5="Bilateral Alternada",3*AE5,IF(AA5="Bilateral Frontal",4*AE5,IF(AA5="Canteiro Central",2*AE5,"erro")))) -> 2 | AM5: 0 | AO5: 0 | AP5: 0 | AQ5: 0 | AR5: - | AS5: =IF(AM5=0,0,IF(AA5="Unilateral",2*AM5,IF(AA5="Bilateral Alternada",3*AM5,IF(AA5="Bilateral Frontal",4*AM5,IF(AA5="Canteiro Central",2*AM5,"erro"))))) -> 0 | AU5: =VLOOKUP(G5,ABNT5101!$I$3:$J$9,2) -> 7.5 | AV5: =VLOOKUP(G5,ABNT5101!$I$3:$M$9,5) -> 0.18 | AW5: =_xlfn.XLOOKUP(G5,ABNT5101!I:I,ABNT5101!L:L) -> - | AX5: =_xlfn.XLOOKUP(G5,ABNT5101!$I:$I,ABNT5101!M:M) -> - | AY5: =_xlfn.XLOOKUP(G5,ABNT5101!$I:$I,ABNT5101!N:N) -> - | AZ5: =_xlfn.XLOOKUP(G5,ABNT5101!$I:$I,ABNT5101!O:O) -> - | BA5: =IF(BK5="NÃO ATENDE","NÃO ATENDE",IF(BV5="NÃO ATENDE","NÃO ATENDE",IF(CE5="NÃO ATENDE","NÃO ATENDE","ATENDE"))) -> NÃO ATENDE | BB5: =BE5/AU5-1 -> -1 | BC5: =BF5/AV5-1 -> -1 | BD5: =IF($G5="M6",BG5/AW5-1,"-") -> - | BK5: =IF(OR(BL5="NÃO ATENDE",BM5="NÃO ATENDE",BN5="NÃO ATENDE"),"NÃO ATENDE","ATENDE") -> NÃO ATENDE | BL5: =IF(BE5>=AU5,"ATENDE",IF(BE5>=0.99*AU5,"ATENDIMENTO LIMIAR","NÃO ATENDE")) -> NÃO ATENDE | BM5: =IF(BF5>=AV5,"ATENDE",IF(BF5>=(AV5-0.02),"ATENDIMENTO LIMIAR","NÃO ATENDE")) -> NÃO ATENDE | BN5: =IF(AW5="-","ATENDE",IF(BG5>=AW5,"ATENDE",IF(BG5>=(AW5-0.02),"ATENDIMENTO LIMIAR","NÃO ATENDE"))) -> ATENDE | BO5: =G5 -> P6 | BP5: =I5 -> P6 | BQ5: =IF(BR5="-","-",BR5/BT5-1) -> -1 | BT5: =IF(BP5="-","-",_xlfn.XLOOKUP(BP5,ABNT5101!$B$4:$B$9,ABNT5101!$C$4:$C$9)) -> 3 | BU5: =IF(BP5="-","-",_xlfn.XLOOKUP(BP5,ABNT5101!$B$4:$B$9,ABNT5101!$D$4:$D$9)) -> 0.6 | BV5: =IF(BW5="-","-",IF(BW5="NÃO ATENDE","NÃO ATENDE",IF(BX5="NÃO ATENDE","NÃO ATENDE","ATENDE"))) -> NÃO ATENDE | BW5: =IF(BP5="-","-",IF(BR5>=BT5,"ATENDE",IF(BR5>=(BT5*0.99),"ATENDIMENTO LIMIAR","NÃO ATENDE"))) -> NÃO ATENDE | BX5: =IF(BP5="-","-",IF(BS5>=BU5,"ATENDE","NÃO ATENDE")) -> NÃO ATENDE | BY5: =BP5 -> P6 | BZ5: =IF(CA5="-","-",CA5/CC5-1) -> -1 | CC5: =IF(BY5="-","-",_xlfn.XLOOKUP(BY5,ABNT5101!$B$4:$B$9,ABNT5101!$C$4:$C$9)) -> 3 | CD5: =IF(BY5="-","-",_xlfn.XLOOKUP(BY5,ABNT5101!$B$4:$B$9,ABNT5101!$D$4:$D$9)) -> 0.6 | CE5: =IF(CF5="-","-",IF(CF5="NÃO ATENDE","NÃO ATENDE",IF(CG5="NÃO ATENDE","NÃO ATENDE","ATENDE"))) -> NÃO ATENDE | CF5: =IF(BY5="-","-",IF(CA5>=(CC5),"ATENDE",IF(CA5>=(0.99*CC5),"ATENDIMENTO LIMIAR","NÃO ATENDE"))) -> NÃO ATENDE | CG5: =IF(BY5="-","-",IF(CB5>=CD5,"ATENDE","NÃO ATENDE")) -> NÃO ATENDE | CH5: =_xlfn.XLOOKUP(CI5,'Banco de dados'!$B:$B,'Banco de dados'!$D:$D) -> #N/A | CJ5: =_xlfn.XLOOKUP(CI5,'Banco de dados'!$B:$B,'Banco de dados'!$E:$E) -> #N/A | CL5: =IF(CK5="-","-",_xlfn.XLOOKUP(CK5,'Banco de dados'!$B:$B,'Banco de dados'!$E:$E)) -> #N/A | CM5: =AE5 -> 1 | CN5: =_xlfn.XLOOKUP(CI5,'Banco de dados'!$B:$B,'Banco de dados'!$H:$H) -> 0 | CO5: {=_xludf.XLOOKUP(CK5,'Banco de dados'!$B:$B,'Banco de dados'!$H:$H)} -> #NAME? | CP5: {=_xludf.XLOOKUP(CI5,'Banco de dados'!$B:$B,'Banco de dados'!$F:$F)} -> #NAME? | CQ5: {=_xludf.XLOOKUP(CK5,'Banco de dados'!$B:$B,'Banco de dados'!$F:$F)} -> #NAME? | CR5: 0 | CT5: =IF(AG5=0.5,"Suporte",IF(AND(AG5>='Braços de IP'!$B$9,AG5<='Braços de IP'!$D$9),'Braços de IP'!$E$9,IF(AND(AG5>='Braços de IP'!$B$10,AG5<='Braços de IP'!$D$10),'Braços de IP'!$E$10,IF(AND(AG5>='Braços de IP'!$B$11,AG5<='Braços de IP'!$D$11),'Braços de IP'!$E$11,IF(AND(AG5>='Braços de IP'!$B$12,AG5<='Braços de IP'!$D$12),'Braços de IP'!$E$12,IF(AND(AG5>='Braços de IP'!$B$13,AG5<='Braços de IP'!$D$13),'Braços de IP'!$E$13,IF(AND(AG5>='Braços de IP'!$B$14,AG5<='Braços de IP'!$D$14),'Braços de IP'!$E$14,"ERRO"))))))) -> Médio II | CV5: =IF($CU5="","",VLOOKUP($CU5,'Braços de IP'!$E$9:$I$15,2,0)) | CW5: =IF($CU5="","",VLOOKUP($CU5,'Braços de IP'!$E$9:$I$15,5,0)) | DD5: =CN5 -> 0 | DE5: =K5 -> 96 | DF5: =SUM(DD5:DE5)*CM5 -> 96 | DG5: =1-DD5/DE5 -> 1 | DK5: Sim | DN5: =((K5+L5)-CN5)/(K5+L5) -> #VALUE! | DP5: V4 | DQ5: =COUNTIF(G:G,DP5)/3 -> 0 | DR5: =DQ5/$DQ$434 -> #DIV/0! | DS5: =DQ5/SUM($DQ$326:$DQ$353) -> #DIV/0!
A6: Verificar preenchimento de dados como largura dos passeios e pista, | B6: 37 | C6: PVP | D6: Rua Jornalista Paulo Bittencourt | E6: -8.053576 | F6: -34.899628 | G6: P6 | H6: - | I6: P6 | J6: LED | K6: 96 | L6: Interno | M6: 0 | N6: =K6*AE6*2 -> 192 | O6: 2 | V6: 0 | Y6: 0 | Z6: 1.6 | AA6: Unilateral | AB6: Braço | AC6: 40.3 | AD6: 6.63 | AE6: 1 | AF6: 0.85 | AG6: 2.44 | AH6: =AG6-AF6 -> 1.59 | AI6: - | AJ6: - | AK6: Sim | AL6: =IF(AA6="Unilateral",2*AE6,IF(AA6="Bilateral Alternada",3*AE6,IF(AA6="Bilateral Frontal",4*AE6,IF(AA6="Canteiro Central",2*AE6,"erro")))) -> 2 | AM6: 0 | AO6: 0 | AP6: 0 | AQ6: 0 | AR6: - | AS6: =IF(AM6=0,0,IF(AA6="Unilateral",2*AM6,IF(AA6="Bilateral Alternada",3*AM6,IF(AA6="Bilateral Frontal",4*AM6,IF(AA6="Canteiro Central",2*AM6,"erro"))))) -> 0 | AU6: =VLOOKUP(G6,ABNT5101!$I$3:$J$9,2) -> 7.5 | AV6: =VLOOKUP(G6,ABNT5101!$I$3:$M$9,5) -> 0.18 | AW6: =_xlfn.XLOOKUP(G6,ABNT5101!I:I,ABNT5101!L:L) -> - | AX6: =_xlfn.XLOOKUP(G6,ABNT5101!$I:$I,ABNT5101!M:M) -> - | AY6: =_xlfn.XLOOKUP(G6,ABNT5101!$I:$I,ABNT5101!N:N) -> - | AZ6: =_xlfn.XLOOKUP(G6,ABNT5101!$I:$I,ABNT5101!O:O) -> - | BA6: =IF(BK6="NÃO ATENDE","NÃO ATENDE",IF(BV6="NÃO ATENDE","NÃO ATENDE",IF(CE6="NÃO ATENDE","NÃO ATENDE","ATENDE"))) -> NÃO ATENDE | BB6: =BE6/AU6-1 -> -1 | BC6: =BF6/AV6-1 -> -1 | BD6: =IF($G6="M6",BG6/AW6-1,"-") -> - | BK6: =IF(OR(BL6="NÃO ATENDE",BM6="NÃO ATENDE",BN6="NÃO ATENDE"),"NÃO ATENDE","ATENDE") -> NÃO ATENDE | BL6: =IF(BE6>=AU6,"ATENDE",IF(BE6>=0.99*AU6,"ATENDIMENTO LIMIAR","NÃO ATENDE")) -> NÃO ATENDE | BM6: =IF(BF6>=AV6,"ATENDE",IF(BF6>=(AV6-0.02),"ATENDIMENTO LIMIAR","NÃO ATENDE")) -> NÃO ATENDE | BN6: =IF(AW6="-","ATENDE",IF(BG6>=AW6,"ATENDE",IF(BG6>=(AW6-0.02),"ATENDIMENTO LIMIAR","NÃO ATENDE"))) -> ATENDE | BO6: =G6 -> P6 | BP6: =I6 -> P6 | BQ6: =IF(BR6="-","-",BR6/BT6-1) -> -1 | BT6: =IF(BP6="-","-",_xlfn.XLOOKUP(BP6,ABNT5101!$B$4:$B$9,ABNT5101!$C$4:$C$9)) -> 3 | BU6: =IF(BP6="-","-",_xlfn.XLOOKUP(BP6,ABNT5101!$B$4:$B$9,ABNT5101!$D$4:$D$9)) -> 0.6 | BV6: =IF(BW6="-","-",IF(BW6="NÃO ATENDE","NÃO ATENDE",IF(BX6="NÃO ATENDE","NÃO ATENDE","ATENDE"))) -> NÃO ATENDE | BW6: =IF(BP6="-","-",IF(BR6>=BT6,"ATENDE",IF(BR6>=(BT6*0.99),"ATENDIMENTO LIMIAR","NÃO ATENDE"))) -> NÃO ATENDE | BX6: =IF(BP6="-","-",IF(BS6>=BU6,"ATENDE","NÃO ATENDE")) -> NÃO ATENDE | BY6: =BP6 -> P6 | BZ6: =IF(CA6="-","-",CA6/CC6-1) -> -1 | CC6: =IF(BY6="-","-",_xlfn.XLOOKUP(BY6,ABNT5101!$B$4:$B$9,ABNT5101!$C$4:$C$9)) -> 3 | CD6: =IF(BY6="-","-",_xlfn.XLOOKUP(BY6,ABNT5101!$B$4:$B$9,ABNT5101!$D$4:$D$9)) -> 0.6 | CE6: =IF(CF6="-","-",IF(CF6="NÃO ATENDE","NÃO ATENDE",IF(CG6="NÃO ATENDE","NÃO ATENDE","ATENDE"))) -> NÃO ATENDE | CF6: =IF(BY6="-","-",IF(CA6>=(CC6),"ATENDE",IF(CA6>=(0.99*CC6),"ATENDIMENTO LIMIAR","NÃO ATENDE"))) -> NÃO ATENDE | CG6: =IF(BY6="-","-",IF(CB6>=CD6,"ATENDE","NÃO ATENDE")) -> NÃO ATENDE | CH6: =_xlfn.XLOOKUP(CI6,'Banco de dados'!$B:$B,'Banco de dados'!$D:$D) -> #N/A | CJ6: =_xlfn.XLOOKUP(CI6,'Banco de dados'!$B:$B,'Banco de dados'!$E:$E) -> #N/A | CL6: =IF(CK6="-","-",_xlfn.XLOOKUP(CK6,'Banco de dados'!$B:$B,'Banco de dados'!$E:$E)) -> #N/A | CM6: =AE6 -> 1 | CN6: =_xlfn.XLOOKUP(CI6,'Banco de dados'!$B:$B,'Banco de dados'!$H:$H) -> 0 | CO6: {=_xludf.XLOOKUP(CK6,'Banco de dados'!$B:$B,'Banco de dados'!$H:$H)} -> #NAME? | CP6: {=_xludf.XLOOKUP(CI6,'Banco de dados'!$B:$B,'Banco de dados'!$F:$F)} -> #NAME? | CQ6: {=_xludf.XLOOKUP(CK6,'Banco de dados'!$B:$B,'Banco de dados'!$F:$F)} -> #NAME? | CR6: 0 | CT6: =IF(AG6=0.5,"Suporte",IF(AND(AG6>='Braços de IP'!$B$9,AG6<='Braços de IP'!$D$9),'Braços de IP'!$E$9,IF(AND(AG6>='Braços de IP'!$B$10,AG6<='Braços de IP'!$D$10),'Braços de IP'!$E$10,IF(AND(AG6>='Braços de IP'!$B$11,AG6<='Braços de IP'!$D$11),'Braços de IP'!$E$11,IF(AND(AG6>='Braços de IP'!$B$12,AG6<='Braços de IP'!$D$12),'Braços de IP'!$E$12,IF(AND(AG6>='Braços de IP'!$B$13,AG6<='Braços de IP'!$D$13),'Braços de IP'!$E$13,IF(AND(AG6>='Braços de IP'!$B$14,AG6<='Braços de IP'!$D$14),'Braços de IP'!$E$14,"ERRO"))))))) -> Médio II | CV6: =IF($CU6="","",VLOOKUP($CU6,'Braços de IP'!$E$9:$I$15,2,0)) | CW6: =IF($CU6="","",VLOOKUP($CU6,'Braços de IP'!$E$9:$I$15,5,0)) | DD6: =CN6 -> 0 | DE6: =K6 -> 96 | DF6: =SUM(DD6:DE6)*CM6 -> 96 | DG6: =1-DD6/DE6 -> 1 | DK6: Sim | DN6: =((K6+L6)-CN6)/(K6+L6) -> #VALUE! | DP6: V4 | DQ6: =COUNTIF(G:G,DP6)/3 -> 0 | DR6: =DQ6/$DQ$434 -> #DIV/0! | DS6: =DQ6/SUM($DQ$326:$DQ$353) -> #DIV/0!
A7: Verificar preenchimento de dados como largura dos passeios e pista, | B7: 37 | C7: PVP | D7: Rua Jornalista Paulo Bittencourt | E7: -8.053576 | F7: -34.899628 | G7: P6 | H7: - | I7: P6 | J7: LED | K7: 96 | L7: Interno | M7: 0 | N7: =K7*AE7*2 -> 192 | O7: 2 | V7: 0 | Y7: 0 | Z7: 1.6 | AA7: Unilateral | AB7: Braço | AC7: 40.3 | AD7: 6.63 | AE7: 1 | AF7: 0.85 | AG7: 2.44 | AH7: =AG7-AF7 -> 1.59 | AI7: - | AJ7: - | AK7: Sim | AL7: =IF(AA7="Unilateral",2*AE7,IF(AA7="Bilateral Alternada",3*AE7,IF(AA7="Bilateral Frontal",4*AE7,IF(AA7="Canteiro Central",2*AE7,"erro")))) -> 2 | AM7: 0 | AO7: 0 | AP7: 0 | AQ7: 0 | AR7: - | AS7: =IF(AM7=0,0,IF(AA7="Unilateral",2*AM7,IF(AA7="Bilateral Alternada",3*AM7,IF(AA7="Bilateral Frontal",4*AM7,IF(AA7="Canteiro Central",2*AM7,"erro"))))) -> 0 | AU7: =VLOOKUP(G7,ABNT5101!$I$3:$J$9,2) -> 7.5 | AV7: =VLOOKUP(G7,ABNT5101!$I$3:$M$9,5) -> 0.18 | AW7: =_xlfn.XLOOKUP(G7,ABNT5101!I:I,ABNT5101!L:L) -> - | AX7: =_xlfn.XLOOKUP(G7,ABNT5101!$I:$I,ABNT5101!M:M) -> - | AY7: =_xlfn.XLOOKUP(G7,ABNT5101!$I:$I,ABNT5101!N:N) -> - | AZ7: =_xlfn.XLOOKUP(G7,ABNT5101!$I:$I,ABNT5101!O:O) -> - | BA7: =IF(BK7="NÃO ATENDE","NÃO ATENDE",IF(BV7="NÃO ATENDE","NÃO ATENDE",IF(CE7="NÃO ATENDE","NÃO ATENDE","ATENDE"))) -> NÃO ATENDE | BB7: =BE7/AU7-1 -> -1 | BC7: =BF7/AV7-1 -> -1 | BD7: =IF($G7="M6",BG7/AW7-1,"-") -> - | BK7: =IF(OR(BL7="NÃO ATENDE",BM7="NÃO ATENDE",BN7="NÃO ATENDE"),"NÃO ATENDE","ATENDE") -> NÃO ATENDE | BL7: =IF(BE7>=AU7,"ATENDE",IF(BE7>=0.99*AU7,"ATENDIMENTO LIMIAR","NÃO ATENDE")) -> NÃO ATENDE | BM7: =IF(BF7>=AV7,"ATENDE",IF(BF7>=(AV7-0.02),"ATENDIMENTO LIMIAR","NÃO ATENDE")) -> NÃO ATENDE | BN7: =IF(AW7="-","ATENDE",IF(BG7>=AW7,"ATENDE",IF(BG7>=(AW7-0.02),"ATENDIMENTO LIMIAR","NÃO ATENDE"))) -> ATENDE | BO7: =G7 -> P6 | BP7: =I7 -> P6 | BQ7: =IF(BR7="-","-",BR7/BT7-1) -> -1 | BT7: =IF(BP7="-","-",_xlfn.XLOOKUP(BP7,ABNT5101!$B$4:$B$9,ABNT5101!$C$4:$C$9)) -> 3 | BU7: =IF(BP7="-","-",_xlfn.XLOOKUP(BP7,ABNT5101!$B$4:$B$9,ABNT5101!$D$4:$D$9)) -> 0.6 | BV7: =IF(BW7="-","-",IF(BW7="NÃO ATENDE","NÃO ATENDE",IF(BX7="NÃO ATENDE","NÃO ATENDE","ATENDE"))) -> NÃO ATENDE | BW7: =IF(BP7="-","-",IF(BR7>=BT7,"ATENDE",IF(BR7>=(BT7*0.99),"ATENDIMENTO LIMIAR","NÃO ATENDE"))) -> NÃO ATENDE | BX7: =IF(BP7="-","-",IF(BS7>=BU7,"ATENDE","NÃO ATENDE")) -> NÃO ATENDE | BY7: =BP7 -> P6 | BZ7: =IF(CA7="-","-",CA7/CC7-1) -> -1 | CC7: =IF(BY7="-","-",_xlfn.XLOOKUP(BY7,ABNT5101!$B$4:$B$9,ABNT5101!$C$4:$C$9)) -> 3 | CD7: =IF(BY7="-","-",_xlfn.XLOOKUP(BY7,ABNT5101!$B$4:$B$9,ABNT5101!$D$4:$D$9)) -> 0.6 | CE7: =IF(CF7="-","-",IF(CF7="NÃO ATENDE","NÃO ATENDE",IF(CG7="NÃO ATENDE","NÃO ATENDE","ATENDE"))) -> NÃO ATENDE | CF7: =IF(BY7="-","-",IF(CA7>=(CC7),"ATENDE",IF(CA7>=(0.99*CC7),"ATENDIMENTO LIMIAR","NÃO ATENDE"))) -> NÃO ATENDE | CG7: =IF(BY7="-","-",IF(CB7>=CD7,"ATENDE","NÃO ATENDE")) -> NÃO ATENDE | CH7: =_xlfn.XLOOKUP(CI7,'Banco de dados'!$B:$B,'Banco de dados'!$D:$D) -> #N/A | CJ7: =_xlfn.XLOOKUP(CI7,'Banco de dados'!$B:$B,'Banco de dados'!$E:$E) -> #N/A | CL7: =IF(CK7="-","-",_xlfn.XLOOKUP(CK7,'Banco de dados'!$B:$B,'Banco de dados'!$E:$E)) -> #N/A | CM7: =AE7 -> 1 | CN7: =_xlfn.XLOOKUP(CI7,'Banco de dados'!$B:$B,'Banco de dados'!$H:$H) -> 0 | CO7: {=_xludf.XLOOKUP(CK7,'Banco de dados'!$B:$B,'Banco de dados'!$H:$H)} -> #NAME? | CP7: {=_xludf.XLOOKUP(CI7,'Banco de dados'!$B:$B,'Banco de dados'!$F:$F)} -> #NAME? | CQ7: {=_xludf.XLOOKUP(CK7,'Banco de dados'!$B:$B,'Banco de dados'!$F:$F)} -> #NAME? | CR7: 0 | CT7: =IF(AG7=0.5,"Suporte",IF(AND(AG7>='Braços de IP'!$B$9,AG7<='Braços de IP'!$D$9),'Braços de IP'!$E$9,IF(AND(AG7>='Braços de IP'!$B$10,AG7<='Braços de IP'!$D$10),'Braços de IP'!$E$10,IF(AND(AG7>='Braços de IP'!$B$11,AG7<='Braços de IP'!$D$11),'Braços de IP'!$E$11,IF(AND(AG7>='Braços de IP'!$B$12,AG7<='Braços de IP'!$D$12),'Braços de IP'!$E$12,IF(AND(AG7>='Braços de IP'!$B$13,AG7<='Braços de IP'!$D$13),'Braços de IP'!$E$13,IF(AND(AG7>='Braços de IP'!$B$14,AG7<='Braços de IP'!$D$14),'Braços de IP'!$E$14,"ERRO"))))))) -> Médio II | CV7: =IF($CU7="","",VLOOKUP($CU7,'Braços de IP'!$E$9:$I$15,2,0)) | CW7: =IF($CU7="","",VLOOKUP($CU7,'Braços de IP'!$E$9:$I$15,5,0)) | DD7: =CN7 -> 0 | DE7: =K7 -> 96 | DF7: =SUM(DD7:DE7)*CM7 -> 96 | DG7: =1-DD7/DE7 -> 1 | DK7: Sim | DN7: =((K7+L7)-CN7)/(K7+L7) -> #VALUE! | DP7: V4 | DQ7: =COUNTIF(G:G,DP7)/3 -> 0 | DR7: =DQ7/$DQ$434 -> #DIV/0! | DS7: =DQ7/SUM($DQ$326:$DQ$353) -> #DIV/0!
A8: Verificar preenchimento de dados como largura dos passeios e pista, | B8: 39 | C8: PVP | D8: Avenida Conselheiro Rosa E Silva | E8: -8.048481 | F8: -34.896669 | G8: P5 | H8: - | I8: P5 | J8: LED | K8: 115 | L8: Interno | M8: 0 | N8: =K8*AE8*2 -> 460 | O8: 3 | V8: 0 | Y8: 0 | Z8: 0 | AA8: Bilateral frontal | AB8: Braço | AC8: 50.6 | AD8: 7.9 | AE8: 2 | AF8: 0.77 | AG8: 2.63 | AH8: =AG8-AF8 -> 1.86 | AI8: - | AJ8: - | AK8: Não | AL8: =IF(AA8="Unilateral",2*AE8,IF(AA8="Bilateral Alternada",3*AE8,IF(AA8="Bilateral Frontal",4*AE8,IF(AA8="Canteiro Central",2*AE8,"erro")))) -> 8 | AM8: 0 | AO8: 0 | AP8: 0 | AQ8: 0 | AR8: - | AS8: =IF(AM8=0,0,IF(AA8="Unilateral",2*AM8,IF(AA8="Bilateral Alternada",3*AM8,IF(AA8="Bilateral Frontal",4*AM8,IF(AA8="Canteiro Central",2*AM8,"erro"))))) -> 0 | AU8: =VLOOKUP(G8,ABNT5101!$I$3:$J$9,2) -> 7.5 | AV8: =VLOOKUP(G8,ABNT5101!$I$3:$M$9,5) -> 0.18 | AW8: =_xlfn.XLOOKUP(G8,ABNT5101!I:I,ABNT5101!L:L) -> - | AX8: =_xlfn.XLOOKUP(G8,ABNT5101!$I:$I,ABNT5101!M:M) -> - | AY8: =_xlfn.XLOOKUP(G8,ABNT5101!$I:$I,ABNT5101!N:N) -> - | AZ8: =_xlfn.XLOOKUP(G8,ABNT5101!$I:$I,ABNT5101!O:O) -> - | BA8: =IF(BK8="NÃO ATENDE","NÃO ATENDE",IF(BV8="NÃO ATENDE","NÃO ATENDE",IF(CE8="NÃO ATENDE","NÃO ATENDE","ATENDE"))) -> NÃO ATENDE | BB8: =BE8/AU8-1 -> -1 | BC8: =BF8/AV8-1 -> -1 | BD8: =IF($G8="M6",BG8/AW8-1,"-") -> - | BK8: =IF(OR(BL8="NÃO ATENDE",BM8="NÃO ATENDE",BN8="NÃO ATENDE"),"NÃO ATENDE","ATENDE") -> NÃO ATENDE | BL8: =IF(BE8>=AU8,"ATENDE",IF(BE8>=0.99*AU8,"ATENDIMENTO LIMIAR","NÃO ATENDE")) -> NÃO ATENDE | BM8: =IF(BF8>=AV8,"ATENDE",IF(BF8>=(AV8-0.02),"ATENDIMENTO LIMIAR","NÃO ATENDE")) -> NÃO ATENDE | BN8: =IF(AW8="-","ATENDE",IF(BG8>=AW8,"ATENDE",IF(BG8>=(AW8-0.02),"ATENDIMENTO LIMIAR","NÃO ATENDE"))) -> ATENDE | BO8: =G8 -> P5 | BP8: =I8 -> P5 | BQ8: =IF(BR8="-","-",BR8/BT8-1) -> -1 | BT8: =IF(BP8="-","-",_xlfn.XLOOKUP(BP8,ABNT5101!$B$4:$B$9,ABNT5101!$C$4:$C$9)) -> 5 | BU8: =IF(BP8="-","-",_xlfn.XLOOKUP(BP8,ABNT5101!$B$4:$B$9,ABNT5101!$D$4:$D$9)) -> 1 | BV8: =IF(BW8="-","-",IF(BW8="NÃO ATENDE","NÃO ATENDE",IF(BX8="NÃO ATENDE","NÃO ATENDE","ATENDE"))) -> NÃO ATENDE | BW8: =IF(BP8="-","-",IF(BR8>=BT8,"ATENDE",IF(BR8>=(BT8*0.99),"ATENDIMENTO LIMIAR","NÃO ATENDE"))) -> NÃO ATENDE | BX8: =IF(BP8="-","-",IF(BS8>=BU8,"ATENDE","NÃO ATENDE")) -> NÃO ATENDE | BY8: =BP8 -> P5 | BZ8: =IF(CA8="-","-",CA8/CC8-1) -> -1 | CC8: =IF(BY8="-","-",_xlfn.XLOOKUP(BY8,ABNT5101!$B$4:$B$9,ABNT5101!$C$4:$C$9)) -> 5 | CD8: =IF(BY8="-","-",_xlfn.XLOOKUP(BY8,ABNT5101!$B$4:$B$9,ABNT5101!$D$4:$D$9)) -> 1 | CE8: =IF(CF8="-","-",IF(CF8="NÃO ATENDE","NÃO ATENDE",IF(CG8="NÃO ATENDE","NÃO ATENDE","ATENDE"))) -> NÃO ATENDE | CF8: =IF(BY8="-","-",IF(CA8>=(CC8),"ATENDE",IF(CA8>=(0.99*CC8),"ATENDIMENTO LIMIAR","NÃO ATENDE"))) -> NÃO ATENDE | CG8: =IF(BY8="-","-",IF(CB8>=CD8,"ATENDE","NÃO ATENDE")) -> NÃO ATENDE | CH8: =_xlfn.XLOOKUP(CI8,'Banco de dados'!$B:$B,'Banco de dados'!$D:$D) -> #N/A | CJ8: =_xlfn.XLOOKUP(CI8,'Banco de dados'!$B:$B,'Banco de dados'!$E:$E) -> #N/A | CL8: =IF(CK8="-","-",_xlfn.XLOOKUP(CK8,'Banco de dados'!$B:$B,'Banco de dados'!$E:$E)) -> #N/A | CM8: =AE8 -> 2 | CN8: =_xlfn.XLOOKUP(CI8,'Banco de dados'!$B:$B,'Banco de dados'!$H:$H) -> 0 | CO8: {=_xludf.XLOOKUP(CK8,'Banco de dados'!$B:$B,'Banco de dados'!$H:$H)} -> #NAME? | CP8: {=_xludf.XLOOKUP(CI8,'Banco de dados'!$B:$B,'Banco de dados'!$F:$F)} -> #NAME? | CQ8: {=_xludf.XLOOKUP(CK8,'Banco de dados'!$B:$B,'Banco de dados'!$F:$F)} -> #NAME? | CR8: 0 | CT8: =IF(AG8=0.5,"Suporte",IF(AND(AG8>='Braços de IP'!$B$9,AG8<='Braços de IP'!$D$9),'Braços de IP'!$E$9,IF(AND(AG8>='Braços de IP'!$B$10,AG8<='Braços de IP'!$D$10),'Braços de IP'!$E$10,IF(AND(AG8>='Braços de IP'!$B$11,AG8<='Braços de IP'!$D$11),'Braços de IP'!$E$11,IF(AND(AG8>='Braços de IP'!$B$12,AG8<='Braços de IP'!$D$12),'Braços de IP'!$E$12,IF(AND(AG8>='Braços de IP'!$B$13,AG8<='Braços de IP'!$D$13),'Braços de IP'!$E$13,IF(AND(AG8>='Braços de IP'!$B$14,AG8<='Braços de IP'!$D$14),'Braços de IP'!$E$14,"ERRO"))))))) -> Longo I | CV8: =IF($CU8="","",VLOOKUP($CU8,'Braços de IP'!$E$9:$I$15,2,0)) | CW8: =IF($CU8="","",VLOOKUP($CU8,'Braços de IP'!$E$9:$I$15,5,0)) | DD8: =CN8 -> 0 | DE8: =K8 -> 115 | DF8: =SUM(DD8:DE8)*CM8 -> 230 | DG8: =1-DD8/DE8 -> 1 | DK8: Sim | DN8: =((K8+L8)-CN8)/(K8+L8) -> #VALUE! | DP8: V4 | DQ8: =COUNTIF(G:G,DP8)/3 -> 0 | DR8: =DQ8/$DQ$434 -> #DIV/0! | DS8: =DQ8/SUM($DQ$326:$DQ$353) -> #DIV/0!
A9: Verificar preenchimento de dados como largura dos passeios e pista, | B9: 39 | C9: PVP | D9: Avenida Conselheiro Rosa E Silva | E9: -8.048481 | F9: -34.896669 | G9: P5 | H9: - | I9: P5 | J9: LED | K9: 115 | L9: Interno | M9: 0 | N9: =K9*AE9*2 -> 460 | O9: 3 | V9: 0 | Y9: 0 | Z9: 0 | AA9: Bilateral frontal | AB9: Braço | AC9: 50.6 | AD9: 7.9 | AE9: 2 | AF9: 0.77 | AG9: 2.63 | AH9: =AG9-AF9 -> 1.86 | AI9: - | AJ9: - | AK9: Não | AL9: =IF(AA9="Unilateral",2*AE9,IF(AA9="Bilateral Alternada",3*AE9,IF(AA9="Bilateral Frontal",4*AE9,IF(AA9="Canteiro Central",2*AE9,"erro")))) -> 8 | AM9: 0 | AO9: 0 | AP9: 0 | AQ9: 0 | AR9: - | AS9: =IF(AM9=0,0,IF(AA9="Unilateral",2*AM9,IF(AA9="Bilateral Alternada",3*AM9,IF(AA9="Bilateral Frontal",4*AM9,IF(AA9="Canteiro Central",2*AM9,"erro"))))) -> 0 | AU9: =VLOOKUP(G9,ABNT5101!$I$3:$J$9,2) -> 7.5 | AV9: =VLOOKUP(G9,ABNT5101!$I$3:$M$9,5) -> 0.18 | AW9: =_xlfn.XLOOKUP(G9,ABNT5101!I:I,ABNT5101!L:L) -> - | AX9: =_xlfn.XLOOKUP(G9,ABNT5101!$I:$I,ABNT5101!M:M) -> - | AY9: =_xlfn.XLOOKUP(G9,ABNT5101!$I:$I,ABNT5101!N:N) -> - | AZ9: =_xlfn.XLOOKUP(G9,ABNT5101!$I:$I,ABNT5101!O:O) -> - | BA9: =IF(BK9="NÃO ATENDE","NÃO ATENDE",IF(BV9="NÃO ATENDE","NÃO ATENDE",IF(CE9="NÃO ATENDE","NÃO ATENDE","ATENDE"))) -> NÃO ATENDE | BB9: =BE9/AU9-1 -> -1 | BC9: =BF9/AV9-1 -> -1 | BD9: =IF($G9="M6",BG9/AW9-1,"-") -> - | BK9: =IF(OR(BL9="NÃO ATENDE",BM9="NÃO ATENDE",BN9="NÃO ATENDE"),"NÃO ATENDE","ATENDE") -> NÃO ATENDE | BL9: =IF(BE9>=AU9,"ATENDE",IF(BE9>=0.99*AU9,"ATENDIMENTO LIMIAR","NÃO ATENDE")) -> NÃO ATENDE | BM9: =IF(BF9>=AV9,"ATENDE",IF(BF9>=(AV9-0.02),"ATENDIMENTO LIMIAR","NÃO ATENDE")) -> NÃO ATENDE | BN9: =IF(AW9="-","ATENDE",IF(BG9>=AW9,"ATENDE",IF(BG9>=(AW9-0.02),"ATENDIMENTO LIMIAR","NÃO ATENDE"))) -> ATENDE | BO9: =G9 -> P5 | BP9: =I9 -> P5 | BQ9: =IF(BR9="-","-",BR9/BT9-1) -> -1 | BT9: =IF(BP9="-","-",_xlfn.XLOOKUP(BP9,ABNT5101!$B$4:$B$9,ABNT5101!$C$4:$C$9)) -> 5 | BU9: =IF(BP9="-","-",_xlfn.XLOOKUP(BP9,ABNT5101!$B$4:$B$9,ABNT5101!$D$4:$D$9)) -> 1 | BV9: =IF(BW9="-","-",IF(BW9="NÃO ATENDE","NÃO ATENDE",IF(BX9="NÃO ATENDE","NÃO ATENDE","ATENDE"))) -> NÃO ATENDE | BW9: =IF(BP9="-","-",IF(BR9>=BT9,"ATENDE",IF(BR9>=(BT9*0.99),"ATENDIMENTO LIMIAR","NÃO ATENDE"))) -> NÃO ATENDE | BX9: =IF(BP9="-","-",IF(BS9>=BU9,"ATENDE","NÃO ATENDE")) -> NÃO ATENDE | BY9: =BP9 -> P5 | BZ9: =IF(CA9="-","-",CA9/CC9-1) -> -1 | CC9: =IF(BY9="-","-",_xlfn.XLOOKUP(BY9,ABNT5101!$B$4:$B$9,ABNT5101!$C$4:$C$9)) -> 5 | CD9: =IF(BY9="-","-",_xlfn.XLOOKUP(BY9,ABNT5101!$B$4:$B$9,ABNT5101!$D$4:$D$9)) -> 1 | CE9: =IF(CF9="-","-",IF(CF9="NÃO ATENDE","NÃO ATENDE",IF(CG9="NÃO ATENDE","NÃO ATENDE","ATENDE"))) -> NÃO ATENDE | CF9: =IF(BY9="-","-",IF(CA9>=(CC9),"ATENDE",IF(CA9>=(0.99*CC9),"ATENDIMENTO LIMIAR","NÃO ATENDE"))) -> NÃO ATENDE | CG9: =IF(BY9="-","-",IF(CB9>=CD9,"ATENDE","NÃO ATENDE")) -> NÃO ATENDE | CH9: =_xlfn.XLOOKUP(CI9,'Banco de dados'!$B:$B,'Banco de dados'!$D:$D) -> #N/A | CJ9: =_xlfn.XLOOKUP(CI9,'Banco de dados'!$B:$B,'Banco de dados'!$E:$E) -> #N/A | CL9: =IF(CK9="-","-",_xlfn.XLOOKUP(CK9,'Banco de dados'!$B:$B,'Banco de dados'!$E:$E)) -> #N/A | CM9: =AE9 -> 2 | CN9: =_xlfn.XLOOKUP(CI9,'Banco de dados'!$B:$B,'Banco de dados'!$H:$H) -> 0 | CO9: {=_xludf.XLOOKUP(CK9,'Banco de dados'!$B:$B,'Banco de dados'!$H:$H)} -> #NAME? | CP9: {=_xludf.XLOOKUP(CI9,'Banco de dados'!$B:$B,'Banco de dados'!$F:$F)} -> #NAME? | CQ9: {=_xludf.XLOOKUP(CK9,'Banco de dados'!$B:$B,'Banco de dados'!$F:$F)} -> #NAME? | CR9: 0 | CT9: =IF(AG9=0.5,"Suporte",IF(AND(AG9>='Braços de IP'!$B$9,AG9<='Braços de IP'!$D$9),'Braços de IP'!$E$9,IF(AND(AG9>='Braços de IP'!$B$10,AG9<='Braços de IP'!$D$10),'Braços de IP'!$E$10,IF(AND(AG9>='Braços de IP'!$B$11,AG9<='Braços de IP'!$D$11),'Braços de IP'!$E$11,IF(AND(AG9>='Braços de IP'!$B$12,AG9<='Braços de IP'!$D$12),'Braços de IP'!$E$12,IF(AND(AG9>='Braços de IP'!$B$13,AG9<='Braços de IP'!$D$13),'Braços de IP'!$E$13,IF(AND(AG9>='Braços de IP'!$B$14,AG9<='Braços de IP'!$D$14),'Braços de IP'!$E$14,"ERRO"))))))) -> Longo I | CV9: =IF($CU9="","",VLOOKUP($CU9,'Braços de IP'!$E$9:$I$15,2,0)) | CW9: =IF($CU9="","",VLOOKUP($CU9,'Braços de IP'!$E$9:$I$15,5,0)) | DD9: =CN9 -> 0 | DE9: =K9 -> 115 | DF9: =SUM(DD9:DE9)*CM9 -> 230 | DG9: =1-DD9/DE9 -> 1 | DK9: Sim | DN9: =((K9+L9)-CN9)/(K9+L9) -> #VALUE! | DP9: V4 | DQ9: =COUNTIF(G:G,DP9)/3 -> 0 | DR9: =DQ9/$DQ$434 -> #DIV/0! | DS9: =DQ9/SUM($DQ$326:$DQ$353) -> #DIV/0!
A10: Verificar preenchimento de dados como largura dos passeios e pista, | B10: 39 | C10: PVP | D10: Avenida Conselheiro Rosa E Silva | E10: -8.048481 | F10: -34.896669 | G10: P5 | H10: - | I10: P5 | J10: LED | K10: 115 | L10: Interno | M10: 0 | N10: =K10*AE10*2 -> 460 | O10: 3 | V10: 0 | Y10: 0 | Z10: 0 | AA10: Bilateral frontal | AB10: Braço | AC10: 50.6 | AD10: 7.9 | AE10: 2 | AF10: 0.77 | AG10: 2.63 | AH10: =AG10-AF10 -> 1.86 | AI10: - | AJ10: - | AK10: Não | AL10: =IF(AA10="Unilateral",2*AE10,IF(AA10="Bilateral Alternada",3*AE10,IF(AA10="Bilateral Frontal",4*AE10,IF(AA10="Canteiro Central",2*AE10,"erro")))) -> 8 | AM10: 0 | AO10: 0 | AP10: 0 | AQ10: 0 | AR10: - | AS10: =IF(AM10=0,0,IF(AA10="Unilateral",2*AM10,IF(AA10="Bilateral Alternada",3*AM10,IF(AA10="Bilateral Frontal",4*AM10,IF(AA10="Canteiro Central",2*AM10,"erro"))))) -> 0 | AU10: =VLOOKUP(G10,ABNT5101!$I$3:$J$9,2) -> 7.5 | AV10: =VLOOKUP(G10,ABNT5101!$I$3:$M$9,5) -> 0.18 | AW10: =_xlfn.XLOOKUP(G10,ABNT5101!I:I,ABNT5101!L:L) -> - | AX10: =_xlfn.XLOOKUP(G10,ABNT5101!$I:$I,ABNT5101!M:M) -> - | AY10: =_xlfn.XLOOKUP(G10,ABNT5101!$I:$I,ABNT5101!N:N) -> - | AZ10: =_xlfn.XLOOKUP(G10,ABNT5101!$I:$I,ABNT5101!O:O) -> - | BA10: =IF(BK10="NÃO ATENDE","NÃO ATENDE",IF(BV10="NÃO ATENDE","NÃO ATENDE",IF(CE10="NÃO ATENDE","NÃO ATENDE","ATENDE"))) -> NÃO ATENDE | BB10: =BE10/AU10-1 -> -1 | BC10: =BF10/AV10-1 -> -1 | BD10: =IF($G10="M6",BG10/AW10-1,"-") -> - | BK10: =IF(OR(BL10="NÃO ATENDE",BM10="NÃO ATENDE",BN10="NÃO ATENDE"),"NÃO ATENDE","ATENDE") -> NÃO ATENDE | BL10: =IF(BE10>=AU10,"ATENDE",IF(BE10>=0.99*AU10,"ATENDIMENTO LIMIAR","NÃO ATENDE")) -> NÃO ATENDE | BM10: =IF(BF10>=AV10,"ATENDE",IF(BF10>=(AV10-0.02),"ATENDIMENTO LIMIAR","NÃO ATENDE")) -> NÃO ATENDE | BN10: =IF(AW10="-","ATENDE",IF(BG10>=AW10,"ATENDE",IF(BG10>=(AW10-0.02),"ATENDIMENTO LIMIAR","NÃO ATENDE"))) -> ATENDE | BO10: =G10 -> P5 | BP10: =I10 -> P5 | BQ10: =IF(BR10="-","-",BR10/BT10-1) -> -1 | BT10: =IF(BP10="-","-",_xlfn.XLOOKUP(BP10,ABNT5101!$B$4:$B$9,ABNT5101!$C$4:$C$9)) -> 5 | BU10: =IF(BP10="-","-",_xlfn.XLOOKUP(BP10,ABNT5101!$B$4:$B$9,ABNT5101!$D$4:$D$9)) -> 1 | BV10: =IF(BW10="-","-",IF(BW10="NÃO ATENDE","NÃO ATENDE",IF(BX10="NÃO ATENDE","NÃO ATENDE","ATENDE"))) -> NÃO ATENDE | BW10: =IF(BP10="-","-",IF(BR10>=BT10,"ATENDE",IF(BR10>=(BT10*0.99),"ATENDIMENTO LIMIAR","NÃO ATENDE"))) -> NÃO ATENDE | BX10: =IF(BP10="-","-",IF(BS10>=BU10,"ATENDE","NÃO ATENDE")) -> NÃO ATENDE | BY10: =BP10 -> P5 | BZ10: =IF(CA10="-","-",CA10/CC10-1) -> -1 | CC10: =IF(BY10="-","-",_xlfn.XLOOKUP(BY10,ABNT5101!$B$4:$B$9,ABNT5101!$C$4:$C$9)) -> 5 | CD10: =IF(BY10="-","-",_xlfn.XLOOKUP(BY10,ABNT5101!$B$4:$B$9,ABNT5101!$D$4:$D$9)) -> 1 | CE10: =IF(CF10="-","-",IF(CF10="NÃO ATENDE","NÃO ATENDE",IF(CG10="NÃO ATENDE","NÃO ATENDE","ATENDE"))) -> NÃO ATENDE | CF10: =IF(BY10="-","-",IF(CA10>=(CC10),"ATENDE",IF(CA10>=(0.99*CC10),"ATENDIMENTO LIMIAR","NÃO ATENDE"))) -> NÃO ATENDE | CG10: =IF(BY10="-","-",IF(CB10>=CD10,"ATENDE","NÃO ATENDE")) -> NÃO ATENDE | CH10: =_xlfn.XLOOKUP(CI10,'Banco de dados'!$B:$B,'Banco de dados'!$D:$D) -> #N/A | CJ10: =_xlfn.XLOOKUP(CI10,'Banco de dados'!$B:$B,'Banco de dados'!$E:$E) -> #N/A | CL10: =IF(CK10="-","-",_xlfn.XLOOKUP(CK10,'Banco de dados'!$B:$B,'Banco de dados'!$E:$E)) -> #N/A | CM10: =AE10 -> 2 | CN10: =_xlfn.XLOOKUP(CI10,'Banco de dados'!$B:$B,'Banco de dados'!$H:$H) -> 0 | CO10: {=_xludf.XLOOKUP(CK10,'Banco de dados'!$B:$B,'Banco de dados'!$H:$H)} -> #NAME? | CP10: {=_xludf.XLOOKUP(CI10,'Banco de dados'!$B:$B,'Banco de dados'!$F:$F)} -> #NAME? | CQ10: {=_xludf.XLOOKUP(CK10,'Banco de dados'!$B:$B,'Banco de dados'!$F:$F)} -> #NAME? | CR10: 0 | CT10: =IF(AG10=0.5,"Suporte",IF(AND(AG10>='Braços de IP'!$B$9,AG10<='Braços de IP'!$D$9),'Braços de IP'!$E$9,IF(AND(AG10>='Braços de IP'!$B$10,AG10<='Braços de IP'!$D$10),'Braços de IP'!$E$10,IF(AND(AG10>='Braços de IP'!$B$11,AG10<='Braços de IP'!$D$11),'Braços de IP'!$E$11,IF(AND(AG10>='Braços de IP'!$B$12,AG10<='Braços de IP'!$D$12),'Braços de IP'!$E$12,IF(AND(AG10>='Braços de IP'!$B$13,AG10<='Braços de IP'!$D$13),'Braços de IP'!$E$13,IF(AND(AG10>='Braços de IP'!$B$14,AG10<='Braços de IP'!$D$14),'Braços de IP'!$E$14,"ERRO"))))))) -> Longo I | CV10: =IF($CU10="","",VLOOKUP($CU10,'Braços de IP'!$E$9:$I$15,2,0)) | CW10: =IF($CU10="","",VLOOKUP($CU10,'Braços de IP'!$E$9:$I$15,5,0)) | DD10: =CN10 -> 0 | DE10: =K10 -> 115 | DF10: =SUM(DD10:DE10)*CM10 -> 230 | DG10: =1-DD10/DE10 -> 1 | DK10: Sim | DN10: =((K10+L10)-CN10)/(K10+L10) -> #VALUE! | DP10: V4 | DQ10: =COUNTIF(G:G,DP10)/3 -> 0 | DR10: =DQ10/$DQ$434 -> #DIV/0! | DS10: =DQ10/SUM($DQ$326:$DQ$353) -> #DIV/0!
A11: Verificar preenchimento de dados como largura dos passeios e pista, | B11: 40 | C11: PVP | D11: Rua Das Pernambucanas | E11: -8.050931 | F11: -34.901654 | G11: P6 | H11: - | I11: P6 | J11: LED | K11: 90 | L11: Interno | M11: 0 | N11: =K11*AE11*2 -> 180 | O11: 2 | V11: 0 | Y11: 1.59 | Z11: 0 | AA11: Unilateral | AB11: Braço | AC11: 38.3 | AD11: 6.66 | AE11: 1 | AF11: 0.5 | AG11: 2.67 | AH11: =AG11-AF11 -> 2.17 | AI11: - | AJ11: - | AK11: Não | AL11: =IF(AA11="Unilateral",2*AE11,IF(AA11="Bilateral Alternada",3*AE11,IF(AA11="Bilateral Frontal",4*AE11,IF(AA11="Canteiro Central",2*AE11,"erro")))) -> 2 | AM11: 0 | AO11: 0 | AP11: 0 | AQ11: 0 | AR11: - | AS11: =IF(AM11=0,0,IF(AA11="Unilateral",2*AM11,IF(AA11="Bilateral Alternada",3*AM11,IF(AA11="Bilateral Frontal",4*AM11,IF(AA11="Canteiro Central",2*AM11,"erro"))))) -> 0 | AU11: =VLOOKUP(G11,ABNT5101!$I$3:$J$9,2) -> 7.5 | AV11: =VLOOKUP(G11,ABNT5101!$I$3:$M$9,5) -> 0.18 | AW11: =_xlfn.XLOOKUP(G11,ABNT5101!I:I,ABNT5101!L:L) -> - | AX11: =_xlfn.XLOOKUP(G11,ABNT5101!$I:$I,ABNT5101!M:M) -> - | AY11: =_xlfn.XLOOKUP(G11,ABNT5101!$I:$I,ABNT5101!N:N) -> - | AZ11: =_xlfn.XLOOKUP(G11,ABNT5101!$I:$I,ABNT5101!O:O) -> - | BA11: =IF(BK11="NÃO ATENDE","NÃO ATENDE",IF(BV11="NÃO ATENDE","NÃO ATENDE",IF(CE11="NÃO ATENDE","NÃO ATENDE","ATENDE"))) -> NÃO ATENDE | BB11: =BE11/AU11-1 -> -1 | BC11: =BF11/AV11-1 -> -1 | BD11: =IF($G11="M6",BG11/AW11-1,"-") -> - | BK11: =IF(OR(BL11="NÃO ATENDE",BM11="NÃO ATENDE",BN11="NÃO ATENDE"),"NÃO ATENDE","ATENDE") -> NÃO ATENDE | BL11: =IF(BE11>=AU11,"ATENDE",IF(BE11>=0.99*AU11,"ATENDIMENTO LIMIAR","NÃO ATENDE")) -> NÃO ATENDE | BM11: =IF(BF11>=AV11,"ATENDE",IF(BF11>=(AV11-0.02),"ATENDIMENTO LIMIAR","NÃO ATENDE")) -> NÃO ATENDE | BN11: =IF(AW11="-","ATENDE",IF(BG11>=AW11,"ATENDE",IF(BG11>=(AW11-0.02),"ATENDIMENTO LIMIAR","NÃO ATENDE"))) -> ATENDE | BO11: =G11 -> P6 | BP11: =I11 -> P6 | BQ11: =IF(BR11="-","-",BR11/BT11-1) -> -1 | BT11: =IF(BP11="-","-",_xlfn.XLOOKUP(BP11,ABNT5101!$B$4:$B$9,ABNT5101!$C$4:$C$9)) -> 3 | BU11: =IF(BP11="-","-",_xlfn.XLOOKUP(BP11,ABNT5101!$B$4:$B$9,ABNT5101!$D$4:$D$9)) -> 0.6 | BV11: =IF(BW11="-","-",IF(BW11="NÃO ATENDE","NÃO ATENDE",IF(BX11="NÃO ATENDE","NÃO ATENDE","ATENDE"))) -> NÃO ATENDE | BW11: =IF(BP11="-","-",IF(BR11>=BT11,"ATENDE",IF(BR11>=(BT11*0.99),"ATENDIMENTO LIMIAR","NÃO ATENDE"))) -> NÃO ATENDE | BX11: =IF(BP11="-","-",IF(BS11>=BU11,"ATENDE","NÃO ATENDE")) -> NÃO ATENDE | BY11: =BP11 -> P6 | BZ11: =IF(CA11="-","-",CA11/CC11-1) -> -1 | CC11: =IF(BY11="-","-",_xlfn.XLOOKUP(BY11,ABNT5101!$B$4:$B$9,ABNT5101!$C$4:$C$9)) -> 3 | CD11: =IF(BY11="-","-",_xlfn.XLOOKUP(BY11,ABNT5101!$B$4:$B$9,ABNT5101!$D$4:$D$9)) -> 0.6 | CE11: =IF(CF11="-","-",IF(CF11="NÃO ATENDE","NÃO ATENDE",IF(CG11="NÃO ATENDE","NÃO ATENDE","ATENDE"))) -> NÃO ATENDE | CF11: =IF(BY11="-","-",IF(CA11>=(CC11),"ATENDE",IF(CA11>=(0.99*CC11),"ATENDIMENTO LIMIAR","NÃO ATENDE"))) -> NÃO ATENDE | CG11: =IF(BY11="-","-",IF(CB11>=CD11,"ATENDE","NÃO ATENDE")) -> NÃO ATENDE | CH11: =_xlfn.XLOOKUP(CI11,'Banco de dados'!$B:$B,'Banco de dados'!$D:$D) -> #N/A | CJ11: =_xlfn.XLOOKUP(CI11,'Banco de dados'!$B:$B,'Banco de dados'!$E:$E) -> #N/A | CL11: =IF(CK11="-","-",_xlfn.XLOOKUP(CK11,'Banco de dados'!$B:$B,'Banco de dados'!$E:$E)) -> #N/A | CM11: =AE11 -> 1 | CN11: =_xlfn.XLOOKUP(CI11,'Banco de dados'!$B:$B,'Banco de dados'!$H:$H) -> 0 | CO11: {=_xludf.XLOOKUP(CK11,'Banco de dados'!$B:$B,'Banco de dados'!$H:$H)} -> #NAME? | CP11: {=_xludf.XLOOKUP(CI11,'Banco de dados'!$B:$B,'Banco de dados'!$F:$F)} -> #NAME? | CQ11: {=_xludf.XLOOKUP(CK11,'Banco de dados'!$B:$B,'Banco de dados'!$F:$F)} -> #NAME? | CR11: 0 | CT11: =IF(AG11=0.5,"Suporte",IF(AND(AG11>='Braços de IP'!$B$9,AG11<='Braços de IP'!$D$9),'Braços de IP'!$E$9,IF(AND(AG11>='Braços de IP'!$B$10,AG11<='Braços de IP'!$D$10),'Braços de IP'!$E$10,IF(AND(AG11>='Braços de IP'!$B$11,AG11<='Braços de IP'!$D$11),'Braços de IP'!$E$11,IF(AND(AG11>='Braços de IP'!$B$12,AG11<='Braços de IP'!$D$12),'Braços de IP'!$E$12,IF(AND(AG11>='Braços de IP'!$B$13,AG11<='Braços de IP'!$D$13),'Braços de IP'!$E$13,IF(AND(AG11>='Braços de IP'!$B$14,AG11<='Braços de IP'!$D$14),'Braços de IP'!$E$14,"ERRO"))))))) -> Longo I | CV11: =IF($CU11="","",VLOOKUP($CU11,'Braços de IP'!$E$9:$I$15,2,0)) | CW11: =IF($CU11="","",VLOOKUP($CU11,'Braços de IP'!$E$9:$I$15,5,0)) | DD11: =CN11 -> 0 | DE11: =K11 -> 90 | DF11: =SUM(DD11:DE11)*CM11 -> 90 | DG11: =1-DD11/DE11 -> 1 | DK11: Sim | DN11: =((K11+L11)-CN11)/(K11+L11) -> #VALUE! | DP11: V5 | DQ11: =COUNTIF(G:G,DP11)/3 -> 0 | DR11: =DQ11/$DQ$434 -> #DIV/0! | DS11: =DQ11/SUM($DQ$326:$DQ$353) -> #DIV/0!
A12: Verificar preenchimento de dados como largura dos passeios e pista, | B12: 40 | C12: PVP | D12: Rua Das Pernambucanas | E12: -8.050931 | F12: -34.901654 | G12: P6 | H12: - | I12: P6 | J12: LED | K12: 90 | L12: Interno | M12: 0 | N12: =K12*AE12*2 -> 180 | O12: 2 | V12: 0 | Y12: 1.59 | Z12: 0 | AA12: Unilateral | AB12: Braço | AC12: 38.3 | AD12: 6.66 | AE12: 1 | AF12: 0.5 | AG12: 2.67 | AH12: =AG12-AF12 -> 2.17 | AI12: - | AJ12: - | AK12: Não | AL12: =IF(AA12="Unilateral",2*AE12,IF(AA12="Bilateral Alternada",3*AE12,IF(AA12="Bilateral Frontal",4*AE12,IF(AA12="Canteiro Central",2*AE12,"erro")))) -> 2 | AM12: 0 | AO12: 0 | AP12: 0 | AQ12: 0 | AR12: - | AS12: =IF(AM12=0,0,IF(AA12="Unilateral",2*AM12,IF(AA12="Bilateral Alternada",3*AM12,IF(AA12="Bilateral Frontal",4*AM12,IF(AA12="Canteiro Central",2*AM12,"erro"))))) -> 0 | AU12: =VLOOKUP(G12,ABNT5101!$I$3:$J$9,2) -> 7.5 | AV12: =VLOOKUP(G12,ABNT5101!$I$3:$M$9,5) -> 0.18 | AW12: =_xlfn.XLOOKUP(G12,ABNT5101!I:I,ABNT5101!L:L) -> - | AX12: =_xlfn.XLOOKUP(G12,ABNT5101!$I:$I,ABNT5101!M:M) -> - | AY12: =_xlfn.XLOOKUP(G12,ABNT5101!$I:$I,ABNT5101!N:N) -> - | AZ12: =_xlfn.XLOOKUP(G12,ABNT5101!$I:$I,ABNT5101!O:O) -> - | BA12: =IF(BK12="NÃO ATENDE","NÃO ATENDE",IF(BV12="NÃO ATENDE","NÃO ATENDE",IF(CE12="NÃO ATENDE","NÃO ATENDE","ATENDE"))) -> NÃO ATENDE | BB12: =BE12/AU12-1 -> -1 | BC12: =BF12/AV12-1 -> -1 | BD12: =IF($G12="M6",BG12/AW12-1,"-") -> - | BK12: =IF(OR(BL12="NÃO ATENDE",BM12="NÃO ATENDE",BN12="NÃO ATENDE"),"NÃO ATENDE","ATENDE") -> NÃO ATENDE | BL12: =IF(BE12>=AU12,"ATENDE",IF(BE12>=0.99*AU12,"ATENDIMENTO LIMIAR","NÃO ATENDE")) -> NÃO ATENDE | BM12: =IF(BF12>=AV12,"ATENDE",IF(BF12>=(AV12-0.02),"ATENDIMENTO LIMIAR","NÃO ATENDE")) -> NÃO ATENDE | BN12: =IF(AW12="-","ATENDE",IF(BG12>=AW12,"ATENDE",IF(BG12>=(AW12-0.02),"ATENDIMENTO LIMIAR","NÃO ATENDE"))) -> ATENDE | BO12: =G12 -> P6 | BP12: =I12 -> P6 | BQ12: =IF(BR12="-","-",BR12/BT12-1) -> -1 | BT12: =IF(BP12="-","-",_xlfn.XLOOKUP(BP12,ABNT5101!$B$4:$B$9,ABNT5101!$C$4:$C$9)) -> 3 | BU12: =IF(BP12="-","-",_xlfn.XLOOKUP(BP12,ABNT5101!$B$4:$B$9,ABNT5101!$D$4:$D$9)) -> 0.6 | BV12: =IF(BW12="-","-",IF(BW12="NÃO ATENDE","NÃO ATENDE",IF(BX12="NÃO ATENDE","NÃO ATENDE","ATENDE"))) -> NÃO ATENDE | BW12: =IF(BP12="-","-",IF(BR12>=BT12,"ATENDE",IF(BR12>=(BT12*0.99),"ATENDIMENTO LIMIAR","NÃO ATENDE"))) -> NÃO ATENDE | BX12: =IF(BP12="-","-",IF(BS12>=BU12,"ATENDE","NÃO ATENDE")) -> NÃO ATENDE | BY12: =BP12 -> P6 | BZ12: =IF(CA12="-","-",CA12/CC12-1) -> -1 | CC12: =IF(BY12="-","-",_xlfn.XLOOKUP(BY12,ABNT5101!$B$4:$B$9,ABNT5101!$C$4:$C$9)) -> 3 | CD12: =IF(BY12="-","-",_xlfn.XLOOKUP(BY12,ABNT5101!$B$4:$B$9,ABNT5101!$D$4:$D$9)) -> 0.6 | CE12: =IF(CF12="-","-",IF(CF12="NÃO ATENDE","NÃO ATENDE",IF(CG12="NÃO ATENDE","NÃO ATENDE","ATENDE"))) -> NÃO ATENDE | CF12: =IF(BY12="-","-",IF(CA12>=(CC12),"ATENDE",IF(CA12>=(0.99*CC12),"ATENDIMENTO LIMIAR","NÃO ATENDE"))) -> NÃO ATENDE | CG12: =IF(BY12="-","-",IF(CB12>=CD12,"ATENDE","NÃO ATENDE")) -> NÃO ATENDE | CH12: =_xlfn.XLOOKUP(CI12,'Banco de dados'!$B:$B,'Banco de dados'!$D:$D) -> #N/A | CJ12: =_xlfn.XLOOKUP(CI12,'Banco de dados'!$B:$B,'Banco de dados'!$E:$E) -> #N/A | CL12: =IF(CK12="-","-",_xlfn.XLOOKUP(CK12,'Banco de dados'!$B:$B,'Banco de dados'!$E:$E)) -> #N/A | CM12: =AE12 -> 1 | CN12: =_xlfn.XLOOKUP(CI12,'Banco de dados'!$B:$B,'Banco de dados'!$H:$H) -> 0 | CO12: {=_xludf.XLOOKUP(CK12,'Banco de dados'!$B:$B,'Banco de dados'!$H:$H)} -> #NAME? | CP12: {=_xludf.XLOOKUP(CI12,'Banco de dados'!$B:$B,'Banco de dados'!$F:$F)} -> #NAME? | CQ12: {=_xludf.XLOOKUP(CK12,'Banco de dados'!$B:$B,'Banco de dados'!$F:$F)} -> #NAME? | CR12: 0 | CT12: =IF(AG12=0.5,"Suporte",IF(AND(AG12>='Braços de IP'!$B$9,AG12<='Braços de IP'!$D$9),'Braços de IP'!$E$9,IF(AND(AG12>='Braços de IP'!$B$10,AG12<='Braços de IP'!$D$10),'Braços de IP'!$E$10,IF(AND(AG12>='Braços de IP'!$B$11,AG12<='Braços de IP'!$D$11),'Braços de IP'!$E$11,IF(AND(AG12>='Braços de IP'!$B$12,AG12<='Braços de IP'!$D$12),'Braços de IP'!$E$12,IF(AND(AG12>='Braços de IP'!$B$13,AG12<='Braços de IP'!$D$13),'Braços de IP'!$E$13,IF(AND(AG12>='Braços de IP'!$B$14,AG12<='Braços de IP'!$D$14),'Braços de IP'!$E$14,"ERRO"))))))) -> Longo I | CV12: =IF($CU12="","",VLOOKUP($CU12,'Braços de IP'!$E$9:$I$15,2,0)) | CW12: =IF($CU12="","",VLOOKUP($CU12,'Braços de IP'!$E$9:$I$15,5,0)) | DD12: =CN12 -> 0 | DE12: =K12 -> 90 | DF12: =SUM(DD12:DE12)*CM12 -> 90 | DG12: =1-DD12/DE12 -> 1 | DK12: Sim | DN12: =((K12+L12)-CN12)/(K12+L12) -> #VALUE! | DP12: V5 | DQ12: =COUNTIF(G:G,DP12)/3 -> 0 | DR12: =DQ12/$DQ$434 -> #DIV/0! | DS12: =DQ12/SUM($DQ$326:$DQ$353) -> #DIV/0!
A13: Verificar preenchimento de dados como largura dos passeios e pista, | B13: 40 | C13: PVP | D13: Rua Das Pernambucanas | E13: -8.050931 | F13: -34.901654 | G13: P6 | H13: - | I13: P6 | J13: LED | K13: 90 | L13: Interno | M13: 0 | N13: =K13*AE13*2 -> 180 | O13: 2 | V13: 0 | Y13: 1.59 | Z13: 0 | AA13: Unilateral | AB13: Braço | AC13: 38.3 | AD13: 6.66 | AE13: 1 | AF13: 0.5 | AG13: 2.67 | AH13: =AG13-AF13 -> 2.17 | AI13: - | AJ13: - | AK13: Não | AL13: =IF(AA13="Unilateral",2*AE13,IF(AA13="Bilateral Alternada",3*AE13,IF(AA13="Bilateral Frontal",4*AE13,IF(AA13="Canteiro Central",2*AE13,"erro")))) -> 2 | AM13: 0 | AO13: 0 | AP13: 0 | AQ13: 0 | AR13: - | AS13: =IF(AM13=0,0,IF(AA13="Unilateral",2*AM13,IF(AA13="Bilateral Alternada",3*AM13,IF(AA13="Bilateral Frontal",4*AM13,IF(AA13="Canteiro Central",2*AM13,"erro"))))) -> 0 | AU13: =VLOOKUP(G13,ABNT5101!$I$3:$J$9,2) -> 7.5 | AV13: =VLOOKUP(G13,ABNT5101!$I$3:$M$9,5) -> 0.18 | AW13: =_xlfn.XLOOKUP(G13,ABNT5101!I:I,ABNT5101!L:L) -> - | AX13: =_xlfn.XLOOKUP(G13,ABNT5101!$I:$I,ABNT5101!M:M) -> - | AY13: =_xlfn.XLOOKUP(G13,ABNT5101!$I:$I,ABNT5101!N:N) -> - | AZ13: =_xlfn.XLOOKUP(G13,ABNT5101!$I:$I,ABNT5101!O:O) -> - | BA13: =IF(BK13="NÃO ATENDE","NÃO ATENDE",IF(BV13="NÃO ATENDE","NÃO ATENDE",IF(CE13="NÃO ATENDE","NÃO ATENDE","ATENDE"))) -> NÃO ATENDE | BB13: =BE13/AU13-1 -> -1 | BC13: =BF13/AV13-1 -> -1 | BD13: =IF($G13="M6",BG13/AW13-1,"-") -> - | BK13: =IF(OR(BL13="NÃO ATENDE",BM13="NÃO ATENDE",BN13="NÃO ATENDE"),"NÃO ATENDE","ATENDE") -> NÃO ATENDE | BL13: =IF(BE13>=AU13,"ATENDE",IF(BE13>=0.99*AU13,"ATENDIMENTO LIMIAR","NÃO ATENDE")) -> NÃO ATENDE | BM13: =IF(BF13>=AV13,"ATENDE",IF(BF13>=(AV13-0.02),"ATENDIMENTO LIMIAR","NÃO ATENDE")) -> NÃO ATENDE | BN13: =IF(AW13="-","ATENDE",IF(BG13>=AW13,"ATENDE",IF(BG13>=(AW13-0.02),"ATENDIMENTO LIMIAR","NÃO ATENDE"))) -> ATENDE | BO13: =G13 -> P6 | BP13: =I13 -> P6 | BQ13: =IF(BR13="-","-",BR13/BT13-1) -> -1 | BT13: =IF(BP13="-","-",_xlfn.XLOOKUP(BP13,ABNT5101!$B$4:$B$9,ABNT5101!$C$4:$C$9)) -> 3 | BU13: =IF(BP13="-","-",_xlfn.XLOOKUP(BP13,ABNT5101!$B$4:$B$9,ABNT5101!$D$4:$D$9)) -> 0.6 | BV13: =IF(BW13="-","-",IF(BW13="NÃO ATENDE","NÃO ATENDE",IF(BX13="NÃO ATENDE","NÃO ATENDE","ATENDE"))) -> NÃO ATENDE | BW13: =IF(BP13="-","-",IF(BR13>=BT13,"ATENDE",IF(BR13>=(BT13*0.99),"ATENDIMENTO LIMIAR","NÃO ATENDE"))) -> NÃO ATENDE | BX13: =IF(BP13="-","-",IF(BS13>=BU13,"ATENDE","NÃO ATENDE")) -> NÃO ATENDE | BY13: =BP13 -> P6 | BZ13: =IF(CA13="-","-",CA13/CC13-1) -> -1 | CC13: =IF(BY13="-","-",_xlfn.XLOOKUP(BY13,ABNT5101!$B$4:$B$9,ABNT5101!$C$4:$C$9)) -> 3 | CD13: =IF(BY13="-","-",_xlfn.XLOOKUP(BY13,ABNT5101!$B$4:$B$9,ABNT5101!$D$4:$D$9)) -> 0.6 | CE13: =IF(CF13="-","-",IF(CF13="NÃO ATENDE","NÃO ATENDE",IF(CG13="NÃO ATENDE","NÃO ATENDE","ATENDE"))) -> NÃO ATENDE | CF13: =IF(BY13="-","-",IF(CA13>=(CC13),"ATENDE",IF(CA13>=(0.99*CC13),"ATENDIMENTO LIMIAR","NÃO ATENDE"))) -> NÃO ATENDE | CG13: =IF(BY13="-","-",IF(CB13>=CD13,"ATENDE","NÃO ATENDE")) -> NÃO ATENDE | CH13: =_xlfn.XLOOKUP(CI13,'Banco de dados'!$B:$B,'Banco de dados'!$D:$D) -> #N/A | CJ13: =_xlfn.XLOOKUP(CI13,'Banco de dados'!$B:$B,'Banco de dados'!$E:$E) -> #N/A | CL13: =IF(CK13="-","-",_xlfn.XLOOKUP(CK13,'Banco de dados'!$B:$B,'Banco de dados'!$E:$E)) -> #N/A | CM13: =AE13 -> 1 | CN13: =_xlfn.XLOOKUP(CI13,'Banco de dados'!$B:$B,'Banco de dados'!$H:$H) -> 0 | CO13: {=_xludf.XLOOKUP(CK13,'Banco de dados'!$B:$B,'Banco de dados'!$H:$H)} -> #NAME? | CP13: {=_xludf.XLOOKUP(CI13,'Banco de dados'!$B:$B,'Banco de dados'!$F:$F)} -> #NAME? | CQ13: {=_xludf.XLOOKUP(CK13,'Banco de dados'!$B:$B,'Banco de dados'!$F:$F)} -> #NAME? | CR13: 0 | CT13: =IF(AG13=0.5,"Suporte",IF(AND(AG13>='Braços de IP'!$B$9,AG13<='Braços de IP'!$D$9),'Braços de IP'!$E$9,IF(AND(AG13>='Braços de IP'!$B$10,AG13<='Braços de IP'!$D$10),'Braços de IP'!$E$10,IF(AND(AG13>='Braços de IP'!$B$11,AG13<='Braços de IP'!$D$11),'Braços de IP'!$E$11,IF(AND(AG13>='Braços de IP'!$B$12,AG13<='Braços de IP'!$D$12),'Braços de IP'!$E$12,IF(AND(AG13>='Braços de IP'!$B$13,AG13<='Braços de IP'!$D$13),'Braços de IP'!$E$13,IF(AND(AG13>='Braços de IP'!$B$14,AG13<='Braços de IP'!$D$14),'Braços de IP'!$E$14,"ERRO"))))))) -> Longo I | CV13: =IF($CU13="","",VLOOKUP($CU13,'Braços de IP'!$E$9:$I$15,2,0)) | CW13: =IF($CU13="","",VLOOKUP($CU13,'Braços de IP'!$E$9:$I$15,5,0)) | DD13: =CN13 -> 0 | DE13: =K13 -> 90 | DF13: =SUM(DD13:DE13)*CM13 -> 90 | DG13: =1-DD13/DE13 -> 1 | DK13: Sim | DN13: =((K13+L13)-CN13)/(K13+L13) -> #VALUE! | DP13: V5 | DQ13: =COUNTIF(G:G,DP13)/3 -> 0 | DR13: =DQ13/$DQ$434 -> #DIV/0! | DS13: =DQ13/SUM($DQ$326:$DQ$353) -> #DIV/0!
